Workbook

Sheet 2019 ALL D95
A1: ACARA | B1: FROM DATE | C1: TO DATE | D1: DEPT | E1: WORLD | F1: DIVISION | G1: CLASS | H1: SUPPLIER | I1: BRAND | J1: SKU | K1: ARTICLE | L1: DESCRIPTION | M1: HARGA NORMAL | N1: DISKON | O1: HARGA PROMO | P1: DISCOUNT TYPE
A2: 2019 ALL D95 | B2: 46099 | C2: 46113 | D2: 3272 | E2: 336 | F2: 4 | G2: 1 | H2: 81670 | I2: CHARACTER | J2: 24004104 | K2: RGBATMANWH | L2: 3/2 RAGLAN BATMAN LOGO:WHITE:5-6 | M2: 149900 | N2: 0.95 | O2: =M2*(1-N2) -> 7495 | P2: PERCENTAGE
A3: 2019 ALL D95 | B3: =B2 -> 46099 | C3: =C2 -> 46113 | D3: 3272 | E3: 336 | F3: 4 | G3: 1 | H3: 81670 | I3: CHARACTER | J3: 24004113 | K3: RGBATMANWH | L3: 3/2 RAGLAN BATMAN LOGO:WHITE:7-8 | M3: 149900 | N3: 0.95 | O3: =M3*(1-N3) -> 7495 | P3: PERCENTAGE
A4: 2019 ALL D95 | B4: =B3 -> 46099 | C4: =C3 -> 46113 | D4: 3272 | E4: 336 | F4: 4 | G4: 1 | H4: 81670 | I4: CHARACTER | J4: 24004122 | K4: RGBATMANWH | L4: 3/2 RAGLAN BATMAN LOGO:WHITE:9-10 | M4: 149900 | N4: 0.95 | O4: =M4*(1-N4) -> 7495 | P4: PERCENTAGE
A5: 2019 ALL D95 | B5: =B4 -> 46099 | C5: =C4 -> 46113 | D5: 3272 | E5: 336 | F5: 4 | G5: 1 | H5: 81670 | I5: CHARACTER | J5: 24151213 | K5: KSBAT2YL | L5: LS BATMAN LOGO KOSTUM PAKAI SAYAP:CLASSIC YELLOW:M | M5: 149900 | N5: 0.95 | O5: =M5*(1-N5) -> 7495 | P5: PERCENTAGE
A6: 2019 ALL D95 | B6: =B5 -> 46099 | C6: =C5 -> 46113 | D6: 3272 | E6: 336 | F6: 4 | G6: 1 | H6: 81670 | I6: CHARACTER | J6: 24414475 | K6: LSCBSPBU | L6: LS TSHIRT LAYER TANGAN CHIBBY SUPERMAN KOSTUM:CLASSIC BLUE:S | M6: 149900 | N6: 0.95 | O6: =M6*(1-N6) -> 7495 | P6: PERCENTAGE
A7: 2019 ALL D95 | B7: =B6 -> 46099 | C7: =C6 -> 46113 | D7: 3272 | E7: 336 | F7: 4 | G7: 1 | H7: 81670 | I7: CHARACTER | J7: 24414484 | K7: LSCBSPBU | L7: LS TSHIRT LAYER TANGAN CHIBBY SUPERMAN KOSTUM:CLASSIC BLUE:M | M7: 149900 | N7: 0.95 | O7: =M7*(1-N7) -> 7495 | P7: PERCENTAGE
A8: 2019 ALL D95 | B8: =B7 -> 46099 | C8: =C7 -> 46113 | D8: 3272 | E8: 336 | F8: 4 | G8: 1 | H8: 81670 | I8: CHARACTER | J8: 24414493 | K8: LSCBSPBU | L8: LS TSHIRT LAYER TANGAN CHIBBY SUPERMAN KOSTUM:CLASSIC BLUE:L | M8: 149900 | N8: 0.95 | O8: =M8*(1-N8) -> 7495 | P8: PERCENTAGE
A9: 2019 ALL D95 | B9: =B8 -> 46099 | C9: =C8 -> 46113 | D9: 3272 | E9: 336 | F9: 4 | G9: 1 | H9: 81588 | I9: CHARACTER | J9: 23204275 | K9: TRFW3B | L9: TS TRF OPTIMUS LOGO BULAT:MISTY MEDIUM BLUE:S | M9: 129900 | N9: 0.95 | O9: =M9*(1-N9) -> 6495 | P9: PERCENTAGE
A10: 2019 ALL D95 | B10: =B9 -> 46099 | C10: =C9 -> 46113 | D10: 3272 | E10: 336 | F10: 4 | G10: 1 | H10: 81588 | I10: CHARACTER | J10: 23204284 | K10: TRFW3B | L10: TS TRF OPTIMUS LOGO BULAT:MISTY MEDIUM BLUE:M | M10: 129900 | N10: 0.95 | O10: =M10*(1-N10) -> 6495 | P10: PERCENTAGE
A11: 2019 ALL D95 | B11: =B10 -> 46099 | C11: =C10 -> 46113 | D11: 3272 | E11: 336 | F11: 4 | G11: 1 | H11: 81588 | I11: CHARACTER | J11: 23204293 | K11: TRFW3B | L11: TS TRF OPTIMUS LOGO BULAT:MISTY MEDIUM BLUE:L | M11: 129900 | N11: 0.95 | O11: =M11*(1-N11) -> 6495 | P11: PERCENTAGE
A12: 2019 ALL D95 | B12: =B11 -> 46099 | C12: =C11 -> 46113 | D12: 3272 | E12: 336 | F12: 4 | G12: 1 | H12: 81588 | I12: CHARACTER | J12: 23204300 | K12: TRFW3B | L12: TS TRF OPTIMUS LOGO BULAT:MISTY MEDIUM BLUE:5-6 | M12: 129900 | N12: 0.95 | O12: =M12*(1-N12) -> 6495 | P12: PERCENTAGE
A13: 2019 ALL D95 | B13: =B12 -> 46099 | C13: =C12 -> 46113 | D13: 3272 | E13: 336 | F13: 4 | G13: 1 | H13: 81588 | I13: CHARACTER | J13: 23204319 | K13: TRFW3B | L13: TS TRF OPTIMUS LOGO BULAT:MISTY MEDIUM BLUE:7-8 | M13: 129900 | N13: 0.95 | O13: =M13*(1-N13) -> 6495 | P13: PERCENTAGE
A14: 2019 ALL D95 | B14: =B13 -> 46099 | C14: =C13 -> 46113 | D14: 3272 | E14: 336 | F14: 4 | G14: 1 | H14: 81588 | I14: CHARACTER | J14: 23204328 | K14: TRFW3B | L14: TS TRF OPTIMUS LOGO BULAT:MISTY MEDIUM BLUE:9-10 | M14: 129900 | N14: 0.95 | O14: =M14*(1-N14) -> 6495 | P14: PERCENTAGE

Sheet 2020 ALL D90
A1: ACARA | B1: FROM DATE | C1: TO DATE | D1: DEPT | E1: WORLD | F1: DIVISION | G1: CLASS | H1: SUPPLIER | I1: BRAND | J1: SKU | K1: ARTICLE | L1: DESCRIPTION | M1: HARGA NORMAL | N1: DISKON | O1: HARGA PROMO | P1: DISCOUNT TYPE
A2: 2020 ALL D90 | B2: ='2019 ALL D95'!B2 -> 46099 | C2: ='2019 ALL D95'!C2 -> 46113 | D2: 3272 | E2: 336 | F2: 4 | G2: 1 | H2: 81379 | I2: CHARACTER | J2: 26449658 | K2: HR314 | L2: TS BATMAN FP SPLASH LOGO:BLACK:11-12 | M2: 139900 | N2: 0.9 | O2: =M2*(1-N2) -> 13990 | P2: PERCENTAGE
A3: =A2 -> 2020 ALL D90 | B3: =B2 -> 46099 | C3: =C2 -> 46113 | D3: 3272 | E3: 336 | F3: 4 | G3: 1 | H3: 81379 | I3: CHARACTER | J3: 26635447 | K3: H416A | L3: SS T-SHIRT BATMAN FULLPRINT ACTION LOGO H416A:WHITE:XS:PRINT:SS T-SHIRT | M3: 139900 | N3: 0.9 | O3: =M3*(1-N3) -> 13990 | P3: PERCENTAGE
A4: =A3 -> 2020 ALL D90 | B4: =B3 -> 46099 | C4: =C3 -> 46113 | D4: 3272 | E4: 336 | F4: 4 | G4: 1 | H4: 81379 | I4: CHARACTER | J4: 26635456 | K4: H416A | L4: SS T-SHIRT BATMAN FULLPRINT ACTION LOGO H416A:WHITE:S:PRINT:SS T-SHIRT | M4: 139900 | N4: 0.9 | O4: =M4*(1-N4) -> 13990 | P4: PERCENTAGE
A5: =A4 -> 2020 ALL D90 | B5: =B4 -> 46099 | C5: =C4 -> 46113 | D5: 3272 | E5: 336 | F5: 4 | G5: 1 | H5: 81379 | I5: CHARACTER | J5: 26635465 | K5: H416A | L5: SS T-SHIRT BATMAN FULLPRINT ACTION LOGO H416A:WHITE:M:PRINT:SS T-SHIRT | M5: 139900 | N5: 0.9 | O5: =M5*(1-N5) -> 13990 | P5: PERCENTAGE
A6: =A5 -> 2020 ALL D90 | B6: =B5 -> 46099 | C6: =C5 -> 46113 | D6: 3272 | E6: 336 | F6: 4 | G6: 1 | H6: 81379 | I6: CHARACTER | J6: 26635474 | K6: H416A | L6: SS T-SHIRT BATMAN FULLPRINT ACTION LOGO H416A:WHITE:L:PRINT:SS T-SHIRT | M6: 139900 | N6: 0.9 | O6: =M6*(1-N6) -> 13990 | P6: PERCENTAGE
A7: =A6 -> 2020 ALL D90 | B7: =B6 -> 46099 | C7: =C6 -> 46113 | D7: 3272 | E7: 336 | F7: 4 | G7: 1 | H7: 81379 | I7: CHARACTER | J7: 26635483 | K7: H416A | L7: SS T-SHIRT BATMAN FULLPRINT ACTION LOGO H416A:WHITE:XL:PRINT:SS T-SHIRT | M7: 139900 | N7: 0.9 | O7: =M7*(1-N7) -> 13990 | P7: PERCENTAGE
A8: =A7 -> 2020 ALL D90 | B8: =B7 -> 46099 | C8: =C7 -> 46113 | D8: 3272 | E8: 336 | F8: 4 | G8: 1 | H8: 81379 | I8: CHARACTER | J8: 26635714 | K8: HR202A | L8: SS T-SHIRT BATMAN FLY SPLASH BAHU HR202A:CLASSIC YELLOW:S:GRAPHIC:SS T-SHIRT | M8: 129900 | N8: 0.9 | O8: =M8*(1-N8) -> 12990 | P8: PERCENTAGE
A9: =A8 -> 2020 ALL D90 | B9: =B8 -> 46099 | C9: =C8 -> 46113 | D9: 3272 | E9: 336 | F9: 4 | G9: 1 | H9: 81379 | I9: CHARACTER | J9: 26635732 | K9: HR202A | L9: SS T-SHIRT BATMAN FLY SPLASH BAHU HR202A:CLASSIC YELLOW:L:GRAPHIC:SS T-SHIRT | M9: 129900 | N9: 0.9 | O9: =M9*(1-N9) -> 12990 | P9: PERCENTAGE
A10: =A9 -> 2020 ALL D90 | B10: =B9 -> 46099 | C10: =C9 -> 46113 | D10: 3272 | E10: 336 | F10: 4 | G10: 1 | H10: 81379 | I10: CHARACTER | J10: 26658646 | K10: HR202B | L10: SS T-SHIRT BATMAN FLY SPLASH BAHU HR202B:MISTY MEDIUM G:9-10:GRAPHIC:SS T-SHIRT | M10: 129900 | N10: 0.9 | O10: =M10*(1-N10) -> 12990 | P10: PERCENTAGE
A11: =A10 -> 2020 ALL D90 | B11: =B10 -> 46099 | C11: =C10 -> 46113 | D11: 3272 | E11: 336 | F11: 4 | G11: 1 | H11: 81379 | I11: CHARACTER | J11: 26658655 | K11: HR202B | L11: SS T-SHIRT BATMAN FLY SPLASH BAHU HR202B:MISTY MEDIUM G:11-12:GRAPHIC:SS T-SHIRT | M11: 129900 | N11: 0.9 | O11: =M11*(1-N11) -> 12990 | P11: PERCENTAGE
A12: =A11 -> 2020 ALL D90 | B12: =B11 -> 46099 | C12: =C11 -> 46113 | D12: 3272 | E12: 336 | F12: 4 | G12: 1 | H12: 81379 | I12: CHARACTER | J12: 26649209 | K12: HR430 | L12: SS T-SHIRT BATMAN FLY TALI CITY FLOCKING HR430:WHITE:XS:GRAPHIC:SS T-SHIRT | M12: 129900 | N12: 0.9 | O12: =M12*(1-N12) -> 12990 | P12: PERCENTAGE
A13: =A12 -> 2020 ALL D90 | B13: =B12 -> 46099 | C13: =C12 -> 46113 | D13: 3272 | E13: 336 | F13: 4 | G13: 1 | H13: 81379 | I13: CHARACTER | J13: 26649218 | K13: HR430 | L13: SS T-SHIRT BATMAN FLY TALI CITY FLOCKING HR430:WHITE:S:GRAPHIC:SS T-SHIRT | M13: 129900 | N13: 0.9 | O13: =M13*(1-N13) -> 12990 | P13: PERCENTAGE
A14: =A13 -> 2020 ALL D90 | B14: =B13 -> 46099 | C14: =C13 -> 46113 | D14: 3272 | E14: 336 | F14: 4 | G14: 1 | H14: 81379 | I14: CHARACTER | J14: 26649227 | K14: HR430 | L14: SS T-SHIRT BATMAN FLY TALI CITY FLOCKING HR430:WHITE:M:GRAPHIC:SS T-SHIRT | M14: 129900 | N14: 0.9 | O14: =M14*(1-N14) -> 12990 | P14: PERCENTAGE
... A53: =A52 -> 2020 ALL D90 | B53: =B52 -> 46099 | C53: =C52 -> 46113 | D53: 3272 | E53: 336 | F53: 4 | G53: 5 | H53: 81379 | I53: CHARACTER | J53: 26890242 | K53: N175C | L53: LONG PANTS KNIT BATMAN RIBBON LOGO HANDUK C N175C:MISTY MEDIU:13-14:GRAPHIC:LONG PANTS | M53: 199900 | N53: 0.9 | O53: =M53*(1-N53) -> 19990 | P53: PERCENTAGE

Sheet 2021 ALL D90
A1: ACARA | B1: FROM DATE | C1: TO DATE | D1: DEPT | E1: WORLD | F1: DIVISION | G1: CLASS | H1: SUPPLIER | I1: BRAND | J1: SKU | K1: ARTICLE | L1: DESCRIPTION | M1: HARGA NORMAL | N1: DISKON | O1: HARGA PROMO | P1: DISCOUNT TYPE
A2: 2021 ALL D90 | B2: ='2019 ALL D95'!B2 -> 46099 | C2: ='2019 ALL D95'!C2 -> 46113 | D2: 3272 | E2: 336 | F2: 4 | G2: 1 | H2: 81379 | I2: CHARACTER | J2: 26449989 | K2: N024 | L2: KOSTUM BATMAN SAYAP:MISTY DARK GREY:M | M2: 129900 | N2: 0.9 | O2: =M2*(1-N2) -> 12990 | P2: PERCENTAGE
A3: =A2 -> 2021 ALL D90 | B3: =B2 -> 46099 | C3: =C2 -> 46113 | D3: 3272 | E3: 336 | F3: 4 | G3: 1 | H3: 81379 | I3: CHARACTER | J3: 26449998 | K3: N024 | L3: KOSTUM BATMAN SAYAP:MISTY DARK GREY:L | M3: 129900 | N3: 0.9 | O3: =M3*(1-N3) -> 12990 | P3: PERCENTAGE
A4: =A3 -> 2021 ALL D90 | B4: =B3 -> 46099 | C4: =C3 -> 46113 | D4: 3272 | E4: 336 | F4: 4 | G4: 1 | H4: 81379 | I4: CHARACTER | J4: 26450002 | K4: N024 | L4: KOSTUM BATMAN SAYAP:MISTY DARK GREY:XL | M4: 129900 | N4: 0.9 | O4: =M4*(1-N4) -> 12990 | P4: PERCENTAGE
A5: =A4 -> 2021 ALL D90 | B5: =B4 -> 46099 | C5: =C4 -> 46113 | D5: 3272 | E5: 336 | F5: 4 | G5: 1 | H5: 81379 | I5: CHARACTER | J5: 26450011 | K5: N024 | L5: KOSTUM BATMAN SAYAP:MISTY DARK GREY:XS | M5: 129900 | N5: 0.9 | O5: =M5*(1-N5) -> 12990 | P5: PERCENTAGE
A6: =A5 -> 2021 ALL D90 | B6: =B5 -> 46099 | C6: =C5 -> 46113 | D6: 3272 | E6: 336 | F6: 4 | G6: 1 | H6: 81379 | I6: CHARACTER | J6: 26872628 | K6: N063A | L6: SS T-SHIRT BATMAN RG LGN FULL SABLON A N063A:CLASSIC YELLO:L:TEXT:SS T-SHIRT | M6: 139900 | N6: 0.9 | O6: =M6*(1-N6) -> 13990 | P6: PERCENTAGE
A7: =A6 -> 2021 ALL D90 | B7: =B6 -> 46099 | C7: =C6 -> 46113 | D7: 3272 | E7: 336 | F7: 4 | G7: 1 | H7: 81379 | I7: CHARACTER | J7: 26872637 | K7: N063A | L7: SS T-SHIRT BATMAN RG LGN FULL SABLON A N063A:CLASSIC YELLO:XL:TEXT:SS T-SHIRT | M7: 139900 | N7: 0.9 | O7: =M7*(1-N7) -> 13990 | P7: PERCENTAGE
A8: =A7 -> 2021 ALL D90 | B8: =B7 -> 46099 | C8: =C7 -> 46113 | D8: 3272 | E8: 336 | F8: 4 | G8: 1 | H8: 81379 | I8: CHARACTER | J8: 26780147 | K8: N063C | L8: SS T-SHIRT BATMAN RG LENGAN FULL SABLON C N063C:MISTY LIGHT:11-12:TEXT:SS T-SHIRT | M8: 139900 | N8: 0.9 | O8: =M8*(1-N8) -> 13990 | P8: PERCENTAGE
A9: =A8 -> 2021 ALL D90 | B9: =B8 -> 46099 | C9: =C8 -> 46113 | D9: 3272 | E9: 336 | F9: 4 | G9: 1 | H9: 81379 | I9: CHARACTER | J9: 26780165 | K9: N063C | L9: SS T-SHIRT BATMAN RG LENGAN FULL SABLON C N063C:MISTY LIGHT:15-16:TEXT:SS T-SHIRT | M9: 139900 | N9: 0.9 | O9: =M9*(1-N9) -> 13990 | P9: PERCENTAGE
A10: =A9 -> 2021 ALL D90 | B10: =B9 -> 46099 | C10: =C9 -> 46113 | D10: 3272 | E10: 336 | F10: 4 | G10: 1 | H10: 81379 | I10: CHARACTER | J10: 26780138 | K10: N063C | L10: SS T-SHIRT BATMAN RG LENGAN FULL SABLON C N063C:MISTY LIGHT:9-10:TEXT:SS T-SHIRT | M10: 139900 | N10: 0.9 | O10: =M10*(1-N10) -> 13990 | P10: PERCENTAGE
A11: =A10 -> 2021 ALL D90 | B11: =B10 -> 46099 | C11: =C10 -> 46113 | D11: 3272 | E11: 336 | F11: 4 | G11: 1 | H11: 81379 | I11: CHARACTER | J11: 26872459 | K11: H445C | L11: SS T-SHIRT BATMAN LOGO FLOCKING FP SPLASH C H445C:CLASSIC YEL:7-8:GRAPHIC:SS T-SHIRT | M11: 139900 | N11: 0.9 | O11: =M11*(1-N11) -> 13990 | P11: PERCENTAGE
A12: =A11 -> 2021 ALL D90 | B12: =B11 -> 46099 | C12: =C11 -> 46113 | D12: 3272 | E12: 336 | F12: 4 | G12: 1 | H12: 81676 | I12: CHARACTER | J12: 28487283 | K12: GBMTS2C | L12: SS T-SHIRT BATMAN FLY TIE DYE C GBMTS2C:CLASSIC BLUE:9-10:GRAPHIC:SS T-SHIRT | M12: 129900 | N12: 0.9 | O12: =M12*(1-N12) -> 12990 | P12: PERCENTAGE
A13: =A12 -> 2021 ALL D90 | B13: =B12 -> 46099 | C13: =C12 -> 46113 | D13: 3272 | E13: 336 | F13: 4 | G13: 1 | H13: 81676 | I13: CHARACTER | J13: 28487247 | K13: WBBT9B | L13: SS T-SHIRT TS BATMAN FLY CITY B WBBT9B:WHITE:7-8:GRAPHIC:SS T-SHIRT | M13: 129900 | N13: 0.9 | O13: =M13*(1-N13) -> 12990 | P13: PERCENTAGE
A14: =A13 -> 2021 ALL D90 | B14: =B13 -> 46099 | C14: =C13 -> 46113 | D14: 3272 | E14: 336 | F14: 4 | G14: 1 | H14: 81379 | I14: CHARACTER | J14: 26776947 | K14: N061A | L14: SS T-SHIRT BATMAN RG CRUSADER FLOCKING A N061A:MISTY MEDIUM:M:GRAPHIC:SS T-SHIRT | M14: 129900 | N14: 0.9 | O14: =M14*(1-N14) -> 12990 | P14: PERCENTAGE
... A87: =A86 -> 2021 ALL D90 | B87: =B86 -> 46099 | C87: =C86 -> 46113 | D87: 3272 | E87: 336 | F87: 4 | G87: 5 | H87: 81676 | I87: CHARACTER | J87: 38014729 | K87: GNBTP1C | L87: JOGGER KNIT BATMAN TYPO SAMPING C GNBTP1C:MISTY MEDIUM:15-16:TEXT:JOGGER | M87: 199900 | N87: 0.9 | O87: =M87*(1-N87) -> 19990 | P87: PERCENTAGE

Sheet 2022 ALL D90
A1: ACARA | B1: FROM DATE | C1: TO DATE | D1: DEPT | E1: WORLD | F1: DIVISION | G1: CLASS | H1: SUPPLIER | I1: BRAND | J1: SKU | K1: ARTICLE | L1: DESCRIPTION | M1: HARGA NORMAL | N1: DISKON | O1: HARGA PROMO | P1: DISCOUNT TYPE
A2: 2022 ALL D90 | B2: 46099 | C2: 46113 | D2: 3272 | E2: 336 | F2: 4 | G2: 1 | H2: 81379 | I2: CHARACTER | J2: 38162953 | K2: N132A | L2: SS T-SHIRT BATMAN FP MARBLE LOGO CLASSIC FOIL A N132A:CLASSIC YE:5-6:GRAPHIC:SS T-SHIRT | M2: 139900 | N2: 0.9 | O2: =M2*(1-N2) -> 13990 | P2: PERCENTAGE
A3: =A2 -> 2022 ALL D90 | B3: 46099 | C3: 46113 | D3: 3272 | E3: 336 | F3: 4 | G3: 1 | H3: 81379 | I3: CHARACTER | J3: 38162962 | K3: N132A | L3: SS T-SHIRT BATMAN FP MARBLE LOGO CLASSIC FOIL A N132A:CLASSIC YE:7-8:GRAPHIC:SS T-SHIRT | M3: 139900 | N3: =N2 -> 0.9 | O3: =M3*(1-N3) -> 13990 | P3: PERCENTAGE
A4: =A3 -> 2022 ALL D90 | B4: 46099 | C4: 46113 | D4: 3272 | E4: 336 | F4: 4 | G4: 1 | H4: 81379 | I4: CHARACTER | J4: 38162971 | K4: N132A | L4: SS T-SHIRT BATMAN FP MARBLE LOGO CLASSIC FOIL A N132A:CLASSIC YE:9-10:GRAPHIC:SS T-SHIRT | M4: 139900 | N4: =N3 -> 0.9 | O4: =M4*(1-N4) -> 13990 | P4: PERCENTAGE
A5: =A4 -> 2022 ALL D90 | B5: 46099 | C5: 46113 | D5: 3272 | E5: 336 | F5: 4 | G5: 1 | H5: 81379 | I5: CHARACTER | J5: 38162980 | K5: N132A | L5: SS T-SHIRT BATMAN FP MARBLE LOGO CLASSIC FOIL A N132A:CLASSIC YE:3-4:GRAPHIC:SS T-SHIRT | M5: 139900 | N5: =N4 -> 0.9 | O5: =M5*(1-N5) -> 13990 | P5: PERCENTAGE
A6: =A5 -> 2022 ALL D90 | B6: 46099 | C6: 46113 | D6: 3272 | E6: 336 | F6: 4 | G6: 1 | H6: 81379 | I6: CHARACTER | J6: 38162999 | K6: N132A | L6: SS T-SHIRT BATMAN FP MARBLE LOGO CLASSIC FOIL A N132A:CLASSIC YE:4-5:GRAPHIC:SS T-SHIRT | M6: 139900 | N6: =N5 -> 0.9 | O6: =M6*(1-N6) -> 13990 | P6: PERCENTAGE
A7: =A6 -> 2022 ALL D90 | B7: 46099 | C7: 46113 | D7: 3272 | E7: 336 | F7: 4 | G7: 1 | H7: 81379 | I7: CHARACTER | J7: 55710097 | K7: BN087A | L7: TS BATMAN FP COMICS FLOCKING A:CLASSIC YELLOW:5-6:PRINT:SS T-SHIRT | M7: 139900 | N7: =N6 -> 0.9 | O7: =M7*(1-N7) -> 13990 | P7: PERCENTAGE
A8: =A7 -> 2022 ALL D90 | B8: 46099 | C8: 46113 | D8: 3272 | E8: 336 | F8: 4 | G8: 1 | H8: 81379 | I8: CHARACTER | J8: 55710104 | K8: BN087A | L8: TS BATMAN FP COMICS FLOCKING A:CLASSIC YELLOW:7-8:PRINT:SS T-SHIRT | M8: 139900 | N8: =N7 -> 0.9 | O8: =M8*(1-N8) -> 13990 | P8: PERCENTAGE
A9: =A8 -> 2022 ALL D90 | B9: 46099 | C9: 46113 | D9: 3272 | E9: 336 | F9: 4 | G9: 1 | H9: 81379 | I9: CHARACTER | J9: 55710113 | K9: BN087A | L9: TS BATMAN FP COMICS FLOCKING A:CLASSIC YELLOW:9-10:PRINT:SS T-SHIRT | M9: 139900 | N9: =N8 -> 0.9 | O9: =M9*(1-N9) -> 13990 | P9: PERCENTAGE
A10: =A9 -> 2022 ALL D90 | B10: 46099 | C10: 46113 | D10: 3272 | E10: 336 | F10: 4 | G10: 1 | H10: 81379 | I10: CHARACTER | J10: 55710122 | K10: BN087A | L10: TS BATMAN FP COMICS FLOCKING A:CLASSIC YELLOW:3-4:PRINT:SS T-SHIRT | M10: 139900 | N10: =N9 -> 0.9 | O10: =M10*(1-N10) -> 13990 | P10: PERCENTAGE
A11: =A10 -> 2022 ALL D90 | B11: 46099 | C11: 46113 | D11: 3272 | E11: 336 | F11: 4 | G11: 1 | H11: 81379 | I11: CHARACTER | J11: 55710131 | K11: BN087A | L11: TS BATMAN FP COMICS FLOCKING A:CLASSIC YELLOW:4-5:PRINT:SS T-SHIRT | M11: 139900 | N11: =N10 -> 0.9 | O11: =M11*(1-N11) -> 13990 | P11: PERCENTAGE
A12: =A11 -> 2022 ALL D90 | B12: 46099 | C12: 46113 | D12: 3272 | E12: 336 | F12: 4 | G12: 1 | H12: 81379 | I12: CHARACTER | J12: 55709983 | K12: N144C | L12: TS BATMAN KONTRAS LOGO ALUMINIUM C:BLACK:7-8:GRAPHIC:SS T-SHIRT | M12: 139900 | N12: =N11 -> 0.9 | O12: =M12*(1-N12) -> 13990 | P12: PERCENTAGE
A13: =A12 -> 2022 ALL D90 | B13: 46099 | C13: 46113 | D13: 3272 | E13: 336 | F13: 4 | G13: 1 | H13: 81379 | I13: CHARACTER | J13: 55709992 | K13: N144C | L13: TS BATMAN KONTRAS LOGO ALUMINIUM C:BLACK:9-10:GRAPHIC:SS T-SHIRT | M13: 139900 | N13: =N12 -> 0.9 | O13: =M13*(1-N13) -> 13990 | P13: PERCENTAGE
A14: =A13 -> 2022 ALL D90 | B14: 46099 | C14: 46113 | D14: 3272 | E14: 336 | F14: 4 | G14: 1 | H14: 81379 | I14: CHARACTER | J14: 55710006 | K14: N144C | L14: TS BATMAN KONTRAS LOGO ALUMINIUM C:BLACK:11-12:GRAPHIC:SS T-SHIRT | M14: 139900 | N14: =N13 -> 0.9 | O14: =M14*(1-N14) -> 13990 | P14: PERCENTAGE
... A361: =A360 -> 2022 ALL D90 | B361: 46099 | C361: 46113 | D361: 3272 | E361: 336 | F361: 4 | G361: 6 | H361: 81574 | I361: CHARACTER | J361: 64344887 | K361: TPHR1 | L361: TOPI HARRY POTTER LOGO TPHR1:BLACK:F:GRAPHIC:CAPS | M361: 129900 | N361: =N360 -> 0.9 | O361: =M361*(1-N361) -> 12990 | P361: PERCENTAGE

Sheet 2023 ALL D90
A1: ACARA | B1: FROM DATE | C1: TO DATE | D1: DEPT | E1: WORLD | F1: DIVISION | G1: CLASS | H1: SUPPLIER | I1: BRAND | J1: SKU | K1: ARTICLE | L1: DESCRIPTION | M1: HARGA NORMAL | N1: DISKON | O1: HARGA PROMO | P1: DISCOUNT TYPE
A2: 2023 ALL D90 | B2: ='2019 ALL D95'!B2 -> 46099 | C2: ='2019 ALL D95'!C2 -> 46113 | D2: 3272 | E2: 336 | F2: 4 | G2: 1 | H2: 81379 | I2: CHARACTER | J2: 76512566 | K2: N170C | L2: TS BATMAN DARK KNIGHT CITY C N170C:MISTY MEDIUM GREY:7-8:GRAPHIC:SS T-SHIRT | M2: 149900 | N2: 0.9 | O2: =M2*(1-N2) -> 14990 | P2: PERCENTAGE
A3: =A2 -> 2023 ALL D90 | B3: =B2 -> 46099 | C3: =C2 -> 46113 | D3: 3272 | E3: 336 | F3: 4 | G3: 1 | H3: 81379 | I3: CHARACTER | J3: 76512575 | K3: N170C | L3: TS BATMAN DARK KNIGHT CITY C N170C:MISTY MEDIUM GREY:9-10:GRAPHIC:SS T-SHIRT | M3: 149900 | N3: =N2 -> 0.9 | O3: =M3*(1-N3) -> 14990 | P3: =P2 -> PERCENTAGE
A4: =A3 -> 2023 ALL D90 | B4: =B3 -> 46099 | C4: =C3 -> 46113 | D4: 3272 | E4: 336 | F4: 4 | G4: 1 | H4: 81379 | I4: CHARACTER | J4: 76512584 | K4: N170C | L4: TS BATMAN DARK KNIGHT CITY C N170C:MISTY MEDIUM GREY:11-12:GRAPHIC:SS T-SHIRT | M4: 149900 | N4: =N3 -> 0.9 | O4: =M4*(1-N4) -> 14990 | P4: =P3 -> PERCENTAGE
A5: =A4 -> 2023 ALL D90 | B5: =B4 -> 46099 | C5: =C4 -> 46113 | D5: 3272 | E5: 336 | F5: 4 | G5: 1 | H5: 81379 | I5: CHARACTER | J5: 76512593 | K5: N170C | L5: TS BATMAN DARK KNIGHT CITY C N170C:MISTY MEDIUM GREY:13-14:GRAPHIC:SS T-SHIRT | M5: 149900 | N5: =N4 -> 0.9 | O5: =M5*(1-N5) -> 14990 | P5: =P4 -> PERCENTAGE
A6: =A5 -> 2023 ALL D90 | B6: =B5 -> 46099 | C6: =C5 -> 46113 | D6: 3272 | E6: 336 | F6: 4 | G6: 1 | H6: 81379 | I6: CHARACTER | J6: 76906891 | K6: BMA38C | L6: TS BATMAN LOGO TENGAH RIBBON C BMA38C:CLASSIC YELLOW:7-8:GRAPHIC:SS T-SHIRT | M6: 149900 | N6: =N5 -> 0.9 | O6: =M6*(1-N6) -> 14990 | P6: =P5 -> PERCENTAGE
A7: =A6 -> 2023 ALL D90 | B7: =B6 -> 46099 | C7: =C6 -> 46113 | D7: 3272 | E7: 336 | F7: 4 | G7: 1 | H7: 81379 | I7: CHARACTER | J7: 76906908 | K7: BMA38C | L7: TS BATMAN LOGO TENGAH RIBBON C BMA38C:CLASSIC YELLOW:9-10:GRAPHIC:SS T-SHIRT | M7: 149900 | N7: =N6 -> 0.9 | O7: =M7*(1-N7) -> 14990 | P7: =P6 -> PERCENTAGE
A8: =A7 -> 2023 ALL D90 | B8: =B7 -> 46099 | C8: =C7 -> 46113 | D8: 3272 | E8: 336 | F8: 4 | G8: 1 | H8: 81379 | I8: CHARACTER | J8: 76906926 | K8: BMA38C | L8: TS BATMAN LOGO TENGAH RIBBON C BMA38C:CLASSIC YELLOW:13-14:GRAPHIC:SS T-SHIRT | M8: 149900 | N8: =N7 -> 0.9 | O8: =M8*(1-N8) -> 14990 | P8: =P7 -> PERCENTAGE
A9: =A8 -> 2023 ALL D90 | B9: =B8 -> 46099 | C9: =C8 -> 46113 | D9: 3272 | E9: 336 | F9: 4 | G9: 1 | H9: 81379 | I9: CHARACTER | J9: 76906944 | K9: A80A | L9: TS BATMAN LORENG A A80A:CLASSIC YELLOW:3-4:PRINT:SS T-SHIRT | M9: 149900 | N9: =N8 -> 0.9 | O9: =M9*(1-N9) -> 14990 | P9: =P8 -> PERCENTAGE
A10: =A9 -> 2023 ALL D90 | B10: =B9 -> 46099 | C10: =C9 -> 46113 | D10: 3272 | E10: 336 | F10: 4 | G10: 1 | H10: 81379 | I10: CHARACTER | J10: 76906953 | K10: A80A | L10: TS BATMAN LORENG A A80A:CLASSIC YELLOW:4-5:PRINT:SS T-SHIRT | M10: 149900 | N10: =N9 -> 0.9 | O10: =M10*(1-N10) -> 14990 | P10: =P9 -> PERCENTAGE
A11: =A10 -> 2023 ALL D90 | B11: =B10 -> 46099 | C11: =C10 -> 46113 | D11: 3272 | E11: 336 | F11: 4 | G11: 1 | H11: 81379 | I11: CHARACTER | J11: 76906962 | K11: A80A | L11: TS BATMAN LORENG A A80A:CLASSIC YELLOW:5-6:PRINT:SS T-SHIRT | M11: 149900 | N11: =N10 -> 0.9 | O11: =M11*(1-N11) -> 14990 | P11: =P10 -> PERCENTAGE
A12: =A11 -> 2023 ALL D90 | B12: =B11 -> 46099 | C12: =C11 -> 46113 | D12: 3272 | E12: 336 | F12: 4 | G12: 1 | H12: 81379 | I12: CHARACTER | J12: 76906971 | K12: A80A | L12: TS BATMAN LORENG A A80A:CLASSIC YELLOW:7-8:PRINT:SS T-SHIRT | M12: 149900 | N12: =N11 -> 0.9 | O12: =M12*(1-N12) -> 14990 | P12: =P11 -> PERCENTAGE
A13: =A12 -> 2023 ALL D90 | B13: =B12 -> 46099 | C13: =C12 -> 46113 | D13: 3272 | E13: 336 | F13: 4 | G13: 1 | H13: 81379 | I13: CHARACTER | J13: 76906980 | K13: A80A | L13: TS BATMAN LORENG A A80A:CLASSIC YELLOW:9-10:PRINT:SS T-SHIRT | M13: 149900 | N13: =N12 -> 0.9 | O13: =M13*(1-N13) -> 14990 | P13: =P12 -> PERCENTAGE
A14: =A13 -> 2023 ALL D90 | B14: =B13 -> 46099 | C14: =C13 -> 46113 | D14: 3272 | E14: 336 | F14: 4 | G14: 1 | H14: 81379 | I14: CHARACTER | J14: 76906999 | K14: A86A | L14: TS BATMAN DARK KNIGHT ACTION CITY A A86A:MISTY LIGHT YELLOW:3-4:GRAPHIC:SS T-SHIRT | M14: 139900 | N14: =N13 -> 0.9 | O14: =M14*(1-N14) -> 13990 | P14: =P13 -> PERCENTAGE
... A590: =A589 -> 2023 ALL D90 | B590: =B589 -> 46099 | C590: =C589 -> 46113 | D590: 3272 | E590: 336 | F590: 4 | G590: 6 | H590: 81574 | I590: CHARACTER | J590: 79299542 | K590: TPHRP02 | L590: TOPI HARRY POTTER FP TD LOGO TPHRP02:WHITE:F:TEXT:CAPS | M590: 139900 | N590: =N589 -> 0.9 | O590: =M590*(1-N590) -> 13990 | P590: =P589 -> PERCENTAGE
A591: =A590 -> 2023 ALL D90 | B591: ='2019 ALL D95'!B2 -> 46099 | C591: ='2019 ALL D95'!C2 -> 46113 | D591: 3272 | E591: 336 | F591: 4 | G591: 1 | H591: 81379 | I591: CHARACTER | J591: 83493145 | K591: BL-HN02 | L591: SS T-SHIRT BUMI LANGIT 3 PATRIOT BL-HN02:WHITE:3-4:GRAPHIC:SS T-SHIRT | M591: 99900 | N591: 0.9 | O591: =M591*(1-N591) -> 9990 | P591: PERCENTAGE
A592: =A591 -> 2023 ALL D90 | B592: =B591 -> 46099 | C592: =C591 -> 46113 | D592: 3272 | E592: 336 | F592: 4 | G592: 1 | H592: 81379 | I592: CHARACTER | J592: 83493154 | K592: BL-HN02 | L592: SS T-SHIRT BUMI LANGIT 3 PATRIOT BL-HN02:WHITE:4-5:GRAPHIC:SS T-SHIRT | M592: 99900 | N592: 0.9 | O592: =M592*(1-N592) -> 9990 | P592: PERCENTAGE
A593: =A592 -> 2023 ALL D90 | B593: =B592 -> 46099 | C593: =C592 -> 46113 | D593: 3272 | E593: 336 | F593: 4 | G593: 1 | H593: 81379 | I593: CHARACTER | J593: 83493163 | K593: BL-HN02 | L593: SS T-SHIRT BUMI LANGIT 3 PATRIOT BL-HN02:WHITE:5-6:GRAPHIC:SS T-SHIRT | M593: 99900 | N593: 0.9 | O593: =M593*(1-N593) -> 9990 | P593: PERCENTAGE
A594: =A593 -> 2023 ALL D90 | B594: =B593 -> 46099 | C594: =C593 -> 46113 | D594: 3272 | E594: 336 | F594: 4 | G594: 1 | H594: 81379 | I594: CHARACTER | J594: 83493172 | K594: BL-HN02 | L594: SS T-SHIRT BUMI LANGIT 3 PATRIOT BL-HN02:WHITE:7-8:GRAPHIC:SS T-SHIRT | M594: 99900 | N594: 0.9 | O594: =M594*(1-N594) -> 9990 | P594: PERCENTAGE
A595: =A594 -> 2023 ALL D90 | B595: =B594 -> 46099 | C595: =C594 -> 46113 | D595: 3272 | E595: 336 | F595: 4 | G595: 1 | H595: 81379 | I595: CHARACTER | J595: 83493181 | K595: BL-HN02 | L595: SS T-SHIRT BUMI LANGIT 3 PATRIOT BL-HN02:WHITE:9-10:GRAPHIC:SS T-SHIRT | M595: 99900 | N595: 0.9 | O595: =M595*(1-N595) -> 9990 | P595: PERCENTAGE
A596: =A595 -> 2023 ALL D90 | B596: =B595 -> 46099 | C596: =C595 -> 46113 | D596: 3272 | E596: 336 | F596: 4 | G596: 1 | H596: 81379 | I596: CHARACTER | J596: 83493190 | K596: BL-HN02 | L596: SS T-SHIRT BUMI LANGIT 3 PATRIOT BL-HN02:WHITE:11-12:GRAPHIC:SS T-SHIRT | M596: 99900 | N596: 0.9 | O596: =M596*(1-N596) -> 9990 | P596: PERCENTAGE
A597: =A596 -> 2023 ALL D90 | B597: =B596 -> 46099 | C597: =C596 -> 46113 | D597: 3272 | E597: 336 | F597: 4 | G597: 1 | H597: 81379 | I597: CHARACTER | J597: 83493207 | K597: BL-HN02 | L597: SS T-SHIRT BUMI LANGIT 3 PATRIOT BL-HN02:WHITE:13-14:GRAPHIC:SS T-SHIRT | M597: 99900 | N597: 0.9 | O597: =M597*(1-N597) -> 9990 | P597: PERCENTAGE
A598: =A597 -> 2023 ALL D90 | B598: =B597 -> 46099 | C598: =C597 -> 46113 | D598: 3272 | E598: 336 | F598: 4 | G598: 1 | H598: 81379 | I598: CHARACTER | J598: 83493216 | K598: BL-HN02 | L598: SS T-SHIRT BUMI LANGIT 3 PATRIOT BL-HN02:WHITE:15-16:GRAPHIC:SS T-SHIRT | M598: 99900 | N598: 0.9 | O598: =M598*(1-N598) -> 9990 | P598: PERCENTAGE
A599: =A598 -> 2023 ALL D90 | B599: =B598 -> 46099 | C599: =C598 -> 46113 | D599: 3272 | E599: 336 | F599: 4 | G599: 1 | H599: 81379 | I599: CHARACTER | J599: 83493225 | K599: BL-N004 | L599: SS T-SHIRT BUMI LANGIT GUNDALA BL-N004:WHITE:3-4:GRAPHIC:SS T-SHIRT | M599: 99900 | N599: 0.9 | O599: =M599*(1-N599) -> 9990 | P599: PERCENTAGE
A600: =A599 -> 2023 ALL D90 | B600: =B599 -> 46099 | C600: =C599 -> 46113 | D600: 3272 | E600: 336 | F600: 4 | G600: 1 | H600: 81379 | I600: CHARACTER | J600: 83493234 | K600: BL-N004 | L600: SS T-SHIRT BUMI LANGIT GUNDALA BL-N004:WHITE:4-5:GRAPHIC:SS T-SHIRT | M600: 99900 | N600: 0.9 | O600: =M600*(1-N600) -> 9990 | P600: PERCENTAGE
A601: =A600 -> 2023 ALL D90 | B601: =B600 -> 46099 | C601: =C600 -> 46113 | D601: 3272 | E601: 336 | F601: 4 | G601: 1 | H601: 81379 | I601: CHARACTER | J601: 83493243 | K601: BL-N004 | L601: SS T-SHIRT BUMI LANGIT GUNDALA BL-N004:WHITE:5-6:GRAPHIC:SS T-SHIRT | M601: 99900 | N601: 0.9 | O601: =M601*(1-N601) -> 9990 | P601: PERCENTAGE
A602: =A601 -> 2023 ALL D90 | B602: =B601 -> 46099 | C602: =C601 -> 46113 | D602: 3272 | E602: 336 | F602: 4 | G602: 1 | H602: 81379 | I602: CHARACTER | J602: 83493252 | K602: BL-N004 | L602: SS T-SHIRT BUMI LANGIT GUNDALA BL-N004:WHITE:7-8:GRAPHIC:SS T-SHIRT | M602: 99900 | N602: 0.9 | O602: =M602*(1-N602) -> 9990 | P602: PERCENTAGE
A603: =A602 -> 2023 ALL D90 | B603: =B602 -> 46099 | C603: =C602 -> 46113 | D603: 3272 | E603: 336 | F603: 4 | G603: 1 | H603: 81379 | I603: CHARACTER | J603: 83493261 | K603: BL-N004 | L603: SS T-SHIRT BUMI LANGIT GUNDALA BL-N004:WHITE:9-10:GRAPHIC:SS T-SHIRT | M603: 99900 | N603: 0.9 | O603: =M603*(1-N603) -> 9990 | P603: PERCENTAGE
... A682: =A681 -> 2023 ALL D90 | B682: =B681 -> 46099 | C682: =C681 -> 46113 | D682: 3272 | E682: 336 | F682: 4 | G682: 1 | H682: 81676 | I682: CHARACTER | J682: 83494055 | K682: GBL05 | L682: SS T-SHIRT BUMI LANGIT FP PATRIOT LOGO GBL05:BLACK:15-16:GRAPHIC:SS T-SHIRT | M682: 119900 | N682: 0.9 | O682: =M682*(1-N682) -> 11990 | P682: PERCENTAGE

Sheet 2024 JAN-JUN D70
A1: ACARA | B1: FROM DATE | C1: TO DATE | D1: DEPT | E1: WORLD | F1: DIVISION | G1: CLASS | H1: SUPPLIER | I1: BRAND | J1: SKU | K1: ARTICLE | L1: DESCRIPTION | M1: HARGA NORMAL | N1: DISKON | O1: HARGA PROMO | P1: DISCOUNT TYPE
A2: 2024 JAN-JUN D70 | B2: ='2019 ALL D95'!B2 -> 46099 | C2: ='2019 ALL D95'!C2 -> 46113 | D2: 3272 | E2: 336 | F2: 4 | G2: 1 | H2: 81379 | I2: CHARACTER | J2: 13990284 | K2: KT-HN11A | L2: T-SHIRT BATMAN FP LOGO DARK KNIGHT A KT-HN11A:CLASSIC YELLOW:3-4:GRAPHIC:SS T-SHIRT | M2: 149900 | N2: 0.7 | O2: =M2-((70*M2))/100 -> 44970 | P2: PERCENTAGE
A3: =A2 -> 2024 JAN-JUN D70 | B3: =B2 -> 46099 | C3: =C2 -> 46113 | D3: 3272 | E3: 336 | F3: 4 | G3: 1 | H3: 81379 | I3: CHARACTER | J3: 13990293 | K3: KT-HN11A | L3: T-SHIRT BATMAN FP LOGO DARK KNIGHT A KT-HN11A:CLASSIC YELLOW:4-5:GRAPHIC:SS T-SHIRT | M3: 149900 | N3: =N2 -> 0.7 | O3: =M3-((70*M3))/100 -> 44970 | P3: =P2 -> PERCENTAGE
A4: =A3 -> 2024 JAN-JUN D70 | B4: =B3 -> 46099 | C4: =C3 -> 46113 | D4: 3272 | E4: 336 | F4: 4 | G4: 1 | H4: 81379 | I4: CHARACTER | J4: 13990300 | K4: KT-HN11A | L4: T-SHIRT BATMAN FP LOGO DARK KNIGHT A KT-HN11A:CLASSIC YELLOW:5-6:GRAPHIC:SS T-SHIRT | M4: 149900 | N4: =N3 -> 0.7 | O4: =M4-((70*M4))/100 -> 44970 | P4: =P3 -> PERCENTAGE
A5: =A4 -> 2024 JAN-JUN D70 | B5: =B4 -> 46099 | C5: =C4 -> 46113 | D5: 3272 | E5: 336 | F5: 4 | G5: 1 | H5: 81379 | I5: CHARACTER | J5: 13990319 | K5: KT-HN11A | L5: T-SHIRT BATMAN FP LOGO DARK KNIGHT A KT-HN11A:CLASSIC YELLOW:7-8:GRAPHIC:SS T-SHIRT | M5: 149900 | N5: =N4 -> 0.7 | O5: =M5-((70*M5))/100 -> 44970 | P5: =P4 -> PERCENTAGE
A6: =A5 -> 2024 JAN-JUN D70 | B6: =B5 -> 46099 | C6: =C5 -> 46113 | D6: 3272 | E6: 336 | F6: 4 | G6: 1 | H6: 81379 | I6: CHARACTER | J6: 13990328 | K6: KT-HN11A | L6: T-SHIRT BATMAN FP LOGO DARK KNIGHT A KT-HN11A:CLASSIC YELLOW:9-10:GRAPHIC:SS T-SHIRT | M6: 149900 | N6: =N5 -> 0.7 | O6: =M6-((70*M6))/100 -> 44970 | P6: =P5 -> PERCENTAGE
A7: =A6 -> 2024 JAN-JUN D70 | B7: =B6 -> 46099 | C7: =C6 -> 46113 | D7: 3272 | E7: 336 | F7: 4 | G7: 1 | H7: 81379 | I7: CHARACTER | J7: 13990337 | K7: BT-HN314A | L7: T-SHIRT BATMAN LIS LENGAN CITY A BT-HN314A:BLACK:3-4:GRAPHIC:SS T-SHIRT | M7: 139900 | N7: =N6 -> 0.7 | O7: =M7-((70*M7))/100 -> 41970 | P7: =P6 -> PERCENTAGE
A8: =A7 -> 2024 JAN-JUN D70 | B8: =B7 -> 46099 | C8: =C7 -> 46113 | D8: 3272 | E8: 336 | F8: 4 | G8: 1 | H8: 81379 | I8: CHARACTER | J8: 13990346 | K8: BT-HN314A | L8: T-SHIRT BATMAN LIS LENGAN CITY A BT-HN314A:BLACK:4-5:GRAPHIC:SS T-SHIRT | M8: 139900 | N8: =N7 -> 0.7 | O8: =M8-((70*M8))/100 -> 41970 | P8: =P7 -> PERCENTAGE
A9: =A8 -> 2024 JAN-JUN D70 | B9: =B8 -> 46099 | C9: =C8 -> 46113 | D9: 3272 | E9: 336 | F9: 4 | G9: 1 | H9: 81379 | I9: CHARACTER | J9: 13990355 | K9: BT-HN314A | L9: T-SHIRT BATMAN LIS LENGAN CITY A BT-HN314A:BLACK:5-6:GRAPHIC:SS T-SHIRT | M9: 139900 | N9: =N8 -> 0.7 | O9: =M9-((70*M9))/100 -> 41970 | P9: =P8 -> PERCENTAGE
A10: =A9 -> 2024 JAN-JUN D70 | B10: =B9 -> 46099 | C10: =C9 -> 46113 | D10: 3272 | E10: 336 | F10: 4 | G10: 1 | H10: 81379 | I10: CHARACTER | J10: 13990364 | K10: BT-HN314A | L10: T-SHIRT BATMAN LIS LENGAN CITY A BT-HN314A:BLACK:7-8:GRAPHIC:SS T-SHIRT | M10: 139900 | N10: =N9 -> 0.7 | O10: =M10-((70*M10))/100 -> 41970 | P10: =P9 -> PERCENTAGE
A11: =A10 -> 2024 JAN-JUN D70 | B11: =B10 -> 46099 | C11: =C10 -> 46113 | D11: 3272 | E11: 336 | F11: 4 | G11: 1 | H11: 81379 | I11: CHARACTER | J11: 13990373 | K11: BT-HN314A | L11: T-SHIRT BATMAN LIS LENGAN CITY A BT-HN314A:BLACK:9-10:GRAPHIC:SS T-SHIRT | M11: 139900 | N11: =N10 -> 0.7 | O11: =M11-((70*M11))/100 -> 41970 | P11: =P10 -> PERCENTAGE
A12: =A11 -> 2024 JAN-JUN D70 | B12: =B11 -> 46099 | C12: =C11 -> 46113 | D12: 3272 | E12: 336 | F12: 4 | G12: 1 | H12: 81379 | I12: CHARACTER | J12: 13990382 | K12: KT-HN19A | L12: T-SHIRT BATMAN JUMP CUT SEW A KT-HN19A:BLACK:3-4:GRAPHIC:SS T-SHIRT | M12: 149900 | N12: =N11 -> 0.7 | O12: =M12-((70*M12))/100 -> 44970 | P12: =P11 -> PERCENTAGE
A13: =A12 -> 2024 JAN-JUN D70 | B13: =B12 -> 46099 | C13: =C12 -> 46113 | D13: 3272 | E13: 336 | F13: 4 | G13: 1 | H13: 81379 | I13: CHARACTER | J13: 13990391 | K13: KT-HN19A | L13: T-SHIRT BATMAN JUMP CUT SEW A KT-HN19A:BLACK:4-5:GRAPHIC:SS T-SHIRT | M13: 149900 | N13: =N12 -> 0.7 | O13: =M13-((70*M13))/100 -> 44970 | P13: =P12 -> PERCENTAGE
A14: =A13 -> 2024 JAN-JUN D70 | B14: =B13 -> 46099 | C14: =C13 -> 46113 | D14: 3272 | E14: 336 | F14: 4 | G14: 1 | H14: 81379 | I14: CHARACTER | J14: 13990408 | K14: KT-HN19A | L14: T-SHIRT BATMAN JUMP CUT SEW A KT-HN19A:BLACK:5-6:GRAPHIC:SS T-SHIRT | M14: 149900 | N14: =N13 -> 0.7 | O14: =M14-((70*M14))/100 -> 44970 | P14: =P13 -> PERCENTAGE
... A233: =A232 -> 2024 JAN-JUN D70 | B233: =B232 -> 46099 | C233: =C232 -> 46113 | D233: 3272 | E233: 336 | F233: 4 | G233: 1 | H233: 81379 | I233: CHARACTER | J233: 16623166 | K233: TF-A78 | L233: SS T-SHIRT TF FP DEPAN LOGO LIS TF-A78:MISTY LIGHT GREY:15-16:PRINT:SS T-SHIRT | M233: 139900 | N233: =N232 -> 0.7 | O233: =M233-((70*M233))/100 -> 41970 | P233: =P232 -> PERCENTAGE
A234: =A232 -> 2024 JAN-JUN D70 | B234: =B232 -> 46099 | C234: =C232 -> 46113 | D234: 3272 | E234: 336 | F234: 4 | G234: 1 | H234: 81379 | I234: CHARACTER | J234: 16623175 | K234: TF-HN22 | L234: SS T-SHIRT TF7 BUMBLEBEE LIS LGN TF-HN22:BLACK:3-4:PRINT:SS T-SHIRT | M234: 149900 | N234: =N233 -> 0.7 | O234: =M234-((70*M234))/100 -> 44970 | P234: =P232 -> PERCENTAGE
A235: =A234 -> 2024 JAN-JUN D70 | B235: =B234 -> 46099 | C235: =C234 -> 46113 | D235: 3272 | E235: 336 | F235: 4 | G235: 1 | H235: 81379 | I235: CHARACTER | J235: 16623184 | K235: TF-HN22 | L235: SS T-SHIRT TF7 BUMBLEBEE LIS LGN TF-HN22:BLACK:4-5:PRINT:SS T-SHIRT | M235: 149900 | N235: =N234 -> 0.7 | O235: =M235-((70*M235))/100 -> 44970 | P235: =P234 -> PERCENTAGE
A236: =A235 -> 2024 JAN-JUN D70 | B236: =B235 -> 46099 | C236: =C235 -> 46113 | D236: 3272 | E236: 336 | F236: 4 | G236: 1 | H236: 81379 | I236: CHARACTER | J236: 16623193 | K236: TF-HN22 | L236: SS T-SHIRT TF7 BUMBLEBEE LIS LGN TF-HN22:BLACK:5-6:PRINT:SS T-SHIRT | M236: 149900 | N236: =N235 -> 0.7 | O236: =M236-((70*M236))/100 -> 44970 | P236: =P235 -> PERCENTAGE
A237: =A236 -> 2024 JAN-JUN D70 | B237: =B236 -> 46099 | C237: =C236 -> 46113 | D237: 3272 | E237: 336 | F237: 4 | G237: 1 | H237: 81379 | I237: CHARACTER | J237: 16623200 | K237: TF-HN22 | L237: SS T-SHIRT TF7 BUMBLEBEE LIS LGN TF-HN22:BLACK:7-8:PRINT:SS T-SHIRT | M237: 149900 | N237: =N236 -> 0.7 | O237: =M237-((70*M237))/100 -> 44970 | P237: =P236 -> PERCENTAGE
A238: =A237 -> 2024 JAN-JUN D70 | B238: =B237 -> 46099 | C238: =C237 -> 46113 | D238: 3272 | E238: 336 | F238: 4 | G238: 1 | H238: 81379 | I238: CHARACTER | J238: 16623237 | K238: TF-HN22 | L238: SS T-SHIRT TF7 BUMBLEBEE LIS LGN TF-HN22:BLACK:9-10:PRINT:SS T-SHIRT | M238: 149900 | N238: =N237 -> 0.7 | O238: =M238-((70*M238))/100 -> 44970 | P238: =P237 -> PERCENTAGE
A239: =A238 -> 2024 JAN-JUN D70 | B239: =B238 -> 46099 | C239: =C238 -> 46113 | D239: 3272 | E239: 336 | F239: 4 | G239: 1 | H239: 81379 | I239: CHARACTER | J239: 16623246 | K239: TF-HN22 | L239: SS T-SHIRT TF7 BUMBLEBEE LIS LGN TF-HN22:BLACK:11-12:PRINT:SS T-SHIRT | M239: 149900 | N239: =N238 -> 0.7 | O239: =M239-((70*M239))/100 -> 44970 | P239: =P238 -> PERCENTAGE
A240: =A239 -> 2024 JAN-JUN D70 | B240: =B239 -> 46099 | C240: =C239 -> 46113 | D240: 3272 | E240: 336 | F240: 4 | G240: 1 | H240: 81379 | I240: CHARACTER | J240: 16623273 | K240: TF-HN16 | L240: SS T-SHIRT TF TEAM STAND TF-HN16:BLACK:3-4:PRINT:SS T-SHIRT | M240: 139900 | N240: =N239 -> 0.7 | O240: =M240-((70*M240))/100 -> 41970 | P240: =P239 -> PERCENTAGE
A241: =A240 -> 2024 JAN-JUN D70 | B241: =B240 -> 46099 | C241: =C240 -> 46113 | D241: 3272 | E241: 336 | F241: 4 | G241: 1 | H241: 81379 | I241: CHARACTER | J241: 16623282 | K241: TF-HN16 | L241: SS T-SHIRT TF TEAM STAND TF-HN16:BLACK:4-5:PRINT:SS T-SHIRT | M241: 139900 | N241: =N240 -> 0.7 | O241: =M241-((70*M241))/100 -> 41970 | P241: =P240 -> PERCENTAGE
A242: =A241 -> 2024 JAN-JUN D70 | B242: =B241 -> 46099 | C242: =C241 -> 46113 | D242: 3272 | E242: 336 | F242: 4 | G242: 1 | H242: 81379 | I242: CHARACTER | J242: 16623291 | K242: TF-HN16 | L242: SS T-SHIRT TF TEAM STAND TF-HN16:BLACK:5-6:PRINT:SS T-SHIRT | M242: 139900 | N242: =N241 -> 0.7 | O242: =M242-((70*M242))/100 -> 41970 | P242: =P241 -> PERCENTAGE
A243: =A242 -> 2024 JAN-JUN D70 | B243: =B242 -> 46099 | C243: =C242 -> 46113 | D243: 3272 | E243: 336 | F243: 4 | G243: 1 | H243: 81379 | I243: CHARACTER | J243: 16623308 | K243: TF-HN16 | L243: SS T-SHIRT TF TEAM STAND TF-HN16:BLACK:7-8:PRINT:SS T-SHIRT | M243: 139900 | N243: =N242 -> 0.7 | O243: =M243-((70*M243))/100 -> 41970 | P243: =P242 -> PERCENTAGE
A244: =A243 -> 2024 JAN-JUN D70 | B244: =B243 -> 46099 | C244: =C243 -> 46113 | D244: 3272 | E244: 336 | F244: 4 | G244: 1 | H244: 81379 | I244: CHARACTER | J244: 16623317 | K244: TF-HN16 | L244: SS T-SHIRT TF TEAM STAND TF-HN16:BLACK:9-10:PRINT:SS T-SHIRT | M244: 139900 | N244: =N243 -> 0.7 | O244: =M244-((70*M244))/100 -> 41970 | P244: =P243 -> PERCENTAGE
A245: =A244 -> 2024 JAN-JUN D70 | B245: =B244 -> 46099 | C245: =C244 -> 46113 | D245: 3272 | E245: 336 | F245: 4 | G245: 1 | H245: 81379 | I245: CHARACTER | J245: 16623326 | K245: TF-HN16 | L245: SS T-SHIRT TF TEAM STAND TF-HN16:BLACK:11-12:PRINT:SS T-SHIRT | M245: 139900 | N245: =N244 -> 0.7 | O245: =M245-((70*M245))/100 -> 41970 | P245: =P244 -> PERCENTAGE
A246: =A245 -> 2024 JAN-JUN D70 | B246: =B245 -> 46099 | C246: =C245 -> 46113 | D246: 3272 | E246: 336 | F246: 4 | G246: 1 | H246: 81379 | I246: CHARACTER | J246: 16623335 | K246: TF-HN16 | L246: SS T-SHIRT TF TEAM STAND TF-HN16:BLACK:13-14:PRINT:SS T-SHIRT | M246: 139900 | N246: =N245 -> 0.7 | O246: =M246-((70*M246))/100 -> 41970 | P246: =P245 -> PERCENTAGE
... A466: =A465 -> 2024 JAN-JUN D70 | B466: =B465 -> 46099 | C466: =C465 -> 46113 | D466: 3272 | E466: 336 | F466: 4 | G466: 1 | H466: 81379 | I466: CHARACTER | J466: 15501585 | K466: MB-N037C | L466: T-SHIRT MARIO FP LUIGI BOWSER C MB-N037C:WHITE:15-16:PRINT:SS T-SHIRT | M466: 149900 | N466: =N465 -> 0.7 | O466: =M466-((70*M466))/100 -> 44970 | P466: =P465 -> PERCENTAGE

Sheet 2024 JUL-SEPT B1G2
A1: ACARA | B1: FROM DATE | C1: TO DATE | D1: DEPT | E1: WORLD | F1: DIVISION | G1: CLASS | H1: SUPPLIER | I1: BRAND | J1: SKU | K1: ARTICLE | L1: DESCRIPTION | M1: HARGA NORMAL | N1: DISKON | O1: HARGA PROMO | P1: DISCOUNT TYPE
A2: 2024 JUL-SEPT B1G2 | B2: ='2019 ALL D95'!B2 -> 46099 | C2: ='2019 ALL D95'!C2 -> 46113 | D2: 3272 | E2: 336 | F2: 4 | G2: 3 | H2: 81379 | I2: CHARACTER | J2: 16624209 | K2: MN-N068 | L2: SWEATER MINIONS CLASSIC HOOD MN-N068:BLACK:3-4:PRINT:JACKET | M2: 239900 | N2: BXGY | O2: B1G2 | P2: BXGY
A3: =A2 -> 2024 JUL-SEPT B1G2 | B3: =B2 -> 46099 | C3: =C2 -> 46113 | D3: 3272 | E3: 336 | F3: 4 | G3: 3 | H3: 81379 | I3: CHARACTER | J3: 16624218 | K3: MN-N068 | L3: SWEATER MINIONS CLASSIC HOOD MN-N068:BLACK:4-5:PRINT:JACKET | M3: 239900 | N3: =N2 -> BXGY | O3: =O2 -> B1G2 | P3: =P2 -> BXGY
A4: =A3 -> 2024 JUL-SEPT B1G2 | B4: =B3 -> 46099 | C4: =C3 -> 46113 | D4: 3272 | E4: 336 | F4: 4 | G4: 3 | H4: 81379 | I4: CHARACTER | J4: 16624227 | K4: MN-N068 | L4: SWEATER MINIONS CLASSIC HOOD MN-N068:BLACK:5-6:PRINT:JACKET | M4: 239900 | N4: =N3 -> BXGY | O4: =O3 -> B1G2 | P4: =P3 -> BXGY
A5: =A4 -> 2024 JUL-SEPT B1G2 | B5: =B4 -> 46099 | C5: =C4 -> 46113 | D5: 3272 | E5: 336 | F5: 4 | G5: 3 | H5: 81379 | I5: CHARACTER | J5: 16624236 | K5: MN-N068 | L5: SWEATER MINIONS CLASSIC HOOD MN-N068:BLACK:7-8:PRINT:JACKET | M5: 239900 | N5: =N4 -> BXGY | O5: =O4 -> B1G2 | P5: =P4 -> BXGY
A6: =A5 -> 2024 JUL-SEPT B1G2 | B6: =B5 -> 46099 | C6: =C5 -> 46113 | D6: 3272 | E6: 336 | F6: 4 | G6: 3 | H6: 81379 | I6: CHARACTER | J6: 16624245 | K6: MN-N068 | L6: SWEATER MINIONS CLASSIC HOOD MN-N068:BLACK:9-10:PRINT:JACKET | M6: 239900 | N6: =N5 -> BXGY | O6: =O5 -> B1G2 | P6: =P5 -> BXGY
A7: =A6 -> 2024 JUL-SEPT B1G2 | B7: =B6 -> 46099 | C7: =C6 -> 46113 | D7: 3272 | E7: 336 | F7: 4 | G7: 3 | H7: 81379 | I7: CHARACTER | J7: 16624254 | K7: MN-N068 | L7: SWEATER MINIONS CLASSIC HOOD MN-N068:BLACK:11-12:PRINT:JACKET | M7: 239900 | N7: =N6 -> BXGY | O7: =O6 -> B1G2 | P7: =P6 -> BXGY
A8: =A7 -> 2024 JUL-SEPT B1G2 | B8: =B7 -> 46099 | C8: =C7 -> 46113 | D8: 3272 | E8: 336 | F8: 4 | G8: 3 | H8: 81379 | I8: CHARACTER | J8: 16624263 | K8: MN-N068 | L8: SWEATER MINIONS CLASSIC HOOD MN-N068:BLACK:13-14:PRINT:JACKET | M8: 239900 | N8: =N7 -> BXGY | O8: =O7 -> B1G2 | P8: =P7 -> BXGY
A9: =A8 -> 2024 JUL-SEPT B1G2 | B9: =B8 -> 46099 | C9: =C8 -> 46113 | D9: 3272 | E9: 336 | F9: 4 | G9: 3 | H9: 81379 | I9: CHARACTER | J9: 16624272 | K9: MN-N068 | L9: SWEATER MINIONS CLASSIC HOOD MN-N068:BLACK:15-16:PRINT:JACKET | M9: 239900 | N9: =N8 -> BXGY | O9: =O8 -> B1G2 | P9: =P8 -> BXGY
A10: =A9 -> 2024 JUL-SEPT B1G2 | B10: =B9 -> 46099 | C10: =C9 -> 46113 | D10: 3272 | E10: 336 | F10: 4 | G10: 3 | H10: 81379 | I10: CHARACTER | J10: 18659928 | K10: MN-N010 | L10: SWEATER MINIONS MOVIE HOOD MN-N010:CLASSIC YELLOW:3-4:GRAPHIC:JACKET | M10: 239900 | N10: =N9 -> BXGY | O10: =O9 -> B1G2 | P10: =P9 -> BXGY
A11: =A10 -> 2024 JUL-SEPT B1G2 | B11: =B10 -> 46099 | C11: =C10 -> 46113 | D11: 3272 | E11: 336 | F11: 4 | G11: 3 | H11: 81379 | I11: CHARACTER | J11: 18659937 | K11: MN-N010 | L11: SWEATER MINIONS MOVIE HOOD MN-N010:CLASSIC YELLOW:4-5:GRAPHIC:JACKET | M11: 239900 | N11: =N10 -> BXGY | O11: =O10 -> B1G2 | P11: =P10 -> BXGY
A12: =A11 -> 2024 JUL-SEPT B1G2 | B12: =B11 -> 46099 | C12: =C11 -> 46113 | D12: 3272 | E12: 336 | F12: 4 | G12: 3 | H12: 81379 | I12: CHARACTER | J12: 18659946 | K12: MN-N010 | L12: SWEATER MINIONS MOVIE HOOD MN-N010:CLASSIC YELLOW:5-6:GRAPHIC:JACKET | M12: 239900 | N12: =N11 -> BXGY | O12: =O11 -> B1G2 | P12: =P11 -> BXGY
A13: =A12 -> 2024 JUL-SEPT B1G2 | B13: =B12 -> 46099 | C13: =C12 -> 46113 | D13: 3272 | E13: 336 | F13: 4 | G13: 3 | H13: 81379 | I13: CHARACTER | J13: 18659955 | K13: MN-N010 | L13: SWEATER MINIONS MOVIE HOOD MN-N010:CLASSIC YELLOW:7-8:GRAPHIC:JACKET | M13: 239900 | N13: =N12 -> BXGY | O13: =O12 -> B1G2 | P13: =P12 -> BXGY
A14: =A13 -> 2024 JUL-SEPT B1G2 | B14: =B13 -> 46099 | C14: =C13 -> 46113 | D14: 3272 | E14: 336 | F14: 4 | G14: 3 | H14: 81379 | I14: CHARACTER | J14: 18659964 | K14: MN-N010 | L14: SWEATER MINIONS MOVIE HOOD MN-N010:CLASSIC YELLOW:9-10:GRAPHIC:JACKET | M14: 239900 | N14: =N13 -> BXGY | O14: =O13 -> B1G2 | P14: =P13 -> BXGY
... A194: =A193 -> 2024 JUL-SEPT B1G2 | B194: =B193 -> 46099 | C194: =C193 -> 46113 | D194: 3272 | E194: 336 | F194: 4 | G194: 3 | H194: 81588 | I194: CHARACTER | J194: 20514936 | K194: TF-N068 | L194: JAKET TF ONE KTG HOOD TF-N068:NAVY BLUE:15-16:GRAPHIC:JACKET | M194: 289900 | N194: =N193 -> BXGY | O194: =O193 -> B1G2 | P194: =P193 -> BXGY

Sheet 2024 NOV-DEC B1G2
A1: ACARA | B1: FROM DATE | C1: TO DATE | D1: DEPT | E1: WORLD | F1: DIVISION | G1: CLASS | H1: SUPPLIER | I1: BRAND | J1: SKU | K1: ARTICLE | L1: DESCRIPTION | M1: HARGA NORMAL | N1: DISKON | O1: HARGA PROMO | P1: DISCOUNT TYPE
A2: 2024 NOV-DEC B1G2 | B2: ='2019 ALL D95'!B2 -> 46099 | C2: ='2019 ALL D95'!C2 -> 46113 | D2: 3272 | E2: 336 | F2: 4 | G2: 4 | H2: 81379 | I2: CHARACTER | J2: 45419912 | K2: BM-A95C | L2: SHORT PANTS CP KNIT BATMAN SPLASH BM-A95C:MISTY MEDIUM GREY:5-6:GRAPHIC:SHORT PANTS | M2: 159900 | N2: BXGY | O2: B1G2 | P2: BXGY
A3: =A2 -> 2024 NOV-DEC B1G2 | B3: =B2 -> 46099 | C3: =C2 -> 46113 | D3: 3272 | E3: 336 | F3: 4 | G3: 4 | H3: 81379 | I3: CHARACTER | J3: 45419921 | K3: BM-A95C | L3: SHORT PANTS CP KNIT BATMAN SPLASH BM-A95C:MISTY MEDIUM GREY:7-8:GRAPHIC:SHORT PANTS | M3: 159900 | N3: =N2 -> BXGY | O3: =O2 -> B1G2 | P3: =P2 -> BXGY
A4: =A3 -> 2024 NOV-DEC B1G2 | B4: =B3 -> 46099 | C4: =C3 -> 46113 | D4: 3272 | E4: 336 | F4: 4 | G4: 4 | H4: 81379 | I4: CHARACTER | J4: 45419930 | K4: BM-A95C | L4: SHORT PANTS CP KNIT BATMAN SPLASH BM-A95C:MISTY MEDIUM GREY:9-10:GRAPHIC:SHORT PANTS | M4: 159900 | N4: =N3 -> BXGY | O4: =O3 -> B1G2 | P4: =P3 -> BXGY
A5: =A4 -> 2024 NOV-DEC B1G2 | B5: =B4 -> 46099 | C5: =C4 -> 46113 | D5: 3272 | E5: 336 | F5: 4 | G5: 4 | H5: 81379 | I5: CHARACTER | J5: 45419949 | K5: BM-A95C | L5: SHORT PANTS CP KNIT BATMAN SPLASH BM-A95C:MISTY MEDIUM GREY:11-12:GRAPHIC:SHORT PANTS | M5: 159900 | N5: =N4 -> BXGY | O5: =O4 -> B1G2 | P5: =P4 -> BXGY
A6: =A5 -> 2024 NOV-DEC B1G2 | B6: =B5 -> 46099 | C6: =C5 -> 46113 | D6: 3272 | E6: 336 | F6: 4 | G6: 4 | H6: 81379 | I6: CHARACTER | J6: 45419958 | K6: BM-A95C | L6: SHORT PANTS CP KNIT BATMAN SPLASH BM-A95C:MISTY MEDIUM GREY:13-14:GRAPHIC:SHORT PANTS | M6: 159900 | N6: =N5 -> BXGY | O6: =O5 -> B1G2 | P6: =P5 -> BXGY
A7: =A6 -> 2024 NOV-DEC B1G2 | B7: =B6 -> 46099 | C7: =C6 -> 46113 | D7: 3272 | E7: 336 | F7: 4 | G7: 1 | H7: 81676 | I7: CHARACTER | J7: 45419761 | K7: BG-106C | L7: SS T-SHIRT BATMAN LOGO PRINT BLKG C BG-106C:MISTY LIGHT YELLOW:7-8:GRAPHIC:SS T-SHIRT | M7: 129900 | N7: =N6 -> BXGY | O7: =O6 -> B1G2 | P7: =P6 -> BXGY
A8: =A7 -> 2024 NOV-DEC B1G2 | B8: =B7 -> 46099 | C8: =C7 -> 46113 | D8: 3272 | E8: 336 | F8: 4 | G8: 1 | H8: 81676 | I8: CHARACTER | J8: 45419770 | K8: BG-106C | L8: SS T-SHIRT BATMAN LOGO PRINT BLKG C BG-106C:MISTY LIGHT YELLOW:9-10:GRAPHIC:SS T-SHIRT | M8: 129900 | N8: =N7 -> BXGY | O8: =O7 -> B1G2 | P8: =P7 -> BXGY
A9: =A8 -> 2024 NOV-DEC B1G2 | B9: =B8 -> 46099 | C9: =C8 -> 46113 | D9: 3272 | E9: 336 | F9: 4 | G9: 1 | H9: 81676 | I9: CHARACTER | J9: 45419789 | K9: BG-106C | L9: SS T-SHIRT BATMAN LOGO PRINT BLKG C BG-106C:MISTY LIGHT YELLOW:11-12:GRAPHIC:SS T-SHIRT | M9: 129900 | N9: =N8 -> BXGY | O9: =O8 -> B1G2 | P9: =P8 -> BXGY
A10: =A9 -> 2024 NOV-DEC B1G2 | B10: =B9 -> 46099 | C10: =C9 -> 46113 | D10: 3272 | E10: 336 | F10: 4 | G10: 1 | H10: 81676 | I10: CHARACTER | J10: 45419798 | K10: BG-106C | L10: SS T-SHIRT BATMAN LOGO PRINT BLKG C BG-106C:MISTY LIGHT YELLOW:13-14:GRAPHIC:SS T-SHIRT | M10: 129900 | N10: =N9 -> BXGY | O10: =O9 -> B1G2 | P10: =P9 -> BXGY
A11: =A10 -> 2024 NOV-DEC B1G2 | B11: =B10 -> 46099 | C11: =C10 -> 46113 | D11: 3272 | E11: 336 | F11: 4 | G11: 1 | H11: 81676 | I11: CHARACTER | J11: 45419805 | K11: BG-106C | L11: SS T-SHIRT BATMAN LOGO PRINT BLKG C BG-106C:MISTY LIGHT YELLOW:15-16:GRAPHIC:SS T-SHIRT | M11: 129900 | N11: =N10 -> BXGY | O11: =O10 -> B1G2 | P11: =P10 -> BXGY
A12: =A11 -> 2024 NOV-DEC B1G2 | B12: =B11 -> 46099 | C12: =C11 -> 46113 | D12: 3272 | E12: 336 | F12: 4 | G12: 1 | H12: 81676 | I12: CHARACTER | J12: 45419814 | K12: BG-109A | L12: SS T-SHIRT SUPERMAN FP FLY A BG-109A:WHITE:3-4:PRINT:SS T-SHIRT | M12: 139900 | N12: =N11 -> BXGY | O12: =O11 -> B1G2 | P12: =P11 -> BXGY
A13: =A12 -> 2024 NOV-DEC B1G2 | B13: =B12 -> 46099 | C13: =C12 -> 46113 | D13: 3272 | E13: 336 | F13: 4 | G13: 1 | H13: 81676 | I13: CHARACTER | J13: 45419823 | K13: BG-109A | L13: SS T-SHIRT SUPERMAN FP FLY A BG-109A:WHITE:4-5:PRINT:SS T-SHIRT | M13: 139900 | N13: =N12 -> BXGY | O13: =O12 -> B1G2 | P13: =P12 -> BXGY
A14: =A13 -> 2024 NOV-DEC B1G2 | B14: =B13 -> 46099 | C14: =C13 -> 46113 | D14: 3272 | E14: 336 | F14: 4 | G14: 1 | H14: 81676 | I14: CHARACTER | J14: 45419832 | K14: BG-109A | L14: SS T-SHIRT SUPERMAN FP FLY A BG-109A:WHITE:5-6:PRINT:SS T-SHIRT | M14: 139900 | N14: =N13 -> BXGY | O14: =O13 -> B1G2 | P14: =P13 -> BXGY
... A168: =A167 -> 2024 NOV-DEC B1G2 | B168: =B167 -> 46099 | C168: =C167 -> 46113 | D168: 3272 | E168: 336 | F168: 4 | G168: 1 | H168: 4953 | I168: CHARACTER | J168: 45646319 | K168: MLBH-1 | L168: SS T-SHIRT MLBB ALDOUS FIRE RING MLBH-1:BLACK:15-16:GRAPHIC:SS T-SHIRT | M168: 139900 | N168: =N167 -> BXGY | O168: =O167 -> B1G2 | P168: =P167 -> BXGY
A169: =A168 -> 2024 NOV-DEC B1G2 | B169: =B168 -> 46099 | C169: =C168 -> 46113 | D169: 3272 | E169: 336 | F169: 4 | G169: 1 | H169: 81588 | I169: CHARACTER | J169: 45646837 | K169: TF-HR02 | L169: SS T-SHIRT TF FP LOGO TULISAN HD TF-HR 02:CLASSIC YELLOW:4-5:PRINT:SS T-SHIRT | M169: 149900 | N169: =N168 -> BXGY | O169: B1G2 | P169: =P168 -> BXGY
A170: =A169 -> 2024 NOV-DEC B1G2 | B170: =B169 -> 46099 | C170: =C169 -> 46113 | D170: 3272 | E170: 336 | F170: 4 | G170: 1 | H170: 81588 | I170: CHARACTER | J170: 45646846 | K170: TF-HR02 | L170: SS T-SHIRT TF FP LOGO TULISAN HD TF-HR 02:CLASSIC YELLOW:5-6:PRINT:SS T-SHIRT | M170: 149900 | N170: =N169 -> BXGY | O170: =O169 -> B1G2 | P170: =P169 -> BXGY
A171: =A170 -> 2024 NOV-DEC B1G2 | B171: =B170 -> 46099 | C171: =C170 -> 46113 | D171: 3272 | E171: 336 | F171: 4 | G171: 1 | H171: 81588 | I171: CHARACTER | J171: 45646855 | K171: TF-HR02 | L171: SS T-SHIRT TF FP LOGO TULISAN HD TF-HR 02:CLASSIC YELLOW:7-8:PRINT:SS T-SHIRT | M171: 149900 | N171: =N170 -> BXGY | O171: =O170 -> B1G2 | P171: =P170 -> BXGY
A172: =A171 -> 2024 NOV-DEC B1G2 | B172: =B171 -> 46099 | C172: =C171 -> 46113 | D172: 3272 | E172: 336 | F172: 4 | G172: 1 | H172: 81588 | I172: CHARACTER | J172: 45646864 | K172: TF-HR02 | L172: SS T-SHIRT TF FP LOGO TULISAN HD TF-HR 02:CLASSIC YELLOW:9-10:PRINT:SS T-SHIRT | M172: 149900 | N172: =N171 -> BXGY | O172: =O171 -> B1G2 | P172: =P171 -> BXGY
A173: =A172 -> 2024 NOV-DEC B1G2 | B173: =B172 -> 46099 | C173: =C172 -> 46113 | D173: 3272 | E173: 336 | F173: 4 | G173: 1 | H173: 81588 | I173: CHARACTER | J173: 45646873 | K173: TF-HR02 | L173: SS T-SHIRT TF FP LOGO TULISAN HD TF-HR 02:CLASSIC YELLOW:11-12:PRINT:SS T-SHIRT | M173: 149900 | N173: =N172 -> BXGY | O173: =O172 -> B1G2 | P173: =P172 -> BXGY
A174: =A173 -> 2024 NOV-DEC B1G2 | B174: =B173 -> 46099 | C174: =C173 -> 46113 | D174: 3272 | E174: 336 | F174: 4 | G174: 1 | H174: 81588 | I174: CHARACTER | J174: 45646882 | K174: TF-HR02 | L174: SS T-SHIRT TF FP LOGO TULISAN HD TF-HR 02:CLASSIC YELLOW:13-14:PRINT:SS T-SHIRT | M174: 149900 | N174: =N173 -> BXGY | O174: =O173 -> B1G2 | P174: =P173 -> BXGY
A175: =A174 -> 2024 NOV-DEC B1G2 | B175: =B174 -> 46099 | C175: =C174 -> 46113 | D175: 3272 | E175: 336 | F175: 4 | G175: 1 | H175: 81588 | I175: CHARACTER | J175: 45646891 | K175: TF-HR02 | L175: SS T-SHIRT TF FP LOGO TULISAN HD TF-HR 02:CLASSIC YELLOW:15-16:PRINT:SS T-SHIRT | M175: 149900 | N175: =N174 -> BXGY | O175: =O174 -> B1G2 | P175: =P174 -> BXGY
A176: =A175 -> 2024 NOV-DEC B1G2 | B176: =B175 -> 46099 | C176: =C175 -> 46113 | D176: 3272 | E176: 336 | F176: 4 | G176: 1 | H176: 81588 | I176: CHARACTER | J176: 45646908 | K176: TF-HR01 | L176: SS T-SHIRT TF LOGO LIS GLOW ID TF-HR01:CLASSIC RED:3-4:GRAPHIC:SS T-SHIRT | M176: 139900 | N176: =N175 -> BXGY | O176: =O175 -> B1G2 | P176: =P175 -> BXGY
A177: =A176 -> 2024 NOV-DEC B1G2 | B177: =B176 -> 46099 | C177: =C176 -> 46113 | D177: 3272 | E177: 336 | F177: 4 | G177: 1 | H177: 81588 | I177: CHARACTER | J177: 45646917 | K177: TF-HR01 | L177: SS T-SHIRT TF LOGO LIS GLOW ID TF-HR01:CLASSIC RED:4-5:GRAPHIC:SS T-SHIRT | M177: 139900 | N177: =N176 -> BXGY | O177: =O176 -> B1G2 | P177: =P176 -> BXGY
A178: =A177 -> 2024 NOV-DEC B1G2 | B178: =B177 -> 46099 | C178: =C177 -> 46113 | D178: 3272 | E178: 336 | F178: 4 | G178: 1 | H178: 81588 | I178: CHARACTER | J178: 45646926 | K178: TF-HR01 | L178: SS T-SHIRT TF LOGO LIS GLOW ID TF-HR01:CLASSIC RED:5-6:GRAPHIC:SS T-SHIRT | M178: 139900 | N178: =N177 -> BXGY | O178: =O177 -> B1G2 | P178: =P177 -> BXGY
A179: =A178 -> 2024 NOV-DEC B1G2 | B179: =B178 -> 46099 | C179: =C178 -> 46113 | D179: 3272 | E179: 336 | F179: 4 | G179: 1 | H179: 81588 | I179: CHARACTER | J179: 45646935 | K179: TF-HR01 | L179: SS T-SHIRT TF LOGO LIS GLOW ID TF-HR01:CLASSIC RED:7-8:GRAPHIC:SS T-SHIRT | M179: 139900 | N179: =N178 -> BXGY | O179: =O178 -> B1G2 | P179: =P178 -> BXGY
A180: =A179 -> 2024 NOV-DEC B1G2 | B180: =B179 -> 46099 | C180: =C179 -> 46113 | D180: 3272 | E180: 336 | F180: 4 | G180: 1 | H180: 81588 | I180: CHARACTER | J180: 45646944 | K180: TF-HR01 | L180: SS T-SHIRT TF LOGO LIS GLOW ID TF-HR01:CLASSIC RED:9-10:GRAPHIC:SS T-SHIRT | M180: 139900 | N180: =N179 -> BXGY | O180: =O179 -> B1G2 | P180: =P179 -> BXGY
A181: =A180 -> 2024 NOV-DEC B1G2 | B181: =B180 -> 46099 | C181: =C180 -> 46113 | D181: 3272 | E181: 336 | F181: 4 | G181: 1 | H181: 81588 | I181: CHARACTER | J181: 45646953 | K181: TF-HR01 | L181: SS T-SHIRT TF LOGO LIS GLOW ID TF-HR01:CLASSIC RED:11-12:GRAPHIC:SS T-SHIRT | M181: 139900 | N181: =N180 -> BXGY | O181: =O180 -> B1G2 | P181: =P180 -> BXGY
... A216: =A215 -> 2024 NOV-DEC B1G2 | B216: =B215 -> 46099 | C216: =C215 -> 46113 | D216: 3272 | E216: 336 | F216: 4 | G216: 3 | H216: 81379 | I216: CHARACTER | J216: 45646613 | K216: JP-N033 | L216: JACKET HOOD JURASSIC A JP-N033:GRASS GREEN:9-10:GRAPHIC:JACKET | M216: 279900 | N216: =N215 -> BXGY | O216: =O215 -> B1G2 | P216: =P215 -> BXGY

Sheet 2025 JAN-APR B1G2
A1: ACARA | B1: FROM DATE | C1: TO DATE | D1: DEPT | E1: WORLD | F1: DIVISION | G1: CLASS | H1: SUPPLIER | I1: BRAND | J1: SKU | K1: ARTICLE | L1: DESCRIPTION | M1: HARGA NORMAL | N1: DISKON | O1: HARGA PROMO | P1: DISCOUNT TYPE
A2: 2025 JAN-APR B1G2 | B2: ='2019 ALL D95'!B2 -> 46099 | C2: ='2019 ALL D95'!C2 -> 46113 | D2: 3272 | E2: 336 | F2: 4 | G2: 1 | H2: 81379 | I2: CHARACTER | J2: 15500273 | K2: NC244A | L2: T-SHIRT BATMAN CLASSIC WING A NC244A:MISTY MEDIUM GREY:3-4:PRINT:COSTUME | M2: 149900 | N2: BXGY | O2: B1G2 | P2: BXGY
A3: =A2 -> 2025 JAN-APR B1G2 | B3: =B2 -> 46099 | C3: =C2 -> 46113 | D3: 3272 | E3: 336 | F3: 4 | G3: 1 | H3: 81379 | I3: CHARACTER | J3: 15500282 | K3: NC244A | L3: T-SHIRT BATMAN CLASSIC WING A NC244A:MISTY MEDIUM GREY:4-5:PRINT:COSTUME | M3: 149900 | N3: BXGY | O3: =O2 -> B1G2 | P3: BXGY
A4: =A3 -> 2025 JAN-APR B1G2 | B4: =B3 -> 46099 | C4: =C3 -> 46113 | D4: 3272 | E4: 336 | F4: 4 | G4: 1 | H4: 81379 | I4: CHARACTER | J4: 15500291 | K4: NC244A | L4: T-SHIRT BATMAN CLASSIC WING A NC244A:MISTY MEDIUM GREY:5-6:PRINT:COSTUME | M4: 149900 | N4: BXGY | O4: =O3 -> B1G2 | P4: BXGY
A5: =A4 -> 2025 JAN-APR B1G2 | B5: =B4 -> 46099 | C5: =C4 -> 46113 | D5: 3272 | E5: 336 | F5: 4 | G5: 1 | H5: 81379 | I5: CHARACTER | J5: 15500308 | K5: NC244A | L5: T-SHIRT BATMAN CLASSIC WING A NC244A:MISTY MEDIUM GREY:7-8:PRINT:COSTUME | M5: 149900 | N5: BXGY | O5: =O4 -> B1G2 | P5: BXGY
A6: =A5 -> 2025 JAN-APR B1G2 | B6: =B5 -> 46099 | C6: =C5 -> 46113 | D6: 3272 | E6: 336 | F6: 4 | G6: 1 | H6: 81379 | I6: CHARACTER | J6: 15500317 | K6: NC244A | L6: T-SHIRT BATMAN CLASSIC WING A NC244A:MISTY MEDIUM GREY:9-10:PRINT:COSTUME | M6: 149900 | N6: BXGY | O6: =O5 -> B1G2 | P6: BXGY
A7: =A6 -> 2025 JAN-APR B1G2 | B7: =B6 -> 46099 | C7: =C6 -> 46113 | D7: 3272 | E7: 336 | F7: 4 | G7: 1 | H7: 4953 | I7: CHARACTER | J7: 45646328 | K7: MLBH-2 | L7: SS T-SHIRT MLBB ALDOUS ACTION MLBH-2:NAVY BLUE:7-8:GRAPHIC:SS T-SHIRT | M7: 139900 | N7: BXGY | O7: =O6 -> B1G2 | P7: BXGY
A8: =A7 -> 2025 JAN-APR B1G2 | B8: =B7 -> 46099 | C8: =C7 -> 46113 | D8: 3272 | E8: 336 | F8: 4 | G8: 1 | H8: 4953 | I8: CHARACTER | J8: 45646337 | K8: MLBH-2 | L8: SS T-SHIRT MLBB ALDOUS ACTION MLBH-2:NAVY BLUE:9-10:GRAPHIC:SS T-SHIRT | M8: 139900 | N8: BXGY | O8: =O7 -> B1G2 | P8: BXGY
A9: =A8 -> 2025 JAN-APR B1G2 | B9: =B8 -> 46099 | C9: =C8 -> 46113 | D9: 3272 | E9: 336 | F9: 4 | G9: 1 | H9: 4953 | I9: CHARACTER | J9: 45646346 | K9: MLBH-2 | L9: SS T-SHIRT MLBB ALDOUS ACTION MLBH-2:NAVY BLUE:11-12:GRAPHIC:SS T-SHIRT | M9: 139900 | N9: BXGY | O9: =O8 -> B1G2 | P9: BXGY
A10: =A9 -> 2025 JAN-APR B1G2 | B10: =B9 -> 46099 | C10: =C9 -> 46113 | D10: 3272 | E10: 336 | F10: 4 | G10: 1 | H10: 4953 | I10: CHARACTER | J10: 45646355 | K10: MLBH-2 | L10: SS T-SHIRT MLBB ALDOUS ACTION MLBH-2:NAVY BLUE:13-14:GRAPHIC:SS T-SHIRT | M10: 139900 | N10: BXGY | O10: =O9 -> B1G2 | P10: BXGY
A11: =A10 -> 2025 JAN-APR B1G2 | B11: =B10 -> 46099 | C11: =C10 -> 46113 | D11: 3272 | E11: 336 | F11: 4 | G11: 1 | H11: 4953 | I11: CHARACTER | J11: 45646364 | K11: MLBH-2 | L11: SS T-SHIRT MLBB ALDOUS ACTION MLBH-2:NAVY BLUE:15-16:GRAPHIC:SS T-SHIRT | M11: 139900 | N11: BXGY | O11: =O10 -> B1G2 | P11: BXGY
A12: =A11 -> 2025 JAN-APR B1G2 | B12: =B11 -> 46099 | C12: =C11 -> 46113 | D12: 3272 | E12: 336 | F12: 4 | G12: 1 | H12: 81588 | I12: CHARACTER | J12: 45647069 | K12: TF-HN15 | L12: SS T-SHIRT TF AUTOBOTS TEAM TF-HN15:MISTY LIGHT BLUE:3-4:GRAPHIC:SS T-SHIRT | M12: 139900 | N12: BXGY | O12: =O11 -> B1G2 | P12: BXGY
A13: =A12 -> 2025 JAN-APR B1G2 | B13: =B12 -> 46099 | C13: =C12 -> 46113 | D13: 3272 | E13: 336 | F13: 4 | G13: 1 | H13: 81588 | I13: CHARACTER | J13: 45647078 | K13: TF-HN15 | L13: SS T-SHIRT TF AUTOBOTS TEAM TF-HN15:MISTY LIGHT BLUE:4-5:GRAPHIC:SS T-SHIRT | M13: 139900 | N13: BXGY | O13: =O12 -> B1G2 | P13: BXGY
A14: =A13 -> 2025 JAN-APR B1G2 | B14: =B13 -> 46099 | C14: =C13 -> 46113 | D14: 3272 | E14: 336 | F14: 4 | G14: 1 | H14: 81588 | I14: CHARACTER | J14: 45647087 | K14: TF-HN15 | L14: SS T-SHIRT TF AUTOBOTS TEAM TF-HN15:MISTY LIGHT BLUE:5-6:GRAPHIC:SS T-SHIRT | M14: 139900 | N14: BXGY | O14: =O13 -> B1G2 | P14: BXGY
... A226: =A225 -> 2025 JAN-APR B1G2 | B226: =B225 -> 46099 | C226: =C225 -> 46113 | D226: 3272 | E226: 336 | F226: 4 | G226: 3 | H226: 81588 | I226: CHARACTER | J226: 51523332 | K226: TF-N046 | L226: SWEATER HOOD BUMBLEBEE LIS LGN TF-N046:MISTY MEDIUM GREY:4-5:GRAPHIC:SWEATER | M226: 149900 | N226: BXGY | O226: =O225 -> B1G2 | P226: BXGY
A227: =A226 -> 2025 JAN-APR B1G2 | B227: =B226 -> 46099 | C227: =C226 -> 46113 | D227: =D226 -> 3272 | E227: =E226 -> 336 | F227: =F226 -> 4 | G227: 3 | H227: 81588 | I227: CHARACTER | J227: 51523341 | K227: TF-N046 | L227: SWEATER HOOD BUMBLEBEE LIS LGN TF-N046:MISTY MEDIUM GREY:5-6:GRAPHIC:SWEATER | M227: 149900 | N227: BXGY | O227: =O226 -> B1G2 | P227: BXGY
A228: =A227 -> 2025 JAN-APR B1G2 | B228: =B227 -> 46099 | C228: =C227 -> 46113 | D228: =D227 -> 3272 | E228: =E227 -> 336 | F228: =F227 -> 4 | G228: 3 | H228: 81588 | I228: CHARACTER | J228: 51523350 | K228: TF-N046 | L228: SWEATER HOOD BUMBLEBEE LIS LGN TF-N046:MISTY MEDIUM GREY:7-8:GRAPHIC:SWEATER | M228: 139900 | N228: BXGY | O228: =O227 -> B1G2 | P228: BXGY
A229: =A228 -> 2025 JAN-APR B1G2 | B229: =B228 -> 46099 | C229: =C228 -> 46113 | D229: =D228 -> 3272 | E229: =E228 -> 336 | F229: =F228 -> 4 | G229: 3 | H229: 81588 | I229: CHARACTER | J229: 51523369 | K229: TF-N046 | L229: SWEATER HOOD BUMBLEBEE LIS LGN TF-N046:MISTY MEDIUM GREY:9-10:GRAPHIC:SWEATER | M229: 139900 | N229: BXGY | O229: =O228 -> B1G2 | P229: BXGY
A230: =A229 -> 2025 JAN-APR B1G2 | B230: =B229 -> 46099 | C230: =C229 -> 46113 | D230: =D229 -> 3272 | E230: =E229 -> 336 | F230: =F229 -> 4 | G230: 3 | H230: 81588 | I230: CHARACTER | J230: 51523378 | K230: TF-N046 | L230: SWEATER HOOD BUMBLEBEE LIS LGN TF-N046:MISTY MEDIUM GREY:11-12:GRAPHIC:SWEATER | M230: 139900 | N230: BXGY | O230: =O229 -> B1G2 | P230: BXGY
A231: =A230 -> 2025 JAN-APR B1G2 | B231: =B230 -> 46099 | C231: =C230 -> 46113 | D231: =D230 -> 3272 | E231: =E230 -> 336 | F231: =F230 -> 4 | G231: 4 | H231: 81588 | I231: CHARACTER | J231: 51523547 | K231: TF-A136 | L231: SHORT PANTS CP KNIT TF FP OPTIMUS TF-A136:NAVY BLUE:3-4:PRINT:SHORT PANTS | M231: 139900 | N231: BXGY | O231: =O230 -> B1G2 | P231: BXGY
A232: =A231 -> 2025 JAN-APR B1G2 | B232: =B231 -> 46099 | C232: =C231 -> 46113 | D232: =D231 -> 3272 | E232: =E231 -> 336 | F232: =F231 -> 4 | G232: 4 | H232: 81588 | I232: CHARACTER | J232: 51523556 | K232: TF-A136 | L232: SHORT PANTS CP KNIT TF FP OPTIMUS TF-A136:NAVY BLUE:4-5:PRINT:SHORT PANTS | M232: 139900 | N232: BXGY | O232: =O231 -> B1G2 | P232: BXGY
A233: =A232 -> 2025 JAN-APR B1G2 | B233: =B232 -> 46099 | C233: =C232 -> 46113 | D233: =D232 -> 3272 | E233: =E232 -> 336 | F233: =F232 -> 4 | G233: 4 | H233: 81588 | I233: CHARACTER | J233: 51523565 | K233: TF-A136 | L233: SHORT PANTS CP KNIT TF FP OPTIMUS TF-A136:NAVY BLUE:5-6:PRINT:SHORT PANTS | M233: 139900 | N233: BXGY | O233: =O232 -> B1G2 | P233: BXGY
A234: =A233 -> 2025 JAN-APR B1G2 | B234: =B233 -> 46099 | C234: =C233 -> 46113 | D234: =D233 -> 3272 | E234: =E233 -> 336 | F234: =F233 -> 4 | G234: 4 | H234: 81588 | I234: CHARACTER | J234: 51523574 | K234: TF-A136 | L234: SHORT PANTS CP KNIT TF FP OPTIMUS TF-A136:NAVY BLUE:7-8:PRINT:SHORT PANTS | M234: 139900 | N234: BXGY | O234: =O233 -> B1G2 | P234: BXGY
A235: =A234 -> 2025 JAN-APR B1G2 | B235: =B234 -> 46099 | C235: =C234 -> 46113 | D235: =D234 -> 3272 | E235: =E234 -> 336 | F235: =F234 -> 4 | G235: 4 | H235: 81588 | I235: CHARACTER | J235: 51523583 | K235: TF-A136 | L235: SHORT PANTS CP KNIT TF FP OPTIMUS TF-A136:NAVY BLUE:9-10:PRINT:SHORT PANTS | M235: 139900 | N235: BXGY | O235: =O234 -> B1G2 | P235: BXGY
A236: =A235 -> 2025 JAN-APR B1G2 | B236: =B235 -> 46099 | C236: =C235 -> 46113 | D236: =D235 -> 3272 | E236: =E235 -> 336 | F236: =F235 -> 4 | G236: 4 | H236: 81588 | I236: CHARACTER | J236: 51523592 | K236: TF-A136 | L236: SHORT PANTS CP KNIT TF FP OPTIMUS TF-A136:NAVY BLUE:11-12:PRINT:SHORT PANTS | M236: 139900 | N236: BXGY | O236: =O235 -> B1G2 | P236: BXGY
A237: =A236 -> 2025 JAN-APR B1G2 | B237: =B236 -> 46099 | C237: =C236 -> 46113 | D237: =D236 -> 3272 | E237: =E236 -> 336 | F237: =F236 -> 4 | G237: 4 | H237: 81588 | I237: CHARACTER | J237: 51523609 | K237: TF-A136 | L237: SHORT PANTS CP KNIT TF FP OPTIMUS TF-A136:NAVY BLUE:13-14:PRINT:SHORT PANTS | M237: 139900 | N237: BXGY | O237: =O236 -> B1G2 | P237: BXGY
