Workbook

Sheet 2019 ALL D95
A1: ACARA | B1: FROM DATE | C1: TO DATE | D1: DEPT | E1: WORLD | F1: DIVISION | G1: CLASS | H1: SUPPLIER | I1: BRAND | J1: SKU | K1: ARTICLE | L1: DESCRIPTION | M1: HARGA NORMAL | N1: DISKON | O1: HARGA PROMO | P1: DISCOUNT TYPE
A2: 2019 ALL D95 | B2: 46099 | C2: 46113 | D2: 3273 | E2: 336 | F2: 4 | G2: 1 | H2: 81588 | I2: DISNEY | J2: 21466237 | K2: MR07 | L2: 66020100MIC TS MIC NICE DAYA:WHITE:L | M2: 89900 | N2: 0.95 | O2: =M2-((95*M2)/100) -> 4495 | P2: PERCENTAGE
A3: 2019 ALL D95 | B3: =B2 -> 46099 | C3: =C2 -> 46113 | D3: 3273 | E3: 336 | F3: 4 | G3: 1 | H3: 81588 | I3: DISNEY | J3: 22564049 | K3: MICA16 | L3: 66060100MIC TS MICKEY SPLASH:BLACK:15-16 | M3: 139900 | N3: 0.95 | O3: =M3-((95*M3)/100) -> 6995 | P3: PERCENTAGE
A4: 2019 ALL D95 | B4: =B3 -> 46099 | C4: =C3 -> 46113 | D4: 3273 | E4: 336 | F4: 4 | G4: 1 | H4: 81588 | I4: DISNEY | J4: 22564067 | K4: MICA16 | L4: 66060100MIC TS MICKEY SPLASH:WHITE:11-12 | M4: 139900 | N4: 0.95 | O4: =M4-((95*M4)/100) -> 6995 | P4: PERCENTAGE
A5: 2019 ALL D95 | B5: =B4 -> 46099 | C5: =C4 -> 46113 | D5: 3273 | E5: 336 | F5: 4 | G5: 1 | H5: 81588 | I5: DISNEY | J5: 22564085 | K5: MICA16 | L5: 66060100MIC TS MICKEY SPLASH:WHITE:15-16 | M5: 139900 | N5: 0.95 | O5: =M5-((95*M5)/100) -> 6995 | P5: PERCENTAGE
A6: 2019 ALL D95 | B6: =B5 -> 46099 | C6: =C5 -> 46113 | D6: 3273 | E6: 336 | F6: 4 | G6: 1 | H6: 81221 | I6: DISNEY | J6: 22595471 | K6: MICA16 | L6: 66020100MIC TS MICKEY SPLASH WH:WHITE:S | M6: 139900 | N6: 0.95 | O6: =M6-((95*M6)/100) -> 6995 | P6: PERCENTAGE
A7: 2019 ALL D95 | B7: =B6 -> 46099 | C7: =C6 -> 46113 | D7: 3273 | E7: 336 | F7: 4 | G7: 1 | H7: 81588 | I7: DISNEY | J7: 22595506 | K7: MICA16 | L7: 66020100MIC TS MICKEY SPLASH WH:WHITE:XL | M7: 139900 | N7: 0.95 | O7: =M7-((95*M7)/100) -> 6995 | P7: PERCENTAGE
A8: 2019 ALL D95 | B8: =B7 -> 46099 | C8: =C7 -> 46113 | D8: 3273 | E8: 336 | F8: 4 | G8: 1 | H8: 81676 | I8: DISNEY | J8: 22957955 | K8: HEROR9B | L8: 66040100BH6 TS BIG HERO BAYMAX SLR:WHITE:5-6 | M8: 129900 | N8: 0.95 | O8: =M8-((95*M8)/100) -> 6495 | P8: PERCENTAGE
A9: 2019 ALL D95 | B9: =B8 -> 46099 | C9: =C8 -> 46113 | D9: 3273 | E9: 336 | F9: 4 | G9: 1 | H9: 81676 | I9: DISNEY | J9: 22989368 | K9: HEROR3A | L9: 66020100BH6 TS BIG HERO TEAM:TURQUOISE:S | M9: 129900 | N9: 0.95 | O9: =M9-((95*M9)/100) -> 6495 | P9: PERCENTAGE
A10: 2019 ALL D95 | B10: =B9 -> 46099 | C10: =C9 -> 46113 | D10: 3273 | E10: 336 | F10: 4 | G10: 1 | H10: 81676 | I10: DISNEY | J10: 22989386 | K10: HEROR3A | L10: 66020100BH6 TS BIG HERO TEAM:TURQUOISE:L | M10: 129900 | N10: 0.95 | O10: =M10-((95*M10)/100) -> 6495 | P10: PERCENTAGE
A11: 2019 ALL D95 | B11: =B10 -> 46099 | C11: =C10 -> 46113 | D11: 3273 | E11: 336 | F11: 4 | G11: 1 | H11: 81676 | I11: DISNEY | J11: 22989395 | K11: HEROR3B | L11: 66040100BH6 TS BIG HERO TEAM:TURQUOISE:5-6 | M11: 129900 | N11: 0.95 | O11: =M11-((95*M11)/100) -> 6495 | P11: PERCENTAGE
A12: 2019 ALL D95 | B12: =B11 -> 46099 | C12: =C11 -> 46113 | D12: 3273 | E12: 336 | F12: 4 | G12: 1 | H12: 81676 | I12: DISNEY | J12: 23801772 | K12: 81221 | L12: 66020100MIC TS MICKEY BALL 28:WHITE:XL | M12: 129900 | N12: 0.95 | O12: =M12-((95*M12)/100) -> 6495 | P12: PERCENTAGE
A13: 2019 ALL D95 | B13: =B12 -> 46099 | C13: =C12 -> 46113 | D13: 3273 | E13: 336 | F13: 4 | G13: 1 | H13: 81676 | I13: DISNEY | J13: 24784585 | K13: DISK92 | L13: 66020100MIC TS MICKEY COLOUR STRIPE:MISTY LIGHT GRE:XS | M13: 99900 | N13: 0.95 | O13: =M13-((95*M13)/100) -> 4995 | P13: PERCENTAGE
A14: 2019 ALL D95 | B14: =B13 -> 46099 | C14: =C13 -> 46113 | D14: 3273 | E14: 336 | F14: 4 | G14: 1 | H14: 81676 | I14: DISNEY | J14: 24784594 | K14: DISK92 | L14: 66020100MIC TS MICKEY COLOUR STRIPE:MISTY LIGHT GRE:S | M14: 99900 | N14: 0.95 | O14: =M14-((95*M14)/100) -> 4995 | P14: PERCENTAGE
... A881: 2019 ALL D95 | B881: =B880 -> 46099 | C881: =C880 -> 46113 | D881: 3273 | E881: 336 | F881: 4 | G881: 9 | H881: 81574 | I881: DISNEY | J881: 24962150 | K881: 93575 | L881: 66060100MCS CP DNM SPIDERMAN FACE:MEDIUM DENIM:15-16 | M881: 269900 | N881: 0.95 | O881: =M881-((95*M881)/100) -> 13495 | P881: PERCENTAGE

Sheet 2020-2021 ALL D90
A1: ACARA | B1: FROM DATE | C1: TO DATE | D1: DEPT | E1: WORLD | F1: DIVISION | G1: CLASS | H1: SUPPLIER | I1: BRAND | J1: SKU | K1: ARTICLE | L1: DESCRIPTION | M1: HARGA NORMAL | N1: DISKON | O1: HARGA PROMO | P1: DISCOUNT TYPE
A2: 2020-2021 ALL D90 | B2: ='2019 ALL D95'!B2 -> 46099 | C2: ='2019 ALL D95'!C2 -> 46113 | D2: 3273 | E2: 336 | F2: 4 | G2: 1 | H2: 81221 | I2: DISNEY | J2: 24389940 | K2: TSMKYSL | L2: 66020100MIC TS MIC KOSTUM SALUR:WHITE:XS | M2: 139900 | N2: 0.9 | O2: =M2-((90*M2)/100) -> 13990 | P2: PERCENTAGE
A3: =A2 -> 2020-2021 ALL D90 | B3: =B2 -> 46099 | C3: =C2 -> 46113 | D3: 3273 | E3: 336 | F3: 4 | G3: 1 | H3: 81221 | I3: DISNEY | J3: 24389959 | K3: TSMKYSL | L3: 66020100MIC TS MIC KOSTUM SALUR:WHITE:S | M3: 139900 | N3: 0.9 | O3: =M3-((90*M3)/100) -> 13990 | P3: PERCENTAGE
A4: =A3 -> 2020-2021 ALL D90 | B4: =B3 -> 46099 | C4: =C3 -> 46113 | D4: 3273 | E4: 336 | F4: 4 | G4: 1 | H4: 81221 | I4: DISNEY | J4: 24389968 | K4: TSMKYSL | L4: 66020100MIC TS MIC KOSTUM SALUR:WHITE:M | M4: 139900 | N4: 0.9 | O4: =M4-((90*M4)/100) -> 13990 | P4: PERCENTAGE
A5: =A4 -> 2020-2021 ALL D90 | B5: =B4 -> 46099 | C5: =C4 -> 46113 | D5: 3273 | E5: 336 | F5: 4 | G5: 1 | H5: 81221 | I5: DISNEY | J5: 24389977 | K5: TSMKYSL | L5: 66020100MIC TS MIC KOSTUM SALUR:WHITE:L | M5: 139900 | N5: 0.9 | O5: =M5-((90*M5)/100) -> 13990 | P5: PERCENTAGE
A6: =A5 -> 2020-2021 ALL D90 | B6: =B5 -> 46099 | C6: =C5 -> 46113 | D6: 3273 | E6: 336 | F6: 4 | G6: 1 | H6: 81221 | I6: DISNEY | J6: 24389986 | K6: TSMKYSL | L6: 66020100MIC TS MIC KOSTUM SALUR:WHITE:XL | M6: 139900 | N6: 0.9 | O6: =M6-((90*M6)/100) -> 13990 | P6: PERCENTAGE
A7: =A6 -> 2020-2021 ALL D90 | B7: =B6 -> 46099 | C7: =C6 -> 46113 | D7: 3273 | E7: 336 | F7: 4 | G7: 1 | H7: 81574 | I7: DISNEY | J7: 24970034 | K7: MKYT01 | L7: 66020100MIC TS MICKEY SALUR KANTONG:CLASSIC RED:S | M7: 129900 | N7: 0.9 | O7: =M7-((90*M7)/100) -> 12990 | P7: PERCENTAGE
A8: =A7 -> 2020-2021 ALL D90 | B8: =B7 -> 46099 | C8: =C7 -> 46113 | D8: 3273 | E8: 336 | F8: 4 | G8: 1 | H8: 81574 | I8: DISNEY | J8: 24970043 | K8: MKYT01 | L8: 66020100MIC TS MICKEY SALUR KANTONG:CLASSIC RED:M | M8: 129900 | N8: 0.9 | O8: =M8-((90*M8)/100) -> 12990 | P8: PERCENTAGE
A9: =A8 -> 2020-2021 ALL D90 | B9: =B8 -> 46099 | C9: =C8 -> 46113 | D9: 3273 | E9: 336 | F9: 4 | G9: 1 | H9: 81574 | I9: DISNEY | J9: 24970052 | K9: MKYT01 | L9: 66020100MIC TS MICKEY SALUR KANTONG:CLASSIC RED:L | M9: 129900 | N9: 0.9 | O9: =M9-((90*M9)/100) -> 12990 | P9: PERCENTAGE
A10: =A9 -> 2020-2021 ALL D90 | B10: =B9 -> 46099 | C10: =C9 -> 46113 | D10: 3273 | E10: 336 | F10: 4 | G10: 1 | H10: 81574 | I10: DISNEY | J10: 24970061 | K10: MKYT01 | L10: 66040100MIC TS MICKEY SALUR KANTONG:CLASSIC RED:5-6 | M10: 129900 | N10: 0.9 | O10: =M10-((90*M10)/100) -> 12990 | P10: PERCENTAGE
A11: =A10 -> 2020-2021 ALL D90 | B11: =B10 -> 46099 | C11: =C10 -> 46113 | D11: 3273 | E11: 336 | F11: 4 | G11: 1 | H11: 81574 | I11: DISNEY | J11: 24970070 | K11: MKYT01 | L11: 66040100MIC TS MICKEY SALUR KANTONG:CLASSIC RED:7-8 | M11: 129900 | N11: 0.9 | O11: =M11-((90*M11)/100) -> 12990 | P11: PERCENTAGE
A12: =A11 -> 2020-2021 ALL D90 | B12: =B11 -> 46099 | C12: =C11 -> 46113 | D12: 3273 | E12: 336 | F12: 4 | G12: 1 | H12: 81574 | I12: DISNEY | J12: 24970089 | K12: MKYT01 | L12: 66040100MIC TS MICKEY SALUR KANTONG:CLASSIC RED:9-10 | M12: 129900 | N12: 0.9 | O12: =M12-((90*M12)/100) -> 12990 | P12: PERCENTAGE
A13: =A12 -> 2020-2021 ALL D90 | B13: =B12 -> 46099 | C13: =C12 -> 46113 | D13: 3273 | E13: 336 | F13: 4 | G13: 1 | H13: 81455 | I13: DISNEY | J13: 26132525 | K13: GCDNK02 | L13: 66020100STD TS DONALD DUCK FACE STRIPE KOTAK:CLASSIC YELLO:XS | M13: 99900 | N13: 0.9 | O13: =M13-((90*M13)/100) -> 9990 | P13: PERCENTAGE
A14: =A13 -> 2020-2021 ALL D90 | B14: =B13 -> 46099 | C14: =C13 -> 46113 | D14: 3273 | E14: 336 | F14: 4 | G14: 1 | H14: 81455 | I14: DISNEY | J14: 26132534 | K14: GCDNK02 | L14: 66020100STD TS DONALD DUCK FACE STRIPE KOTAK:CLASSIC YELLO:S | M14: 99900 | N14: 0.9 | O14: =M14-((90*M14)/100) -> 9990 | P14: PERCENTAGE
... A1902: =A1901 -> 2020-2021 ALL D90 | B1902: =B1901 -> 46099 | C1902: =C1901 -> 46113 | D1902: 3273 | E1902: 336 | F1902: 4 | G1902: 6 | H1902: 81676 | I1902: DISNEY | J1902: 31004869 | K1902: DISK116 | L1902: 66040100OAV TS AVG 9 KTK LOGO FACE DISK116:CLASSIC RED:7-8:GRAPHIC:SS T-SHIRT | M1902: 119900 | N1902: 0.9 | O1902: =M1902-((90*M1902)/100) -> 11990 | P1902: PERCENTAGE
A1903: =A1902 -> 2020-2021 ALL D90 | B1903: =B1902 -> 46099 | C1903: =C1902 -> 46113 | D1903: 3273 | E1903: 336 | F1903: 4 | G1903: 6 | H1903: 81676 | I1903: DISNEY | J1903: 28507564 | K1903: #REF! | L1903: #REF! | M1903: #REF! | N1903: 0.9 | O1903: =M1903-((90*M1903)/100) -> #REF! | P1903: PERCENTAGE
A1904: =A1903 -> 2020-2021 ALL D90 | B1904: =B1903 -> 46099 | C1904: =C1903 -> 46113 | D1904: 3273 | E1904: 336 | F1904: 4 | G1904: 7 | H1904: 81507 | I1904: DISNEY | J1904: 26571720 | K1904: 1901903 | L1904: 66020100MCS KMJ LS SPD KOKO WAFFLE FP:WHITE:S | M1904: 239900 | N1904: 0.9 | O1904: =M1904-((90*M1904)/100) -> 23990 | P1904: PERCENTAGE
A1905: =A1904 -> 2020-2021 ALL D90 | B1905: =B1904 -> 46099 | C1905: =C1904 -> 46113 | D1905: 3273 | E1905: 336 | F1905: 4 | G1905: 7 | H1905: 81507 | I1905: DISNEY | J1905: 26571748 | K1905: 1901903 | L1905: 66020100MCS KMJ LS SPD KOKO WAFFLE FP:WHITE:M | M1905: 239900 | N1905: 0.9 | O1905: =M1905-((90*M1905)/100) -> 23990 | P1905: PERCENTAGE
A1906: =A1905 -> 2020-2021 ALL D90 | B1906: =B1905 -> 46099 | C1906: =C1905 -> 46113 | D1906: 3273 | E1906: 336 | F1906: 4 | G1906: 7 | H1906: 81507 | I1906: DISNEY | J1906: 26571766 | K1906: 1901903 | L1906: 66020100MCS KMJ LS SPD KOKO WAFFLE FP:WHITE:L | M1906: 239900 | N1906: 0.9 | O1906: =M1906-((90*M1906)/100) -> 23990 | P1906: PERCENTAGE
A1907: =A1906 -> 2020-2021 ALL D90 | B1907: =B1906 -> 46099 | C1907: =C1906 -> 46113 | D1907: 3273 | E1907: 336 | F1907: 4 | G1907: 7 | H1907: 81507 | I1907: DISNEY | J1907: 26571784 | K1907: 1901903 | L1907: 66040100MCS KMJ LS SPD KOKO WAFFLE FP:WHITE:5-6 | M1907: 239900 | N1907: 0.9 | O1907: =M1907-((90*M1907)/100) -> 23990 | P1907: PERCENTAGE
A1908: =A1907 -> 2020-2021 ALL D90 | B1908: =B1907 -> 46099 | C1908: =C1907 -> 46113 | D1908: 3273 | E1908: 336 | F1908: 4 | G1908: 7 | H1908: 81507 | I1908: DISNEY | J1908: 26571800 | K1908: 1901903 | L1908: 66040100MCS KMJ LS SPD KOKO WAFFLE FP:WHITE:7-8 | M1908: 239900 | N1908: 0.9 | O1908: =M1908-((90*M1908)/100) -> 23990 | P1908: PERCENTAGE
A1909: =A1908 -> 2020-2021 ALL D90 | B1909: =B1908 -> 46099 | C1909: =C1908 -> 46113 | D1909: 3273 | E1909: 336 | F1909: 4 | G1909: 7 | H1909: 81507 | I1909: DISNEY | J1909: 26571828 | K1909: 1901903 | L1909: 66040100MCS KMJ LS SPD KOKO WAFFLE FP:WHITE:9-10 | M1909: 239900 | N1909: 0.9 | O1909: =M1909-((90*M1909)/100) -> 23990 | P1909: PERCENTAGE
A1910: =A1909 -> 2020-2021 ALL D90 | B1910: =B1909 -> 46099 | C1910: =C1909 -> 46113 | D1910: 3273 | E1910: 336 | F1910: 4 | G1910: 7 | H1910: 81507 | I1910: DISNEY | J1910: 26571846 | K1910: 1901903 | L1910: 66060100MCS KMJ LS SPD KOKO WAFFLE FP:WHITE:11-12 | M1910: 239900 | N1910: 0.9 | O1910: =M1910-((90*M1910)/100) -> 23990 | P1910: PERCENTAGE
A1911: =A1910 -> 2020-2021 ALL D90 | B1911: =B1910 -> 46099 | C1911: =C1910 -> 46113 | D1911: 3273 | E1911: 336 | F1911: 4 | G1911: 7 | H1911: 81507 | I1911: DISNEY | J1911: 26571864 | K1911: 1901903 | L1911: 66060100MCS KMJ LS SPD KOKO WAFFLE FP:WHITE:13-14 | M1911: 239900 | N1911: 0.9 | O1911: =M1911-((90*M1911)/100) -> 23990 | P1911: PERCENTAGE
A1912: =A1911 -> 2020-2021 ALL D90 | B1912: =B1911 -> 46099 | C1912: =C1911 -> 46113 | D1912: 3273 | E1912: 336 | F1912: 4 | G1912: 7 | H1912: 81507 | I1912: DISNEY | J1912: 26571882 | K1912: 1901903 | L1912: 66060100MCS KMJ LS SPD KOKO WAFFLE FP:WHITE:15-16 | M1912: 239900 | N1912: 0.9 | O1912: =M1912-((90*M1912)/100) -> 23990 | P1912: PERCENTAGE
A1913: =A1912 -> 2020-2021 ALL D90 | B1913: =B1912 -> 46099 | C1913: =C1912 -> 46113 | D1913: 3273 | E1913: 336 | F1913: 4 | G1913: 7 | H1913: 81507 | I1913: DISNEY | J1913: 26572452 | K1913: 1901904 | L1913: 66020100OAV KMJ LS AVG KOKO LOGO AMRIK:LIGHT BLUE:S | M1913: 239900 | N1913: 0.9 | O1913: =M1913-((90*M1913)/100) -> 23990 | P1913: PERCENTAGE
A1914: =A1913 -> 2020-2021 ALL D90 | B1914: =B1913 -> 46099 | C1914: =C1913 -> 46113 | D1914: 3273 | E1914: 336 | F1914: 4 | G1914: 7 | H1914: 81507 | I1914: DISNEY | J1914: 26572461 | K1914: 1901904 | L1914: 66020100OAV KMJ LS AVG KOKO LOGO AMRIK:LIGHT BLUE:M | M1914: 239900 | N1914: 0.9 | O1914: =M1914-((90*M1914)/100) -> 23990 | P1914: PERCENTAGE
A1915: =A1914 -> 2020-2021 ALL D90 | B1915: =B1914 -> 46099 | C1915: =C1914 -> 46113 | D1915: 3273 | E1915: 336 | F1915: 4 | G1915: 7 | H1915: 81507 | I1915: DISNEY | J1915: 26572470 | K1915: 1901904 | L1915: 66020100OAV KMJ LS AVG KOKO LOGO AMRIK:LIGHT BLUE:L | M1915: 239900 | N1915: 0.9 | O1915: =M1915-((90*M1915)/100) -> 23990 | P1915: PERCENTAGE
... A2181: =A2180 -> 2020-2021 ALL D90 | B2181: =B2180 -> 46099 | C2181: =C2180 -> 46113 | D2181: 3273 | E2181: 336 | F2181: 4 | G2181: 9 | H2181: 81676 | I2181: DISNEY | J2181: 28104025 | K2181: DISK70A | L2181: 66060100OAV CP KN SLR TEXTURE ZIPPER DISK70A:NAVY BLUE:11-12:SOLID:SHORT PANTS | M2181: 149900 | N2181: 0.9 | O2181: =M2181-((90*M2181)/100) -> 14990 | P2181: PERCENTAGE

Sheet 2022 ALL D90
A1: ACARA | B1: FROM DATE | C1: TO DATE | D1: DEPT | E1: WORLD | F1: DIVISION | G1: CLASS | H1: SUPPLIER | I1: BRAND | J1: SKU | K1: ARTICLE | L1: DESCRIPTION | M1: HARGA NORMAL | N1: DISKON | O1: HARGA PROMO | P1: DISCOUNT TYPE
A2: 2022 ALL D90 | B2: ='2019 ALL D95'!B2 -> 46099 | C2: ='2019 ALL D95'!C2 -> 46113 | D2: 3273 | E2: 336 | F2: 4 | G2: 11 | H2: 81588 | I2: DISNEY | J2: 55710293 | K2: A45 | L2: 66020100SWS TS SW FP MARBLE LOGO:BLACK:5-6:PRINT:SS T-SHIRT | M2: 139900 | N2: 0.9 | O2: =M2-((90*M2)/100) -> 13990 | P2: PERCENTAGE
A3: =A2 -> 2022 ALL D90 | B3: =B2 -> 46099 | C3: =C2 -> 46113 | D3: 3273 | E3: 336 | F3: 4 | G3: 11 | H3: 81588 | I3: DISNEY | J3: 55710300 | K3: A45 | L3: 66040100SWS TS SW FP MARBLE LOGO:BLACK:7-8:PRINT:SS T-SHIRT | M3: 139900 | N3: =N2 -> 0.9 | O3: =M3-((90*M3)/100) -> 13990 | P3: PERCENTAGE
A4: =A3 -> 2022 ALL D90 | B4: =B3 -> 46099 | C4: =C3 -> 46113 | D4: 3273 | E4: 336 | F4: 4 | G4: 11 | H4: 81588 | I4: DISNEY | J4: 55710319 | K4: A45 | L4: 66040100SWS TS SW FP MARBLE LOGO:BLACK:9-10:PRINT:SS T-SHIRT | M4: 139900 | N4: =N3 -> 0.9 | O4: =M4-((90*M4)/100) -> 13990 | P4: PERCENTAGE
A5: =A4 -> 2022 ALL D90 | B5: =B4 -> 46099 | C5: =C4 -> 46113 | D5: 3273 | E5: 336 | F5: 4 | G5: 11 | H5: 81588 | I5: DISNEY | J5: 55710328 | K5: A45 | L5: 66040100SWS TS SW FP MARBLE LOGO:BLACK:11-12:PRINT:SS T-SHIRT | M5: 139900 | N5: =N4 -> 0.9 | O5: =M5-((90*M5)/100) -> 13990 | P5: PERCENTAGE
A6: =A5 -> 2022 ALL D90 | B6: =B5 -> 46099 | C6: =C5 -> 46113 | D6: 3273 | E6: 336 | F6: 4 | G6: 11 | H6: 81588 | I6: DISNEY | J6: 55710337 | K6: A45 | L6: 66060100SWS TS SW FP MARBLE LOGO:BLACK:13-14:PRINT:SS T-SHIRT | M6: 139900 | N6: =N5 -> 0.9 | O6: =M6-((90*M6)/100) -> 13990 | P6: PERCENTAGE
A7: =A6 -> 2022 ALL D90 | B7: =B6 -> 46099 | C7: =C6 -> 46113 | D7: 3273 | E7: 336 | F7: 4 | G7: 11 | H7: 81588 | I7: DISNEY | J7: 55710346 | K7: A45 | L7: 660600100SWS TS SW FP MARBLE LOGO:BLACK:15-16:PRINT:SS T-SHIRT | M7: 139900 | N7: =N6 -> 0.9 | O7: =M7-((90*M7)/100) -> 13990 | P7: PERCENTAGE
A8: =A7 -> 2022 ALL D90 | B8: =B7 -> 46099 | C8: =C7 -> 46113 | D8: 3273 | E8: 336 | F8: 4 | G8: 11 | H8: 81588 | I8: DISNEY | J8: 55710355 | K8: A45 | L8: 66020100SWS TS SW FP MARBLE LOGO:BLACK:3-4:PRINT:SS T-SHIRT | M8: 139900 | N8: =N7 -> 0.9 | O8: =M8-((90*M8)/100) -> 13990 | P8: PERCENTAGE
A9: =A8 -> 2022 ALL D90 | B9: =B8 -> 46099 | C9: =C8 -> 46113 | D9: 3273 | E9: 336 | F9: 4 | G9: 11 | H9: 81588 | I9: DISNEY | J9: 55710364 | K9: A45 | L9: 66020100SWS TS SW FP MARBLE LOGO:BLACK:4-5:PRINT:SS T-SHIRT | M9: 139900 | N9: =N8 -> 0.9 | O9: =M9-((90*M9)/100) -> 13990 | P9: PERCENTAGE
A10: =A9 -> 2022 ALL D90 | B10: =B9 -> 46099 | C10: =C9 -> 46113 | D10: 3273 | E10: 336 | F10: 4 | G10: 11 | H10: 81588 | I10: DISNEY | J10: 55710426 | K10: N209 | L10: 66040100SWS TS SW STORMTROOPS:MISTY MEDIUM GRE:5-6:GRAPHIC:SS T-SHIRT | M10: 129900 | N10: =N9 -> 0.9 | O10: =M10-((90*M10)/100) -> 12990 | P10: PERCENTAGE
A11: =A10 -> 2022 ALL D90 | B11: =B10 -> 46099 | C11: =C10 -> 46113 | D11: 3273 | E11: 336 | F11: 4 | G11: 11 | H11: 81588 | I11: DISNEY | J11: 55710435 | K11: N209 | L11: 66040100SWS TS SW STORMTROOPS:MISTY MEDIUM GRE:7-8:GRAPHIC:SS T-SHIRT | M11: 129900 | N11: =N10 -> 0.9 | O11: =M11-((90*M11)/100) -> 12990 | P11: PERCENTAGE
A12: =A11 -> 2022 ALL D90 | B12: =B11 -> 46099 | C12: =C11 -> 46113 | D12: 3273 | E12: 336 | F12: 4 | G12: 11 | H12: 81588 | I12: DISNEY | J12: 55710444 | K12: N209 | L12: 66040100SWS TS SW STORMTROOPS:MISTY MEDIUM GRE:9-10:GRAPHIC:SS T-SHIRT | M12: 129900 | N12: =N11 -> 0.9 | O12: =M12-((90*M12)/100) -> 12990 | P12: PERCENTAGE
A13: =A12 -> 2022 ALL D90 | B13: =B12 -> 46099 | C13: =C12 -> 46113 | D13: 3273 | E13: 336 | F13: 4 | G13: 11 | H13: 81588 | I13: DISNEY | J13: 55710453 | K13: N209 | L13: 66060100SWS TS SW STORMTROOPS:MISTY MEDIUM GRE:11-12:GRAPHIC:SS T-SHIRT | M13: 129900 | N13: =N12 -> 0.9 | O13: =M13-((90*M13)/100) -> 12990 | P13: PERCENTAGE
A14: =A13 -> 2022 ALL D90 | B14: =B13 -> 46099 | C14: =C13 -> 46113 | D14: 3273 | E14: 336 | F14: 4 | G14: 11 | H14: 81588 | I14: DISNEY | J14: 55710462 | K14: N209 | L14: 66060100SWS TS SW STORMTROOPS:MISTY MEDIUM GRE:13-14:GRAPHIC:SS T-SHIRT | M14: 129900 | N14: =N13 -> 0.9 | O14: =M14-((90*M14)/100) -> 12990 | P14: PERCENTAGE
... A2082: =A2081 -> 2022 ALL D90 | B2082: =B2081 -> 46099 | C2082: =C2081 -> 46113 | D2082: 3273 | E2082: 336 | F2082: 4 | G2082: 12 | H2082: 81574 | I2082: DISNEY | J2082: 59363278 | K2082: KKSW11 | L2082: 66040100SWS KMJ SS KOKO SW DARTH KKSW11:WHITE:15-16:PRINT:SS SHIRT | M2082: 229900 | N2082: =N2081 -> 0.9 | O2082: =M2082-((90*M2082)/100) -> 22990 | P2082: PERCENTAGE

Sheet 2023 ALL D90
A1: ACARA | B1: FROM DATE | C1: TO DATE | D1: DEPT | E1: WORLD | F1: DIVISION | G1: CLASS | H1: SUPPLIER | I1: BRAND | J1: SKU | K1: ARTICLE | L1: DESCRIPTION | M1: HARGA NORMAL | N1: DISKON | O1: HARGA PROMO | P1: DISCOUNT TYPE
A2: 2023 ALL D90 | B2: ='2019 ALL D95'!B2 -> 46099 | C2: ='2019 ALL D95'!C2 -> 46113 | D2: 3273 | E2: 336 | F2: 4 | G2: 11 | H2: 81588 | I2: DISNEY | J2: 76763778 | K2: N508 | L2: 66040100SWS TS STARWARS DARTH VADER ANIME N508:BLACK:5-6:GRAPHIC:SS T-SHIRT | M2: 149900 | N2: 0.9 | O2: =M2-((90*M2)/100) -> 14990 | P2: PERCENTAGE
A3: =A2 -> 2023 ALL D90 | B3: =B2 -> 46099 | C3: =C2 -> 46113 | D3: 3273 | E3: 336 | F3: 4 | G3: 11 | H3: 81588 | I3: DISNEY | J3: 76763787 | K3: N508 | L3: 66040100SWS TS STARWARS DARTH VADER ANIME N508:BLACK:7-8:GRAPHIC:SS T-SHIRT | M3: 149900 | N3: =N2 -> 0.9 | O3: =M3-((90*M3)/100) -> 14990 | P3: =P2 -> PERCENTAGE
A4: =A3 -> 2023 ALL D90 | B4: =B3 -> 46099 | C4: =C3 -> 46113 | D4: 3273 | E4: 336 | F4: 4 | G4: 11 | H4: 81588 | I4: DISNEY | J4: 76763796 | K4: N508 | L4: 66040100SWS TS STARWARS DARTH VADER ANIME N508:BLACK:9-10:GRAPHIC:SS T-SHIRT | M4: 149900 | N4: =N3 -> 0.9 | O4: =M4-((90*M4)/100) -> 14990 | P4: =P3 -> PERCENTAGE
A5: =A4 -> 2023 ALL D90 | B5: =B4 -> 46099 | C5: =C4 -> 46113 | D5: 3273 | E5: 336 | F5: 4 | G5: 11 | H5: 81588 | I5: DISNEY | J5: 76763803 | K5: N508 | L5: 66060100SWS TS STARWARS DARTH VADER ANIME N508:BLACK:11-12:GRAPHIC:SS T-SHIRT | M5: 149900 | N5: =N4 -> 0.9 | O5: =M5-((90*M5)/100) -> 14990 | P5: =P4 -> PERCENTAGE
A6: =A5 -> 2023 ALL D90 | B6: =B5 -> 46099 | C6: =C5 -> 46113 | D6: 3273 | E6: 336 | F6: 4 | G6: 11 | H6: 81588 | I6: DISNEY | J6: 76763812 | K6: N508 | L6: 66060100SWS TS STARWARS DARTH VADER ANIME N508:BLACK:13-14:GRAPHIC:SS T-SHIRT | M6: 149900 | N6: =N5 -> 0.9 | O6: =M6-((90*M6)/100) -> 14990 | P6: =P5 -> PERCENTAGE
A7: =A6 -> 2023 ALL D90 | B7: =B6 -> 46099 | C7: =C6 -> 46113 | D7: 3273 | E7: 336 | F7: 4 | G7: 11 | H7: 81588 | I7: DISNEY | J7: 76763821 | K7: N508 | L7: 66060100SWS TS STARWARS DARTH VADER ANIME N508:BLACK:15-16:GRAPHIC:SS T-SHIRT | M7: 149900 | N7: =N6 -> 0.9 | O7: =M7-((90*M7)/100) -> 14990 | P7: =P6 -> PERCENTAGE
A8: =A7 -> 2023 ALL D90 | B8: =B7 -> 46099 | C8: =C7 -> 46113 | D8: 3273 | E8: 336 | F8: 4 | G8: 11 | H8: 81676 | I8: DISNEY | J8: 76764295 | K8: GNSW04 | L8: 66020100SWS TS SW CUTSEWN PRINT KTG LGN KOMB GNSW04:CHARCOAL:3-4:GRAPHIC:SS T-SHIRT | M8: 139900 | N8: =N7 -> 0.9 | O8: =M8-((90*M8)/100) -> 13990 | P8: =P7 -> PERCENTAGE
A9: =A8 -> 2023 ALL D90 | B9: =B8 -> 46099 | C9: =C8 -> 46113 | D9: 3273 | E9: 336 | F9: 4 | G9: 11 | H9: 81676 | I9: DISNEY | J9: 76764302 | K9: GNSW04 | L9: 66020100SWS TS SW CUTSEWN PRINT KTG LGN KOMB GNSW04:CHARCOAL:4-5:GRAPHIC:SS T-SHIRT | M9: 139900 | N9: =N8 -> 0.9 | O9: =M9-((90*M9)/100) -> 13990 | P9: =P8 -> PERCENTAGE
A10: =A9 -> 2023 ALL D90 | B10: =B9 -> 46099 | C10: =C9 -> 46113 | D10: 3273 | E10: 336 | F10: 4 | G10: 11 | H10: 81676 | I10: DISNEY | J10: 76764311 | K10: GNSW04 | L10: 66020100SWS TS SW CUTSEWN PRINT KTG LGN KOMB GNSW04:CHARCOAL:5-6:GRAPHIC:SS T-SHIRT | M10: 139900 | N10: =N9 -> 0.9 | O10: =M10-((90*M10)/100) -> 13990 | P10: =P9 -> PERCENTAGE
A11: =A10 -> 2023 ALL D90 | B11: =B10 -> 46099 | C11: =C10 -> 46113 | D11: 3273 | E11: 336 | F11: 4 | G11: 11 | H11: 81676 | I11: DISNEY | J11: 76764320 | K11: GNSW04 | L11: 66040100SWS TS SW CUTSEWN PRINT KTG LGN KOMB GNSW04:CHARCOAL:7-8:GRAPHIC:SS T-SHIRT | M11: 139900 | N11: =N10 -> 0.9 | O11: =M11-((90*M11)/100) -> 13990 | P11: =P10 -> PERCENTAGE
A12: =A11 -> 2023 ALL D90 | B12: =B11 -> 46099 | C12: =C11 -> 46113 | D12: 3273 | E12: 336 | F12: 4 | G12: 11 | H12: 81676 | I12: DISNEY | J12: 76764339 | K12: GNSW04 | L12: 66040100SWS TS SW CUTSEWN PRINT KTG LGN KOMB GNSW04:CHARCOAL:9-10:GRAPHIC:SS T-SHIRT | M12: 139900 | N12: =N11 -> 0.9 | O12: =M12-((90*M12)/100) -> 13990 | P12: =P11 -> PERCENTAGE
A13: =A12 -> 2023 ALL D90 | B13: =B12 -> 46099 | C13: =C12 -> 46113 | D13: 3273 | E13: 336 | F13: 4 | G13: 11 | H13: 81676 | I13: DISNEY | J13: 76764348 | K13: GNSW04 | L13: 66040100SWS TS SW CUTSEWN PRINT KTG LGN KOMB GNSW04:CHARCOAL:11-12:GRAPHIC:SS T-SHIRT | M13: 139900 | N13: =N12 -> 0.9 | O13: =M13-((90*M13)/100) -> 13990 | P13: =P12 -> PERCENTAGE
A14: =A13 -> 2023 ALL D90 | B14: =B13 -> 46099 | C14: =C13 -> 46113 | D14: 3273 | E14: 336 | F14: 4 | G14: 11 | H14: 81676 | I14: DISNEY | J14: 76764357 | K14: GNSW04 | L14: 66060100SWS TS SW CUTSEWN PRINT KTG LGN KOMB GNSW04:CHARCOAL:13-14:GRAPHIC:SS T-SHIRT | M14: 139900 | N14: =N13 -> 0.9 | O14: =M14-((90*M14)/100) -> 13990 | P14: =P13 -> PERCENTAGE
... A2059: =A2058 -> 2023 ALL D90 | B2059: =B2058 -> 46099 | C2059: =C2058 -> 46113 | D2059: 3273 | E2059: 336 | F2059: 4 | G2059: 7 | H2059: 81574 | I2059: DISNEY | J2059: 84037663 | K2059: KKRT09 | L2059: 66060100OAV SS SHIRT AVG CAPT AMRIK C KKRT09:WHITE:15-16:TEXT:SS SHIRT | M2059: 249900 | N2059: =N2058 -> 0.9 | O2059: =M2059-((90*M2059)/100) -> 24990 | P2059: =P2058 -> PERCENTAGE

Sheet 2024 JAN-JUN D70
A1: ACARA | B1: FROM DATE | C1: TO DATE | D1: DEPT | E1: WORLD | F1: DIVISION | G1: CLASS | H1: SUPPLIER | I1: BRAND | J1: SKU | K1: ARTICLE | L1: DESCRIPTION | M1: HARGA NORMAL | N1: DISKON | O1: HARGA PROMO | P1: DISCOUNT TYPE
A2: 2024 JAN-JUN D70 | B2: ='2019 ALL D95'!B2 -> 46099 | C2: ='2019 ALL D95'!C2 -> 46113 | D2: 3273 | E2: 336 | F2: 4 | G2: 11 | H2: 81676 | I2: DISNEY | J2: 86003767 | K2: GNSW10 | L2: 66020100SWS TS STARWARS MARBLE FLOCKING STAR GNSW10:WHITE:3-4:TEXT:SS T-SHIRT | M2: 139900 | N2: 0.7 | O2: =M2*(1-N2) -> 41970 | P2: PERCENTAGE
A3: =A2 -> 2024 JAN-JUN D70 | B3: =B2 -> 46099 | C3: =C2 -> 46113 | D3: 3273 | E3: 336 | F3: 4 | G3: 11 | H3: 81676 | I3: DISNEY | J3: 86003776 | K3: GNSW10 | L3: 66020100SWS TS STARWARS MARBLE FLOCKING STAR GNSW10:WHITE:4-5:TEXT:SS T-SHIRT | M3: 139900 | N3: =N2 -> 0.7 | O3: =M3*(1-N3) -> 41970 | P3: =P2 -> PERCENTAGE
A4: =A3 -> 2024 JAN-JUN D70 | B4: =B3 -> 46099 | C4: =C3 -> 46113 | D4: 3273 | E4: 336 | F4: 4 | G4: 11 | H4: 81676 | I4: DISNEY | J4: 86003785 | K4: GNSW10 | L4: 66020100SWS TS STARWARS MARBLE FLOCKING STAR GNSW10:WHITE:5-6:TEXT:SS T-SHIRT | M4: 139900 | N4: =N3 -> 0.7 | O4: =M4*(1-N4) -> 41970 | P4: =P3 -> PERCENTAGE
A5: =A4 -> 2024 JAN-JUN D70 | B5: =B4 -> 46099 | C5: =C4 -> 46113 | D5: 3273 | E5: 336 | F5: 4 | G5: 11 | H5: 81676 | I5: DISNEY | J5: 86003794 | K5: GNSW10 | L5: 66040100SWS TS STARWARS MARBLE FLOCKING STAR GNSW10:WHITE:7-8:TEXT:SS T-SHIRT | M5: 139900 | N5: =N4 -> 0.7 | O5: =M5*(1-N5) -> 41970 | P5: =P4 -> PERCENTAGE
A6: =A5 -> 2024 JAN-JUN D70 | B6: =B5 -> 46099 | C6: =C5 -> 46113 | D6: 3273 | E6: 336 | F6: 4 | G6: 11 | H6: 81676 | I6: DISNEY | J6: 86003801 | K6: GNSW10 | L6: 66040100SWS TS STARWARS MARBLE FLOCKING STAR GNSW10:WHITE:9-10:TEXT:SS T-SHIRT | M6: 139900 | N6: =N5 -> 0.7 | O6: =M6*(1-N6) -> 41970 | P6: =P5 -> PERCENTAGE
A7: =A6 -> 2024 JAN-JUN D70 | B7: =B6 -> 46099 | C7: =C6 -> 46113 | D7: 3273 | E7: 336 | F7: 4 | G7: 11 | H7: 81676 | I7: DISNEY | J7: 86003810 | K7: GNSW10 | L7: 66040100SWS TS STARWARS MARBLE FLOCKING STAR GNSW10:WHITE:11-12:TEXT:SS T-SHIRT | M7: 139900 | N7: =N6 -> 0.7 | O7: =M7*(1-N7) -> 41970 | P7: =P6 -> PERCENTAGE
A8: =A7 -> 2024 JAN-JUN D70 | B8: =B7 -> 46099 | C8: =C7 -> 46113 | D8: 3273 | E8: 336 | F8: 4 | G8: 11 | H8: 81676 | I8: DISNEY | J8: 86003829 | K8: GNSW10 | L8: 66060100SWS TS STARWARS MARBLE FLOCKING STAR GNSW10:WHITE:13-14:TEXT:SS T-SHIRT | M8: 139900 | N8: =N7 -> 0.7 | O8: =M8*(1-N8) -> 41970 | P8: =P7 -> PERCENTAGE
A9: =A8 -> 2024 JAN-JUN D70 | B9: =B8 -> 46099 | C9: =C8 -> 46113 | D9: 3273 | E9: 336 | F9: 4 | G9: 11 | H9: 81676 | I9: DISNEY | J9: 86003838 | K9: GNSW10 | L9: 66060100SWS TS STARWARS MARBLE FLOCKING STAR GNSW10:WHITE:15-16:TEXT:SS T-SHIRT | M9: 139900 | N9: =N8 -> 0.7 | O9: =M9*(1-N9) -> 41970 | P9: =P8 -> PERCENTAGE
A10: =A9 -> 2024 JAN-JUN D70 | B10: =B9 -> 46099 | C10: =C9 -> 46113 | D10: 3273 | E10: 336 | F10: 4 | G10: 11 | H10: 81588 | I10: DISNEY | J10: 15638018 | K10: A132 | L10: 66040100SWS TS STARWARS VADER THE BOSS FP A132:WHITE:5-6:GRAPHIC:SS T-SHIRT | M10: 149900 | N10: =N9 -> 0.7 | O10: =M10*(1-N10) -> 44970 | P10: =P9 -> PERCENTAGE
A11: =A10 -> 2024 JAN-JUN D70 | B11: =B10 -> 46099 | C11: =C10 -> 46113 | D11: 3273 | E11: 336 | F11: 4 | G11: 11 | H11: 81588 | I11: DISNEY | J11: 15638027 | K11: A132 | L11: 66040100SWS TS STARWARS VADER THE BOSS FP A132:WHITE:7-8:GRAPHIC:SS T-SHIRT | M11: 149900 | N11: =N10 -> 0.7 | O11: =M11*(1-N11) -> 44970 | P11: =P10 -> PERCENTAGE
A12: =A11 -> 2024 JAN-JUN D70 | B12: =B11 -> 46099 | C12: =C11 -> 46113 | D12: 3273 | E12: 336 | F12: 4 | G12: 11 | H12: 81588 | I12: DISNEY | J12: 15638036 | K12: A132 | L12: 66040100SWS TS STARWARS VADER THE BOSS FP A132:WHITE:9-10:GRAPHIC:SS T-SHIRT | M12: 149900 | N12: =N11 -> 0.7 | O12: =M12*(1-N12) -> 44970 | P12: =P11 -> PERCENTAGE
A13: =A12 -> 2024 JAN-JUN D70 | B13: =B12 -> 46099 | C13: =C12 -> 46113 | D13: 3273 | E13: 336 | F13: 4 | G13: 11 | H13: 81588 | I13: DISNEY | J13: 15638045 | K13: A132 | L13: 66060100SWS TS STARWARS VADER THE BOSS FP A132:WHITE:11-12:GRAPHIC:SS T-SHIRT | M13: 149900 | N13: =N12 -> 0.7 | O13: =M13*(1-N13) -> 44970 | P13: =P12 -> PERCENTAGE
A14: =A13 -> 2024 JAN-JUN D70 | B14: =B13 -> 46099 | C14: =C13 -> 46113 | D14: 3273 | E14: 336 | F14: 4 | G14: 11 | H14: 81588 | I14: DISNEY | J14: 15638054 | K14: A132 | L14: 66060100SWS TS STARWARS VADER THE BOSS FP A132:WHITE:13-14:GRAPHIC:SS T-SHIRT | M14: 149900 | N14: =N13 -> 0.7 | O14: =M14*(1-N14) -> 44970 | P14: =P13 -> PERCENTAGE
... A1056: =A1055 -> 2024 JAN-JUN D70 | B1056: =B1055 -> 46099 | C1056: =C1055 -> 46113 | D1056: 3273 | E1056: 336 | F1056: 4 | G1056: 10 | H1056: 81574 | I1056: DISNEY | J1056: 18869219 | K1056: TPSPD29 | L1056: 68040202MCS TOPI SPD FACE SPLASH MESH TPSPD29:CLASSIC RED:F:GRAPHIC:SS T-SHIRT | M1056: 139900 | N1056: =N1055 -> 0.7 | O1056: =M1056*(1-N1056) -> 41970 | P1056: =P1055 -> PERCENTAGE

Sheet 2024 JUL-AUG B1G2
A1: ACARA | B1: FROM DATE | C1: TO DATE | D1: DEPT | E1: WORLD | F1: DIVISION | G1: CLASS | H1: SUPPLIER | I1: BRAND | J1: SKU | K1: ARTICLE | L1: DESCRIPTION | M1: HARGA NORMAL | N1: DISKON | O1: HARGA PROMO | P1: DISCOUNT TYPE
A2: 2024 JUL-AUG B1G2 | B2: ='2019 ALL D95'!B26 -> 46099 | C2: ='2019 ALL D95'!C26 -> 46113 | D2: 3273 | E2: 336 | F2: 4 | G2: 1 | H2: 81588 | I2: DISNEY | J2: 20672533 | K2: TSNT15 | L2: 66020100TS TS TOY STORY REX FACE SMILE TAIL TSNT15:OLIVE:3-4:GRAPHIC:SS T-SHIRT | M2: 139900 | N2: BXGY | O2: B1G2 | P2: BXGY
A3: =A2 -> 2024 JUL-AUG B1G2 | B3: =B2 -> 46099 | C3: =C2 -> 46113 | D3: 3273 | E3: 336 | F3: 4 | G3: 1 | H3: 81588 | I3: DISNEY | J3: 20672542 | K3: TSNT15 | L3: 66020100TS TS TOY STORY REX FACE SMILE TAIL TSNT15:OLIVE:4-5:GRAPHIC:SS T-SHIRT | M3: 139900 | N3: =N2 -> BXGY | O3: =O2 -> B1G2 | P3: =P2 -> BXGY
A4: =A3 -> 2024 JUL-AUG B1G2 | B4: =B3 -> 46099 | C4: =C3 -> 46113 | D4: 3273 | E4: 336 | F4: 4 | G4: 1 | H4: 81588 | I4: DISNEY | J4: 20672551 | K4: TSNT15 | L4: 66020100TS TS TOY STORY REX FACE SMILE TAIL TSNT15:OLIVE:5-6:GRAPHIC:SS T-SHIRT | M4: 139900 | N4: =N3 -> BXGY | O4: =O3 -> B1G2 | P4: =P3 -> BXGY
A5: =A4 -> 2024 JUL-AUG B1G2 | B5: =B4 -> 46099 | C5: =C4 -> 46113 | D5: 3273 | E5: 336 | F5: 4 | G5: 1 | H5: 81588 | I5: DISNEY | J5: 20672560 | K5: TSNT15 | L5: 66020100TS TS TOY STORY REX FACE SMILE TAIL TSNT15:OLIVE:7-8:GRAPHIC:SS T-SHIRT | M5: 139900 | N5: =N4 -> BXGY | O5: =O4 -> B1G2 | P5: =P4 -> BXGY
A6: =A5 -> 2024 JUL-AUG B1G2 | B6: =B5 -> 46099 | C6: =C5 -> 46113 | D6: 3273 | E6: 336 | F6: 4 | G6: 1 | H6: 81588 | I6: DISNEY | J6: 20672579 | K6: TSNT15 | L6: 66020100TS TS TOY STORY REX FACE SMILE TAIL TSNT15:OLIVE:9-10:GRAPHIC:SS T-SHIRT | M6: 139900 | N6: =N5 -> BXGY | O6: =O5 -> B1G2 | P6: =P5 -> BXGY
A7: =A6 -> 2024 JUL-AUG B1G2 | B7: =B6 -> 46099 | C7: =C6 -> 46113 | D7: 3273 | E7: 336 | F7: 4 | G7: 1 | H7: 81588 | I7: DISNEY | J7: 20672588 | K7: TSN026 | L7: 66020100TS TS TOY STORY REX FEAR ME PLEASE TSN026:MISTY LIGHT KHAKI:3-4:GRAPHIC:SS T-SHIRT | M7: 139900 | N7: =N6 -> BXGY | O7: =O6 -> B1G2 | P7: =P6 -> BXGY
A8: =A7 -> 2024 JUL-AUG B1G2 | B8: =B7 -> 46099 | C8: =C7 -> 46113 | D8: 3273 | E8: 336 | F8: 4 | G8: 1 | H8: 81588 | I8: DISNEY | J8: 20672597 | K8: TSN026 | L8: 66020100TS TS TOY STORY REX FEAR ME PLEASE TSN026:MISTY LIGHT KHAKI:4-5:GRAPHIC:SS T-SHIRT | M8: 139900 | N8: =N7 -> BXGY | O8: =O7 -> B1G2 | P8: =P7 -> BXGY
A9: =A8 -> 2024 JUL-AUG B1G2 | B9: =B8 -> 46099 | C9: =C8 -> 46113 | D9: 3273 | E9: 336 | F9: 4 | G9: 1 | H9: 81588 | I9: DISNEY | J9: 20672604 | K9: TSN026 | L9: 66020100TS TS TOY STORY REX FEAR ME PLEASE TSN026:MISTY LIGHT KHAKI:5-6:GRAPHIC:SS T-SHIRT | M9: 139900 | N9: =N8 -> BXGY | O9: =O8 -> B1G2 | P9: =P8 -> BXGY
A10: =A9 -> 2024 JUL-AUG B1G2 | B10: =B9 -> 46099 | C10: =C9 -> 46113 | D10: 3273 | E10: 336 | F10: 4 | G10: 1 | H10: 81588 | I10: DISNEY | J10: 20672613 | K10: TSN026 | L10: 66020100TS TS TOY STORY REX FEAR ME PLEASE TSN026:MISTY LIGHT KHAKI:7-8:GRAPHIC:SS T-SHIRT | M10: 139900 | N10: =N9 -> BXGY | O10: =O9 -> B1G2 | P10: =P9 -> BXGY
A11: =A10 -> 2024 JUL-AUG B1G2 | B11: =B10 -> 46099 | C11: =C10 -> 46113 | D11: 3273 | E11: 336 | F11: 4 | G11: 1 | H11: 81588 | I11: DISNEY | J11: 20672622 | K11: TSN026 | L11: 66020100TS TS TOY STORY REX FEAR ME PLEASE TSN026:MISTY LIGHT KHAKI:9-10:GRAPHIC:SS T-SHIRT | M11: 139900 | N11: =N10 -> BXGY | O11: =O10 -> B1G2 | P11: =P10 -> BXGY
A12: =A11 -> 2024 JUL-AUG B1G2 | B12: =B11 -> 46099 | C12: =C11 -> 46113 | D12: 3273 | E12: 336 | F12: 4 | G12: 11 | H12: 81588 | I12: DISNEY | J12: 19918208 | K12: HNT18 | L12: 66040100SWS TS STARWARS DARTH VADER DARK SIDE HNT18:BLACK:5-6:GRAPHIC:SS T-SHIRT | M12: 139900 | N12: =N11 -> BXGY | O12: =O11 -> B1G2 | P12: =P11 -> BXGY
A13: =A12 -> 2024 JUL-AUG B1G2 | B13: =B12 -> 46099 | C13: =C12 -> 46113 | D13: 3273 | E13: 336 | F13: 4 | G13: 11 | H13: 81588 | I13: DISNEY | J13: 19918217 | K13: HNT18 | L13: 66040100SWS TS STARWARS DARTH VADER DARK SIDE HNT18:BLACK:7-8:GRAPHIC:SS T-SHIRT | M13: 139900 | N13: =N12 -> BXGY | O13: =O12 -> B1G2 | P13: =P12 -> BXGY
A14: =A13 -> 2024 JUL-AUG B1G2 | B14: =B13 -> 46099 | C14: =C13 -> 46113 | D14: 3273 | E14: 336 | F14: 4 | G14: 11 | H14: 81588 | I14: DISNEY | J14: 19918226 | K14: HNT18 | L14: 66040100SWS TS STARWARS DARTH VADER DARK SIDE HNT18:BLACK:9-10:GRAPHIC:SS T-SHIRT | M14: 139900 | N14: =N13 -> BXGY | O14: =O13 -> B1G2 | P14: =P13 -> BXGY
... A243: =A242 -> 2024 JUL-AUG B1G2 | B243: =B242 -> 46099 | C243: =C242 -> 46113 | D243: 3273 | E243: 336 | F243: 4 | G243: 8 | H243: 81588 | I243: DISNEY | J243: 23128625 | K243: HR419 | L243: 66060100MCS SWEATSHIRT SPD WEB HEAD LGN ATAS KOMB HR419:NAVY BLUE:15-16:GRAPHIC:SWEATSHIRT | M243: 239900 | N243: =N242 -> BXGY | O243: =O242 -> B1G2 | P243: =P242 -> BXGY

Sheet 2024 OCT-DES B1G2
A1: ACARA | B1: FROM DATE | C1: TO DATE | D1: DEPT | E1: WORLD | F1: DIVISION | G1: CLASS | H1: SUPPLIER | I1: BRAND | J1: SKU | K1: ARTICLE | L1: DESCRIPTION | M1: HARGA NORMAL | N1: DISKON | O1: HARGA PROMO | P1: DISCOUNT TYPE
A2: 2024 OCT-DES B1G2 | B2: ='2024 JUL-AUG B1G2'!B243 -> 46099 | C2: ='2024 JUL-AUG B1G2'!C243 -> 46113 | D2: 3273 | E2: 336 | F2: 4 | G2: 7 | H2: 81574 | I2: DISNEY | J2: 45248286 | K2: KSPDCL72 | L2: 66020100MCS SS SHIRT SPD DENIM LASER PRNT KTG FACE KSPDCL72:DARK DENIM:3-4:GRAPHIC:SS SHIRT | M2: 259900 | N2: ='2024 JUL-AUG B1G2'!N243 -> BXGY | O2: B1G2 | P2: ='2024 JUL-AUG B1G2'!P243 -> BXGY
A3: =A2 -> 2024 OCT-DES B1G2 | B3: =B2 -> 46099 | C3: =C2 -> 46113 | D3: 3273 | E3: 336 | F3: 4 | G3: 7 | H3: 81574 | I3: DISNEY | J3: 45248295 | K3: KSPDCL72 | L3: 66020100MCS SS SHIRT SPD DENIM LASER PRNT KTG FACE KSPDCL72:DARK DENIM:4-5:GRAPHIC:SS SHIRT | M3: 259900 | N3: =N2 -> BXGY | O3: =O2 -> B1G2 | P3: =P2 -> BXGY
A4: =A3 -> 2024 OCT-DES B1G2 | B4: =B3 -> 46099 | C4: =C3 -> 46113 | D4: 3273 | E4: 336 | F4: 4 | G4: 7 | H4: 81574 | I4: DISNEY | J4: 45248302 | K4: KSPDCL72 | L4: 66020100MCS SS SHIRT SPD DENIM LASER PRNT KTG FACE KSPDCL72:DARK DENIM:5-6:GRAPHIC:SS SHIRT | M4: 259900 | N4: =N3 -> BXGY | O4: =O3 -> B1G2 | P4: =P3 -> BXGY
A5: =A4 -> 2024 OCT-DES B1G2 | B5: =B4 -> 46099 | C5: =C4 -> 46113 | D5: 3273 | E5: 336 | F5: 4 | G5: 7 | H5: 81574 | I5: DISNEY | J5: 45248311 | K5: KSPDCL72 | L5: 66020100MCS SS SHIRT SPD DENIM LASER PRNT KTG FACE KSPDCL72:DARK DENIM:7-8:GRAPHIC:SS SHIRT | M5: 259900 | N5: =N4 -> BXGY | O5: =O4 -> B1G2 | P5: =P4 -> BXGY
A6: =A5 -> 2024 OCT-DES B1G2 | B6: =B5 -> 46099 | C6: =C5 -> 46113 | D6: 3273 | E6: 336 | F6: 4 | G6: 7 | H6: 81574 | I6: DISNEY | J6: 45248320 | K6: KSPDCL72 | L6: 66020100MCS SS SHIRT SPD DENIM LASER PRNT KTG FACE KSPDCL72:DARK DENIM:9-10:GRAPHIC:SS SHIRT | M6: 259900 | N6: =N5 -> BXGY | O6: =O5 -> B1G2 | P6: =P5 -> BXGY
A7: =A6 -> 2024 OCT-DES B1G2 | B7: =B6 -> 46099 | C7: =C6 -> 46113 | D7: 3273 | E7: 336 | F7: 4 | G7: 7 | H7: 81574 | I7: DISNEY | J7: 45248339 | K7: KSPDCL72 | L7: 66020100MCS SS SHIRT SPD DENIM LASER PRNT KTG FACE KSPDCL72:DARK DENIM:11-12:GRAPHIC:SS SHIRT | M7: 259900 | N7: =N6 -> BXGY | O7: =O6 -> B1G2 | P7: =P6 -> BXGY
A8: =A7 -> 2024 OCT-DES B1G2 | B8: =B7 -> 46099 | C8: =C7 -> 46113 | D8: 3273 | E8: 336 | F8: 4 | G8: 7 | H8: 81574 | I8: DISNEY | J8: 45248348 | K8: KSPDCL72 | L8: 66020100MCS SS SHIRT SPD DENIM LASER PRNT KTG FACE KSPDCL72:DARK DENIM:13-14:GRAPHIC:SS SHIRT | M8: 259900 | N8: =N7 -> BXGY | O8: =O7 -> B1G2 | P8: =P7 -> BXGY
A9: =A8 -> 2024 OCT-DES B1G2 | B9: =B8 -> 46099 | C9: =C8 -> 46113 | D9: 3273 | E9: 336 | F9: 4 | G9: 7 | H9: 81574 | I9: DISNEY | J9: 45248357 | K9: KSPDCL72 | L9: 66020100MCS SS SHIRT SPD DENIM LASER PRNT KTG FACE KSPDCL72:DARK DENIM:15-16:GRAPHIC:SS SHIRT | M9: 259900 | N9: =N8 -> BXGY | O9: =O8 -> B1G2 | P9: =P8 -> BXGY
A10: =A9 -> 2024 OCT-DES B1G2 | B10: =B9 -> 46099 | C10: =C9 -> 46113 | D10: 3273 | E10: 336 | F10: 4 | G10: 7 | H10: 81574 | I10: DISNEY | J10: 45248366 | K10: KSPDCL150 | L10: 66020100MCS SS SHIRT SPD KOTAK KTG PARKA KSPDCL150:CLASSIC RED:3-4:CHECKS:SS SHIRT | M10: 249900 | N10: =N9 -> BXGY | O10: =O9 -> B1G2 | P10: =P9 -> BXGY
A11: =A10 -> 2024 OCT-DES B1G2 | B11: =B10 -> 46099 | C11: =C10 -> 46113 | D11: 3273 | E11: 336 | F11: 4 | G11: 7 | H11: 81574 | I11: DISNEY | J11: 45248375 | K11: KSPDCL150 | L11: 66020100MCS SS SHIRT SPD KOTAK KTG PARKA KSPDCL150:CLASSIC RED:4-5:CHECKS:SS SHIRT | M11: 249900 | N11: =N10 -> BXGY | O11: =O10 -> B1G2 | P11: =P10 -> BXGY
A12: =A11 -> 2024 OCT-DES B1G2 | B12: =B11 -> 46099 | C12: =C11 -> 46113 | D12: 3273 | E12: 336 | F12: 4 | G12: 7 | H12: 81574 | I12: DISNEY | J12: 45248384 | K12: KSPDCL150 | L12: 66020100MCS SS SHIRT SPD KOTAK KTG PARKA KSPDCL150:CLASSIC RED:5-6:CHECKS:SS SHIRT | M12: 249900 | N12: =N11 -> BXGY | O12: =O11 -> B1G2 | P12: =P11 -> BXGY
A13: =A12 -> 2024 OCT-DES B1G2 | B13: =B12 -> 46099 | C13: =C12 -> 46113 | D13: 3273 | E13: 336 | F13: 4 | G13: 7 | H13: 81574 | I13: DISNEY | J13: 45248393 | K13: KSPDCL150 | L13: 66020100MCS SS SHIRT SPD KOTAK KTG PARKA KSPDCL150:CLASSIC RED:7-8:CHECKS:SS SHIRT | M13: 249900 | N13: =N12 -> BXGY | O13: =O12 -> B1G2 | P13: =P12 -> BXGY
A14: =A13 -> 2024 OCT-DES B1G2 | B14: =B13 -> 46099 | C14: =C13 -> 46113 | D14: 3273 | E14: 336 | F14: 4 | G14: 7 | H14: 81574 | I14: DISNEY | J14: 45248400 | K14: KSPDCL150 | L14: 66020100MCS SS SHIRT SPD KOTAK KTG PARKA KSPDCL150:CLASSIC RED:9-10:CHECKS:SS SHIRT | M14: 249900 | N14: =N13 -> BXGY | O14: =O13 -> B1G2 | P14: =P13 -> BXGY
... A99: =A98 -> 2024 OCT-DES B1G2 | B99: =B98 -> 46099 | C99: =C98 -> 46113 | D99: 3273 | E99: 336 | F99: 4 | G99: 1 | H99: 81676 | I99: DISNEY | J99: 45247072 | K99: GNDN09 | L99: 66020100TS TS TOYS STORY BUZZ RESCUE PATCH GNDN09:PASTEL GREY:3-4:GRAPHIC:SS T-SHIRT | M99: 139900 | N99: =N98 -> BXGY | O99: =O98 -> B1G2 | P99: =P98 -> BXGY
A100: =A99 -> 2024 OCT-DES B1G2 | B100: =B99 -> 46099 | C100: =C99 -> 46113 | D100: 3273 | E100: 336 | F100: 4 | G100: 1 | H100: 81676 | I100: =I99 -> DISNEY | J100: 45247081 | K100: GNDN09 | L100: 66020100TS TS TOYS STORY BUZZ RESCUE PATCH GNDN09:PASTEL GREY:4-5:GRAPHIC:SS T-SHIRT | M100: 139900 | N100: =N99 -> BXGY | O100: =O99 -> B1G2 | P100: =P99 -> BXGY
A101: =A100 -> 2024 OCT-DES B1G2 | B101: =B100 -> 46099 | C101: =C100 -> 46113 | D101: 3273 | E101: 336 | F101: 4 | G101: 1 | H101: 81676 | I101: =I100 -> DISNEY | J101: 45247090 | K101: GNDN09 | L101: 66020100TS TS TOYS STORY BUZZ RESCUE PATCH GNDN09:PASTEL GREY:5-6:GRAPHIC:SS T-SHIRT | M101: 139900 | N101: =N100 -> BXGY | O101: =O100 -> B1G2 | P101: =P100 -> BXGY
A102: =A101 -> 2024 OCT-DES B1G2 | B102: =B101 -> 46099 | C102: =C101 -> 46113 | D102: 3273 | E102: 336 | F102: 4 | G102: 1 | H102: 81676 | I102: =I101 -> DISNEY | J102: 45247107 | K102: GNDN09 | L102: 66020100TS TS TOYS STORY BUZZ RESCUE PATCH GNDN09:PASTEL GREY:7-8:GRAPHIC:SS T-SHIRT | M102: 139900 | N102: =N101 -> BXGY | O102: =O101 -> B1G2 | P102: =P101 -> BXGY
A103: =A102 -> 2024 OCT-DES B1G2 | B103: =B102 -> 46099 | C103: =C102 -> 46113 | D103: 3273 | E103: 336 | F103: 4 | G103: 1 | H103: 81676 | I103: =I102 -> DISNEY | J103: 45247116 | K103: GNDN09 | L103: 66020100TS TS TOYS STORY BUZZ RESCUE PATCH GNDN09:PASTEL GREY:9-10:GRAPHIC:SS T-SHIRT | M103: 139900 | N103: =N102 -> BXGY | O103: =O102 -> B1G2 | P103: =P102 -> BXGY
A104: =A103 -> 2024 OCT-DES B1G2 | B104: =B103 -> 46099 | C104: =C103 -> 46113 | D104: 3273 | E104: 336 | F104: 4 | G104: 1 | H104: 81676 | I104: =I103 -> DISNEY | J104: 45247125 | K104: GNDN09 | L104: 66020100TS TS TOYS STORY BUZZ RESCUE PATCH GNDN09:PASTEL GREY:11-12:GRAPHIC:SS T-SHIRT | M104: 139900 | N104: =N103 -> BXGY | O104: =O103 -> B1G2 | P104: =P103 -> BXGY
A105: =A104 -> 2024 OCT-DES B1G2 | B105: =B104 -> 46099 | C105: =C104 -> 46113 | D105: 3273 | E105: 336 | F105: 4 | G105: 1 | H105: 81676 | I105: =I104 -> DISNEY | J105: 45247134 | K105: GNDN10 | L105: 66020100TS TS TOYS STORY BUZZ GALAXY FP GNDN10:CLASSIC BLUE:3-4:PRINT:SS T-SHIRT | M105: 139900 | N105: =N104 -> BXGY | O105: =O104 -> B1G2 | P105: =P104 -> BXGY
A106: =A105 -> 2024 OCT-DES B1G2 | B106: =B105 -> 46099 | C106: =C105 -> 46113 | D106: 3273 | E106: 336 | F106: 4 | G106: 1 | H106: 81676 | I106: =I105 -> DISNEY | J106: 45247143 | K106: GNDN10 | L106: 66020100TS TS TOYS STORY BUZZ GALAXY FP GNDN10:CLASSIC BLUE:4-5:PRINT:SS T-SHIRT | M106: 139900 | N106: =N105 -> BXGY | O106: =O105 -> B1G2 | P106: =P105 -> BXGY
A107: =A106 -> 2024 OCT-DES B1G2 | B107: =B106 -> 46099 | C107: =C106 -> 46113 | D107: 3273 | E107: 336 | F107: 4 | G107: 1 | H107: 81676 | I107: =I106 -> DISNEY | J107: 45247152 | K107: GNDN10 | L107: 66020100TS TS TOYS STORY BUZZ GALAXY FP GNDN10:CLASSIC BLUE:5-6:PRINT:SS T-SHIRT | M107: 139900 | N107: =N106 -> BXGY | O107: =O106 -> B1G2 | P107: =P106 -> BXGY
A108: =A107 -> 2024 OCT-DES B1G2 | B108: =B107 -> 46099 | C108: =C107 -> 46113 | D108: 3273 | E108: 336 | F108: 4 | G108: 1 | H108: 81676 | I108: =I107 -> DISNEY | J108: 45247161 | K108: GNDN10 | L108: 66020100TS TS TOYS STORY BUZZ GALAXY FP GNDN10:CLASSIC BLUE:7-8:PRINT:SS T-SHIRT | M108: 139900 | N108: =N107 -> BXGY | O108: =O107 -> B1G2 | P108: =P107 -> BXGY
A109: =A108 -> 2024 OCT-DES B1G2 | B109: =B108 -> 46099 | C109: =C108 -> 46113 | D109: 3273 | E109: 336 | F109: 4 | G109: 1 | H109: 81676 | I109: =I108 -> DISNEY | J109: 45247170 | K109: GNDN10 | L109: 66020100TS TS TOYS STORY BUZZ GALAXY FP GNDN10:CLASSIC BLUE:9-10:PRINT:SS T-SHIRT | M109: 139900 | N109: =N108 -> BXGY | O109: =O108 -> B1G2 | P109: =P108 -> BXGY
A110: =A109 -> 2024 OCT-DES B1G2 | B110: =B109 -> 46099 | C110: =C109 -> 46113 | D110: 3273 | E110: 336 | F110: 4 | G110: 1 | H110: 81676 | I110: =I109 -> DISNEY | J110: 45247189 | K110: GNDN10 | L110: 66020100TS TS TOYS STORY BUZZ GALAXY FP GNDN10:CLASSIC BLUE:11-12:PRINT:SS T-SHIRT | M110: 139900 | N110: =N109 -> BXGY | O110: =O109 -> B1G2 | P110: =P109 -> BXGY
A111: =A110 -> 2024 OCT-DES B1G2 | B111: =B110 -> 46099 | C111: =C110 -> 46113 | D111: 3273 | E111: 336 | F111: 4 | G111: 1 | H111: 81676 | I111: =I110 -> DISNEY | J111: 45247198 | K111: GNDN08 | L111: 66020100TS TS TOYS STORY REX TYRANNOSAURUS GNDN08:CLASSIC GREEN:3-4:GRAPHIC:SS T-SHIRT | M111: 129900 | N111: =N110 -> BXGY | O111: =O110 -> B1G2 | P111: =P110 -> BXGY
... A288: =A287 -> 2024 OCT-DES B1G2 | B288: =B287 -> 46099 | C288: =C287 -> 46113 | D288: 3273 | E288: 336 | F288: 4 | G288: 6 | H288: 81676 | I288: =I287 -> DISNEY | J288: 82609889 | K288: GNAVG38 | L288: 66020100OAV TS AVG MARVEL EMBOSS CHAR FP GNAVG38:NAVY BLUE:15-16:TEXT:SS T-SHIRT | M288: 139900 | N288: =N287 -> BXGY | O288: =O287 -> B1G2 | P288: =P287 -> BXGY
A289: =A288 -> 2024 OCT-DES B1G2 | B289: =B288 -> 46099 | C289: =C288 -> 46113 | D289: 3273 | E289: 336 | F289: 4 | G289: 10 | H289: 81574 | I289: DISNEY | J289: 45920503 | K289: TPAVGR28 | L289: 68040202OAV TOPI AVG LOGO CAPT AMRIK TIEDYE STRIPE TPAVGR28:WHITE:F:PRINT:CAPS | M289: 149900 | N289: =N288 -> BXGY | O289: =O288 -> B1G2 | P289: =P288 -> BXGY
A290: =A289 -> 2024 OCT-DES B1G2 | B290: =B289 -> 46099 | C290: =C289 -> 46113 | D290: =D289 -> 3273 | E290: =E289 -> 336 | F290: =F289 -> 4 | G290: 10 | H290: 81574 | I290: =I289 -> DISNEY | J290: 45920512 | K290: TPAVGR35 | L290: 68040202OAV TOPI AVG LOGO OMBRE FP COMIC TPAVGR35:WHITE:F:PRINT:CAPS | M290: 149900 | N290: =N289 -> BXGY | O290: =O289 -> B1G2 | P290: =P289 -> BXGY
A291: =A290 -> 2024 OCT-DES B1G2 | B291: =B290 -> 46099 | C291: =C290 -> 46113 | D291: =D290 -> 3273 | E291: =E290 -> 336 | F291: =F290 -> 4 | G291: 10 | H291: 81574 | I291: =I290 -> DISNEY | J291: 45921360 | K291: TPSPDR33 | L291: 68040202MCS TOPI SPIDERMAN FACE POLOS TPSPDR33:BLACK:F:PRINT:CAPS | M291: 139900 | N291: =N290 -> BXGY | O291: =O290 -> B1G2 | P291: =P290 -> BXGY
A292: =A291 -> 2024 OCT-DES B1G2 | B292: =B291 -> 46099 | C292: =C291 -> 46113 | D292: =D291 -> 3273 | E292: =E291 -> 336 | F292: =F291 -> 4 | G292: 10 | H292: 81574 | I292: =I291 -> DISNEY | J292: 48258359 | K292: TPAVG27 | L292: 68040202OAV TOPI AVG CAPT FIRST AVG TIEDYE TPAVG27:NAVY BLUE:F:PRINT:CAPS | M292: 149900 | N292: =N291 -> BXGY | O292: =O291 -> B1G2 | P292: =P291 -> BXGY
A293: =A292 -> 2024 OCT-DES B1G2 | B293: =B292 -> 46099 | C293: =C292 -> 46113 | D293: =D292 -> 3273 | E293: =E292 -> 336 | F293: =F292 -> 4 | G293: 10 | H293: 81574 | I293: =I292 -> DISNEY | J293: 48258368 | K293: TPSPD30A | L293: 68040202MCS TOPI SPD AMAZING FACE SPLASH TPSPD30A:BLACK:F:GRAPHIC:CAPS | M293: 139900 | N293: =N292 -> BXGY | O293: =O292 -> B1G2 | P293: =P292 -> BXGY
A294: =A293 -> 2024 OCT-DES B1G2 | B294: =B293 -> 46099 | C294: =C293 -> 46113 | D294: =D293 -> 3273 | E294: =E293 -> 336 | F294: =F293 -> 4 | G294: 9 | H294: 81588 | I294: =I293 -> DISNEY | J294: 45920683 | K294: N062 | L294: 66020100MCS LP KNIT SPD FACE DOUBLE KTG TAPE N062:NAVY BLUE:3-4:GRAPHIC:LONG PANTS | M294: 239900 | N294: =N293 -> BXGY | O294: =O293 -> B1G2 | P294: =P293 -> BXGY
A295: =A294 -> 2024 OCT-DES B1G2 | B295: =B294 -> 46099 | C295: =C294 -> 46113 | D295: =D294 -> 3273 | E295: =E294 -> 336 | F295: =F294 -> 4 | G295: 9 | H295: 81588 | I295: =I294 -> DISNEY | J295: 45920692 | K295: N062 | L295: 66020100MCS LP KNIT SPD FACE DOUBLE KTG TAPE N062:NAVY BLUE:4-5:GRAPHIC:LONG PANTS | M295: 239900 | N295: =N294 -> BXGY | O295: =O294 -> B1G2 | P295: =P294 -> BXGY
A296: =A295 -> 2024 OCT-DES B1G2 | B296: =B295 -> 46099 | C296: =C295 -> 46113 | D296: =D295 -> 3273 | E296: =E295 -> 336 | F296: =F295 -> 4 | G296: 9 | H296: 81588 | I296: =I295 -> DISNEY | J296: 45920709 | K296: N062 | L296: 66020100MCS LP KNIT SPD FACE DOUBLE KTG TAPE N062:NAVY BLUE:5-6:GRAPHIC:LONG PANTS | M296: 239900 | N296: =N295 -> BXGY | O296: =O295 -> B1G2 | P296: =P295 -> BXGY
A297: =A296 -> 2024 OCT-DES B1G2 | B297: =B296 -> 46099 | C297: =C296 -> 46113 | D297: =D296 -> 3273 | E297: =E296 -> 336 | F297: =F296 -> 4 | G297: 9 | H297: 81588 | I297: =I296 -> DISNEY | J297: 45920718 | K297: N062 | L297: 66040100MCS LP KNIT SPD FACE DOUBLE KTG TAPE N062:NAVY BLUE:7-8:GRAPHIC:LONG PANTS | M297: 239900 | N297: =N296 -> BXGY | O297: =O296 -> B1G2 | P297: =P296 -> BXGY
A298: =A297 -> 2024 OCT-DES B1G2 | B298: =B297 -> 46099 | C298: =C297 -> 46113 | D298: =D297 -> 3273 | E298: =E297 -> 336 | F298: =F297 -> 4 | G298: 9 | H298: 81588 | I298: =I297 -> DISNEY | J298: 45920727 | K298: N062 | L298: 66040100MCS LP KNIT SPD FACE DOUBLE KTG TAPE N062:NAVY BLUE:9-10:GRAPHIC:LONG PANTS | M298: 239900 | N298: =N297 -> BXGY | O298: =O297 -> B1G2 | P298: =P297 -> BXGY
A299: =A298 -> 2024 OCT-DES B1G2 | B299: =B298 -> 46099 | C299: =C298 -> 46113 | D299: =D298 -> 3273 | E299: =E298 -> 336 | F299: =F298 -> 4 | G299: 9 | H299: 81588 | I299: =I298 -> DISNEY | J299: 45920736 | K299: N062 | L299: 66040100MCS LP KNIT SPD FACE DOUBLE KTG TAPE N062:NAVY BLUE:11-12:GRAPHIC:LONG PANTS | M299: 239900 | N299: =N298 -> BXGY | O299: =O298 -> B1G2 | P299: =P298 -> BXGY
A300: =A299 -> 2024 OCT-DES B1G2 | B300: =B299 -> 46099 | C300: =C299 -> 46113 | D300: =D299 -> 3273 | E300: =E299 -> 336 | F300: =F299 -> 4 | G300: 9 | H300: 81588 | I300: =I299 -> DISNEY | J300: 45920745 | K300: N062 | L300: 66060100MCS LP KNIT SPD FACE DOUBLE KTG TAPE N062:NAVY BLUE:13-14:GRAPHIC:LONG PANTS | M300: 239900 | N300: =N299 -> BXGY | O300: =O299 -> B1G2 | P300: =P299 -> BXGY
...

Sheet KOSTUM D80
A1: ACARA | B1: FROM DATE | C1: TO DATE | D1: DEPT | E1: WORLD | F1: DIVISION | G1: CLASS | H1: SUPPLIER | I1: BRAND | J1: SKU | K1: ARTICLE | L1: DESCRIPTION | M1: HARGA NORMAL | N1: DISKON | O1: HARGA PROMO | P1: DISCOUNT TYPE
A2: KOSTUM D80 | B2: ='2019 ALL D95'!B26 -> 46099 | C2: ='2019 ALL D95'!C26 -> 46113 | D2: 3273 | E2: 336 | F2: 4 | G2: 1 | H2: 81588 | I2: DISNEY | J2: 18633553 | K2: TOYSA01 | L2: 66020100TS KOSTUM TOYSTORY WOODY:GOLDEN BROWN:3-4:GRAPHIC:LS T-SHIRT | M2: 279900 | N2: 0.8 | O2: =M2-((80*M2)/100) -> 55980 | P2: PERCENTAGE
A3: =A2 -> KOSTUM D80 | B3: =B2 -> 46099 | C3: =C2 -> 46113 | D3: 3273 | E3: 336 | F3: 4 | G3: 1 | H3: 81588 | I3: DISNEY | J3: 18633562 | K3: TOYSA01 | L3: 66020100TS KOSTUM TOYSTORY WOODY:GOLDEN BROWN:4-5:GRAPHIC:LS T-SHIRT | M3: 279900 | N3: =N2 -> 0.8 | O3: =M3-((80*M3)/100) -> 55980 | P3: =P2 -> PERCENTAGE
A4: =A3 -> KOSTUM D80 | B4: =B3 -> 46099 | C4: =C3 -> 46113 | D4: 3273 | E4: 336 | F4: 4 | G4: 1 | H4: 81588 | I4: DISNEY | J4: 18633571 | K4: TOYSA01 | L4: 66020100TS KOSTUM TOYSTORY WOODY:GOLDEN BROWN:5-6:GRAPHIC:LS T-SHIRT | M4: 279900 | N4: =N3 -> 0.8 | P4: =P3 -> PERCENTAGE
A5: =A4 -> KOSTUM D80 | B5: =B4 -> 46099 | C5: =C4 -> 46113 | D5: 3273 | E5: 336 | F5: 4 | G5: 1 | H5: 81588 | I5: DISNEY | J5: 18633580 | K5: TOYSA01 | L5: 66020100TS KOSTUM TOYSTORY WOODY:GOLDEN BROWN:7-8:GRAPHIC:LS T-SHIRT | M5: 279900 | N5: =N4 -> 0.8 | O5: =M5-((80*M5)/100) -> 55980 | P5: =P4 -> PERCENTAGE
A6: =A5 -> KOSTUM D80 | B6: =B5 -> 46099 | C6: =C5 -> 46113 | D6: 3273 | E6: 336 | F6: 4 | G6: 1 | H6: 81588 | I6: DISNEY | J6: 18633599 | K6: TOYSA01 | L6: 66020100TS KOSTUM TOYSTORY WOODY:GOLDEN BROWN:9-10:GRAPHIC:LS T-SHIRT | M6: 279900 | N6: =N5 -> 0.8 | O6: =M6-((80*M6)/100) -> 55980 | P6: =P5 -> PERCENTAGE
A7: =A6 -> KOSTUM D80 | B7: =B6 -> 46099 | C7: =C6 -> 46113 | D7: 3273 | E7: 336 | F7: 4 | G7: 1 | H7: 81588 | I7: DISNEY | J7: 18633606 | K7: TOYSA02 | L7: 66020100TS KOSTUM TOYSTORY BUZZ LIGHTYEAR:WHITE:3-4:GRAPHIC:LS T-SHIRT | M7: 279900 | N7: =N6 -> 0.8 | O7: =M7-((80*M7)/100) -> 55980 | P7: =P6 -> PERCENTAGE
A8: =A7 -> KOSTUM D80 | B8: =B7 -> 46099 | C8: =C7 -> 46113 | D8: 3273 | E8: 336 | F8: 4 | G8: 1 | H8: 81588 | I8: DISNEY | J8: 18633633 | K8: TOYSA02 | L8: 66020100TS KOSTUM TOYSTORY BUZZ LIGHTYEAR:WHITE:4-5:GRAPHIC:LS T-SHIRT | M8: 279900 | N8: =N7 -> 0.8 | O8: =M8-((80*M8)/100) -> 55980 | P8: =P7 -> PERCENTAGE
A9: =A8 -> KOSTUM D80 | B9: =B8 -> 46099 | C9: =C8 -> 46113 | D9: 3273 | E9: 336 | F9: 4 | G9: 1 | H9: 81588 | I9: DISNEY | J9: 18633642 | K9: TOYSA02 | L9: 66020100TS KOSTUM TOYSTORY BUZZ LIGHTYEAR:WHITE:5-6:GRAPHIC:LS T-SHIRT | M9: 279900 | N9: =N8 -> 0.8 | O9: =M9-((80*M9)/100) -> 55980 | P9: =P8 -> PERCENTAGE
A10: =A9 -> KOSTUM D80 | B10: =B9 -> 46099 | C10: =C9 -> 46113 | D10: 3273 | E10: 336 | F10: 4 | G10: 1 | H10: 81588 | I10: DISNEY | J10: 18633651 | K10: TOYSA02 | L10: 66020100TS KOSTUM TOYSTORY BUZZ LIGHTYEAR:WHITE:7-8:GRAPHIC:LS T-SHIRT | M10: 279900 | N10: =N9 -> 0.8 | O10: =M10-((80*M10)/100) -> 55980 | P10: =P9 -> PERCENTAGE
A11: =A10 -> KOSTUM D80 | B11: =B10 -> 46099 | C11: =C10 -> 46113 | D11: 3273 | E11: 336 | F11: 4 | G11: 1 | H11: 81588 | I11: DISNEY | J11: 18633679 | K11: TOYSA02 | L11: 66020100TS KOSTUM TOYSTORY BUZZ LIGHTYEAR:WHITE:9-10:GRAPHIC:LS T-SHIRT | M11: 279900 | N11: =N10 -> 0.8 | O11: =M11-((80*M11)/100) -> 55980 | P11: =P10 -> PERCENTAGE
A12: =A11 -> KOSTUM D80 | B12: =B11 -> 46099 | C12: =C11 -> 46113 | D12: 3273 | E12: 336 | F12: 4 | G12: 6 | H12: 81588 | I12: DISNEY | J12: 84318681 | K12: N820 | L12: 66020100MCS KOSTUM SPIDERMAN LOOK-A-LIKE N820:CLASSIC RED:3-4:PRINT:COSTUME | M12: 279900 | N12: =N11 -> 0.8 | O12: =M12-((80*M12)/100) -> 55980 | P12: =P11 -> PERCENTAGE
A13: =A12 -> KOSTUM D80 | B13: =B12 -> 46099 | C13: =C12 -> 46113 | D13: 3273 | E13: 336 | F13: 4 | G13: 6 | H13: 81588 | I13: DISNEY | J13: 84318690 | K13: N820 | L13: 66020100MCS KOSTUM SPIDERMAN LOOK-A-LIKE N820:CLASSIC RED:4-5:PRINT:COSTUME | M13: 279900 | N13: =N12 -> 0.8 | O13: =M13-((80*M13)/100) -> 55980 | P13: =P12 -> PERCENTAGE
A14: =A13 -> KOSTUM D80 | B14: =B13 -> 46099 | C14: =C13 -> 46113 | D14: 3273 | E14: 336 | F14: 4 | G14: 6 | H14: 81588 | I14: DISNEY | J14: 84318707 | K14: N820 | L14: 66020100MCS KOSTUM SPIDERMAN LOOK-A-LIKE N820:CLASSIC RED:5-6:PRINT:COSTUME | M14: 279900 | N14: =N13 -> 0.8 | O14: =M14-((80*M14)/100) -> 55980 | P14: =P13 -> PERCENTAGE
A15: =A14 -> KOSTUM D80 | B15: =B14 -> 46099 | C15: =C14 -> 46113 | D15: 3273 | E15: 336 | F15: 4 | G15: 6 | H15: 81588 | I15: DISNEY | J15: 84318716 | K15: N820 | L15: 66020100MCS KOSTUM SPIDERMAN LOOK-A-LIKE N820:CLASSIC RED:7-8:PRINT:COSTUME | M15: 279900 | N15: =N14 -> 0.8 | O15: =M15-((80*M15)/100) -> 55980 | P15: =P14 -> PERCENTAGE
A16: =A15 -> KOSTUM D80 | B16: =B15 -> 46099 | C16: =C15 -> 46113 | D16: 3273 | E16: 336 | F16: 4 | G16: 6 | H16: 81588 | I16: DISNEY | J16: 84318725 | K16: N820 | L16: 66020100MCS KOSTUM SPIDERMAN LOOK-A-LIKE N820:CLASSIC RED:9-10:PRINT:COSTUME | M16: 279900 | N16: =N15 -> 0.8 | O16: =M16-((80*M16)/100) -> 55980 | P16: =P15 -> PERCENTAGE
... A36: =A35 -> KOSTUM D80 | B36: =B35 -> 46099 | C36: =C35 -> 46113 | D36: 3273 | E36: 336 | F36: 4 | G36: 6 | H36: 81588 | I36: DISNEY | J36: 84318672 | K36: N800 | L36: 66020100OAV KOSTUM BLACK PANTHER LOOK-A-LIKE A N800:BLACK:9-10:PRINT:COSTUME | M36: 279900 | N36: =N35 -> 0.8 | O36: =M36-((80*M36)/100) -> 55980 | P36: =P35 -> PERCENTAGE

Sheet 2025 Q1 SEASONAL D80
A1: ACARA | B1: FROM DATE | C1: TO DATE | D1: DEPT | E1: WORLD | F1: DIVISION | G1: CLASS | H1: SUPPLIER | I1: BRAND | J1: SKU | K1: ARTICLE | L1: DESCRIPTION | M1: HARGA NORMAL | N1: DISKON | O1: HARGA PROMO | P1: DISCOUNT TYPE
A2: 2025 Q1 SEASONAL D80 | B2: ='2019 ALL D95'!B26 -> 46099 | C2: ='2019 ALL D95'!C26 -> 46113 | D2: 3273 | E2: 336 | F2: 4 | G2: 7 | H2: 81747 | I2: DISNEY | J2: 51102322 | K2: MKGBP1 | L2: 66040100OAV LS SHIRT KOKO BLACK PANTHER PATTERN MKGBP1:WHITE:5-6:GRAPHIC:LS SHIRT | M2: 269900 | N2: 0.8 | O2: =M2-((80*M2)/100) -> 53980 | P2: PERCENTAGE
A3: =A2 -> 2025 Q1 SEASONAL D80 | B3: =B2 -> 46099 | C3: =C2 -> 46113 | D3: 3273 | E3: 336 | F3: 4 | G3: 7 | H3: 81747 | I3: DISNEY | J3: 51102331 | K3: MKGBP1 | L3: 66040100OAV LS SHIRT KOKO BLACK PANTHER PATTERN MKGBP1:WHITE:7-8:GRAPHIC:LS SHIRT | M3: 269900 | N3: =N2 -> 0.8 | O3: =M3-((80*M3)/100) -> 53980 | P3: =P2 -> PERCENTAGE
A4: =A3 -> 2025 Q1 SEASONAL D80 | B4: =B3 -> 46099 | C4: =C3 -> 46113 | D4: 3273 | E4: 336 | F4: 4 | G4: 7 | H4: 81747 | I4: DISNEY | J4: 51102340 | K4: MKGBP1 | L4: 66040100OAV LS SHIRT KOKO BLACK PANTHER PATTERN MKGBP1:WHITE:9-10:GRAPHIC:LS SHIRT | M4: 269900 | N4: =N3 -> 0.8 | O4: =M4-((80*M4)/100) -> 53980 | P4: =P3 -> PERCENTAGE
A5: =A4 -> 2025 Q1 SEASONAL D80 | B5: =B4 -> 46099 | C5: =C4 -> 46113 | D5: 3273 | E5: 336 | F5: 4 | G5: 7 | H5: 81747 | I5: DISNEY | J5: 51102359 | K5: MKGBP1 | L5: 66060100OAV LS SHIRT KOKO BLACK PANTHER PATTERN MKGBP1:WHITE:11-12:GRAPHIC:LS SHIRT | M5: 269900 | N5: =N4 -> 0.8 | O5: =M5-((80*M5)/100) -> 53980 | P5: =P4 -> PERCENTAGE
A6: =A5 -> 2025 Q1 SEASONAL D80 | B6: =B5 -> 46099 | C6: =C5 -> 46113 | D6: 3273 | E6: 336 | F6: 4 | G6: 7 | H6: 81747 | I6: DISNEY | J6: 51102368 | K6: MKGBP1 | L6: 66060100OAV LS SHIRT KOKO BLACK PANTHER PATTERN MKGBP1:WHITE:13-14:GRAPHIC:LS SHIRT | M6: 269900 | N6: =N5 -> 0.8 | O6: =M6-((80*M6)/100) -> 53980 | P6: =P5 -> PERCENTAGE
A7: =A6 -> 2025 Q1 SEASONAL D80 | B7: =B6 -> 46099 | C7: =C6 -> 46113 | D7: 3273 | E7: 336 | F7: 4 | G7: 7 | H7: 81747 | I7: DISNEY | J7: 51102377 | K7: MKGBP1 | L7: 66060100OAV LS SHIRT KOKO BLACK PANTHER PATTERN MKGBP1:WHITE:15-16:GRAPHIC:LS SHIRT | M7: 269900 | N7: =N6 -> 0.8 | O7: =M7-((80*M7)/100) -> 53980 | P7: =P6 -> PERCENTAGE
A8: =A7 -> 2025 Q1 SEASONAL D80 | B8: =B7 -> 46099 | C8: =C7 -> 46113 | D8: 3273 | E8: 336 | F8: 4 | G8: 7 | H8: 81574 | I8: DISNEY | J8: 51601971 | K8: KAVCL119 | L8: 66020100MCS SS SHIRT KOKO SPD FACE WEB HEAD KAVCL119:MISTY LIGHT BROWN:3-4:GRAPHIC:SS KOKO | M8: 249900 | N8: =N7 -> 0.8 | O8: =M8-((80*M8)/100) -> 49980 | P8: =P7 -> PERCENTAGE
A9: =A8 -> 2025 Q1 SEASONAL D80 | B9: =B8 -> 46099 | C9: =C8 -> 46113 | D9: 3273 | E9: 336 | F9: 4 | G9: 7 | H9: 81574 | I9: DISNEY | J9: 51601980 | K9: KAVCL119 | L9: 66020100MCS SS SHIRT KOKO SPD FACE WEB HEAD KAVCL119:MISTY LIGHT BROWN:4-5:GRAPHIC:SS KOKO | M9: 249900 | N9: =N8 -> 0.8 | O9: =M9-((80*M9)/100) -> 49980 | P9: =P8 -> PERCENTAGE
A10: =A9 -> 2025 Q1 SEASONAL D80 | B10: =B9 -> 46099 | C10: =C9 -> 46113 | D10: 3273 | E10: 336 | F10: 4 | G10: 7 | H10: 81574 | I10: DISNEY | J10: 51601999 | K10: KAVCL119 | L10: 66020100MCS SS SHIRT KOKO SPD FACE WEB HEAD KAVCL119:MISTY LIGHT BROWN:5-6:GRAPHIC:SS KOKO | M10: 249900 | N10: =N9 -> 0.8 | O10: =M10-((80*M10)/100) -> 49980 | P10: =P9 -> PERCENTAGE
A11: =A10 -> 2025 Q1 SEASONAL D80 | B11: =B10 -> 46099 | C11: =C10 -> 46113 | D11: 3273 | E11: 336 | F11: 4 | G11: 7 | H11: 81574 | I11: DISNEY | J11: 51602005 | K11: KAVCL119 | L11: 66040100MCS SS SHIRT KOKO SPD FACE WEB HEAD KAVCL119:MISTY LIGHT BROWN:7-8:GRAPHIC:SS KOKO | M11: 249900 | N11: =N10 -> 0.8 | O11: =M11-((80*M11)/100) -> 49980 | P11: =P10 -> PERCENTAGE
A12: =A11 -> 2025 Q1 SEASONAL D80 | B12: =B11 -> 46099 | C12: =C11 -> 46113 | D12: 3273 | E12: 336 | F12: 4 | G12: 7 | H12: 81574 | I12: DISNEY | J12: 51602014 | K12: KAVCL119 | L12: 66040100MCS SS SHIRT KOKO SPD FACE WEB HEAD KAVCL119:MISTY LIGHT BROWN:9-10:GRAPHIC:SS KOKO | M12: 249900 | N12: =N11 -> 0.8 | O12: =M12-((80*M12)/100) -> 49980 | P12: =P11 -> PERCENTAGE
A13: =A12 -> 2025 Q1 SEASONAL D80 | B13: =B12 -> 46099 | C13: =C12 -> 46113 | D13: 3273 | E13: 336 | F13: 4 | G13: 7 | H13: 81574 | I13: DISNEY | J13: 51602023 | K13: KAVCL119 | L13: 66040100MCS SS SHIRT KOKO SPD FACE WEB HEAD KAVCL119:MISTY LIGHT BROWN:11-12:GRAPHIC:SS KOKO | M13: 249900 | N13: =N12 -> 0.8 | O13: =M13-((80*M13)/100) -> 49980 | P13: =P12 -> PERCENTAGE
A14: =A13 -> 2025 Q1 SEASONAL D80 | B14: =B13 -> 46099 | C14: =C13 -> 46113 | D14: 3273 | E14: 336 | F14: 4 | G14: 7 | H14: 81574 | I14: DISNEY | J14: 51602032 | K14: KAVCL119 | L14: 66060100MCS SS SHIRT KOKO SPD FACE WEB HEAD KAVCL119:MISTY LIGHT BROWN:13-14:GRAPHIC:SS KOKO | M14: 249900 | N14: =N13 -> 0.8 | O14: =M14-((80*M14)/100) -> 49980 | P14: =P13 -> PERCENTAGE
... A72: =A71 -> 2025 Q1 SEASONAL D80 | B72: =B71 -> 46099 | C72: =C71 -> 46113 | D72: 3273 | E72: 336 | F72: 4 | G72: 7 | H72: 81747 | I72: DISNEY | J72: 51105534 | K72: MKGSPD1 | L72: 66060100MCS SS SHIRT SPD FACE FP MKGSPD1:WHITE:15-16:PRINT:SS SHIRT | M72: 249900 | N72: =N71 -> 0.8 | O72: =M72-((80*M72)/100) -> 49980 | P72: =P71 -> PERCENTAGE
A73: =A72 -> 2025 Q1 SEASONAL D80 | B73: =B72 -> 46099 | C73: =C72 -> 46113 | D73: 3273 | E73: 336 | F73: 4 | G73: 12 | H73: 81574 | I73: =I72 -> DISNEY | J73: 51101832 | K73: KAVCL157 | L73: 66020100OAV SS SHIRT AVG CAPT AMRIK STRIPE PATTERN KANTONG KAVCL157:MISTY LIGHT GREY:3-4:STRIPES:SS | M73: 249900 | N73: =N72 -> 0.8 | O73: =M73-((80*M73)/100) -> 49980 | P73: =P72 -> PERCENTAGE
A74: =A73 -> 2025 Q1 SEASONAL D80 | B74: =B73 -> 46099 | C74: =C73 -> 46113 | D74: 3273 | E74: 336 | F74: 4 | G74: 12 | H74: 81574 | I74: =I73 -> DISNEY | J74: 51101841 | K74: KAVCL157 | L74: 66020100OAV SS SHIRT AVG CAPT AMRIK STRIPE PATTERN KANTONG KAVCL157:MISTY LIGHT GREY:4-5:STRIPES:SS | M74: 249900 | N74: =N73 -> 0.8 | O74: =M74-((80*M74)/100) -> 49980 | P74: =P73 -> PERCENTAGE
A75: =A74 -> 2025 Q1 SEASONAL D80 | B75: =B74 -> 46099 | C75: =C74 -> 46113 | D75: 3273 | E75: 336 | F75: 4 | G75: 12 | H75: 81574 | I75: =I74 -> DISNEY | J75: 51101850 | K75: KAVCL157 | L75: 66020100OAV SS SHIRT AVG CAPT AMRIK STRIPE PATTERN KANTONG KAVCL157:MISTY LIGHT GREY:5-6:STRIPES:SS | M75: 249900 | N75: =N74 -> 0.8 | O75: =M75-((80*M75)/100) -> 49980 | P75: =P74 -> PERCENTAGE
A76: =A75 -> 2025 Q1 SEASONAL D80 | B76: =B75 -> 46099 | C76: =C75 -> 46113 | D76: 3273 | E76: 336 | F76: 4 | G76: 12 | H76: 81574 | I76: =I75 -> DISNEY | J76: 51101869 | K76: KAVCL157 | L76: 66040100OAV SS SHIRT AVG CAPT AMRIK STRIPE PATTERN KANTONG KAVCL157:MISTY LIGHT GREY:7-8:STRIPES:SS | M76: 249900 | N76: =N75 -> 0.8 | O76: =M76-((80*M76)/100) -> 49980 | P76: =P75 -> PERCENTAGE
A77: =A76 -> 2025 Q1 SEASONAL D80 | B77: =B76 -> 46099 | C77: =C76 -> 46113 | D77: 3273 | E77: 336 | F77: 4 | G77: 12 | H77: 81574 | I77: =I76 -> DISNEY | J77: 51101878 | K77: KAVCL157 | L77: 66040100OAV SS SHIRT AVG CAPT AMRIK STRIPE PATTERN KANTONG KAVCL157:MISTY LIGHT GREY:9-10:STRIPES:SS | M77: 249900 | N77: =N76 -> 0.8 | O77: =M77-((80*M77)/100) -> 49980 | P77: =P76 -> PERCENTAGE
