Workbook

Sheet 2023 SP 79
A1: ACARA | B1: FROM DATE | C1: TO DATE | D1: DEPT | E1: WORLD | F1: DIVISION | G1: CLASS | H1: SUPPLIER | I1: BRAND | J1: SKU | K1: ARTICLE | L1: DESCRIPTION | M1: HARGA NORMAL | N1: DISKON | O1: HARGA PROMO | P1: DISCOUNT TYPE
A2: 2023 All item SP 79 | B2: 2026-03-27 | C2: 2026-04-01 | D2: 3328 | E2: 347 | F2: 5 | G2: 7 | I2: SUKO | J2: 80744843 | K2: R1D02351 | L2: GAUN WAFFLE LS KNIT DRESS KERAH BULAT LENGAN PANJANG R1D02351:MISTY LIGHT GREY:S:SOLID:GAUN WAFFLE | M2: 349900 | N2: SP | O2: 79000 | P2: SPECIAL PRICE
A3: 2023 All item SP 79 | B3: =$B$2 -> 2026-03-27 | C3: =$C$2 -> 2026-04-01 | D3: 3328 | E3: 347 | F3: 5 | G3: 7 | I3: SUKO | J3: 80744852 | K3: R1D02351 | L3: GAUN WAFFLE LS KNIT DRESS KERAH BULAT LENGAN PANJANG R1D02351:MISTY LIGHT GREY:M:SOLID:GAUN WAFFLE | M3: 349900 | N3: SP | O3: 79000 | P3: SPECIAL PRICE
A4: 2023 All item SP 79 | B4: =$B$2 -> 2026-03-27 | C4: =$C$2 -> 2026-04-01 | D4: 3328 | E4: 347 | F4: 5 | G4: 7 | I4: SUKO | J4: 80744870 | K4: R1D02351 | L4: GAUN WAFFLE LS KNIT DRESS KERAH BULAT LENGAN PANJANG R1D02351:MISTY LIGHT GREY:XL:SOLID:GAUN WAFFLE | M4: 349900 | N4: SP | O4: 79000 | P4: SPECIAL PRICE
A5: 2023 All item SP 79 | B5: =$B$2 -> 2026-03-27 | C5: =$C$2 -> 2026-04-01 | D5: 3328 | E5: 347 | F5: 5 | G5: 7 | I5: SUKO | J5: 80744889 | K5: R1D02351 | L5: GAUN WAFFLE LS KNIT DRESS KERAH BULAT LENGAN PANJANG R1D02351:NAVY BLUE:S:SOLID:GAUN WAFFLE | M5: 349900 | N5: SP | O5: 79000 | P5: SPECIAL PRICE
A6: 2023 All item SP 79 | B6: =$B$2 -> 2026-03-27 | C6: =$C$2 -> 2026-04-01 | D6: 3328 | E6: 347 | F6: 5 | G6: 7 | I6: SUKO | J6: 80744898 | K6: R1D02351 | L6: GAUN WAFFLE LS KNIT DRESS KERAH BULAT LENGAN PANJANG R1D02351:NAVY BLUE:M:SOLID:GAUN WAFFLE | M6: 349900 | N6: SP | O6: 79000 | P6: SPECIAL PRICE
A7: 2023 All item SP 79 | B7: =$B$2 -> 2026-03-27 | C7: =$C$2 -> 2026-04-01 | D7: 3328 | E7: 347 | F7: 5 | G7: 7 | I7: SUKO | J7: 80744914 | K7: R1D02351 | L7: GAUN WAFFLE LS KNIT DRESS KERAH BULAT LENGAN PANJANG R1D02351:NAVY BLUE:XL:SOLID:GAUN WAFFLE | M7: 349900 | N7: SP | O7: 79000 | P7: SPECIAL PRICE
A8: 2023 All item SP 79 | B8: =$B$2 -> 2026-03-27 | C8: =$C$2 -> 2026-04-01 | D8: 3328 | E8: 347 | F8: 5 | G8: 1 | I8: SUKO | J8: 80859694 | K8: T4KT5352 | L8: 3/4 OVERSIZED T-SHIRT STRIPED GARIS LENGAN 3/4 T4KT5352:MAROON:S:STRIPES:3/4 OVERSIZED T-SHIRT | M8: 249900 | N8: SP | O8: 79000 | P8: SPECIAL PRICE
A9: 2023 All item SP 79 | B9: =$B$2 -> 2026-03-27 | C9: =$C$2 -> 2026-04-01 | D9: 3328 | E9: 347 | F9: 5 | G9: 1 | I9: SUKO | J9: 80859701 | K9: T4KT5352 | L9: 3/4 OVERSIZED T-SHIRT STRIPED GARIS LENGAN 3/4 T4KT5352:MAROON:M:STRIPES:3/4 OVERSIZED T-SHIRT | M9: 249900 | N9: SP | O9: 79000 | P9: SPECIAL PRICE
A10: 2023 All item SP 79 | B10: =$B$2 -> 2026-03-27 | C10: =$C$2 -> 2026-04-01 | D10: 3328 | E10: 347 | F10: 5 | G10: 1 | I10: SUKO | J10: 80859710 | K10: T4KT5352 | L10: 3/4 OVERSIZED T-SHIRT STRIPED GARIS LENGAN 3/4 T4KT5352:MAROON:L:STRIPES:3/4 OVERSIZED T-SHIRT | M10: 249900 | N10: SP | O10: 79000 | P10: SPECIAL PRICE
A11: 2023 All item SP 79 | B11: =$B$2 -> 2026-03-27 | C11: =$C$2 -> 2026-04-01 | D11: 3328 | E11: 347 | F11: 5 | G11: 1 | I11: SUKO | J11: 80968067 | K11: T4KT5352 | L11: 3/4 OVERSIZED T-SHIRT STRIPED GARIS LENGAN 3/4 T4KT5352:MAROON:XL:STRIPES:3/4 OVERSIZED T-SHIRT | M11: 249900 | N11: SP | O11: 79000 | P11: SPECIAL PRICE
A12: 2023 All item SP 79 | B12: =$B$2 -> 2026-03-27 | C12: =$C$2 -> 2026-04-01 | D12: 3328 | E12: 347 | F12: 5 | G12: 1 | I12: SUKO | J12: 80859658 | K12: T4KT5352 | L12: 3/4 OVERSIZED T-SHIRT STRIPED GARIS LENGAN 3/4 T4KT5352:NAVY BLUE:S:STRIPES:3/4 OVERSIZED T-SHIRT | M12: 249900 | N12: SP | O12: 79000 | P12: SPECIAL PRICE
A13: 2023 All item SP 79 | B13: =$B$2 -> 2026-03-27 | C13: =$C$2 -> 2026-04-01 | D13: 3328 | E13: 347 | F13: 5 | G13: 1 | I13: SUKO | J13: 80859667 | K13: T4KT5352 | L13: 3/4 OVERSIZED T-SHIRT STRIPED GARIS LENGAN 3/4 T4KT5352:NAVY BLUE:M:STRIPES:3/4 OVERSIZED T-SHIRT | M13: 249900 | N13: SP | O13: 79000 | P13: SPECIAL PRICE
A14: 2023 All item SP 79 | B14: =$B$2 -> 2026-03-27 | C14: =$C$2 -> 2026-04-01 | D14: 3328 | E14: 347 | F14: 5 | G14: 1 | I14: SUKO | J14: 80859676 | K14: T4KT5352 | L14: 3/4 OVERSIZED T-SHIRT STRIPED GARIS LENGAN 3/4 T4KT5352:NAVY BLUE:L:STRIPES:3/4 OVERSIZED T-SHIRT | M14: 249900 | N14: SP | O14: 79000 | P14: SPECIAL PRICE
... A131: 2023 All item SP 79 | B131: =$B$2 -> 2026-03-27 | C131: =$C$2 -> 2026-04-01 | D131: 3328 | E131: 347 | F131: 5 | G131: 7 | I131: SUKO | J131: 13472487 | K131: R1KL43J1 | L131: GAUN HOODIE KNIT 3/4 SLEEVE PLAIN JERSEY ASYMMETRIC LENGTH LENGAN 3/4 R1KL43J1:DUSTY PINK:L/XL:SOLID | M131: 299900 | N131: SP | O131: 79000 | P131: SPECIAL PRICE
A132: 2023 All item SP 79 | B132: ='2023 SP 79'!$B$2 -> 2026-03-27 | C132: ='2023 SP 79'!$C$2 -> 2026-04-01 | D132: 3328 | E132: 347 | F132: 5 | G132: 1 | I132: SUKO | J132: 13472941 | K132: T2DN23J1 | L132: T-SHIRT DROP NEEDLE TEE LS KNIT TOP LS KERAH BULAT LENGAN PANJANG T2DN23J1:TAUPE GREY:S:SOLID:T-SHIR | M132: 149900 | N132: SP | O132: 79000 | P132: SPECIAL PRICE
A133: 2023 All item SP 79 | B133: ='2023 SP 79'!$B$2 -> 2026-03-27 | C133: ='2023 SP 79'!$C$2 -> 2026-04-01 | D133: 3328 | E133: 347 | F133: 5 | G133: 1 | I133: SUKO | J133: 13472950 | K133: T2DN23J1 | L133: T-SHIRT DROP NEEDLE TEE LS KNIT TOP LS KERAH BULAT LENGAN PANJANG T2DN23J1:TAUPE GREY:M:SOLID:T-SHIR | M133: 149900 | N133: SP | O133: 79000 | P133: SPECIAL PRICE
A134: 2023 All item SP 79 | B134: ='2023 SP 79'!$B$2 -> 2026-03-27 | C134: ='2023 SP 79'!$C$2 -> 2026-04-01 | D134: 3328 | E134: 347 | F134: 5 | G134: 1 | I134: SUKO | J134: 13472969 | K134: T2DN23J1 | L134: T-SHIRT DROP NEEDLE TEE LS KNIT TOP LS KERAH BULAT LENGAN PANJANG T2DN23J1:TAUPE GREY:L:SOLID:T-SHIR | M134: 149900 | N134: SP | O134: 79000 | P134: SPECIAL PRICE
A135: 2023 All item SP 79 | B135: ='2023 SP 79'!$B$2 -> 2026-03-27 | C135: ='2023 SP 79'!$C$2 -> 2026-04-01 | D135: 3328 | E135: 347 | F135: 5 | G135: 1 | I135: SUKO | J135: 13472978 | K135: T2DN23J1 | L135: T-SHIRT DROP NEEDLE TEE LS KNIT TOP LS KERAH BULAT LENGAN PANJANG T2DN23J1:TAUPE GREY:XL:SOLID:T-SHI | M135: 149900 | N135: SP | O135: 79000 | P135: SPECIAL PRICE
A136: 2023 All item SP 79 | B136: ='2023 SP 79'!$B$2 -> 2026-03-27 | C136: ='2023 SP 79'!$C$2 -> 2026-04-01 | D136: 3328 | E136: 347 | F136: 5 | G136: 5 | I136: SUKO | J136: 80745128 | K136: W2B05353 | L136: CELANA ANKLE RELAX ANKLE PANTS W2B05353:NAVY BLUE:S:SOLID:CELANA ANKLE RELAX | M136: 249900 | N136: SP | O136: 79000 | P136: SPECIAL PRICE
A137: 2023 All item SP 79 | B137: ='2023 SP 79'!$B$2 -> 2026-03-27 | C137: ='2023 SP 79'!$C$2 -> 2026-04-01 | D137: 3328 | E137: 347 | F137: 5 | G137: 5 | I137: SUKO | J137: 80745137 | K137: W2B05353 | L137: CELANA ANKLE RELAX ANKLE PANTS W2B05353:NAVY BLUE:M:SOLID:CELANA ANKLE RELAX | M137: 249900 | N137: SP | O137: 79000 | P137: SPECIAL PRICE
A138: 2023 All item SP 79 | B138: ='2023 SP 79'!$B$2 -> 2026-03-27 | C138: ='2023 SP 79'!$C$2 -> 2026-04-01 | D138: 3328 | E138: 347 | F138: 5 | G138: 5 | I138: SUKO | J138: 80745146 | K138: W2B05353 | L138: CELANA ANKLE RELAX ANKLE PANTS W2B05353:NAVY BLUE:L:SOLID:CELANA ANKLE RELAX | M138: 249900 | N138: SP | O138: 79000 | P138: SPECIAL PRICE
A139: 2023 All item SP 79 | B139: ='2023 SP 79'!$B$2 -> 2026-03-27 | C139: ='2023 SP 79'!$C$2 -> 2026-04-01 | D139: 3328 | E139: 347 | F139: 5 | G139: 5 | I139: SUKO | J139: 80745155 | K139: W2B05353 | L139: CELANA ANKLE RELAX ANKLE PANTS W2B05353:NAVY BLUE:XL:SOLID:CELANA ANKLE RELAX | M139: 249900 | N139: SP | O139: 79000 | P139: SPECIAL PRICE

Sheet 2024 H1 SP 79
A1: ACARA | B1: FROM DATE | C1: TO DATE | D1: DEPT | E1: WORLD | F1: DIVISION | G1: CLASS | H1: SUPPLIER | I1: BRAND | J1: SKU | K1: ARTICLE | L1: DESCRIPTION | M1: HARGA NORMAL | N1: DISKON | O1: HARGA PROMO | P1: DISCOUNT TYPE
A2: 2024 H1 ALL ITEM SP 79 | B2: ='2023 SP 79'!$B$2 -> 2026-03-27 | C2: ='2023 SP 79'!$C$2 -> 2026-04-01 | D2: 3328 | E2: 347 | F2: 5 | G2: 5 | I2: SUKO | J2: 18738066 | K2: W2L294D1 | L2: CELANA PARASUT PANJANG WOVEN BOTTOM PANTS W2L294D1:FROST GREY:S:SOLID:CELANA PARASUT PANJANG | M2: 299900 | N2: SP | O2: 79000 | P2: SPECIAL PRICE
A3: 2024 H1 ALL ITEM SP 79 | B3: ='2023 SP 79'!$B$2 -> 2026-03-27 | C3: ='2023 SP 79'!$C$2 -> 2026-04-01 | D3: 3328 | E3: 347 | F3: 5 | G3: 5 | I3: SUKO | J3: 18738075 | K3: W2L294D1 | L3: CELANA PARASUT PANJANG WOVEN BOTTOM PANTS W2L294D1:FROST GREY:M:SOLID:CELANA PARASUT PANJANG | M3: 299900 | N3: SP | O3: 79000 | P3: SPECIAL PRICE
A4: 2024 H1 ALL ITEM SP 79 | B4: ='2023 SP 79'!$B$2 -> 2026-03-27 | C4: ='2023 SP 79'!$C$2 -> 2026-04-01 | D4: 3328 | E4: 347 | F4: 5 | G4: 5 | I4: SUKO | J4: 18738084 | K4: W2L294D1 | L4: CELANA PARASUT PANJANG WOVEN BOTTOM PANTS W2L294D1:FROST GREY:L:SOLID:CELANA PARASUT PANJANG | M4: 299900 | N4: SP | O4: 79000 | P4: SPECIAL PRICE
A5: 2024 H1 ALL ITEM SP 79 | B5: ='2023 SP 79'!$B$2 -> 2026-03-27 | C5: ='2023 SP 79'!$C$2 -> 2026-04-01 | D5: 3328 | E5: 347 | F5: 5 | G5: 5 | I5: SUKO | J5: 18738093 | K5: W2L294D1 | L5: CELANA PARASUT PANJANG WOVEN BOTTOM PANTS W2L294D1:FROST GREY:XL:SOLID:CELANA PARASUT PANJANG | M5: 299900 | N5: SP | O5: 79000 | P5: SPECIAL PRICE
A6: 2024 H1 ALL ITEM SP 79 | B6: ='2023 SP 79'!$B$2 -> 2026-03-27 | C6: ='2023 SP 79'!$C$2 -> 2026-04-01 | D6: 3328 | E6: 347 | F6: 5 | G6: 5 | I6: SUKO | J6: 18737889 | K6: W2L294D1 | L6: CELANA PARASUT PANJANG WOVEN BOTTOM PANTS W2L294D1:OLIVE:S:SOLID:CELANA PARASUT PANJANG | M6: 299900 | N6: SP | O6: 79000 | P6: SPECIAL PRICE
A7: 2024 H1 ALL ITEM SP 79 | B7: ='2023 SP 79'!$B$2 -> 2026-03-27 | C7: ='2023 SP 79'!$C$2 -> 2026-04-01 | D7: 3328 | E7: 347 | F7: 5 | G7: 5 | I7: SUKO | J7: 18737898 | K7: W2L294D1 | L7: CELANA PARASUT PANJANG WOVEN BOTTOM PANTS W2L294D1:OLIVE:M:SOLID:CELANA PARASUT PANJANG | M7: 299900 | N7: SP | O7: 79000 | P7: SPECIAL PRICE
A8: 2024 H1 ALL ITEM SP 79 | B8: ='2023 SP 79'!$B$2 -> 2026-03-27 | C8: ='2023 SP 79'!$C$2 -> 2026-04-01 | D8: 3328 | E8: 347 | F8: 5 | G8: 5 | I8: SUKO | J8: 18737905 | K8: W2L294D1 | L8: CELANA PARASUT PANJANG WOVEN BOTTOM PANTS W2L294D1:OLIVE:L:SOLID:CELANA PARASUT PANJANG | M8: 299900 | N8: SP | O8: 79000 | P8: SPECIAL PRICE
A9: 2024 H1 ALL ITEM SP 79 | B9: ='2023 SP 79'!$B$2 -> 2026-03-27 | C9: ='2023 SP 79'!$C$2 -> 2026-04-01 | D9: 3328 | E9: 347 | F9: 5 | G9: 5 | I9: SUKO | J9: 18737914 | K9: W2L294D1 | L9: CELANA PARASUT PANJANG WOVEN BOTTOM PANTS W2L294D1:OLIVE:XL:SOLID:CELANA PARASUT PANJANG | M9: 299900 | N9: SP | O9: 79000 | P9: SPECIAL PRICE
A10: 2024 H1 ALL ITEM SP 79 | B10: ='2023 SP 79'!$B$2 -> 2026-03-27 | C10: ='2023 SP 79'!$C$2 -> 2026-04-01 | D10: 3328 | E10: 347 | F10: 5 | G10: 5 | I10: SUKO | J10: 18737923 | K10: W2L294D1 | L10: CELANA PARASUT PANJANG WOVEN BOTTOM PANTS W2L294D1:WOOD BROWN:S:SOLID:CELANA PARASUT PANJANG | M10: 299900 | N10: SP | O10: 79000 | P10: SPECIAL PRICE
A11: 2024 H1 ALL ITEM SP 79 | B11: ='2023 SP 79'!$B$2 -> 2026-03-27 | C11: ='2023 SP 79'!$C$2 -> 2026-04-01 | D11: 3328 | E11: 347 | F11: 5 | G11: 5 | I11: SUKO | J11: 18737941 | K11: W2L294D1 | L11: CELANA PARASUT PANJANG WOVEN BOTTOM PANTS W2L294D1:WOOD BROWN:M:SOLID:CELANA PARASUT PANJANG | M11: 299900 | N11: SP | O11: 79000 | P11: SPECIAL PRICE
A12: 2024 H1 ALL ITEM SP 79 | B12: ='2023 SP 79'!$B$2 -> 2026-03-27 | C12: ='2023 SP 79'!$C$2 -> 2026-04-01 | D12: 3328 | E12: 347 | F12: 5 | G12: 5 | I12: SUKO | J12: 18737950 | K12: W2L294D1 | L12: CELANA PARASUT PANJANG WOVEN BOTTOM PANTS W2L294D1:WOOD BROWN:L:SOLID:CELANA PARASUT PANJANG | M12: 299900 | N12: SP | O12: 79000 | P12: SPECIAL PRICE
A13: 2024 H1 ALL ITEM SP 79 | B13: ='2023 SP 79'!$B$2 -> 2026-03-27 | C13: ='2023 SP 79'!$C$2 -> 2026-04-01 | D13: 3328 | E13: 347 | F13: 5 | G13: 5 | I13: SUKO | J13: 18737969 | K13: W2L294D1 | L13: CELANA PARASUT PANJANG WOVEN BOTTOM PANTS W2L294D1:WOOD BROWN:XL:SOLID:CELANA PARASUT PANJANG | M13: 299900 | N13: SP | O13: 79000 | P13: SPECIAL PRICE
... A149: 2024 H1 ALL ITEM SP 79 | B149: ='2023 SP 79'!$B$2 -> 2026-03-27 | C149: ='2023 SP 79'!$C$2 -> 2026-04-01 | D149: 3328 | E149: 347 | F149: 5 | G149: 1 | I149: SUKO | J149: 13472932 | K149: T2DN23J1 | L149: T-SHIRT DROP NEEDLE TEE LS KNIT TOP LS KERAH BULAT LENGAN PANJANG T2DN23J1:DUSTY PINK:XL:SOLID:T-SHI | M149: 149900 | N149: SP | O149: 79000 | P149: SPECIAL PRICE

Sheet 2024 H2 SP 79
A1: ACARA | B1: FROM DATE | C1: TO DATE | D1: DEPT | E1: WORLD | F1: DIVISION | G1: CLASS | H1: SUPPLIER | I1: BRAND | J1: SKU | K1: ARTICLE | L1: DESCRIPTION | M1: HARGA NORMAL | N1: DISKON | O1: HARGA PROMO | P1: DISCOUNT TYPE
A2: 2024 H2 Knit Top dan KI SP 79 | B2: ='2023 SP 79'!$B$2 -> 2026-03-27 | C2: ='2023 SP 79'!$C$2 -> 2026-04-01 | D2: 3328 | E2: 347 | F2: 5 | G2: 1 | I2: SUKO | J2: 45424246 | K2: T4L3B4J1 | L2: T-SHIRT OVERSIZED GRAPHIC POCKET PRINT KERAH BULAT LENGAN PENDEK T4L3B4J1:KHAKI:S:GRAPHIC:T-SHIRT OV | M2: 159900 | N2: SP | O2: 79000 | P2: SPECIAL PRICE
A3: 2024 H2 Knit Top dan KI SP 79 | B3: ='2023 SP 79'!$B$2 -> 2026-03-27 | C3: ='2023 SP 79'!$C$2 -> 2026-04-01 | D3: 3328 | E3: 347 | F3: 5 | G3: 1 | I3: SUKO | J3: 45424255 | K3: T4L3B4J1 | L3: T-SHIRT OVERSIZED GRAPHIC POCKET PRINT KERAH BULAT LENGAN PENDEK T4L3B4J1:KHAKI:M:GRAPHIC:T-SHIRT OV | M3: 159900 | N3: SP | O3: 79000 | P3: SPECIAL PRICE
A4: 2024 H2 Knit Top dan KI SP 79 | B4: ='2023 SP 79'!$B$2 -> 2026-03-27 | C4: ='2023 SP 79'!$C$2 -> 2026-04-01 | D4: 3328 | E4: 347 | F4: 5 | G4: 1 | I4: SUKO | J4: 45424264 | K4: T4L3B4J1 | L4: T-SHIRT OVERSIZED GRAPHIC POCKET PRINT KERAH BULAT LENGAN PENDEK T4L3B4J1:KHAKI:L:GRAPHIC:T-SHIRT OV | M4: 159900 | N4: SP | O4: 79000 | P4: SPECIAL PRICE
A5: 2024 H2 Knit Top dan KI SP 79 | B5: ='2023 SP 79'!$B$2 -> 2026-03-27 | C5: ='2023 SP 79'!$C$2 -> 2026-04-01 | D5: 3328 | E5: 347 | F5: 5 | G5: 1 | I5: SUKO | J5: 45424273 | K5: T4L3B4J1 | L5: T-SHIRT OVERSIZED GRAPHIC POCKET PRINT KERAH BULAT LENGAN PENDEK T4L3B4J1:KHAKI:XL:GRAPHIC:T-SHIRT O | M5: 159900 | N5: SP | O5: 79000 | P5: SPECIAL PRICE
A6: 2024 H2 Knit Top dan KI SP 79 | B6: ='2023 SP 79'!$B$2 -> 2026-03-27 | C6: ='2023 SP 79'!$C$2 -> 2026-04-01 | D6: 3328 | E6: 347 | F6: 5 | G6: 1 | I6: SUKO | J6: 45424200 | K6: T4L3A4J1 | L6: T-SHIRT OVERSIZED GRAPHIC PRINT KERAH BULAT LENGAN PENDEK T4L3A4J1:JADE:S:GRAPHIC:T-SHIRT OVERSIZED | M6: 159900 | N6: SP | O6: 79000 | P6: SPECIAL PRICE
A7: 2024 H2 Knit Top dan KI SP 79 | B7: ='2023 SP 79'!$B$2 -> 2026-03-27 | C7: ='2023 SP 79'!$C$2 -> 2026-04-01 | D7: 3328 | E7: 347 | F7: 5 | G7: 1 | I7: SUKO | J7: 45424219 | K7: T4L3A4J1 | L7: T-SHIRT OVERSIZED GRAPHIC PRINT KERAH BULAT LENGAN PENDEK T4L3A4J1:JADE:M:GRAPHIC:T-SHIRT OVERSIZED | M7: 159900 | N7: SP | O7: 79000 | P7: SPECIAL PRICE
A8: 2024 H2 Knit Top dan KI SP 79 | B8: ='2023 SP 79'!$B$2 -> 2026-03-27 | C8: ='2023 SP 79'!$C$2 -> 2026-04-01 | D8: 3328 | E8: 347 | F8: 5 | G8: 1 | I8: SUKO | J8: 45424228 | K8: T4L3A4J1 | L8: T-SHIRT OVERSIZED GRAPHIC PRINT KERAH BULAT LENGAN PENDEK T4L3A4J1:JADE:L:GRAPHIC:T-SHIRT OVERSIZED | M8: 159900 | N8: SP | O8: 79000 | P8: SPECIAL PRICE
A9: 2024 H2 Knit Top dan KI SP 79 | B9: ='2023 SP 79'!$B$2 -> 2026-03-27 | C9: ='2023 SP 79'!$C$2 -> 2026-04-01 | D9: 3328 | E9: 347 | F9: 5 | G9: 1 | I9: SUKO | J9: 45424237 | K9: T4L3A4J1 | L9: T-SHIRT OVERSIZED GRAPHIC PRINT KERAH BULAT LENGAN PENDEK T4L3A4J1:JADE:XL:GRAPHIC:T-SHIRT OVERSIZED | M9: 159900 | N9: SP | O9: 79000 | P9: SPECIAL PRICE
A10: 2024 H2 Knit Top dan KI SP 79 | B10: ='2023 SP 79'!$B$2 -> 2026-03-27 | C10: ='2023 SP 79'!$C$2 -> 2026-04-01 | D10: 3328 | E10: 347 | F10: 5 | G10: 1 | I10: SUKO | J10: 45424282 | K10: T4L3A4J1 | L10: T-SHIRT OVERSIZED GRAPHIC PRINT KERAH BULAT LENGAN PENDEK T4L3A4J1:GOLDEN BROWN:S:GRAPHIC:T-SHIRT OV | M10: 159900 | N10: SP | O10: 79000 | P10: SPECIAL PRICE
A11: 2024 H2 Knit Top dan KI SP 79 | B11: ='2023 SP 79'!$B$2 -> 2026-03-27 | C11: ='2023 SP 79'!$C$2 -> 2026-04-01 | D11: 3328 | E11: 347 | F11: 5 | G11: 1 | I11: SUKO | J11: 45424291 | K11: T4L3A4J1 | L11: T-SHIRT OVERSIZED GRAPHIC PRINT KERAH BULAT LENGAN PENDEK T4L3A4J1:GOLDEN BROWN:M:GRAPHIC:T-SHIRT OV | M11: 159900 | N11: SP | O11: 79000 | P11: SPECIAL PRICE
A12: 2024 H2 Knit Top dan KI SP 79 | B12: ='2023 SP 79'!$B$2 -> 2026-03-27 | C12: ='2023 SP 79'!$C$2 -> 2026-04-01 | D12: 3328 | E12: 347 | F12: 5 | G12: 1 | I12: SUKO | J12: 45424308 | K12: T4L3A4J1 | L12: T-SHIRT OVERSIZED GRAPHIC PRINT KERAH BULAT LENGAN PENDEK T4L3A4J1:GOLDEN BROWN:L:GRAPHIC:T-SHIRT OV | M12: 159900 | N12: SP | O12: 79000 | P12: SPECIAL PRICE
A13: 2024 H2 Knit Top dan KI SP 79 | B13: ='2023 SP 79'!$B$2 -> 2026-03-27 | C13: ='2023 SP 79'!$C$2 -> 2026-04-01 | D13: 3328 | E13: 347 | F13: 5 | G13: 1 | I13: SUKO | J13: 45424317 | K13: T4L3A4J1 | L13: T-SHIRT OVERSIZED GRAPHIC PRINT KERAH BULAT LENGAN PENDEK T4L3A4J1:GOLDEN BROWN:XL:GRAPHIC:T-SHIRT O | M13: 159900 | N13: SP | O13: 79000 | P13: SPECIAL PRICE
... A55: 2024 H2 Knit Top dan KI SP 79 | B55: ='2023 SP 79'!$B$2 -> 2026-03-27 | C55: ='2023 SP 79'!$C$2 -> 2026-04-01 | D55: 3328 | E55: 347 | F55: 5 | G55: 8 | I55: SUKO | J55: 80744512 | K55: T2KT7351 | L55: T-SHIRT WAFFLE L/S KERAH BULAT LENGAN PANJANG T2KT7351:MISTY LIGHT GREY:XL:SOLID:T-SHIRT WAFFLE | M55: 169900 | N55: SP | O55: 79000 | P55: SPECIAL PRICE

Sheet 2024 H2 SP99
A1: ACARA | B1: FROM DATE | C1: TO DATE | D1: DEPT | E1: WORLD | F1: DIVISION | G1: CLASS | H1: SUPPLIER | I1: BRAND | J1: SKU | K1: ARTICLE | L1: DESCRIPTION | M1: HARGA NORMAL | N1: DISKON | O1: HARGA PROMO | P1: DISCOUNT TYPE
A2: 2024 H2 Woven Top, Outerwear, Woven Bottom, Dress SP 99 | B2: ='2023 SP 79'!$B$2 -> 2026-03-27 | C2: ='2023 SP 79'!$C$2 -> 2026-04-01 | D2: 3328 | E2: 347 | F2: 5 | G2: 2 | I2: SUKO | J2: 45337279 | K2: S3L474J1 | L2: BLUES LINEN BLEND VOLUME SS LENGAN PENDEK S3L474J1:PASTEL BLUE:S:SOLID:BLUES LINEN | M2: 249900 | N2: SP | O2: 99000 | P2: SPECIAL PRICE
A3: 2024 H2 Woven Top, Outerwear, Woven Bottom, Dress SP 99 | B3: ='2023 SP 79'!$B$2 -> 2026-03-27 | C3: ='2023 SP 79'!$C$2 -> 2026-04-01 | D3: 3328 | E3: 347 | F3: 5 | G3: 2 | I3: SUKO | J3: 45337288 | K3: S3L474J1 | L3: BLUES LINEN BLEND VOLUME SS LENGAN PENDEK S3L474J1:PASTEL BLUE:M:SOLID:BLUES LINEN | M3: 249900 | N3: SP | O3: 99000 | P3: SPECIAL PRICE
A4: 2024 H2 Woven Top, Outerwear, Woven Bottom, Dress SP 99 | B4: ='2023 SP 79'!$B$2 -> 2026-03-27 | C4: ='2023 SP 79'!$C$2 -> 2026-04-01 | D4: 3328 | E4: 347 | F4: 5 | G4: 2 | I4: SUKO | J4: 45337297 | K4: S3L474J1 | L4: BLUES LINEN BLEND VOLUME SS LENGAN PENDEK S3L474J1:PASTEL BLUE:L:SOLID:BLUES LINEN | M4: 249900 | N4: SP | O4: 99000 | P4: SPECIAL PRICE
A5: 2024 H2 Woven Top, Outerwear, Woven Bottom, Dress SP 99 | B5: ='2023 SP 79'!$B$2 -> 2026-03-27 | C5: ='2023 SP 79'!$C$2 -> 2026-04-01 | D5: 3328 | E5: 347 | F5: 5 | G5: 2 | I5: SUKO | J5: 45337304 | K5: S3L474J1 | L5: BLUES LINEN BLEND VOLUME SS LENGAN PENDEK S3L474J1:PASTEL BLUE:XL:SOLID:BLUES LINEN | M5: 249900 | N5: SP | O5: 99000 | P5: SPECIAL PRICE
A6: 2024 H2 Woven Top, Outerwear, Woven Bottom, Dress SP 99 | B6: ='2023 SP 79'!$B$2 -> 2026-03-27 | C6: ='2023 SP 79'!$C$2 -> 2026-04-01 | D6: 3328 | E6: 347 | F6: 5 | G6: 2 | I6: SUKO | J6: 45337233 | K6: S3L474J1 | L6: BLUES LINEN BLEND VOLUME SS LENGAN PENDEK S3L474J1:VANILLA:S:SOLID:BLUES LINEN | M6: 249900 | N6: SP | O6: 99000 | P6: SPECIAL PRICE
A7: 2024 H2 Woven Top, Outerwear, Woven Bottom, Dress SP 99 | B7: ='2023 SP 79'!$B$2 -> 2026-03-27 | C7: ='2023 SP 79'!$C$2 -> 2026-04-01 | D7: 3328 | E7: 347 | F7: 5 | G7: 2 | I7: SUKO | J7: 45337242 | K7: S3L474J1 | L7: BLUES LINEN BLEND VOLUME SS LENGAN PENDEK S3L474J1:VANILLA:M:SOLID:BLUES LINEN | M7: 249900 | N7: SP | O7: 99000 | P7: SPECIAL PRICE
A8: 2024 H2 Woven Top, Outerwear, Woven Bottom, Dress SP 99 | B8: ='2023 SP 79'!$B$2 -> 2026-03-27 | C8: ='2023 SP 79'!$C$2 -> 2026-04-01 | D8: 3328 | E8: 347 | F8: 5 | G8: 2 | I8: SUKO | J8: 45337251 | K8: S3L474J1 | L8: BLUES LINEN BLEND VOLUME SS LENGAN PENDEK S3L474J1:VANILLA:L:SOLID:BLUES LINEN | M8: 249900 | N8: SP | O8: 99000 | P8: SPECIAL PRICE
A9: 2024 H2 Woven Top, Outerwear, Woven Bottom, Dress SP 99 | B9: ='2023 SP 79'!$B$2 -> 2026-03-27 | C9: ='2023 SP 79'!$C$2 -> 2026-04-01 | D9: 3328 | E9: 347 | F9: 5 | G9: 2 | I9: SUKO | J9: 45337260 | K9: S3L474J1 | L9: BLUES LINEN BLEND VOLUME SS LENGAN PENDEK S3L474J1:VANILLA:XL:SOLID:BLUES LINEN | M9: 249900 | N9: SP | O9: 99000 | P9: SPECIAL PRICE
A10: 2024 H2 Woven Top, Outerwear, Woven Bottom, Dress SP 99 | B10: ='2023 SP 79'!$B$2 -> 2026-03-27 | C10: ='2023 SP 79'!$C$2 -> 2026-04-01 | D10: 3328 | E10: 347 | F10: 5 | G10: 2 | I10: SUKO | J10: 45337199 | K10: S3L474J1 | L10: BLUES LINEN BLEND VOLUME SS LENGAN PENDEK S3L474J1:WHITE:S:SOLID:BLUES LINEN | M10: 249900 | N10: SP | O10: 99000 | P10: SPECIAL PRICE
A11: 2024 H2 Woven Top, Outerwear, Woven Bottom, Dress SP 99 | B11: ='2023 SP 79'!$B$2 -> 2026-03-27 | C11: ='2023 SP 79'!$C$2 -> 2026-04-01 | D11: 3328 | E11: 347 | F11: 5 | G11: 2 | I11: SUKO | J11: 45337206 | K11: S3L474J1 | L11: BLUES LINEN BLEND VOLUME SS LENGAN PENDEK S3L474J1:WHITE:M:SOLID:BLUES LINEN | M11: 249900 | N11: SP | O11: 99000 | P11: SPECIAL PRICE
A12: 2024 H2 Woven Top, Outerwear, Woven Bottom, Dress SP 99 | B12: ='2023 SP 79'!$B$2 -> 2026-03-27 | C12: ='2023 SP 79'!$C$2 -> 2026-04-01 | D12: 3328 | E12: 347 | F12: 5 | G12: 2 | I12: SUKO | J12: 45337215 | K12: S3L474J1 | L12: BLUES LINEN BLEND VOLUME SS LENGAN PENDEK S3L474J1:WHITE:L:SOLID:BLUES LINEN | M12: 249900 | N12: SP | O12: 99000 | P12: SPECIAL PRICE
A13: 2024 H2 Woven Top, Outerwear, Woven Bottom, Dress SP 99 | B13: ='2023 SP 79'!$B$2 -> 2026-03-27 | C13: ='2023 SP 79'!$C$2 -> 2026-04-01 | D13: 3328 | E13: 347 | F13: 5 | G13: 2 | I13: SUKO | J13: 45337224 | K13: S3L474J1 | L13: BLUES LINEN BLEND VOLUME SS LENGAN PENDEK S3L474J1:WHITE:XL:SOLID:BLUES LINEN | M13: 249900 | N13: SP | O13: 99000 | P13: SPECIAL PRICE
... A55: 2024 H2 Woven Top, Outerwear, Woven Bottom, Dress SP 99 | B55: ='2023 SP 79'!$B$2 -> 2026-03-27 | C55: ='2023 SP 79'!$C$2 -> 2026-04-01 | D55: 3328 | E55: 347 | F55: 5 | G55: 7 | I55: SUKO | J55: 45337546 | K55: R1L454J3 | L55: GAUN LINEN BLEND LENGAN PENDEK R1L454J3:GOLDEN BROWN:M:SOLID:GAUN LINEN | M55: 329900 | N55: SP | O55: 99000 | P55: SPECIAL PRICE

Sheet 2024 H2 SP 199
A1: ACARA | B1: FROM DATE | C1: TO DATE | D1: DEPT | E1: WORLD | F1: DIVISION | G1: CLASS | H1: SUPPLIER | I1: BRAND | J1: SKU | K1: ARTICLE | L1: DESCRIPTION | M1: HARGA NORMAL | N1: DISKON | O1: HARGA PROMO | P1: DISCOUNT TYPE
A2: 2024 Woven Top SP 199 | B2: ='2023 SP 79'!$B$2 -> 2026-03-27 | C2: ='2023 SP 79'!$C$2 -> 2026-04-01 | D2: 3328 | E2: 347 | F2: 5 | G2: 2 | I2: SUKO | J2: 22246679 | K2: S2OS13J2 | L2: KEMEJA OXFORD OVERSIZED STRIPED SHIRT L/S WOVEN TOP GARIS LENGAN PANJANG S2OS13J2:PASTEL GREEN:S:STR | M2: 249900 | N2: SP | O2: 199000 | P2: SPECIAL PRICE
A3: 2024 Woven Top SP 199 | B3: ='2023 SP 79'!$B$2 -> 2026-03-27 | C3: ='2023 SP 79'!$C$2 -> 2026-04-01 | D3: 3328 | E3: 347 | F3: 5 | G3: 2 | I3: SUKO | J3: 22246688 | K3: S2OS13J2 | L3: KEMEJA OXFORD OVERSIZED STRIPED SHIRT L/S WOVEN TOP GARIS LENGAN PANJANG S2OS13J2:PASTEL GREEN:M:STR | M3: 249900 | N3: SP | O3: 199000 | P3: SPECIAL PRICE
A4: 2024 Woven Top SP 199 | B4: ='2023 SP 79'!$B$2 -> 2026-03-27 | C4: ='2023 SP 79'!$C$2 -> 2026-04-01 | D4: 3328 | E4: 347 | F4: 5 | G4: 2 | I4: SUKO | J4: 22246697 | K4: S2OS13J2 | L4: KEMEJA OXFORD OVERSIZED STRIPED SHIRT L/S WOVEN TOP GARIS LENGAN PANJANG S2OS13J2:PASTEL GREEN:L:STR | M4: 249900 | N4: SP | O4: 199000 | P4: SPECIAL PRICE
A5: 2024 Woven Top SP 199 | B5: ='2023 SP 79'!$B$2 -> 2026-03-27 | C5: ='2023 SP 79'!$C$2 -> 2026-04-01 | D5: 3328 | E5: 347 | F5: 5 | G5: 2 | I5: SUKO | J5: 22246704 | K5: S2OS13J2 | L5: KEMEJA OXFORD OVERSIZED STRIPED SHIRT L/S WOVEN TOP GARIS LENGAN PANJANG S2OS13J2:PASTEL GREEN:XL:ST | M5: 249900 | N5: SP | O5: 199000 | P5: SPECIAL PRICE

Sheet 2024-2025 KI NORMAL PRICE
A1: ACARA | B1: FROM DATE | C1: TO DATE | D1: DEPT | E1: WORLD | F1: DIVISION | G1: CLASS | H1: SUPPLIER | I1: BRAND | J1: SKU | K1: ARTICLE | L1: DESCRIPTION | M1: HARGA NORMAL | N1: DISKON | O1: HARGA PROMO | P1: DISCOUNT TYPE
A2: 2024-2025 KI NORMAL PRICE | B2: ='2023 SP 79'!$B$2 -> 2026-03-27 | C2: ='2023 SP 79'!$C$2 -> 2026-04-01 | D2: 3328 | E2: 347 | F2: 5 | G2: 8 | I2: SUKO | J2: 80744441 | K2: T1KT1351 | L2: T-SHIRT SS ROUND NECK KERAH BULAT LENGAN PENDEK T1KT1351:BLACK:S:SOLID:T-SHIRT | M2: 129900 | N2: 0 | O2: NORMAL PRICE | P2: AMOUNT
A3: 2024-2025 KI NORMAL PRICE | B3: ='2023 SP 79'!$B$2 -> 2026-03-27 | C3: ='2023 SP 79'!$C$2 -> 2026-04-01 | D3: 3328 | E3: 347 | F3: 5 | G3: 8 | I3: SUKO | J3: 80744450 | K3: T1KT1351 | L3: T-SHIRT SS ROUND NECK KERAH BULAT LENGAN PENDEK T1KT1351:BLACK:M:SOLID:T-SHIRT | M3: 129900 | N3: 0 | O3: NORMAL PRICE | P3: AMOUNT
A4: 2024-2025 KI NORMAL PRICE | B4: ='2023 SP 79'!$B$2 -> 2026-03-27 | C4: ='2023 SP 79'!$C$2 -> 2026-04-01 | D4: 3328 | E4: 347 | F4: 5 | G4: 8 | I4: SUKO | J4: 80744469 | K4: T1KT1351 | L4: T-SHIRT SS ROUND NECK KERAH BULAT LENGAN PENDEK T1KT1351:BLACK:L:SOLID:T-SHIRT | M4: 129900 | N4: 0 | O4: NORMAL PRICE | P4: AMOUNT
A5: 2024-2025 KI NORMAL PRICE | B5: ='2023 SP 79'!$B$2 -> 2026-03-27 | C5: ='2023 SP 79'!$C$2 -> 2026-04-01 | D5: 3328 | E5: 347 | F5: 5 | G5: 8 | I5: SUKO | J5: 80744478 | K5: T1KT1351 | L5: T-SHIRT SS ROUND NECK KERAH BULAT LENGAN PENDEK T1KT1351:BLACK:XL:SOLID:T-SHIRT | M5: 129900 | N5: 0 | O5: NORMAL PRICE | P5: AMOUNT
A6: 2024-2025 KI NORMAL PRICE | B6: ='2023 SP 79'!$B$2 -> 2026-03-27 | C6: ='2023 SP 79'!$C$2 -> 2026-04-01 | D6: 3328 | E6: 347 | F6: 5 | G6: 8 | I6: SUKO | J6: 45395126 | K6: T1KT1351 | L6: T-SHIRT SS ROUND NECK KERAH BULAT LENGAN PENDEK T1KT1351:WHITE:S:SOLID:T-SHIRT | M6: 129900 | N6: 0 | O6: NORMAL PRICE | P6: AMOUNT
A7: 2024-2025 KI NORMAL PRICE | B7: ='2023 SP 79'!$B$2 -> 2026-03-27 | C7: ='2023 SP 79'!$C$2 -> 2026-04-01 | D7: 3328 | E7: 347 | F7: 5 | G7: 8 | I7: SUKO | J7: 45395135 | K7: T1KT1351 | L7: T-SHIRT SS ROUND NECK KERAH BULAT LENGAN PENDEK T1KT1351:WHITE:M:SOLID:T-SHIRT | M7: 129900 | N7: 0 | O7: NORMAL PRICE | P7: AMOUNT
A8: 2024-2025 KI NORMAL PRICE | B8: ='2023 SP 79'!$B$2 -> 2026-03-27 | C8: ='2023 SP 79'!$C$2 -> 2026-04-01 | D8: 3328 | E8: 347 | F8: 5 | G8: 8 | I8: SUKO | J8: 45395144 | K8: T1KT1351 | L8: T-SHIRT SS ROUND NECK KERAH BULAT LENGAN PENDEK T1KT1351:WHITE:L:SOLID:T-SHIRT | M8: 129900 | N8: 0 | O8: NORMAL PRICE | P8: AMOUNT
A9: 2024-2025 KI NORMAL PRICE | B9: ='2023 SP 79'!$B$2 -> 2026-03-27 | C9: ='2023 SP 79'!$C$2 -> 2026-04-01 | D9: 3328 | E9: 347 | F9: 5 | G9: 8 | I9: SUKO | J9: 45395153 | K9: T1KT1351 | L9: T-SHIRT SS ROUND NECK KERAH BULAT LENGAN PENDEK T1KT1351:WHITE:XL:SOLID:T-SHIRT | M9: 129900 | N9: 0 | O9: NORMAL PRICE | P9: AMOUNT
A10: 2024-2025 KI NORMAL PRICE | B10: ='2023 SP 79'!$B$2 -> 2026-03-27 | C10: ='2023 SP 79'!$C$2 -> 2026-04-01 | D10: 3328 | E10: 347 | F10: 5 | G10: 8 | I10: SUKO | J10: 80744361 | K10: T1KT1351 | L10: T-SHIRT SS ROUND NECK KERAH BULAT LENGAN PENDEK T1KT1351:KHAKI:S:SOLID:T-SHIRT | M10: 129900 | N10: 0 | O10: NORMAL PRICE | P10: AMOUNT
A11: 2024-2025 KI NORMAL PRICE | B11: ='2023 SP 79'!$B$2 -> 2026-03-27 | C11: ='2023 SP 79'!$C$2 -> 2026-04-01 | D11: 3328 | E11: 347 | F11: 5 | G11: 8 | I11: SUKO | J11: 80744370 | K11: T1KT1351 | L11: T-SHIRT SS ROUND NECK KERAH BULAT LENGAN PENDEK T1KT1351:KHAKI:M:SOLID:T-SHIRT | M11: 129900 | N11: 0 | O11: NORMAL PRICE | P11: AMOUNT
A12: 2024-2025 KI NORMAL PRICE | B12: ='2023 SP 79'!$B$2 -> 2026-03-27 | C12: ='2023 SP 79'!$C$2 -> 2026-04-01 | D12: 3328 | E12: 347 | F12: 5 | G12: 8 | I12: SUKO | J12: 80744389 | K12: T1KT1351 | L12: T-SHIRT SS ROUND NECK KERAH BULAT LENGAN PENDEK T1KT1351:KHAKI:L:SOLID:T-SHIRT | M12: 129900 | N12: 0 | O12: NORMAL PRICE | P12: AMOUNT
A13: 2024-2025 KI NORMAL PRICE | B13: ='2023 SP 79'!$B$2 -> 2026-03-27 | C13: ='2023 SP 79'!$C$2 -> 2026-04-01 | D13: 3328 | E13: 347 | F13: 5 | G13: 8 | I13: SUKO | J13: 80744398 | K13: T1KT1351 | L13: T-SHIRT SS ROUND NECK KERAH BULAT LENGAN PENDEK T1KT1351:KHAKI:XL:SOLID:T-SHIRT | M13: 129900 | N13: 0 | O13: NORMAL PRICE | P13: AMOUNT
... A75: 2024-2025 KI NORMAL PRICE | B75: ='2023 SP 79'!$B$2 -> 2026-03-27 | C75: ='2023 SP 79'!$C$2 -> 2026-04-01 | D75: 3328 | E75: 347 | F75: 5 | G75: 8 | I75: SUKO | J75: 53508659 | K75: T1KT1351 | L75: T-SHIRT SS ROUND NECK KERAH BULAT LENGAN PENDEK T1KT1351:CERAMIC:XL:SOLID:T-SHIRT | M75: 129900 | N75: 0 | O75: NORMAL PRICE | P75: AMOUNT

Sheet 2024-2025 KI SP 99
A1: ACARA | B1: FROM DATE | C1: TO DATE | D1: DEPT | E1: WORLD | F1: DIVISION | G1: CLASS | H1: SUPPLIER | I1: BRAND | J1: SKU | K1: ARTICLE | L1: DESCRIPTION | M1: HARGA NORMAL | N1: DISKON | O1: HARGA PROMO | P1: DISCOUNT TYPE
A2: 2024-2025 DISCONTINUE KI SP 99 | B2: ='2023 SP 79'!$B$2 -> 2026-03-27 | C2: ='2023 SP 79'!$C$2 -> 2026-04-01 | D2: 3328 | E2: 347 | F2: 5 | G2: 8 | I2: SUKO | J2: 18748313 | K2: T1BT13J1 | L2: OVERSIZED T-SHIRT BABY TERRY TEE CROP S/S KNIT TOP CROPPED LENGTH KERAH BULAT LENGAN PENDEK T1BT13J1 | M2: 149900 | N2: SP | O2: 99000 | P2: SPECIAL PRICE
A3: 2024-2025 DISCONTINUE KI SP 99 | B3: ='2023 SP 79'!$B$2 -> 2026-03-27 | C3: ='2023 SP 79'!$C$2 -> 2026-04-01 | D3: 3328 | E3: 347 | F3: 5 | G3: 8 | I3: SUKO | J3: 18748322 | K3: T1BT13J1 | L3: OVERSIZED T-SHIRT BABY TERRY TEE CROP S/S KNIT TOP CROPPED LENGTH KERAH BULAT LENGAN PENDEK T1BT13J1 | M3: 149900 | N3: SP | O3: 99000 | P3: SPECIAL PRICE
A4: 2024-2025 DISCONTINUE KI SP 99 | B4: ='2023 SP 79'!$B$2 -> 2026-03-27 | C4: ='2023 SP 79'!$C$2 -> 2026-04-01 | D4: 3328 | E4: 347 | F4: 5 | G4: 8 | I4: SUKO | J4: 18748331 | K4: T1BT13J1 | L4: OVERSIZED T-SHIRT BABY TERRY TEE CROP S/S KNIT TOP CROPPED LENGTH KERAH BULAT LENGAN PENDEK T1BT13J1 | M4: 149900 | N4: SP | O4: 99000 | P4: SPECIAL PRICE
A5: 2024-2025 DISCONTINUE KI SP 99 | B5: ='2023 SP 79'!$B$2 -> 2026-03-27 | C5: ='2023 SP 79'!$C$2 -> 2026-04-01 | D5: 3328 | E5: 347 | F5: 5 | G5: 8 | I5: SUKO | J5: 18748340 | K5: T1BT13J1 | L5: OVERSIZED T-SHIRT BABY TERRY TEE CROP S/S KNIT TOP CROPPED LENGTH KERAH BULAT LENGAN PENDEK T1BT13J1 | M5: 149900 | N5: SP | O5: 99000 | P5: SPECIAL PRICE
A6: 2024-2025 DISCONTINUE KI SP 99 | B6: ='2023 SP 79'!$B$2 -> 2026-03-27 | C6: ='2023 SP 79'!$C$2 -> 2026-04-01 | D6: 3328 | E6: 347 | F6: 5 | G6: 8 | I6: SUKO | J6: 18748279 | K6: T1BT13J1 | L6: OVERSIZED T-SHIRT BABY TERRY TEE CROP S/S KNIT TOP CROPPED LENGTH KERAH BULAT LENGAN PENDEK T1BT13J1 | M6: 149900 | N6: SP | O6: 99000 | P6: SPECIAL PRICE
A7: 2024-2025 DISCONTINUE KI SP 99 | B7: ='2023 SP 79'!$B$2 -> 2026-03-27 | C7: ='2023 SP 79'!$C$2 -> 2026-04-01 | D7: 3328 | E7: 347 | F7: 5 | G7: 8 | I7: SUKO | J7: 18748288 | K7: T1BT13J1 | L7: OVERSIZED T-SHIRT BABY TERRY TEE CROP S/S KNIT TOP CROPPED LENGTH KERAH BULAT LENGAN PENDEK T1BT13J1 | M7: 149900 | N7: SP | O7: 99000 | P7: SPECIAL PRICE
A8: 2024-2025 DISCONTINUE KI SP 99 | B8: ='2023 SP 79'!$B$2 -> 2026-03-27 | C8: ='2023 SP 79'!$C$2 -> 2026-04-01 | D8: 3328 | E8: 347 | F8: 5 | G8: 8 | I8: SUKO | J8: 18748297 | K8: T1BT13J1 | L8: OVERSIZED T-SHIRT BABY TERRY TEE CROP S/S KNIT TOP CROPPED LENGTH KERAH BULAT LENGAN PENDEK T1BT13J1 | M8: 149900 | N8: SP | O8: 99000 | P8: SPECIAL PRICE
A9: 2024-2025 DISCONTINUE KI SP 99 | B9: ='2023 SP 79'!$B$2 -> 2026-03-27 | C9: ='2023 SP 79'!$C$2 -> 2026-04-01 | D9: 3328 | E9: 347 | F9: 5 | G9: 8 | I9: SUKO | J9: 18748304 | K9: T1BT13J1 | L9: OVERSIZED T-SHIRT BABY TERRY TEE CROP S/S KNIT TOP CROPPED LENGTH KERAH BULAT LENGAN PENDEK T1BT13J1 | M9: 149900 | N9: SP | O9: 99000 | P9: SPECIAL PRICE
A10: 2024-2025 DISCONTINUE KI SP 99 | B10: ='2023 SP 79'!$B$2 -> 2026-03-27 | C10: ='2023 SP 79'!$C$2 -> 2026-04-01 | D10: 3328 | E10: 347 | F10: 5 | G10: 8 | I10: SUKO | J10: 45395242 | K10: T1BT13J1 | L10: OVERSIZED T-SHIRT BABY TERRY TEE CROP SS KNIT TOP CROPPED LENGTH KERAH BULAT LENGAN PENDEK T1BT13J1: | M10: 149900 | N10: SP | O10: 99000 | P10: SPECIAL PRICE
A11: 2024-2025 DISCONTINUE KI SP 99 | B11: ='2023 SP 79'!$B$2 -> 2026-03-27 | C11: ='2023 SP 79'!$C$2 -> 2026-04-01 | D11: 3328 | E11: 347 | F11: 5 | G11: 8 | I11: SUKO | J11: 45395251 | K11: T1BT13J1 | L11: OVERSIZED T-SHIRT BABY TERRY TEE CROP SS KNIT TOP CROPPED LENGTH KERAH BULAT LENGAN PENDEK T1BT13J1: | M11: 149900 | N11: SP | O11: 99000 | P11: SPECIAL PRICE
A12: 2024-2025 DISCONTINUE KI SP 99 | B12: ='2023 SP 79'!$B$2 -> 2026-03-27 | C12: ='2023 SP 79'!$C$2 -> 2026-04-01 | D12: 3328 | E12: 347 | F12: 5 | G12: 8 | I12: SUKO | J12: 45395260 | K12: T1BT13J1 | L12: OVERSIZED T-SHIRT BABY TERRY TEE CROP SS KNIT TOP CROPPED LENGTH KERAH BULAT LENGAN PENDEK T1BT13J1: | M12: 149900 | N12: SP | O12: 99000 | P12: SPECIAL PRICE
A13: 2024-2025 DISCONTINUE KI SP 99 | B13: ='2023 SP 79'!$B$2 -> 2026-03-27 | C13: ='2023 SP 79'!$C$2 -> 2026-04-01 | D13: 3328 | E13: 347 | F13: 5 | G13: 8 | I13: SUKO | J13: 45395279 | K13: T1BT13J1 | L13: OVERSIZED T-SHIRT BABY TERRY TEE CROP SS KNIT TOP CROPPED LENGTH KERAH BULAT LENGAN PENDEK T1BT13J1: | M13: 149900 | N13: SP | O13: 99000 | P13: SPECIAL PRICE
... A85: 2024-2025 DISCONTINUE KI SP 99 | B85: ='2023 SP 79'!$B$2 -> 2026-03-27 | C85: ='2023 SP 79'!$C$2 -> 2026-04-01 | D85: 3328 | E85: 347 | F85: 5 | G85: 8 | I85: SUKO | J85: 54636250 | K85: T2L314G1 | L85: T-SHIRT 3/4 JERSEY KERAH BULAT LENGAN 3/4 T2L314G1:SAND:S:SOLID:T-SHIRT 3/4 | M85: 149900 | N85: SP | O85: 99000 | P85: SPECIAL PRICE

Sheet 2024-2025 KI SP109
A1: ACARA | B1: FROM DATE | C1: TO DATE | D1: DEPT | E1: WORLD | F1: DIVISION | G1: CLASS | H1: SUPPLIER | I1: BRAND | J1: SKU | K1: ARTICLE | L1: DESCRIPTION | M1: HARGA NORMAL | N1: DISKON | O1: HARGA PROMO | P1: DISCOUNT TYPE
A2: 2024-2025 DISCONTINUE KI SP 109 | B2: ='2023 SP 79'!$B$2 -> 2026-03-27 | C2: ='2023 SP 79'!$C$2 -> 2026-04-01 | D2: 3328 | E2: 347 | F2: 5 | G2: 8 | I2: SUKO | J2: 51880858 | K2: T1L415A1 | L2: T-SHIRT WAFFLE KERAH BULAT LENGAN PANJANG T1L415A1:AQUA:S:SOLID:T-SHIRT WAFFLE | M2: 169900 | N2: SP | O2: 109000 | P2: SPECIAL PRICE
A3: 2024-2025 DISCONTINUE KI SP 109 | B3: ='2023 SP 79'!$B$2 -> 2026-03-27 | C3: ='2023 SP 79'!$C$2 -> 2026-04-01 | D3: 3328 | E3: 347 | F3: 5 | G3: 8 | I3: SUKO | J3: 51880867 | K3: T1L415A1 | L3: T-SHIRT WAFFLE KERAH BULAT LENGAN PANJANG T1L415A1:AQUA:M:SOLID:T-SHIRT WAFFLE | M3: 169900 | N3: SP | O3: 109000 | P3: SPECIAL PRICE
A4: 2024-2025 DISCONTINUE KI SP 109 | B4: ='2023 SP 79'!$B$2 -> 2026-03-27 | C4: ='2023 SP 79'!$C$2 -> 2026-04-01 | D4: 3328 | E4: 347 | F4: 5 | G4: 8 | I4: SUKO | J4: 51880876 | K4: T1L415A1 | L4: T-SHIRT WAFFLE KERAH BULAT LENGAN PANJANG T1L415A1:AQUA:L:SOLID:T-SHIRT WAFFLE | M4: 169900 | N4: SP | O4: 109000 | P4: SPECIAL PRICE
A5: 2024-2025 DISCONTINUE KI SP 109 | B5: ='2023 SP 79'!$B$2 -> 2026-03-27 | C5: ='2023 SP 79'!$C$2 -> 2026-04-01 | D5: 3328 | E5: 347 | F5: 5 | G5: 8 | I5: SUKO | J5: 51880885 | K5: T1L415A1 | L5: T-SHIRT WAFFLE KERAH BULAT LENGAN PANJANG T1L415A1:AQUA:XL:SOLID:T-SHIRT WAFFLE | M5: 169900 | N5: SP | O5: 109000 | P5: SPECIAL PRICE
A6: 2024-2025 DISCONTINUE KI SP 109 | B6: ='2023 SP 79'!$B$2 -> 2026-03-27 | C6: ='2023 SP 79'!$C$2 -> 2026-04-01 | D6: 3328 | E6: 347 | F6: 5 | G6: 8 | I6: SUKO | J6: 54377423 | K6: T1L415A1 | L6: T-SHIRT WAFFLE KERAH BULAT LENGAN PANJANG T1L415A1:MISTY LIGHT GREY:S:SOLID:T-SHIRT WAFFLE | M6: 169900 | N6: SP | O6: 109000 | P6: SPECIAL PRICE
A7: 2024-2025 DISCONTINUE KI SP 109 | B7: ='2023 SP 79'!$B$2 -> 2026-03-27 | C7: ='2023 SP 79'!$C$2 -> 2026-04-01 | D7: 3328 | E7: 347 | F7: 5 | G7: 8 | I7: SUKO | J7: 54377432 | K7: T1L415A1 | L7: T-SHIRT WAFFLE KERAH BULAT LENGAN PANJANG T1L415A1:MISTY LIGHT GREY:M:SOLID:T-SHIRT WAFFLE | M7: 169900 | N7: SP | O7: 109000 | P7: SPECIAL PRICE
A8: 2024-2025 DISCONTINUE KI SP 109 | B8: ='2023 SP 79'!$B$2 -> 2026-03-27 | C8: ='2023 SP 79'!$C$2 -> 2026-04-01 | D8: 3328 | E8: 347 | F8: 5 | G8: 8 | I8: SUKO | J8: 54377441 | K8: T1L415A1 | L8: T-SHIRT WAFFLE KERAH BULAT LENGAN PANJANG T1L415A1:MISTY LIGHT GREY:L:SOLID:T-SHIRT WAFFLE | M8: 169900 | N8: SP | O8: 109000 | P8: SPECIAL PRICE
A9: 2024-2025 DISCONTINUE KI SP 109 | B9: ='2023 SP 79'!$B$2 -> 2026-03-27 | C9: ='2023 SP 79'!$C$2 -> 2026-04-01 | D9: 3328 | E9: 347 | F9: 5 | G9: 8 | I9: SUKO | J9: 54377450 | K9: T1L415A1 | L9: T-SHIRT WAFFLE KERAH BULAT LENGAN PANJANG T1L415A1:MISTY LIGHT GREY:XL:SOLID:T-SHIRT WAFFLE | M9: 169900 | N9: SP | O9: 109000 | P9: SPECIAL PRICE
A10: 2024-2025 DISCONTINUE KI SP 109 | B10: ='2023 SP 79'!$B$2 -> 2026-03-27 | C10: ='2023 SP 79'!$C$2 -> 2026-04-01 | D10: 3328 | E10: 347 | F10: 5 | G10: 8 | I10: SUKO | J10: 53511529 | K10: T1L415A1 | L10: T-SHIRT WAFFLE KERAH BULAT LENGAN PANJANG T1L415A1:SALMON:S:SOLID:T-SHIRT WAFFLE | M10: 169900 | N10: SP | O10: 109000 | P10: SPECIAL PRICE
A11: 2024-2025 DISCONTINUE KI SP 109 | B11: ='2023 SP 79'!$B$2 -> 2026-03-27 | C11: ='2023 SP 79'!$C$2 -> 2026-04-01 | D11: 3328 | E11: 347 | F11: 5 | G11: 8 | I11: SUKO | J11: 53511538 | K11: T1L415A1 | L11: T-SHIRT WAFFLE KERAH BULAT LENGAN PANJANG T1L415A1:SALMON:M:SOLID:T-SHIRT WAFFLE | M11: 169900 | N11: SP | O11: 109000 | P11: SPECIAL PRICE
A12: 2024-2025 DISCONTINUE KI SP 109 | B12: ='2023 SP 79'!$B$2 -> 2026-03-27 | C12: ='2023 SP 79'!$C$2 -> 2026-04-01 | D12: 3328 | E12: 347 | F12: 5 | G12: 8 | I12: SUKO | J12: 53511547 | K12: T1L415A1 | L12: T-SHIRT WAFFLE KERAH BULAT LENGAN PANJANG T1L415A1:SALMON:L:SOLID:T-SHIRT WAFFLE | M12: 169900 | N12: SP | O12: 109000 | P12: SPECIAL PRICE
A13: 2024-2025 DISCONTINUE KI SP 109 | B13: ='2023 SP 79'!$B$2 -> 2026-03-27 | C13: ='2023 SP 79'!$C$2 -> 2026-04-01 | D13: 3328 | E13: 347 | F13: 5 | G13: 8 | I13: SUKO | J13: 53511556 | K13: T1L415A1 | L13: T-SHIRT WAFFLE KERAH BULAT LENGAN PANJANG T1L415A1:SALMON:XL:SOLID:T-SHIRT WAFFLE | M13: 169900 | N13: SP | O13: 109000 | P13: SPECIAL PRICE
... A45: 2024-2025 DISCONTINUE KI SP 109 | B45: ='2023 SP 79'!$B$2 -> 2026-03-27 | C45: ='2023 SP 79'!$C$2 -> 2026-04-01 | D45: 3328 | E45: 347 | F45: 5 | G45: 8 | I45: SUKO | J45: 54377414 | K45: T1L415A1 | L45: T-SHIRT WAFFLE KERAH BULAT LENGAN PANJANG T1L415A1:DUSTY PINK:XL:SOLID:T-SHIRT WAFFLE | M45: 169900 | N45: SP | O45: 109000 | P45: SPECIAL PRICE

Sheet 2025 H1 SP99
A1: ACARA | B1: FROM DATE | C1: TO DATE | D1: DEPT | E1: WORLD | F1: DIVISION | G1: CLASS | H1: SUPPLIER | I1: BRAND | J1: SKU | K1: ARTICLE | L1: DESCRIPTION | M1: HARGA NORMAL | N1: DISKON | O1: HARGA PROMO | P1: DISCOUNT TYPE
A2: 2025 H1 Knit Top, Woven Top, Woven Bottom, Dress SP99 | B2: ='2023 SP 79'!$B$2 -> 2026-03-27 | C2: ='2023 SP 79'!$C$2 -> 2026-04-01 | D2: 3328 | E2: 347 | F2: 5 | G2: 2 | I2: SUKO | J2: 51716026 | K2: S4L545A4-2 | L2: KEMEJA MOTIF PRINTED TUNIC LS LENGAN PANJANG S4L545A4-2:PASTEL GREY:S:PRINT:KEMEJA MOTIF | M2: 279900 | N2: SP | O2: 99000 | P2: SPECIAL PRICE
A3: 2025 H1 Knit Top, Woven Top, Woven Bottom, Dress SP99 | B3: ='2023 SP 79'!$B$2 -> 2026-03-27 | C3: ='2023 SP 79'!$C$2 -> 2026-04-01 | D3: 3328 | E3: 347 | F3: 5 | G3: 2 | I3: SUKO | J3: 51716035 | K3: S4L545A4-2 | L3: KEMEJA MOTIF PRINTED TUNIC LS LENGAN PANJANG S4L545A4-2:PASTEL GREY:M:PRINT:KEMEJA MOTIF | M3: 279900 | N3: SP | O3: 99000 | P3: SPECIAL PRICE
A4: 2025 H1 Knit Top, Woven Top, Woven Bottom, Dress SP99 | B4: ='2023 SP 79'!$B$2 -> 2026-03-27 | C4: ='2023 SP 79'!$C$2 -> 2026-04-01 | D4: 3328 | E4: 347 | F4: 5 | G4: 2 | I4: SUKO | J4: 51716044 | K4: S4L545A4-2 | L4: KEMEJA MOTIF PRINTED TUNIC LS LENGAN PANJANG S4L545A4-2:PASTEL GREY:L:PRINT:KEMEJA MOTIF | M4: 279900 | N4: SP | O4: 99000 | P4: SPECIAL PRICE
A5: 2025 H1 Knit Top, Woven Top, Woven Bottom, Dress SP99 | B5: ='2023 SP 79'!$B$2 -> 2026-03-27 | C5: ='2023 SP 79'!$C$2 -> 2026-04-01 | D5: 3328 | E5: 347 | F5: 5 | G5: 2 | I5: SUKO | J5: 51716053 | K5: S4L545A4-2 | L5: KEMEJA MOTIF PRINTED TUNIC LS LENGAN PANJANG S4L545A4-2:PASTEL GREY:XL:PRINT:KEMEJA MOTIF | M5: 279900 | N5: SP | O5: 99000 | P5: SPECIAL PRICE
A6: 2025 H1 Knit Top, Woven Top, Woven Bottom, Dress SP99 | B6: ='2023 SP 79'!$B$2 -> 2026-03-27 | C6: ='2023 SP 79'!$C$2 -> 2026-04-01 | D6: 3328 | E6: 347 | F6: 5 | G6: 2 | I6: SUKO | J6: 51715983 | K6: S4L545A4-1 | L6: KEMEJA MOTIF PRINTED TUNIC LS LENGAN PANJANG S4L545A4-1:VANILLA:S:PRINT:KEMEJA MOTIF | M6: 279900 | N6: SP | O6: 99000 | P6: SPECIAL PRICE
A7: 2025 H1 Knit Top, Woven Top, Woven Bottom, Dress SP99 | B7: ='2023 SP 79'!$B$2 -> 2026-03-27 | C7: ='2023 SP 79'!$C$2 -> 2026-04-01 | D7: 3328 | E7: 347 | F7: 5 | G7: 2 | I7: SUKO | J7: 51715992 | K7: S4L545A4-1 | L7: KEMEJA MOTIF PRINTED TUNIC LS LENGAN PANJANG S4L545A4-1:VANILLA:M:PRINT:KEMEJA MOTIF | M7: 279900 | N7: SP | O7: 99000 | P7: SPECIAL PRICE
A8: 2025 H1 Knit Top, Woven Top, Woven Bottom, Dress SP99 | B8: ='2023 SP 79'!$B$2 -> 2026-03-27 | C8: ='2023 SP 79'!$C$2 -> 2026-04-01 | D8: 3328 | E8: 347 | F8: 5 | G8: 2 | I8: SUKO | J8: 51716008 | K8: S4L545A4-1 | L8: KEMEJA MOTIF PRINTED TUNIC LS LENGAN PANJANG S4L545A4-1:VANILLA:L:PRINT:KEMEJA MOTIF | M8: 279900 | N8: SP | O8: 99000 | P8: SPECIAL PRICE
A9: 2025 H1 Knit Top, Woven Top, Woven Bottom, Dress SP99 | B9: ='2023 SP 79'!$B$2 -> 2026-03-27 | C9: ='2023 SP 79'!$C$2 -> 2026-04-01 | D9: 3328 | E9: 347 | F9: 5 | G9: 2 | I9: SUKO | J9: 51716017 | K9: S4L545A4-1 | L9: KEMEJA MOTIF PRINTED TUNIC LS LENGAN PANJANG S4L545A4-1:VANILLA:XL:PRINT:KEMEJA MOTIF | M9: 279900 | N9: SP | O9: 99000 | P9: SPECIAL PRICE
A10: 2025 H1 Knit Top, Woven Top, Woven Bottom, Dress SP99 | B10: ='2023 SP 79'!$B$2 -> 2026-03-27 | C10: ='2023 SP 79'!$C$2 -> 2026-04-01 | D10: 3328 | E10: 347 | F10: 5 | G10: 2 | I10: SUKO | J10: 51716062 | K10: S4L545A4-3 | L10: KEMEJA MOTIF PRINTED TUNIC LS LENGAN PANJANG S4L545A4-3:PASTEL GREEN:S:PRINT:KEMEJA MOTIF | M10: 279900 | N10: SP | O10: 99000 | P10: SPECIAL PRICE
A11: 2025 H1 Knit Top, Woven Top, Woven Bottom, Dress SP99 | B11: ='2023 SP 79'!$B$2 -> 2026-03-27 | C11: ='2023 SP 79'!$C$2 -> 2026-04-01 | D11: 3328 | E11: 347 | F11: 5 | G11: 2 | I11: SUKO | J11: 51716071 | K11: S4L545A4-3 | L11: KEMEJA MOTIF PRINTED TUNIC LS LENGAN PANJANG S4L545A4-3:PASTEL GREEN:M:PRINT:KEMEJA MOTIF | M11: 279900 | N11: SP | O11: 99000 | P11: SPECIAL PRICE
A12: 2025 H1 Knit Top, Woven Top, Woven Bottom, Dress SP99 | B12: ='2023 SP 79'!$B$2 -> 2026-03-27 | C12: ='2023 SP 79'!$C$2 -> 2026-04-01 | D12: 3328 | E12: 347 | F12: 5 | G12: 2 | I12: SUKO | J12: 51716080 | K12: S4L545A4-3 | L12: KEMEJA MOTIF PRINTED TUNIC LS LENGAN PANJANG S4L545A4-3:PASTEL GREEN:L:PRINT:KEMEJA MOTIF | M12: 279900 | N12: SP | O12: 99000 | P12: SPECIAL PRICE
A13: 2025 H1 Knit Top, Woven Top, Woven Bottom, Dress SP99 | B13: ='2023 SP 79'!$B$2 -> 2026-03-27 | C13: ='2023 SP 79'!$C$2 -> 2026-04-01 | D13: 3328 | E13: 347 | F13: 5 | G13: 2 | I13: SUKO | J13: 51716099 | K13: S4L545A4-3 | L13: KEMEJA MOTIF PRINTED TUNIC LS LENGAN PANJANG S4L545A4-3:PASTEL GREEN:XL:PRINT:KEMEJA MOTIF | M13: 279900 | N13: SP | O13: 99000 | P13: SPECIAL PRICE
... A94: 2025 H1 Knit Top, Woven Top, Woven Bottom, Dress SP99 | B94: ='2023 SP 79'!$B$2 -> 2026-03-27 | C94: ='2023 SP 79'!$C$2 -> 2026-04-01 | D94: 3328 | E94: 347 | F94: 5 | G94: 1 | I94: SUKO | J94: 53703054 | K94: T3L695D4 | L94: KNIT TOP RAJUT SS T-SHIRT KERAH BULAT LENGAN PENDEK T3L695D4:PASTEL PINK:XL:SOLID:KNIT TOP RAJUT | M94: 179900 | N94: SP | O94: 99000 | P94: SPECIAL PRICE

Sheet 2025 H1 SP129
A1: ACARA | B1: FROM DATE | C1: TO DATE | D1: DEPT | E1: WORLD | F1: DIVISION | G1: CLASS | H1: SUPPLIER | I1: BRAND | J1: SKU | K1: ARTICLE | L1: DESCRIPTION | M1: HARGA NORMAL | N1: DISKON | O1: HARGA PROMO | P1: DISCOUNT TYPE
A2: 2025 H1 Knit Top, Woven Top, Woven Bottom, Knit Bottom SP 129 | B2: ='2023 SP 79'!$B$2 -> 2026-03-27 | C2: ='2023 SP 79'!$C$2 -> 2026-04-01 | D2: 3328 | E2: 347 | F2: 5 | G2: 1 | I2: SUKO | J2: 53702699 | K2: T2L815D1 | L2: T-SHIRT KERAH BULAT LENGAN PANJANG T2L815D1:SALMON:XL:SOLID:T-SHIRT | M2: 179900 | N2: SP | O2: 129000 | P2: SPECIAL PRICE
A3: 2025 H1 Knit Top, Woven Top, Woven Bottom, Knit Bottom SP 129 | B3: ='2023 SP 79'!$B$2 -> 2026-03-27 | C3: ='2023 SP 79'!$C$2 -> 2026-04-01 | D3: 3328 | E3: 347 | F3: 5 | G3: 1 | I3: SUKO | J3: 53702724 | K3: T2L815D1 | L3: T-SHIRT KERAH BULAT LENGAN PANJANG T2L815D1:OLIVE:L:SOLID:T-SHIRT | M3: 179900 | N3: SP | O3: 129000 | P3: SPECIAL PRICE
A4: 2025 H1 Knit Top, Woven Top, Woven Bottom, Knit Bottom SP 129 | B4: ='2023 SP 79'!$B$2 -> 2026-03-27 | C4: ='2023 SP 79'!$C$2 -> 2026-04-01 | D4: 3328 | E4: 347 | F4: 5 | G4: 1 | I4: SUKO | J4: 53702733 | K4: T2L815D1 | L4: T-SHIRT KERAH BULAT LENGAN PANJANG T2L815D1:OLIVE:XL:SOLID:T-SHIRT | M4: 179900 | N4: SP | O4: 129000 | P4: SPECIAL PRICE
A5: 2025 H1 Knit Top, Woven Top, Woven Bottom, Knit Bottom SP 129 | B5: ='2023 SP 79'!$B$2 -> 2026-03-27 | C5: ='2023 SP 79'!$C$2 -> 2026-04-01 | D5: 3328 | E5: 347 | F5: 5 | G5: 1 | I5: SUKO | J5: 53702742 | K5: T2L815D1 | L5: T-SHIRT KERAH BULAT LENGAN PANJANG T2L815D1:BLACK:S:SOLID:T-SHIRT | M5: 179900 | N5: SP | O5: 129000 | P5: SPECIAL PRICE
A6: 2025 H1 Knit Top, Woven Top, Woven Bottom, Knit Bottom SP 129 | B6: ='2023 SP 79'!$B$2 -> 2026-03-27 | C6: ='2023 SP 79'!$C$2 -> 2026-04-01 | D6: 3328 | E6: 347 | F6: 5 | G6: 1 | I6: SUKO | J6: 53702751 | K6: T2L815D1 | L6: T-SHIRT KERAH BULAT LENGAN PANJANG T2L815D1:BLACK:M:SOLID:T-SHIRT | M6: 179900 | N6: SP | O6: 129000 | P6: SPECIAL PRICE
A7: 2025 H1 Knit Top, Woven Top, Woven Bottom, Knit Bottom SP 129 | B7: ='2023 SP 79'!$B$2 -> 2026-03-27 | C7: ='2023 SP 79'!$C$2 -> 2026-04-01 | D7: 3328 | E7: 347 | F7: 5 | G7: 1 | I7: SUKO | J7: 53702797 | K7: T2L815D1 | L7: T-SHIRT KERAH BULAT LENGAN PANJANG T2L815D1:WHITE:M:SOLID:T-SHIRT | M7: 179900 | N7: SP | O7: 129000 | P7: SPECIAL PRICE
A8: 2025 H1 Knit Top, Woven Top, Woven Bottom, Knit Bottom SP 129 | B8: ='2023 SP 79'!$B$2 -> 2026-03-27 | C8: ='2023 SP 79'!$C$2 -> 2026-04-01 | D8: 3328 | E8: 347 | F8: 5 | G8: 1 | I8: SUKO | J8: 53702760 | K8: T2L815D1 | L8: T-SHIRT KERAH BULAT LENGAN PANJANG T2L815D1:BLACK:L:SOLID:T-SHIRT | M8: 179900 | N8: SP | O8: 129000 | P8: SPECIAL PRICE
A9: 2025 H1 Knit Top, Woven Top, Woven Bottom, Knit Bottom SP 129 | B9: ='2023 SP 79'!$B$2 -> 2026-03-27 | C9: ='2023 SP 79'!$C$2 -> 2026-04-01 | D9: 3328 | E9: 347 | F9: 5 | G9: 1 | I9: SUKO | J9: 53702788 | K9: T2L815D1 | L9: T-SHIRT KERAH BULAT LENGAN PANJANG T2L815D1:WHITE:S:SOLID:T-SHIRT | M9: 179900 | N9: SP | O9: 129000 | P9: SPECIAL PRICE
A10: 2025 H1 Knit Top, Woven Top, Woven Bottom, Knit Bottom SP 129 | B10: ='2023 SP 79'!$B$2 -> 2026-03-27 | C10: ='2023 SP 79'!$C$2 -> 2026-04-01 | D10: 3328 | E10: 347 | F10: 5 | G10: 1 | I10: SUKO | J10: 53702813 | K10: T2L815D1 | L10: T-SHIRT KERAH BULAT LENGAN PANJANG T2L815D1:WHITE:XL:SOLID:T-SHIRT | M10: 179900 | N10: SP | O10: 129000 | P10: SPECIAL PRICE
A11: 2025 H1 Knit Top, Woven Top, Woven Bottom, Knit Bottom SP 129 | B11: ='2023 SP 79'!$B$2 -> 2026-03-27 | C11: ='2023 SP 79'!$C$2 -> 2026-04-01 | D11: 3328 | E11: 347 | F11: 5 | G11: 1 | I11: SUKO | J11: 53702706 | K11: T2L815D1 | L11: T-SHIRT KERAH BULAT LENGAN PANJANG T2L815D1:OLIVE:S:SOLID:T-SHIRT | M11: 179900 | N11: SP | O11: 129000 | P11: SPECIAL PRICE
A12: 2025 H1 Knit Top, Woven Top, Woven Bottom, Knit Bottom SP 129 | B12: ='2023 SP 79'!$B$2 -> 2026-03-27 | C12: ='2023 SP 79'!$C$2 -> 2026-04-01 | D12: 3328 | E12: 347 | F12: 5 | G12: 1 | I12: SUKO | J12: 53702804 | K12: T2L815D1 | L12: T-SHIRT KERAH BULAT LENGAN PANJANG T2L815D1:WHITE:L:SOLID:T-SHIRT | M12: 179900 | N12: SP | O12: 129000 | P12: SPECIAL PRICE
A13: 2025 H1 Knit Top, Woven Top, Woven Bottom, Knit Bottom SP 129 | B13: ='2023 SP 79'!$B$2 -> 2026-03-27 | C13: ='2023 SP 79'!$C$2 -> 2026-04-01 | D13: 3328 | E13: 347 | F13: 5 | G13: 1 | I13: SUKO | J13: 53702779 | K13: T2L815D1 | L13: T-SHIRT KERAH BULAT LENGAN PANJANG T2L815D1:BLACK:XL:SOLID:T-SHIRT | M13: 179900 | N13: SP | O13: 129000 | P13: SPECIAL PRICE
... A161: 2025 H1 Knit Top, Woven Top, Woven Bottom, Knit Bottom SP 129 | B161: ='2023 SP 79'!$B$2 -> 2026-03-27 | C161: ='2023 SP 79'!$C$2 -> 2026-04-01 | D161: 3328 | E161: 347 | F161: 5 | G161: 1 | I161: SUKO | J161: 53703296 | K161: T3L725D4 | L161: KNIT TOP RAJUT LS T-SHIRT KERAH BULAT LENGAN PANJANG T3L725D4:BLACK:XL:SOLID:KNIT TOP RAJUT | M161: 199900 | N161: SP | O161: 129000 | P161: SPECIAL PRICE

Sheet 2025 H1 GRAPHIC SP129
A1: ACARA | B1: FROM DATE | C1: TO DATE | D1: DEPT | E1: WORLD | F1: DIVISION | G1: CLASS | H1: SUPPLIER | I1: BRAND | J1: SKU | K1: ARTICLE | L1: DESCRIPTION | M1: HARGA NORMAL | N1: DISKON | O1: HARGA PROMO | P1: DISCOUNT TYPE
A2: 2025 H1 Knit Top: Graphic tee SP129 | B2: ='2023 SP 79'!$B$2 -> 2026-03-27 | C2: ='2023 SP 79'!$C$2 -> 2026-04-01 | D2: 3328 | E2: 347 | F2: 5 | G2: 1 | I2: SUKO | J2: 53702420 | K2: DSTSL5-5 | L2: T-SHIRT OVERSIZED GRAPHIC DISNEY KERAH BULAT LENGAN PENDEK DSTSL5-5:WINE:S:GRAPHIC:T-SHIRT OVERSIZED | M2: 169900 | N2: SP | O2: 129000 | P2: SPECIAL PRICE
A3: 2025 H1 Knit Top: Graphic tee SP129 | B3: ='2023 SP 79'!$B$2 -> 2026-03-27 | C3: ='2023 SP 79'!$C$2 -> 2026-04-01 | D3: 3328 | E3: 347 | F3: 5 | G3: 1 | I3: SUKO | J3: 53702439 | K3: DSTSL5-5 | L3: T-SHIRT OVERSIZED GRAPHIC DISNEY KERAH BULAT LENGAN PENDEK DSTSL5-5:WINE:M:GRAPHIC:T-SHIRT OVERSIZED | M3: 169900 | N3: SP | O3: 129000 | P3: SPECIAL PRICE
A4: 2025 H1 Knit Top: Graphic tee SP129 | B4: ='2023 SP 79'!$B$2 -> 2026-03-27 | C4: ='2023 SP 79'!$C$2 -> 2026-04-01 | D4: 3328 | E4: 347 | F4: 5 | G4: 1 | I4: SUKO | J4: 53702448 | K4: DSTSL5-5 | L4: T-SHIRT OVERSIZED GRAPHIC DISNEY KERAH BULAT LENGAN PENDEK DSTSL5-5:WINE:L:GRAPHIC:T-SHIRT OVERSIZED | M4: 169900 | N4: SP | O4: 129000 | P4: SPECIAL PRICE
A5: 2025 H1 Knit Top: Graphic tee SP129 | B5: ='2023 SP 79'!$B$2 -> 2026-03-27 | C5: ='2023 SP 79'!$C$2 -> 2026-04-01 | D5: 3328 | E5: 347 | F5: 5 | G5: 1 | I5: SUKO | J5: 53702457 | K5: DSTSL5-5 | L5: T-SHIRT OVERSIZED GRAPHIC DISNEY KERAH BULAT LENGAN PENDEK DSTSL5-5:WINE:XL:GRAPHIC:T-SHIRT OVERSIZE | M5: 169900 | N5: SP | O5: 129000 | P5: SPECIAL PRICE
A6: 2025 H1 Knit Top: Graphic tee SP129 | B6: ='2023 SP 79'!$B$2 -> 2026-03-27 | C6: ='2023 SP 79'!$C$2 -> 2026-04-01 | D6: 3328 | E6: 347 | F6: 5 | G6: 1 | I6: SUKO | J6: 53702466 | K6: DSTSL5-6 | L6: T-SHIRT OVERSIZED GRAPHIC DISNEY KERAH BULAT LENGAN PENDEK DSTSL5-6:VANILLA:S:GRAPHIC:T-SHIRT OVERSI | M6: 169900 | N6: SP | O6: 129000 | P6: SPECIAL PRICE
A7: 2025 H1 Knit Top: Graphic tee SP129 | B7: ='2023 SP 79'!$B$2 -> 2026-03-27 | C7: ='2023 SP 79'!$C$2 -> 2026-04-01 | D7: 3328 | E7: 347 | F7: 5 | G7: 1 | I7: SUKO | J7: 53702475 | K7: DSTSL5-6 | L7: T-SHIRT OVERSIZED GRAPHIC DISNEY KERAH BULAT LENGAN PENDEK DSTSL5-6:VANILLA:M:GRAPHIC:T-SHIRT OVERSI | M7: 169900 | N7: SP | O7: 129000 | P7: SPECIAL PRICE
A8: 2025 H1 Knit Top: Graphic tee SP129 | B8: ='2023 SP 79'!$B$2 -> 2026-03-27 | C8: ='2023 SP 79'!$C$2 -> 2026-04-01 | D8: 3328 | E8: 347 | F8: 5 | G8: 1 | I8: SUKO | J8: 53702484 | K8: DSTSL5-6 | L8: T-SHIRT OVERSIZED GRAPHIC DISNEY KERAH BULAT LENGAN PENDEK DSTSL5-6:VANILLA:L:GRAPHIC:T-SHIRT OVERSI | M8: 169900 | N8: SP | O8: 129000 | P8: SPECIAL PRICE
A9: 2025 H1 Knit Top: Graphic tee SP129 | B9: ='2023 SP 79'!$B$2 -> 2026-03-27 | C9: ='2023 SP 79'!$C$2 -> 2026-04-01 | D9: 3328 | E9: 347 | F9: 5 | G9: 1 | I9: SUKO | J9: 53702493 | K9: DSTSL5-6 | L9: T-SHIRT OVERSIZED GRAPHIC DISNEY KERAH BULAT LENGAN PENDEK DSTSL5-6:VANILLA:XL:GRAPHIC:T-SHIRT OVERS | M9: 169900 | N9: SP | O9: 129000 | P9: SPECIAL PRICE
A10: 2025 H1 Knit Top: Graphic tee SP129 | B10: ='2023 SP 79'!$B$2 -> 2026-03-27 | C10: ='2023 SP 79'!$C$2 -> 2026-04-01 | D10: 3328 | E10: 347 | F10: 5 | G10: 1 | I10: SUKO | J10: 53702500 | K10: DSTSL5-7 | L10: T-SHIRT OVERSIZED GRAPHIC DISNEY KERAH BULAT LENGAN PENDEK DSTSL5-7:CERAMIC:S:GRAPHIC:T-SHIRT OVERSI | M10: 169900 | N10: SP | O10: 129000 | P10: SPECIAL PRICE
A11: 2025 H1 Knit Top: Graphic tee SP129 | B11: ='2023 SP 79'!$B$2 -> 2026-03-27 | C11: ='2023 SP 79'!$C$2 -> 2026-04-01 | D11: 3328 | E11: 347 | F11: 5 | G11: 1 | I11: SUKO | J11: 53702519 | K11: DSTSL5-7 | L11: T-SHIRT OVERSIZED GRAPHIC DISNEY KERAH BULAT LENGAN PENDEK DSTSL5-7:CERAMIC:M:GRAPHIC:T-SHIRT OVERSI | M11: 169900 | N11: SP | O11: 129000 | P11: SPECIAL PRICE
A12: 2025 H1 Knit Top: Graphic tee SP129 | B12: ='2023 SP 79'!$B$2 -> 2026-03-27 | C12: ='2023 SP 79'!$C$2 -> 2026-04-01 | D12: 3328 | E12: 347 | F12: 5 | G12: 1 | I12: SUKO | J12: 53702528 | K12: DSTSL5-7 | L12: T-SHIRT OVERSIZED GRAPHIC DISNEY KERAH BULAT LENGAN PENDEK DSTSL5-7:CERAMIC:L:GRAPHIC:T-SHIRT OVERSI | M12: 169900 | N12: SP | O12: 129000 | P12: SPECIAL PRICE
A13: 2025 H1 Knit Top: Graphic tee SP129 | B13: ='2023 SP 79'!$B$2 -> 2026-03-27 | C13: ='2023 SP 79'!$C$2 -> 2026-04-01 | D13: 3328 | E13: 347 | F13: 5 | G13: 1 | I13: SUKO | J13: 53702537 | K13: DSTSL5-7 | L13: T-SHIRT OVERSIZED GRAPHIC DISNEY KERAH BULAT LENGAN PENDEK DSTSL5-7:CERAMIC:XL:GRAPHIC:T-SHIRT OVERS | M13: 169900 | N13: SP | O13: 129000 | P13: SPECIAL PRICE
... A73: 2025 H1 Knit Top: Graphic tee SP129 | B73: ='2023 SP 79'!$B$2 -> 2026-03-27 | C73: ='2023 SP 79'!$C$2 -> 2026-04-01 | D73: 3328 | E73: 347 | F73: 5 | G73: 1 | I73: SUKO | J73: 51717356 | K73: T4L625A1-6 | L73: T-SHIRT OVERSIZED GRAPHIC KERAH BULAT LENGAN PENDEK T4L625A1-6:SUNSHINE YELLOW:XL:GRAPHIC:T-SHIRT OV | M73: 169900 | N73: SP | O73: 129000 | P73: SPECIAL PRICE

Sheet 2025 H1 SP 159
A1: ACARA | B1: FROM DATE | C1: TO DATE | D1: DEPT | E1: WORLD | F1: DIVISION | G1: CLASS | H1: SUPPLIER | I1: BRAND | J1: SKU | K1: ARTICLE | L1: DESCRIPTION | M1: HARGA NORMAL | N1: DISKON | O1: HARGA PROMO | P1: DISCOUNT TYPE
A2: 2025 H1 Woven Top, Woven Bottom, Dress SP 159 | B2: ='2023 SP 79'!$B$2 -> 2026-03-27 | C2: ='2023 SP 79'!$C$2 -> 2026-04-01 | D2: 3328 | E2: 347 | F2: 5 | G2: 2 | I2: SUKO | J2: 51715956 | K2: S2L535A2 | L2: KEMEJA OXFORD OVERSIZED LENGAN PANJANG S2L535A2:FROST GREY:M:SOLID:KEMEJA OXFORD OVERSIZED | M2: 249900 | N2: SP | O2: 159000 | P2: SPECIAL PRICE
A3: 2025 H1 Woven Top, Woven Bottom, Dress SP 159 | B3: ='2023 SP 79'!$B$2 -> 2026-03-27 | C3: ='2023 SP 79'!$C$2 -> 2026-04-01 | D3: 3328 | E3: 347 | F3: 5 | G3: 2 | I3: SUKO | J3: 51715876 | K3: S2L535A2 | L3: KEMEJA OXFORD OVERSIZED LENGAN PANJANG S2L535A2:PASTEL GREY:M:SOLID:KEMEJA OXFORD OVERSIZED | M3: 249900 | N3: SP | O3: 159000 | P3: SPECIAL PRICE
A4: 2025 H1 Woven Top, Woven Bottom, Dress SP 159 | B4: ='2023 SP 79'!$B$2 -> 2026-03-27 | C4: ='2023 SP 79'!$C$2 -> 2026-04-01 | D4: 3328 | E4: 347 | F4: 5 | G4: 2 | I4: SUKO | J4: 51715830 | K4: S2L535A2 | L4: KEMEJA OXFORD OVERSIZED LENGAN PANJANG S2L535A2:WHITE:M:SOLID:KEMEJA OXFORD OVERSIZED | M4: 249900 | N4: SP | O4: 159000 | P4: SPECIAL PRICE
A5: 2025 H1 Woven Top, Woven Bottom, Dress SP 159 | B5: ='2023 SP 79'!$B$2 -> 2026-03-27 | C5: ='2023 SP 79'!$C$2 -> 2026-04-01 | D5: 3328 | E5: 347 | F5: 5 | G5: 2 | I5: SUKO | J5: 51715910 | K5: S2L535A2 | L5: KEMEJA OXFORD OVERSIZED LENGAN PANJANG S2L535A2:SUNSHINE YELLOW:M:SOLID:KEMEJA OXFORD OVERSIZED | M5: 249900 | N5: SP | O5: 159000 | P5: SPECIAL PRICE
A6: 2025 H1 Woven Top, Woven Bottom, Dress SP 159 | B6: ='2023 SP 79'!$B$2 -> 2026-03-27 | C6: ='2023 SP 79'!$C$2 -> 2026-04-01 | D6: 3328 | E6: 347 | F6: 5 | G6: 2 | I6: SUKO | J6: 51715821 | K6: S2L535A2 | L6: KEMEJA OXFORD OVERSIZED LENGAN PANJANG S2L535A2:WHITE:S:SOLID:KEMEJA OXFORD OVERSIZED | M6: 249900 | N6: SP | O6: 159000 | P6: SPECIAL PRICE
A7: 2025 H1 Woven Top, Woven Bottom, Dress SP 159 | B7: ='2023 SP 79'!$B$2 -> 2026-03-27 | C7: ='2023 SP 79'!$C$2 -> 2026-04-01 | D7: 3328 | E7: 347 | F7: 5 | G7: 2 | I7: SUKO | J7: 51715849 | K7: S2L535A2 | L7: KEMEJA OXFORD OVERSIZED LENGAN PANJANG S2L535A2:WHITE:L:SOLID:KEMEJA OXFORD OVERSIZED | M7: 249900 | N7: SP | O7: 159000 | P7: SPECIAL PRICE
A8: 2025 H1 Woven Top, Woven Bottom, Dress SP 159 | B8: ='2023 SP 79'!$B$2 -> 2026-03-27 | C8: ='2023 SP 79'!$C$2 -> 2026-04-01 | D8: 3328 | E8: 347 | F8: 5 | G8: 2 | I8: SUKO | J8: 51715858 | K8: S2L535A2 | L8: KEMEJA OXFORD OVERSIZED LENGAN PANJANG S2L535A2:WHITE:XL:SOLID:KEMEJA OXFORD OVERSIZED | M8: 249900 | N8: SP | O8: 159000 | P8: SPECIAL PRICE
A9: 2025 H1 Woven Top, Woven Bottom, Dress SP 159 | B9: ='2023 SP 79'!$B$2 -> 2026-03-27 | C9: ='2023 SP 79'!$C$2 -> 2026-04-01 | D9: 3328 | E9: 347 | F9: 5 | G9: 2 | I9: SUKO | J9: 51715867 | K9: S2L535A2 | L9: KEMEJA OXFORD OVERSIZED LENGAN PANJANG S2L535A2:PASTEL GREY:S:SOLID:KEMEJA OXFORD OVERSIZED | M9: 249900 | N9: SP | O9: 159000 | P9: SPECIAL PRICE
A10: 2025 H1 Woven Top, Woven Bottom, Dress SP 159 | B10: ='2023 SP 79'!$B$2 -> 2026-03-27 | C10: ='2023 SP 79'!$C$2 -> 2026-04-01 | D10: 3328 | E10: 347 | F10: 5 | G10: 2 | I10: SUKO | J10: 51715885 | K10: S2L535A2 | L10: KEMEJA OXFORD OVERSIZED LENGAN PANJANG S2L535A2:PASTEL GREY:L:SOLID:KEMEJA OXFORD OVERSIZED | M10: 249900 | N10: SP | O10: 159000 | P10: SPECIAL PRICE
A11: 2025 H1 Woven Top, Woven Bottom, Dress SP 159 | B11: ='2023 SP 79'!$B$2 -> 2026-03-27 | C11: ='2023 SP 79'!$C$2 -> 2026-04-01 | D11: 3328 | E11: 347 | F11: 5 | G11: 2 | I11: SUKO | J11: 51715894 | K11: S2L535A2 | L11: KEMEJA OXFORD OVERSIZED LENGAN PANJANG S2L535A2:PASTEL GREY:XL:SOLID:KEMEJA OXFORD OVERSIZED | M11: 249900 | N11: SP | O11: 159000 | P11: SPECIAL PRICE
A12: 2025 H1 Woven Top, Woven Bottom, Dress SP 159 | B12: ='2023 SP 79'!$B$2 -> 2026-03-27 | C12: ='2023 SP 79'!$C$2 -> 2026-04-01 | D12: 3328 | E12: 347 | F12: 5 | G12: 2 | I12: SUKO | J12: 51715901 | K12: S2L535A2 | L12: KEMEJA OXFORD OVERSIZED LENGAN PANJANG S2L535A2:SUNSHINE YELLOW:S:SOLID:KEMEJA OXFORD OVERSIZED | M12: 249900 | N12: SP | O12: 159000 | P12: SPECIAL PRICE
A13: 2025 H1 Woven Top, Woven Bottom, Dress SP 159 | B13: ='2023 SP 79'!$B$2 -> 2026-03-27 | C13: ='2023 SP 79'!$C$2 -> 2026-04-01 | D13: 3328 | E13: 347 | F13: 5 | G13: 2 | I13: SUKO | J13: 51715929 | K13: S2L535A2 | L13: KEMEJA OXFORD OVERSIZED LENGAN PANJANG S2L535A2:SUNSHINE YELLOW:L:SOLID:KEMEJA OXFORD OVERSIZED | M13: 249900 | N13: SP | O13: 159000 | P13: SPECIAL PRICE
... A97: 2025 H1 Woven Top, Woven Bottom, Dress SP 159 | B97: ='2023 SP 79'!$B$2 -> 2026-03-27 | C97: ='2023 SP 79'!$C$2 -> 2026-04-01 | D97: 3328 | E97: 347 | F97: 5 | G97: 2 | I97: SUKO | J97: 53809002 | K97: S2L4A5D1 | L97: BLOUSE BALON SS KERAH BULAT LENGAN PENDEK S2L4A5D1:PASTEL PINK:XL:SOLID:BLOUSE BALON | M97: 249900 | N97: SP | O97: 159000 | P97: SPECIAL PRICE

Sheet 2025 SP 199
A1: ACARA | B1: FROM DATE | C1: TO DATE | D1: DEPT | E1: WORLD | F1: DIVISION | G1: CLASS | H1: SUPPLIER | I1: BRAND | J1: SKU | K1: ARTICLE | L1: DESCRIPTION | M1: HARGA NORMAL | N1: DISKON | O1: HARGA PROMO | P1: DISCOUNT TYPE
A2: 2025 Woven Top (fine cotton) SP 199 | B2: ='2023 SP 79'!$B$2 -> 2026-03-27 | C2: ='2023 SP 79'!$C$2 -> 2026-04-01 | D2: 3328 | E2: 347 | F2: 5 | G2: 2 | I2: SUKO | J2: 45337153 | K2: S2L3A4J2 | L2: KEMEJA FINE KATUN LS LENGAN PANJANG S2L3A4J2:BLACK:S:SOLID:KEMEJA FINE KATUN | M2: 279900 | N2: SP | O2: 199000 | P2: SPECIAL PRICE
A3: 2025 Woven Top (fine cotton) SP 199 | B3: ='2023 SP 79'!$B$2 -> 2026-03-27 | C3: ='2023 SP 79'!$C$2 -> 2026-04-01 | D3: 3328 | E3: 347 | F3: 5 | G3: 2 | I3: SUKO | J3: 45337162 | K3: S2L3A4J2 | L3: KEMEJA FINE KATUN LS LENGAN PANJANG S2L3A4J2:BLACK:M:SOLID:KEMEJA FINE KATUN | M3: 279900 | N3: SP | O3: 199000 | P3: SPECIAL PRICE
A4: 2025 Woven Top (fine cotton) SP 199 | B4: ='2023 SP 79'!$B$2 -> 2026-03-27 | C4: ='2023 SP 79'!$C$2 -> 2026-04-01 | D4: 3328 | E4: 347 | F4: 5 | G4: 2 | I4: SUKO | J4: 45337171 | K4: S2L3A4J2 | L4: KEMEJA FINE KATUN LS LENGAN PANJANG S2L3A4J2:BLACK:L:SOLID:KEMEJA FINE KATUN | M4: 279900 | N4: SP | O4: 199000 | P4: SPECIAL PRICE
A5: 2025 Woven Top (fine cotton) SP 199 | B5: ='2023 SP 79'!$B$2 -> 2026-03-27 | C5: ='2023 SP 79'!$C$2 -> 2026-04-01 | D5: 3328 | E5: 347 | F5: 5 | G5: 2 | I5: SUKO | J5: 45337180 | K5: S2L3A4J2 | L5: KEMEJA FINE KATUN LS LENGAN PANJANG S2L3A4J2:BLACK:XL:SOLID:KEMEJA FINE KATUN | M5: 279900 | N5: SP | O5: 199000 | P5: SPECIAL PRICE
A6: 2025 Woven Top (fine cotton) SP 199 | B6: ='2023 SP 79'!$B$2 -> 2026-03-27 | C6: ='2023 SP 79'!$C$2 -> 2026-04-01 | D6: 3328 | E6: 347 | F6: 5 | G6: 2 | I6: SUKO | J6: 45337117 | K6: S2L3A4J2 | L6: KEMEJA FINE KATUN LS LENGAN PANJANG S2L3A4J2:WHITE:S:SOLID:KEMEJA FINE KATUN | M6: 279900 | N6: SP | O6: 199000 | P6: SPECIAL PRICE
