Workbook

Sheet KI DISCONTINUE D85
A1: ACARA | B1: FROM DATE | C1: TO DATE | D1: DEPT | E1: WORLD | F1: DIVISION | G1: CLASS | H1: SUPPLIER | I1: BRAND | J1: SKU | K1: ARTICLE | L1: DESCRIPTION | M1: HARGA NORMAL | N1: DISKON | O1: HARGA PROMO | P1: DISCOUNT TYPE
A2: KI Discontinue D85 | B2: 46093 | C2: 46098 | D2: 3259 | E2: 333 | F2: 3 | G2: 9 | I2: COLE | J2: 18214774 | K2: OBLWHT | L2: OBL BASIC ROUND NECK WHITE S:WHITE:XS | M2: 99900 | N2: 0.85 | O2: =M2-((85*M2)/100) -> 14985 | P2: PERCENTAGE
A3: KI Discontinue D85 | B3: =B2 -> 46093 | C3: =C2 -> 46098 | D3: 3259 | E3: 333 | F3: 3 | G3: 9 | I3: COLE | J3: 18214783 | K3: OBLWHT | L3: OBL BASIC ROUND NECK WHITE S:WHITE:S | M3: 99900 | N3: 0.85 | O3: =M3-((85*M3)/100) -> 14985 | P3: PERCENTAGE
A4: KI Discontinue D85 | B4: =B3 -> 46093 | C4: =C3 -> 46098 | D4: 3259 | E4: 333 | F4: 3 | G4: 9 | I4: COLE | J4: 18214792 | K4: OBLWHT | L4: OBL BASIC ROUND NECK WHITE S:WHITE:M | M4: 99900 | N4: 0.85 | O4: =M4-((85*M4)/100) -> 14985 | P4: PERCENTAGE
A5: KI Discontinue D85 | B5: =B4 -> 46093 | C5: =C4 -> 46098 | D5: 3259 | E5: 333 | F5: 3 | G5: 9 | I5: COLE | J5: 18214809 | K5: OBLWHT | L5: OBL BASIC ROUND NECK WHITE S:WHITE:L | M5: 99900 | N5: 0.85 | O5: =M5-((85*M5)/100) -> 14985 | P5: PERCENTAGE
A6: KI Discontinue D85 | B6: =B5 -> 46093 | C6: =C5 -> 46098 | D6: 3259 | E6: 333 | F6: 3 | G6: 9 | I6: COLE | J6: 18214818 | K6: OBLWHT | L6: OBL BASIC ROUND NECK WHITE S:WHITE:XL | M6: 99900 | N6: 0.85 | O6: =M6-((85*M6)/100) -> 14985 | P6: PERCENTAGE
A7: KI Discontinue D85 | B7: =B6 -> 46093 | C7: =C6 -> 46098 | D7: 3259 | E7: 333 | F7: 3 | G7: 9 | I7: COLE | J7: 18214827 | K7: OBLBLK | L7: OBL BLACK ROUND NECK BLACK:BLACK:XS | M7: 99900 | N7: 0.85 | O7: =M7-((85*M7)/100) -> 14985 | P7: PERCENTAGE
A8: KI Discontinue D85 | B8: =B7 -> 46093 | C8: =C7 -> 46098 | D8: 3259 | E8: 333 | F8: 3 | G8: 9 | I8: COLE | J8: 18214836 | K8: OBLBLK | L8: OBL BLACK ROUND NECK BLACK:BLACK:S | M8: 99900 | N8: 0.85 | O8: =M8-((85*M8)/100) -> 14985 | P8: PERCENTAGE
A9: KI Discontinue D85 | B9: =B8 -> 46093 | C9: =C8 -> 46098 | D9: 3259 | E9: 333 | F9: 3 | G9: 9 | I9: COLE | J9: 18214845 | K9: OBLBLK | L9: OBL BLACK ROUND NECK BLACK:BLACK:M | M9: 99900 | N9: 0.85 | O9: =M9-((85*M9)/100) -> 14985 | P9: PERCENTAGE
A10: KI Discontinue D85 | B10: =B9 -> 46093 | C10: =C9 -> 46098 | D10: 3259 | E10: 333 | F10: 3 | G10: 9 | I10: COLE | J10: 18214854 | K10: OBLBLK | L10: OBL BLACK ROUND NECK BLACK:BLACK:L | M10: 99900 | N10: 0.85 | O10: =M10-((85*M10)/100) -> 14985 | P10: PERCENTAGE
A11: KI Discontinue D85 | B11: =B10 -> 46093 | C11: =C10 -> 46098 | D11: 3259 | E11: 333 | F11: 3 | G11: 9 | I11: COLE | J11: 18214863 | K11: OBLBLK | L11: OBL BLACK ROUND NECK BLACK:BLACK:XL | M11: 99900 | N11: 0.85 | O11: =M11-((85*M11)/100) -> 14985 | P11: PERCENTAGE
A12: KI Discontinue D85 | B12: =B11 -> 46093 | C12: =C11 -> 46098 | D12: 3259 | E12: 333 | F12: 3 | G12: 9 | I12: COLE | J12: 18223531 | K12: OBLM81 | L12: OBL BASIC ROUND NECK M81:MISTY DARK GREY:XS | M12: 109900 | N12: 0.85 | O12: =M12-((85*M12)/100) -> 16485 | P12: PERCENTAGE
A13: KI Discontinue D85 | B13: =B12 -> 46093 | C13: =C12 -> 46098 | D13: 3259 | E13: 333 | F13: 3 | G13: 9 | I13: COLE | J13: 18223657 | K13: OBLMRN | L13: OBL BASIC ROUND NECK MAROON:MAROON:M | M13: 99900 | N13: 0.85 | O13: =M13-((85*M13)/100) -> 14985 | P13: PERCENTAGE
A14: KI Discontinue D85 | B14: =B13 -> 46093 | C14: =C13 -> 46098 | D14: 3259 | E14: 333 | F14: 3 | G14: 9 | I14: COLE | J14: 18223835 | K14: OBLMBL | L14: OBL BASIC ROUND NECK MS.BLUE:MISTY MEDIUM BLUE:XS | M14: 109900 | N14: 0.85 | O14: =M14-((85*M14)/100) -> 16485 | P14: PERCENTAGE
... A215: KI Discontinue D85 | B215: =B214 -> 46093 | C215: =C214 -> 46098 | D215: 3259 | E215: 333 | F215: 3 | G215: 9 | I215: COLE | J215: 33474385 | K215: ESSRN | L215: SS T-SHIRT OBL BASIC ROUND NECK ESSRN:WINE:XL:SOLID:SS T-SHIRT | M215: 109900 | N215: 0.85 | O215: =M215-((85*M215)/100) -> 16485 | P215: PERCENTAGE
A216: KI Discontinue D85 | B216: ='KI DISCONTINUE D85'!B$2 -> 46093 | C216: ='KI DISCONTINUE D85'!C$2 -> 46098 | D216: 3259 | E216: 333 | F216: 3 | G216: 10 | I216: COLE | J216: 17258774 | K216: BSW-CRXS | L216: WK POLO BASIC LACOSE CORAL XS / BSW-CR:CORAL:XS | M216: 149900 | N216: 0.85 | O216: =M216-(M216*N216) -> 22485 | P216: PERCENTAGE
A217: KI Discontinue D85 | B217: ='KI DISCONTINUE D85'!B$2 -> 46093 | C217: ='KI DISCONTINUE D85'!C$2 -> 46098 | D217: 3259 | E217: 333 | F217: 3 | G217: 10 | I217: COLE | J217: 17258783 | K217: BSW-CRS | L217: WK POLO BASIC LACOSE CORAL S / BSW-CR:CORAL:S | M217: 149900 | N217: 0.85 | O217: =M217-(M217*N217) -> 22485 | P217: PERCENTAGE
A218: KI Discontinue D85 | B218: ='KI DISCONTINUE D85'!B$2 -> 46093 | C218: ='KI DISCONTINUE D85'!C$2 -> 46098 | D218: 3259 | E218: 333 | F218: 3 | G218: 10 | I218: COLE | J218: 17258809 | K218: BSW-CRL | L218: WK POLO BASIC LACOSE CORAL L / BSW-CR:CORAL:L | M218: 149900 | N218: 0.85 | O218: =M218-(M218*N218) -> 22485 | P218: PERCENTAGE
A219: KI Discontinue D85 | B219: ='KI DISCONTINUE D85'!B$2 -> 46093 | C219: ='KI DISCONTINUE D85'!C$2 -> 46098 | D219: 3259 | E219: 333 | F219: 3 | G219: 10 | I219: COLE | J219: 18232021 | K219: BSW-WH | L219: WK POLO BASIC LACOSE WHITE/BSW-WH:WHITE:XS | M219: 149900 | N219: 0.85 | O219: =M219-(M219*N219) -> 22485 | P219: PERCENTAGE
A220: KI Discontinue D85 | B220: ='KI DISCONTINUE D85'!B$2 -> 46093 | C220: ='KI DISCONTINUE D85'!C$2 -> 46098 | D220: 3259 | E220: 333 | F220: 3 | G220: 10 | I220: COLE | J220: 18232165 | K220: BSW-RD | L220: WK POLO BASIC LACOSE RED/BSW-RD:CLASSIC RED:XS | M220: 149900 | N220: 0.85 | O220: =M220-(M220*N220) -> 22485 | P220: PERCENTAGE
A221: KI Discontinue D85 | B221: ='KI DISCONTINUE D85'!B$2 -> 46093 | C221: ='KI DISCONTINUE D85'!C$2 -> 46098 | D221: 3259 | E221: 333 | F221: 3 | G221: 10 | I221: COLE | J221: 18232174 | K221: BSW-RD | L221: WK POLO BASIC LACOSE RED/BSW-RD:CLASSIC RED:S | M221: 149900 | N221: 0.85 | O221: =M221-(M221*N221) -> 22485 | P221: PERCENTAGE
A222: KI Discontinue D85 | B222: ='KI DISCONTINUE D85'!B$2 -> 46093 | C222: ='KI DISCONTINUE D85'!C$2 -> 46098 | D222: 3259 | E222: 333 | F222: 3 | G222: 10 | I222: COLE | J222: 18232183 | K222: BSW-RD | L222: WK POLO BASIC LACOSE RED/BSW-RD:CLASSIC RED:M | M222: 149900 | N222: 0.85 | O222: =M222-(M222*N222) -> 22485 | P222: PERCENTAGE
A223: KI Discontinue D85 | B223: ='KI DISCONTINUE D85'!B$2 -> 46093 | C223: ='KI DISCONTINUE D85'!C$2 -> 46098 | D223: 3259 | E223: 333 | F223: 3 | G223: 10 | I223: COLE | J223: 18232192 | K223: BSW-RD | L223: WK POLO BASIC LACOSE RED/BSW-RD:CLASSIC RED:L | M223: 149900 | N223: 0.85 | O223: =M223-(M223*N223) -> 22485 | P223: PERCENTAGE
A224: KI Discontinue D85 | B224: ='KI DISCONTINUE D85'!B$2 -> 46093 | C224: ='KI DISCONTINUE D85'!C$2 -> 46098 | D224: 3259 | E224: 333 | F224: 3 | G224: 10 | I224: COLE | J224: 18232209 | K224: BSW-RD | L224: WK POLO BASIC LACOSE RED/BSW-RD:CLASSIC RED:XL | M224: 149900 | N224: 0.85 | O224: =M224-(M224*N224) -> 22485 | P224: PERCENTAGE
A225: KI Discontinue D85 | B225: ='KI DISCONTINUE D85'!B$2 -> 46093 | C225: ='KI DISCONTINUE D85'!C$2 -> 46098 | D225: 3259 | E225: 333 | F225: 3 | G225: 10 | I225: COLE | J225: 18232398 | K225: BSW-MR | L225: WK POLO BASIC LACOSE MAROON/BSW-MR:MAROON:XS | M225: 149900 | N225: 0.85 | O225: =M225-(M225*N225) -> 22485 | P225: PERCENTAGE
A226: KI Discontinue D85 | B226: ='KI DISCONTINUE D85'!B$2 -> 46093 | C226: ='KI DISCONTINUE D85'!C$2 -> 46098 | D226: 3259 | E226: 333 | F226: 3 | G226: 10 | I226: COLE | J226: 18232405 | K226: BSW-MR | L226: WK POLO BASIC LACOSE MAROON/BSW-MR:MAROON:S | M226: 149900 | N226: 0.85 | O226: =M226-(M226*N226) -> 22485 | P226: PERCENTAGE
A227: KI Discontinue D85 | B227: ='KI DISCONTINUE D85'!B$2 -> 46093 | C227: ='KI DISCONTINUE D85'!C$2 -> 46098 | D227: 3259 | E227: 333 | F227: 3 | G227: 10 | I227: COLE | J227: 18232414 | K227: BSW-MR | L227: WK POLO BASIC LACOSE MAROON/BSW-MR:MAROON:M | M227: 149900 | N227: 0.85 | O227: =M227-(M227*N227) -> 22485 | P227: PERCENTAGE
... A244: KI Discontinue D85 | B244: ='KI DISCONTINUE D85'!B$2 -> 46093 | C244: ='KI DISCONTINUE D85'!C$2 -> 46098 | D244: 3259 | E244: 333 | F244: 3 | G244: 10 | I244: COLE | J244: 18233146 | K244: BSW-TL | L244: WK POLO BASIC LACOSE TEAL/BSW-TL:TEAL:XL | M244: 149900 | N244: 0.85 | O244: =M244-(M244*N244) -> 22485 | P244: PERCENTAGE
A245: KI Discontinue D85 | B245: ='KI DISCONTINUE D85'!$B$2 -> 46093 | C245: ='KI DISCONTINUE D85'!$C$2 -> 46098 | D245: 3259 | E245: 333 | F245: 3 | G245: 10 | I245: COLE | J245: 18233379 | K245: BSW-NVA233 | L245: WK BASIC LACOSE NAVY A233/BSW-NVA233:NAVY BLUE:XS | M245: 149900 | N245: 0.85 | O245: =M245-(M245*N245) -> 22485 | P245: PERCENTAGE
A246: KI Discontinue D85 | B246: ='KI DISCONTINUE D85'!$B$2 -> 46093 | C246: ='KI DISCONTINUE D85'!$C$2 -> 46098 | D246: 3259 | E246: 333 | F246: 3 | G246: 10 | I246: COLE | J246: 18233388 | K246: BSW-NVA233 | L246: WK BASIC LACOSE NAVY A233/BSW-NVA233:NAVY BLUE:S | M246: 149900 | N246: 0.85 | O246: =M246-(M246*N246) -> 22485 | P246: PERCENTAGE
A247: KI Discontinue D85 | B247: ='KI DISCONTINUE D85'!$B$2 -> 46093 | C247: ='KI DISCONTINUE D85'!$C$2 -> 46098 | D247: 3259 | E247: 333 | F247: 3 | G247: 10 | I247: COLE | J247: 18233397 | K247: BSW-NVA233 | L247: WK BASIC LACOSE NAVY A233/BSW-NVA233:NAVY BLUE:M | M247: 149900 | N247: 0.85 | O247: =M247-(M247*N247) -> 22485 | P247: PERCENTAGE
A248: KI Discontinue D85 | B248: ='KI DISCONTINUE D85'!$B$2 -> 46093 | C248: ='KI DISCONTINUE D85'!$C$2 -> 46098 | D248: 3259 | E248: 333 | F248: 3 | G248: 10 | I248: COLE | J248: 18233404 | K248: BSW-NVA233 | L248: WK BASIC LACOSE NAVY A233/BSW-NVA233:NAVY BLUE:L | M248: 149900 | N248: 0.85 | O248: =M248-(M248*N248) -> 22485 | P248: PERCENTAGE
A249: KI Discontinue D85 | B249: ='KI DISCONTINUE D85'!$B$2 -> 46093 | C249: ='KI DISCONTINUE D85'!$C$2 -> 46098 | D249: 3259 | E249: 333 | F249: 3 | G249: 10 | I249: COLE | J249: 18233413 | K249: BSW-NVA233 | L249: WK BASIC LACOSE NAVY A233/BSW-NVA233:NAVY BLUE:XL | M249: 149900 | N249: 0.85 | O249: =M249-(M249*N249) -> 22485 | P249: PERCENTAGE
A250: KI Discontinue D85 | B250: ='KI DISCONTINUE D85'!B$2 -> 46093 | C250: ='KI DISCONTINUE D85'!C$2 -> 46098 | D250: 3259 | E250: 333 | F250: 3 | G250: 10 | I250: COLE | J250: 18270310 | K250: BSW-M71 | L250: WK POLO BASIC LACOSE M71/BSW-M71:MISTY MEDIUM GRE:XS | M250: 169900 | N250: 0.85 | O250: =M250-(M250*N250) -> 25485 | P250: PERCENTAGE
A251: KI Discontinue D85 | B251: ='KI DISCONTINUE D85'!B$2 -> 46093 | C251: ='KI DISCONTINUE D85'!C$2 -> 46098 | D251: 3259 | E251: 333 | F251: 3 | G251: 10 | I251: COLE | J251: 18270329 | K251: BSW-M71 | L251: WK POLO BASIC LACOSE M71/BSW-M71:MISTY MEDIUM GRE:S | M251: 169900 | N251: 0.85 | O251: =M251-(M251*N251) -> 25485 | P251: PERCENTAGE
A252: KI Discontinue D85 | B252: ='KI DISCONTINUE D85'!B$2 -> 46093 | C252: ='KI DISCONTINUE D85'!C$2 -> 46098 | D252: 3259 | E252: 333 | F252: 3 | G252: 10 | I252: COLE | J252: 18270338 | K252: BSW-M71 | L252: WK POLO BASIC LACOSE M71/BSW-M71:MISTY MEDIUM GRE:M | M252: 169900 | N252: 0.85 | O252: =M252-(M252*N252) -> 25485 | P252: PERCENTAGE
A253: KI Discontinue D85 | B253: ='KI DISCONTINUE D85'!B$2 -> 46093 | C253: ='KI DISCONTINUE D85'!C$2 -> 46098 | D253: 3259 | E253: 333 | F253: 3 | G253: 10 | I253: COLE | J253: 18270347 | K253: BSW-M71 | L253: WK POLO BASIC LACOSE M71/BSW-M71:MISTY MEDIUM GRE:L | M253: 169900 | N253: 0.85 | O253: =M253-(M253*N253) -> 25485 | P253: PERCENTAGE
A254: KI Discontinue D85 | B254: ='KI DISCONTINUE D85'!B$2 -> 46093 | C254: ='KI DISCONTINUE D85'!C$2 -> 46098 | D254: 3259 | E254: 333 | F254: 3 | G254: 10 | I254: COLE | J254: 18270356 | K254: BSW-M71 | L254: WK POLO BASIC LACOSE M71/BSW-M71:MISTY MEDIUM GRE:XL | M254: 169900 | N254: 0.85 | O254: =M254-(M254*N254) -> 25485 | P254: PERCENTAGE
A255: KI Discontinue D85 | B255: ='KI DISCONTINUE D85'!B$2 -> 46093 | C255: ='KI DISCONTINUE D85'!C$2 -> 46098 | D255: 3259 | E255: 333 | F255: 3 | G255: 10 | I255: COLE | J255: 18272327 | K255: BSW-M81 | L255: WK POLO BASIC LACOSE M81 / BSW-M81:MISTY DARK GREY:XS | M255: 169900 | N255: 0.85 | O255: =M255-(M255*N255) -> 25485 | P255: PERCENTAGE
A256: KI Discontinue D85 | B256: ='KI DISCONTINUE D85'!$B$2 -> 46093 | C256: ='KI DISCONTINUE D85'!$C$2 -> 46098 | D256: 3259 | E256: 333 | F256: 3 | G256: 10 | I256: COLE | J256: 18272336 | K256: BSW-M81 | L256: WK POLO BASIC LACOSE M81 / BSW-M81:MISTY DARK GREY:S | M256: 169900 | N256: 0.85 | O256: =M256-(M256*N256) -> 25485 | P256: PERCENTAGE
...

Sheet 2019 ALL D95
A1: ACARA | B1: FROM DATE | C1: TO DATE | D1: DEPT | E1: WORLD | F1: DIVISION | G1: CLASS | H1: SUPPLIER | I1: BRAND | J1: SKU | K1: ARTICLE | L1: DESCRIPTION | M1: HARGA NORMAL | N1: DISKON | O1: HARGA PROMO | P1: DISCOUNT TYPE
A2: 2019 & Older TOP All Items (Exclude KI) D95 | B2: ='KI DISCONTINUE D85'!$B$2 -> 46093 | C2: ='KI DISCONTINUE D85'!$C$2 -> 46098 | D2: 3259 | E2: 333 | F2: 3 | G2: 9 | I2: COLE | J2: 13889206 | K2: OBBSWM | L2: OBL BASIC ROUND NECK WHITE M / OBBSWM | M2: 89900 | N2: 0.95 | O2: =M2-((95*M2)/100) -> 4495 | P2: PERCENTAGE
A3: 2019 & Older TOP All Items (Exclude KI) D95 | B3: ='KI DISCONTINUE D85'!$B$2 -> 46093 | C3: ='KI DISCONTINUE D85'!$C$2 -> 46098 | D3: 3259 | E3: 333 | F3: 3 | G3: 9 | I3: COLE | J3: 13889215 | K3: OBBSWL | L3: OBL BASIC ROUND NECK WHITE L / OBBSWL | M3: 89900 | N3: 0.95 | O3: =M3-((95*M3)/100) -> 4495 | P3: PERCENTAGE
A4: 2019 & Older TOP All Items (Exclude KI) D95 | B4: ='KI DISCONTINUE D85'!$B$2 -> 46093 | C4: ='KI DISCONTINUE D85'!$C$2 -> 46098 | D4: 3259 | E4: 333 | F4: 3 | G4: 9 | I4: COLE | J4: 13889224 | K4: OBBSWXL | L4: OBL BASIC ROUND NECK WHITE XL / OBBSWXL | M4: 89900 | N4: 0.95 | O4: =M4-((95*M4)/100) -> 4495 | P4: PERCENTAGE
A5: 2019 & Older TOP All Items (Exclude KI) D95 | B5: ='KI DISCONTINUE D85'!$B$2 -> 46093 | C5: ='KI DISCONTINUE D85'!$C$2 -> 46098 | D5: 3259 | E5: 333 | F5: 3 | G5: 9 | I5: COLE | J5: 13889448 | K5: OBBSBLXL | L5: OBL BASIC ROUND NECK BLACK XL / OBBSBLXL | M5: 89900 | N5: 0.95 | O5: =M5-((95*M5)/100) -> 4495 | P5: PERCENTAGE
A6: 2019 & Older TOP All Items (Exclude KI) D95 | B6: ='KI DISCONTINUE D85'!$B$2 -> 46093 | C6: ='KI DISCONTINUE D85'!$C$2 -> 46098 | D6: 3259 | E6: 333 | F6: 3 | G6: 10 | I6: COLE | J6: 13903529 | K6: BSW-81M | L6: WK POLO BASIC LACOSE M81 / BSW-81M | M6: 139900 | N6: 0.95 | O6: =M6-((95*M6)/100) -> 6995 | P6: PERCENTAGE
A7: 2019 & Older TOP All Items (Exclude KI) D95 | B7: ='KI DISCONTINUE D85'!$B$2 -> 46093 | C7: ='KI DISCONTINUE D85'!$C$2 -> 46098 | D7: 3259 | E7: 333 | F7: 3 | G7: 10 | I7: COLE | J7: 13903565 | K7: BSW-81XL | L7: WK POLO BASIC LACOSE M81 / BSW-81XL | M7: 139900 | N7: 0.95 | O7: =M7-((95*M7)/100) -> 6995 | P7: PERCENTAGE
A8: 2019 & Older TOP All Items (Exclude KI) D95 | B8: ='KI DISCONTINUE D85'!$B$2 -> 46093 | C8: ='KI DISCONTINUE D85'!$C$2 -> 46098 | D8: 3259 | E8: 333 | F8: 3 | G8: 10 | I8: COLE | J8: 13912279 | K8: BSW-TRS | L8: WK POLO BASIC LACOSE TRCT / BSW-TRS | M8: 139900 | N8: 0.95 | O8: =M8-((95*M8)/100) -> 6995 | P8: PERCENTAGE
A9: 2019 & Older TOP All Items (Exclude KI) D95 | B9: ='KI DISCONTINUE D85'!$B$2 -> 46093 | C9: ='KI DISCONTINUE D85'!$C$2 -> 46098 | D9: 3259 | E9: 333 | F9: 3 | G9: 10 | I9: COLE | J9: 13912297 | K9: BSW-TRL | L9: WK POLO BASIC LACOSE TRCT / BSW-TRL | M9: 139900 | N9: 0.95 | O9: =M9-((95*M9)/100) -> 6995 | P9: PERCENTAGE
A10: 2019 & Older TOP All Items (Exclude KI) D95 | B10: ='KI DISCONTINUE D85'!$B$2 -> 46093 | C10: ='KI DISCONTINUE D85'!$C$2 -> 46098 | D10: 3259 | E10: 333 | F10: 3 | G10: 10 | I10: COLE | J10: 13984273 | K10: BSWK-WS | L10: WK BASIC LACOSE WHITE S / BSWK-WS | M10: 139900 | N10: 0.95 | O10: =M10-((95*M10)/100) -> 6995 | P10: PERCENTAGE
A11: 2019 & Older TOP All Items (Exclude KI) D95 | B11: ='KI DISCONTINUE D85'!$B$2 -> 46093 | C11: ='KI DISCONTINUE D85'!$C$2 -> 46098 | D11: 3259 | E11: 333 | F11: 3 | G11: 10 | I11: COLE | J11: 13984282 | K11: BSWK-WM | L11: WK BASIC LACOSE WHITE M / BSWK-WM | M11: 139900 | N11: 0.95 | O11: =M11-((95*M11)/100) -> 6995 | P11: PERCENTAGE
A12: 2019 & Older TOP All Items (Exclude KI) D95 | B12: ='KI DISCONTINUE D85'!$B$2 -> 46093 | C12: ='KI DISCONTINUE D85'!$C$2 -> 46098 | D12: 3259 | E12: 333 | F12: 3 | G12: 10 | I12: COLE | J12: 13984291 | K12: BSWK-WL | L12: WK BASIC LACOSE WHITE L / BSWK-WL | M12: 139900 | N12: 0.95 | O12: =M12-((95*M12)/100) -> 6995 | P12: PERCENTAGE
A13: 2019 & Older TOP All Items (Exclude KI) D95 | B13: ='KI DISCONTINUE D85'!$B$2 -> 46093 | C13: ='KI DISCONTINUE D85'!$C$2 -> 46098 | D13: 3259 | E13: 333 | F13: 3 | G13: 10 | I13: COLE | J13: 13984308 | K13: BSWK-WXL | L13: WK BASIC LACOSE WHITE XL / BSWK-WXL | M13: 139900 | N13: 0.95 | O13: =M13-((95*M13)/100) -> 6995 | P13: PERCENTAGE
... A3704: 2019 & Older TOP All Items (Exclude KI) D95 | B3704: ='KI DISCONTINUE D85'!$B$2 -> 46093 | C3704: ='KI DISCONTINUE D85'!$C$2 -> 46098 | D3704: 3259 | E3704: 333 | F3704: 3 | G3704: 1 | I3704: COLE | J3704: 24388638 | K3704: RKDNMNV | L3704: OBL REG PRINT DNM URBAN:NAVY BLUE:M | M3704: 139900 | N3704: 0.95 | O3704: =M3704-((95*M3704)/100) -> 6995 | P3704: PERCENTAGE
A3705: 2019 & Older TOP All Items (Exclude KI) D95 | B3705: ='KI DISCONTINUE D85'!B$2 -> 46093 | C3705: ='KI DISCONTINUE D85'!$C$2 -> 46098 | D3705: 3259 | E3705: 333 | F3705: 3 | G3705: 1 | I3705: COLE | J3705: 24388647 | K3705: RKDNMNV | L3705: OBL REG PRINT DNM URBAN:NAVY BLUE:L | M3705: 139900 | N3705: 0.95 | O3705: =M3705-((95*M3705)/100) -> 6995 | P3705: PERCENTAGE
A3706: 2019 & Older TOP All Items (Exclude KI) D95 | B3706: ='KI DISCONTINUE D85'!$B$2 -> 46093 | C3706: ='KI DISCONTINUE D85'!$C$2 -> 46098 | D3706: 3259 | E3706: 333 | F3706: 3 | G3706: 1 | I3706: COLE | J3706: 24388656 | K3706: RKDNMNV | L3706: OBL REG PRINT DNM URBAN:NAVY BLUE:XL | M3706: 139900 | N3706: 0.95 | O3706: =M3706-((95*M3706)/100) -> 6995 | P3706: PERCENTAGE
A3707: 2019 & Older TOP All Items (Exclude KI) D95 | B3707: ='KI DISCONTINUE D85'!$B$2 -> 46093 | C3707: ='KI DISCONTINUE D85'!$C$2 -> 46098 | D3707: 3259 | E3707: 333 | F3707: 3 | G3707: 1 | I3707: COLE | J3707: 24388665 | K3707: RKDNMTR | L3707: OBL REG PRINT DNM URBAN:MANDARIN ORANGE:XS | M3707: 139900 | N3707: 0.95 | O3707: =M3707-((95*M3707)/100) -> 6995 | P3707: PERCENTAGE
A3708: 2019 & Older TOP All Items (Exclude KI) D95 | B3708: ='KI DISCONTINUE D85'!$B$2 -> 46093 | C3708: ='KI DISCONTINUE D85'!$C$2 -> 46098 | D3708: 3259 | E3708: 333 | F3708: 3 | G3708: 1 | I3708: COLE | J3708: 24388674 | K3708: RKDNMTR | L3708: OBL REG PRINT DNM URBAN:MANDARIN ORANGE:S | M3708: 139900 | N3708: 0.95 | O3708: =M3708-((95*M3708)/100) -> 6995 | P3708: PERCENTAGE
A3709: 2019 & Older TOP All Items (Exclude KI) D95 | B3709: ='KI DISCONTINUE D85'!$B$2 -> 46093 | C3709: ='KI DISCONTINUE D85'!$C$2 -> 46098 | D3709: 3259 | E3709: 333 | F3709: 3 | G3709: 1 | I3709: COLE | J3709: 24388683 | K3709: RKDNMTR | L3709: OBL REG PRINT DNM URBAN:MANDARIN ORANGE:M | M3709: 139900 | N3709: 0.95 | O3709: =M3709-((95*M3709)/100) -> 6995 | P3709: PERCENTAGE
A3710: 2019 & Older TOP All Items (Exclude KI) D95 | B3710: ='KI DISCONTINUE D85'!$B$2 -> 46093 | C3710: ='KI DISCONTINUE D85'!$C$2 -> 46098 | D3710: 3259 | E3710: 333 | F3710: 3 | G3710: 1 | I3710: COLE | J3710: 24388736 | K3710: SRBK2NV | L3710: SSRNSTRBAHUPOLOS:NAVYBLUE:S | M3710: 169900 | N3710: 0.95 | O3710: =M3710-((95*M3710)/100) -> 8495 | P3710: PERCENTAGE
A3711: 2019 & Older TOP All Items (Exclude KI) D95 | B3711: ='KI DISCONTINUE D85'!$B$2 -> 46093 | C3711: ='KI DISCONTINUE D85'!$C$2 -> 46098 | D3711: 3259 | E3711: 333 | F3711: 3 | G3711: 1 | I3711: COLE | J3711: 24388745 | K3711: SRBK2NV | L3711: SSRNSTRBAHUPOLOS:NAVYBLUE:M | M3711: 169900 | N3711: 0.95 | O3711: =M3711-((95*M3711)/100) -> 8495 | P3711: PERCENTAGE
A3712: 2019 & Older TOP All Items (Exclude KI) D95 | B3712: ='KI DISCONTINUE D85'!$B$2 -> 46093 | C3712: ='KI DISCONTINUE D85'!$C$2 -> 46098 | D3712: 3259 | E3712: 333 | F3712: 3 | G3712: 1 | I3712: COLE | J3712: 24388754 | K3712: SRBK2NV | L3712: SSRNSTRBAHUPOLOS:NAVYBLUE:L | M3712: 169900 | N3712: 0.95 | O3712: =M3712-((95*M3712)/100) -> 8495 | P3712: PERCENTAGE
A3713: 2019 & Older TOP All Items (Exclude KI) D95 | B3713: ='KI DISCONTINUE D85'!$B$2 -> 46093 | C3713: ='KI DISCONTINUE D85'!$C$2 -> 46098 | D3713: 3259 | E3713: 333 | F3713: 3 | G3713: 1 | I3713: COLE | J3713: 24388763 | K3713: SRBK2NV | L3713: SSRNSTRBAHUPOLOS:NAVYBLUE:XL | M3713: 169900 | N3713: 0.95 | O3713: =M3713-((95*M3713)/100) -> 8495 | P3713: PERCENTAGE
A3714: 2019 & Older TOP All Items (Exclude KI) D95 | B3714: ='KI DISCONTINUE D85'!$B$2 -> 46093 | C3714: ='KI DISCONTINUE D85'!$C$2 -> 46098 | D3714: 3259 | E3714: 333 | F3714: 3 | G3714: 1 | I3714: COLE | J3714: 24388772 | K3714: SRBK2MR | L3714: SSRNSTRBAHUPOLOS:MAROON:S | M3714: 169900 | N3714: 0.95 | O3714: =M3714-((95*M3714)/100) -> 8495 | P3714: PERCENTAGE
A3715: 2019 & Older TOP All Items (Exclude KI) D95 | B3715: ='KI DISCONTINUE D85'!$B$2 -> 46093 | C3715: ='KI DISCONTINUE D85'!$C$2 -> 46098 | D3715: 3259 | E3715: 333 | F3715: 3 | G3715: 1 | I3715: COLE | J3715: 24388781 | K3715: SRBK2MR | L3715: SSRNSTRBAHUPOLOS:MAROON:M | M3715: 169900 | N3715: 0.95 | O3715: =M3715-((95*M3715)/100) -> 8495 | P3715: PERCENTAGE
A3716: 2019 & Older TOP All Items (Exclude KI) D95 | B3716: ='KI DISCONTINUE D85'!$B$2 -> 46093 | C3716: ='KI DISCONTINUE D85'!$C$2 -> 46098 | D3716: 3259 | E3716: 333 | F3716: 3 | G3716: 1 | I3716: COLE | J3716: 24388790 | K3716: SRBK2MR | L3716: SSRNSTRBAHUPOLOS:MAROON:L | M3716: 169900 | N3716: 0.95 | O3716: =M3716-((95*M3716)/100) -> 8495 | P3716: PERCENTAGE
A3717: 2019 & Older TOP All Items (Exclude KI) D95 | B3717: ='KI DISCONTINUE D85'!$B$2 -> 46093 | C3717: ='KI DISCONTINUE D85'!$C$2 -> 46098 | D3717: 3259 | E3717: 333 | F3717: 3 | G3717: 1 | I3717: COLE | J3717: 24388807 | K3717: SRBK2MR | L3717: SSRNSTRBAHUPOLOS:MAROON:XL | M3717: 169900 | N3717: 0.95 | O3717: =M3717-((95*M3717)/100) -> 8495 | P3717: PERCENTAGE
... A4202: 2019 & Older TOP All Items (Exclude KI) D95 | B4202: ='KI DISCONTINUE D85'!$B$2 -> 46093 | C4202: ='KI DISCONTINUE D85'!$C$2 -> 46098 | D4202: 3259 | E4202: 333 | F4202: 3 | G4202: 1 | I4202: COLE | J4202: 25415098 | K4202: RKNYNV | L4202: TSHIRTREGPRINTNEWYORK:NAVYBLUE:XS | M4202: 139900 | N4202: 0.95 | O4202: =M4202-((95*M4202)/100) -> 6995 | P4202: PERCENTAGE

Sheet 2020 ALL D90
A1: ACARA | B1: FROM DATE | C1: TO DATE | D1: DEPT | E1: WORLD | F1: DIVISION | G1: CLASS | H1: SUPPLIER | I1: BRAND | J1: SKU | K1: ARTICLE | L1: DESCRIPTION | M1: HARGA NORMAL | N1: DISKON | O1: HARGA PROMO | P1: DISCOUNT TYPE
A2: 2020 ALL TOP D90 | B2: ='KI DISCONTINUE D85'!B2 -> 46093 | C2: ='KI DISCONTINUE D85'!C2 -> 46098 | D2: 3259 | E2: 333 | F2: 3 | G2: 1 | I2: COLE | J2: 23208735 | K2: DBTSMIX | L2: DOORBUSTER TSHIRT PRINT:ASSORTIVE COLOR:XS | M2: 129900 | N2: 0.9 | O2: =M2-(M2*N2) -> 12990 | P2: PERCENTAGE
A3: 2020 ALL TOP D90 | B3: =B2 -> 46093 | C3: =C2 -> 46098 | D3: 3259 | E3: 333 | F3: 3 | G3: 1 | I3: COLE | J3: 23208744 | K3: DBTSMIX | L3: DOORBUSTER TSHIRT PRINT:ASSORTIVE COLOR:S | M3: 129900 | N3: 0.9 | O3: =M3-(M3*N3) -> 12990 | P3: PERCENTAGE
A4: 2020 ALL TOP D90 | B4: =B3 -> 46093 | C4: =C3 -> 46098 | D4: 3259 | E4: 333 | F4: 3 | G4: 1 | I4: COLE | J4: 23208753 | K4: DBTSMIX | L4: DOORBUSTER TSHIRT PRINT:ASSORTIVE COLOR:M | M4: 129900 | N4: 0.9 | O4: =M4-(M4*N4) -> 12990 | P4: PERCENTAGE
A5: 2020 ALL TOP D90 | B5: =B4 -> 46093 | C5: =C4 -> 46098 | D5: 3259 | E5: 333 | F5: 3 | G5: 1 | I5: COLE | J5: 23208762 | K5: DBTSMIX | L5: DOORBUSTER TSHIRT PRINT:ASSORTIVE COLOR:L | M5: 129900 | N5: 0.9 | O5: =M5-(M5*N5) -> 12990 | P5: PERCENTAGE
A6: 2020 ALL TOP D90 | B6: =B5 -> 46093 | C6: =C5 -> 46098 | D6: 3259 | E6: 333 | F6: 3 | G6: 1 | I6: COLE | J6: 23208771 | K6: DBTSMIX | L6: DOORBUSTER TSHIRT PRINT:ASSORTIVE COLOR:XL | M6: 129900 | N6: 0.9 | O6: =M6-(M6*N6) -> 12990 | P6: PERCENTAGE
A7: 2020 ALL TOP D90 | B7: =B6 -> 46093 | C7: =C6 -> 46098 | D7: 3259 | E7: 333 | F7: 3 | G7: 1 | I7: COLE | J7: 26167346 | K7: RKCNYC34 | L7: TSHIRT REG PRINT COLE NYC:MISTY LIGHT BLUE:XS | M7: 139900 | N7: 0.9 | O7: =M7-(M7*N7) -> 13990 | P7: PERCENTAGE
A8: 2020 ALL TOP D90 | B8: =B7 -> 46093 | C8: =C7 -> 46098 | D8: 3259 | E8: 333 | F8: 3 | G8: 1 | I8: COLE | J8: 26167355 | K8: RKCNYC34 | L8: TSHIRT REG PRINT COLE NYC:MISTY LIGHT BLUE:S | M8: 139900 | N8: 0.9 | O8: =M8-(M8*N8) -> 13990 | P8: PERCENTAGE
A9: 2020 ALL TOP D90 | B9: =B8 -> 46093 | C9: =C8 -> 46098 | D9: 3259 | E9: 333 | F9: 3 | G9: 1 | I9: COLE | J9: 26167364 | K9: RKCNYC34 | L9: TSHIRT REG PRINT COLE NYC:MISTY LIGHT BLUE:M | M9: 139900 | N9: 0.9 | O9: =M9-(M9*N9) -> 13990 | P9: PERCENTAGE
A10: 2020 ALL TOP D90 | B10: =B9 -> 46093 | C10: =C9 -> 46098 | D10: 3259 | E10: 333 | F10: 3 | G10: 1 | I10: COLE | J10: 26167373 | K10: RKCNYC34 | L10: TSHIRT REG PRINT COLE NYC:MISTY LIGHT BLUE:L | M10: 139900 | N10: 0.9 | O10: =M10-(M10*N10) -> 13990 | P10: PERCENTAGE
A11: 2020 ALL TOP D90 | B11: =B10 -> 46093 | C11: =C10 -> 46098 | D11: 3259 | E11: 333 | F11: 3 | G11: 1 | I11: COLE | J11: 26167382 | K11: RKCNYC34 | L11: TSHIRT REG PRINT COLE NYC:MISTY LIGHT BLUE:XL | M11: 139900 | N11: 0.9 | O11: =M11-(M11*N11) -> 13990 | P11: PERCENTAGE
A12: 2020 ALL TOP D90 | B12: =B11 -> 46093 | C12: =C11 -> 46098 | D12: 3259 | E12: 333 | F12: 3 | G12: 1 | I12: COLE | J12: 26167293 | K12: RKCNYCGY | L12: TSHIRT REG PRINT COLE NYC:MISTY DARK GREY:XS | M12: 139900 | N12: 0.9 | O12: =M12-(M12*N12) -> 13990 | P12: PERCENTAGE
A13: 2020 ALL TOP D90 | B13: =B12 -> 46093 | C13: =C12 -> 46098 | D13: 3259 | E13: 333 | F13: 3 | G13: 1 | I13: COLE | J13: 26167300 | K13: RKCNYCGY | L13: TSHIRT REG PRINT COLE NYC:MISTY DARK GREY:S | M13: 139900 | N13: 0.9 | O13: =M13-(M13*N13) -> 13990 | P13: PERCENTAGE
A14: 2020 ALL TOP D90 | B14: =B13 -> 46093 | C14: =C13 -> 46098 | D14: 3259 | E14: 333 | F14: 3 | G14: 1 | I14: COLE | J14: 26167319 | K14: RKCNYCGY | L14: TSHIRT REG PRINT COLE NYC:MISTY DARK GREY:M | M14: 139900 | N14: 0.9 | O14: =M14-(M14*N14) -> 13990 | P14: PERCENTAGE
... A324: 2020 ALL TOP D90 | B324: =B323 -> 46093 | C324: =C323 -> 46098 | D324: 3259 | E324: 333 | F324: 3 | G324: 1 | I324: COLE | J324: 26653285 | K324: RKTRIADV | L324: SS T-SHIRT PRINT ADVENTURE RKTRIADV:OLIVE:XS:PRINT:SS T-SHIRT | M324: 139900 | N324: 0.9 | O324: =M324-(M324*N324) -> 13990 | P324: PERCENTAGE
A325: 2020 ALL TOP D90 | B325: =B324 -> 46093 | C325: =C324 -> 46098 | D325: 3259 | E325: 333 | F325: 3 | G325: 1 | J325: 26653294 | K325: RKTRIADV | L325: SS T-SHIRT PRINT ADVENTURE RKTRIADV:OLIVE:S:PRINT:SS T-SHIRT | M325: 139900 | N325: 0.9 | O325: =M325-(M325*N325) -> 13990 | P325: PERCENTAGE
A326: 2020 ALL TOP D90 | B326: =B325 -> 46093 | C326: =C325 -> 46098 | D326: 3259 | E326: 333 | F326: 3 | G326: 1 | J326: 26653301 | K326: RKTRIADV | L326: SS T-SHIRT PRINT ADVENTURE RKTRIADV:OLIVE:M:PRINT:SS T-SHIRT | M326: 139900 | N326: 0.9 | O326: =M326-(M326*N326) -> 13990 | P326: PERCENTAGE
A327: 2020 ALL TOP D90 | B327: =B326 -> 46093 | C327: =C326 -> 46098 | D327: 3259 | E327: 333 | F327: 3 | G327: 1 | J327: 26653310 | K327: RKTRIADV | L327: SS T-SHIRT PRINT ADVENTURE RKTRIADV:OLIVE:L:PRINT:SS T-SHIRT | M327: 139900 | N327: 0.9 | O327: =M327-(M327*N327) -> 13990 | P327: PERCENTAGE
A328: 2020 ALL TOP D90 | B328: =B327 -> 46093 | C328: =C327 -> 46098 | D328: 3259 | E328: 333 | F328: 3 | G328: 1 | J328: 26653329 | K328: RKTRIADV | L328: SS T-SHIRT PRINT ADVENTURE RKTRIADV:OLIVE:XL:PRINT:SS T-SHIRT | M328: 139900 | N328: 0.9 | O328: =M328-(M328*N328) -> 13990 | P328: PERCENTAGE
A329: 2020 ALL TOP D90 | B329: =B328 -> 46093 | C329: =C328 -> 46098 | D329: 3259 | E329: 333 | F329: 3 | G329: 1 | J329: 27026979 | K329: RKLIM71 | L329: SS T-SHIRT PRINT LESS RKLIM71:MISTY MEDIUM GRE:XS:TEXT:SS T-SHIRT | M329: 139900 | N329: 0.9 | O329: =M329-(M329*N329) -> 13990 | P329: PERCENTAGE
A330: 2020 ALL TOP D90 | B330: =B329 -> 46093 | C330: =C329 -> 46098 | D330: 3259 | E330: 333 | F330: 3 | G330: 1 | J330: 27026988 | K330: RKLIM71 | L330: SS T-SHIRT PRINT LESS RKLIM71:MISTY MEDIUM GRE:S:TEXT:SS T-SHIRT | M330: 139900 | N330: 0.9 | O330: =M330-(M330*N330) -> 13990 | P330: PERCENTAGE
A331: 2020 ALL TOP D90 | B331: =B330 -> 46093 | C331: =C330 -> 46098 | D331: 3259 | E331: 333 | F331: 3 | G331: 1 | J331: 27026997 | K331: RKLIM71 | L331: SS T-SHIRT PRINT LESS RKLIM71:MISTY MEDIUM GRE:M:TEXT:SS T-SHIRT | M331: 139900 | N331: 0.9 | O331: =M331-(M331*N331) -> 13990 | P331: PERCENTAGE
A332: 2020 ALL TOP D90 | B332: =B331 -> 46093 | C332: =C331 -> 46098 | D332: 3259 | E332: 333 | F332: 3 | G332: 1 | J332: 27027003 | K332: RKLIM71 | L332: SS T-SHIRT PRINT LESS RKLIM71:MISTY MEDIUM GRE:L:TEXT:SS T-SHIRT | M332: 139900 | N332: 0.9 | O332: =M332-(M332*N332) -> 13990 | P332: PERCENTAGE
A333: 2020 ALL TOP D90 | B333: =B332 -> 46093 | C333: =C332 -> 46098 | D333: 3259 | E333: 333 | F333: 3 | G333: 1 | J333: 27027012 | K333: RKLIM71 | L333: SS T-SHIRT PRINT LESS RKLIM71:MISTY MEDIUM GRE:XL:TEXT:SS T-SHIRT | M333: 139900 | N333: 0.9 | O333: =M333-(M333*N333) -> 13990 | P333: PERCENTAGE
A334: 2020 ALL TOP D90 | B334: =B333 -> 46093 | C334: =C333 -> 46098 | D334: 3259 | E334: 333 | F334: 3 | G334: 1 | J334: 27026782 | K334: RKEXPOL | L334: SS T-SHIRT PRINT EXPLORE RKEXPOL:OLIVE:S:TEXT:SS T-SHIRT | M334: 139900 | N334: 0.9 | O334: =M334-(M334*N334) -> 13990 | P334: PERCENTAGE
A335: 2020 ALL TOP D90 | B335: =B334 -> 46093 | C335: =C334 -> 46098 | D335: 3259 | E335: 333 | F335: 3 | G335: 1 | J335: 27026791 | K335: RKEXPOL | L335: SS T-SHIRT PRINT EXPLORE RKEXPOL:OLIVE:M:TEXT:SS T-SHIRT | M335: 139900 | N335: 0.9 | O335: =M335-(M335*N335) -> 13990 | P335: PERCENTAGE
A336: 2020 ALL TOP D90 | B336: =B335 -> 46093 | C336: =C335 -> 46098 | D336: 3259 | E336: 333 | F336: 3 | G336: 1 | J336: 27026808 | K336: RKEXPOL | L336: SS T-SHIRT PRINT EXPLORE RKEXPOL:OLIVE:L:TEXT:SS T-SHIRT | M336: 139900 | N336: 0.9 | O336: =M336-(M336*N336) -> 13990 | P336: PERCENTAGE
... A393: 2020 ALL TOP D90 | B393: =B392 -> 46093 | C393: =C392 -> 46098 | D393: 3259 | E393: 333 | F393: 3 | G393: 1 | J393: 27026620 | K393: TSTK1H86 | L393: SS T-SHIRT STRIPE TSTK1H86:MAROON:XL:STRIPE:SS T-SHIRT | M393: 149900 | N393: 0.9 | O393: =M393-(M393*N393) -> 14990 | P393: PERCENTAGE
A394: 2020 ALL TOP D90 | B394: =B393 -> 46093 | C394: =C393 -> 46098 | D394: 3259 | E394: 333 | F394: 3 | G394: 1 | I394: COLE | J394: 24187677 | K394: LRAB1MR | L394: LS STRIPE AB 1 CM:MAROON:XS | M394: 169900 | N394: 0.9 | O394: =M394-(M394*N394) -> 16990 | P394: PERCENTAGE
A395: 2020 ALL TOP D90 | B395: =B394 -> 46093 | C395: =C394 -> 46098 | D395: 3259 | E395: 333 | F395: 3 | G395: 1 | I395: COLE | J395: 24187686 | K395: LRAB1MR | L395: LS STRIPE AB 1 CM:MAROON:S | M395: 169900 | N395: 0.9 | O395: =M395-(M395*N395) -> 16990 | P395: PERCENTAGE
A396: 2020 ALL TOP D90 | B396: =B395 -> 46093 | C396: =C395 -> 46098 | D396: 3259 | E396: 333 | F396: 3 | G396: 1 | I396: COLE | J396: 24187695 | K396: LRAB1MR | L396: LS STRIPE AB 1 CM:MAROON:M | M396: 169900 | N396: 0.9 | O396: =M396-(M396*N396) -> 16990 | P396: PERCENTAGE
A397: 2020 ALL TOP D90 | B397: =B396 -> 46093 | C397: =C396 -> 46098 | D397: 3259 | E397: 333 | F397: 3 | G397: 1 | I397: COLE | J397: 24187702 | K397: LRAB1MR | L397: LS STRIPE AB 1 CM:MAROON:L | M397: 169900 | N397: 0.9 | O397: =M397-(M397*N397) -> 16990 | P397: PERCENTAGE
A398: 2020 ALL TOP D90 | B398: =B397 -> 46093 | C398: =C397 -> 46098 | D398: 3259 | E398: 333 | F398: 3 | G398: 1 | I398: COLE | J398: 24187711 | K398: LRAB1MR | L398: LS STRIPE AB 1 CM:MAROON:XL | M398: 169900 | N398: 0.9 | O398: =M398-(M398*N398) -> 16990 | P398: PERCENTAGE
A399: 2020 ALL TOP D90 | B399: =B398 -> 46093 | C399: =C398 -> 46098 | D399: 3259 | E399: 333 | F399: 3 | G399: 1 | I399: COLE | J399: 24187622 | K399: LRAB1NV | L399: LS STRIPE AB 1 CM:NAVY BLUE:XS | M399: 169900 | N399: 0.9 | O399: =M399-(M399*N399) -> 16990 | P399: PERCENTAGE
A400: 2020 ALL TOP D90 | B400: =B399 -> 46093 | C400: =C399 -> 46098 | D400: 3259 | E400: 333 | F400: 3 | G400: 1 | I400: COLE | J400: 24187631 | K400: LRAB1NV | L400: LS STRIPE AB 1 CM:NAVY BLUE:S | M400: 169900 | N400: 0.9 | O400: =M400-(M400*N400) -> 16990 | P400: PERCENTAGE
A401: 2020 ALL TOP D90 | B401: =B400 -> 46093 | C401: =C400 -> 46098 | D401: 3259 | E401: 333 | F401: 3 | G401: 1 | I401: COLE | J401: 24187640 | K401: LRAB1NV | L401: LS STRIPE AB 1 CM:NAVY BLUE:M | M401: 169900 | N401: 0.9 | O401: =M401-(M401*N401) -> 16990 | P401: PERCENTAGE
A402: 2020 ALL TOP D90 | B402: =B401 -> 46093 | C402: =C401 -> 46098 | D402: 3259 | E402: 333 | F402: 3 | G402: 1 | I402: COLE | J402: 24187659 | K402: LRAB1NV | L402: LS STRIPE AB 1 CM:NAVY BLUE:L | M402: 169900 | N402: 0.9 | O402: =M402-(M402*N402) -> 16990 | P402: PERCENTAGE
A403: 2020 ALL TOP D90 | B403: =B402 -> 46093 | C403: =C402 -> 46098 | D403: 3259 | E403: 333 | F403: 3 | G403: 1 | I403: COLE | J403: 24187668 | K403: LRAB1NV | L403: LS STRIPE AB 1 CM:NAVY BLUE:XL | M403: 169900 | N403: 0.9 | O403: =M403-(M403*N403) -> 16990 | P403: PERCENTAGE
A404: 2020 ALL TOP D90 | B404: =B403 -> 46093 | C404: =C403 -> 46098 | D404: 3259 | E404: 333 | F404: 3 | G404: 1 | I404: COLE | J404: 24187579 | K404: LRAB1OL | L404: LS STRIPE AB 1 CM:OLIVE:XS | M404: 169900 | N404: 0.9 | O404: =M404-(M404*N404) -> 16990 | P404: PERCENTAGE
A405: 2020 ALL TOP D90 | B405: =B404 -> 46093 | C405: =C404 -> 46098 | D405: 3259 | E405: 333 | F405: 3 | G405: 1 | I405: COLE | J405: 24187588 | K405: LRAB1OL | L405: LS STRIPE AB 1 CM:OLIVE:S | M405: 169900 | N405: 0.9 | O405: =M405-(M405*N405) -> 16990 | P405: PERCENTAGE
...

Sheet 2021 ALL D90
A1: ACARA | B1: FROM DATE | C1: TO DATE | D1: DEPT | E1: WORLD | F1: DIVISION | G1: CLASS | H1: SUPPLIER | I1: BRAND | J1: SKU | K1: ARTICLE | L1: DESCRIPTION | M1: HARGA NORMAL | N1: DISKON | O1: HARGA PROMO | P1: DISCOUNT TYPE
A2: 2021 ALL TOP D90 | B2: ='KI DISCONTINUE D85'!$B$2 -> 46093 | C2: ='KI DISCONTINUE D85'!$C$2 -> 46098 | D2: 3259 | E2: 333 | F2: 3 | G2: 1 | I2: COLE | J2: 29254746 | K2: STXCOLE | L2: SS T-SHIRT TSHIRT TEXTURED PRINT STXCOLE:MISTY MEDIUM G:S:TEXT:SS T-SHIRT | M2: 169900 | N2: 0.9 | O2: =M2-(M2*N2) -> 16990 | P2: PERCENTAGE
A3: 2021 ALL TOP D90 | B3: ='KI DISCONTINUE D85'!$B$2 -> 46093 | C3: ='KI DISCONTINUE D85'!$C$2 -> 46098 | D3: 3259 | E3: 333 | F3: 3 | G3: 1 | I3: COLE | J3: 29254755 | K3: STXCOLE | L3: SS T-SHIRT TSHIRT TEXTURED PRINT STXCOLE:MISTY MEDIUM G:M:TEXT:SS T-SHIRT | M3: 169900 | N3: 0.9 | O3: =M3-(M3*N3) -> 16990 | P3: PERCENTAGE
A4: 2021 ALL TOP D90 | B4: ='KI DISCONTINUE D85'!$B$2 -> 46093 | C4: ='KI DISCONTINUE D85'!$C$2 -> 46098 | D4: 3259 | E4: 333 | F4: 3 | G4: 1 | I4: COLE | J4: 29254764 | K4: STXCOLE | L4: SS T-SHIRT TSHIRT TEXTURED PRINT STXCOLE:MISTY MEDIUM G:L:TEXT:SS T-SHIRT | M4: 169900 | N4: 0.9 | O4: =M4-(M4*N4) -> 16990 | P4: PERCENTAGE
A5: 2021 ALL TOP D90 | B5: ='KI DISCONTINUE D85'!$B$2 -> 46093 | C5: ='KI DISCONTINUE D85'!$C$2 -> 46098 | D5: 3259 | E5: 333 | F5: 3 | G5: 1 | I5: COLE | J5: 29254773 | K5: STXCOLE | L5: SS T-SHIRT TSHIRT TEXTURED PRINT STXCOLE:MISTY MEDIUM G:XL:TEXT:SS T-SHIRT | M5: 169900 | N5: 0.9 | O5: =M5-(M5*N5) -> 16990 | P5: PERCENTAGE
A6: 2021 ALL TOP D90 | B6: ='KI DISCONTINUE D85'!$B$2 -> 46093 | C6: ='KI DISCONTINUE D85'!$C$2 -> 46098 | D6: 3259 | E6: 333 | F6: 3 | G6: 1 | I6: COLE | J6: 29259465 | K6: STXCOLEBT | L6: SS T-SHIRT TSHIRT TEXTURED PRINT STXCOLEBT:MANDARIN ORAN:S:TEXT:SS T-SHIRT | M6: 169900 | N6: 0.9 | O6: =M6-(M6*N6) -> 16990 | P6: PERCENTAGE
A7: 2021 ALL TOP D90 | B7: ='KI DISCONTINUE D85'!$B$2 -> 46093 | C7: ='KI DISCONTINUE D85'!$C$2 -> 46098 | D7: 3259 | E7: 333 | F7: 3 | G7: 1 | I7: COLE | J7: 29259474 | K7: STXCOLEBT | L7: SS T-SHIRT TSHIRT TEXTURED PRINT STXCOLEBT:MANDARIN ORAN:M:TEXT:SS T-SHIRT | M7: 169900 | N7: 0.9 | O7: =M7-(M7*N7) -> 16990 | P7: PERCENTAGE
A8: 2021 ALL TOP D90 | B8: ='KI DISCONTINUE D85'!$B$2 -> 46093 | C8: ='KI DISCONTINUE D85'!$C$2 -> 46098 | D8: 3259 | E8: 333 | F8: 3 | G8: 1 | I8: COLE | J8: 29259483 | K8: STXCOLEBT | L8: SS T-SHIRT TSHIRT TEXTURED PRINT STXCOLEBT:MANDARIN ORAN:L:TEXT:SS T-SHIRT | M8: 169900 | N8: 0.9 | O8: =M8-(M8*N8) -> 16990 | P8: PERCENTAGE
A9: 2021 ALL TOP D90 | B9: ='KI DISCONTINUE D85'!$B$2 -> 46093 | C9: ='KI DISCONTINUE D85'!$C$2 -> 46098 | D9: 3259 | E9: 333 | F9: 3 | G9: 1 | I9: COLE | J9: 29259492 | K9: STXCOLEBT | L9: SS T-SHIRT TSHIRT TEXTURED PRINT STXCOLEBT:MANDARIN ORAN:XL:TEXT:SS T-SHIRT | M9: 169900 | N9: 0.9 | O9: =M9-(M9*N9) -> 16990 | P9: PERCENTAGE
A10: 2021 ALL TOP D90 | B10: ='KI DISCONTINUE D85'!$B$2 -> 46093 | C10: ='KI DISCONTINUE D85'!$C$2 -> 46098 | D10: 3259 | E10: 333 | F10: 3 | G10: 1 | I10: COLE | J10: 33368973 | K10: TSSTRHK46 | L10: SS T-SHIRT REG TSHIRT STRIPE TSSTRHK46:WOOD BROWN:S:STRIPES:SS T-SHIRT | M10: 169900 | N10: 0.9 | O10: =M10-(M10*N10) -> 16990 | P10: PERCENTAGE
A11: 2021 ALL TOP D90 | B11: ='KI DISCONTINUE D85'!$B$2 -> 46093 | C11: ='KI DISCONTINUE D85'!$C$2 -> 46098 | D11: 3259 | E11: 333 | F11: 3 | G11: 1 | I11: COLE | J11: 33368982 | K11: TSSTRHK46 | L11: SS T-SHIRT REG TSHIRT STRIPE TSSTRHK46:WOOD BROWN:M:STRIPES:SS T-SHIRT | M11: 169900 | N11: 0.9 | O11: =M11-(M11*N11) -> 16990 | P11: PERCENTAGE
A12: 2021 ALL TOP D90 | B12: ='KI DISCONTINUE D85'!$B$2 -> 46093 | C12: ='KI DISCONTINUE D85'!$C$2 -> 46098 | D12: 3259 | E12: 333 | F12: 3 | G12: 1 | I12: COLE | J12: 33368991 | K12: TSSTRHK46 | L12: SS T-SHIRT REG TSHIRT STRIPE TSSTRHK46:WOOD BROWN:L:STRIPES:SS T-SHIRT | M12: 169900 | N12: 0.9 | O12: =M12-(M12*N12) -> 16990 | P12: PERCENTAGE
A13: 2021 ALL TOP D90 | B13: ='KI DISCONTINUE D85'!$B$2 -> 46093 | C13: ='KI DISCONTINUE D85'!$C$2 -> 46098 | D13: 3259 | E13: 333 | F13: 3 | G13: 1 | I13: COLE | J13: 33369007 | K13: TSSTRHK46 | L13: SS T-SHIRT REG TSHIRT STRIPE TSSTRHK46:WOOD BROWN:XL:STRIPES:SS T-SHIRT | M13: 169900 | N13: 0.9 | O13: =M13-(M13*N13) -> 16990 | P13: PERCENTAGE
... A1103: 2021 ALL TOP D90 | B1103: ='KI DISCONTINUE D85'!$B$2 -> 46093 | C1103: ='KI DISCONTINUE D85'!$C$2 -> 46098 | D1103: 3259 | E1103: 333 | F1103: 3 | G1103: 8 | I1103: COLE | J1103: 26451707 | K1103: LEBSS83OBU | L1103: SS KOKO OXFORD:CLASSIC BLUE:S | M1103: 249900 | N1103: 0.9 | O1103: =M1103-(M1103*N1103) -> 24990 | P1103: PERCENTAGE

Sheet 2022 ALL D90
A1: ACARA | B1: FROM DATE | C1: TO DATE | D1: DEPT | E1: WORLD | F1: DIVISION | G1: CLASS | H1: SUPPLIER | I1: BRAND | J1: SKU | K1: ARTICLE | L1: DESCRIPTION | M1: HARGA NORMAL | N1: DISKON | O1: HARGA PROMO | P1: DISCOUNT TYPE
A2: 2022 ALL TOP D90 | B2: ='KI DISCONTINUE D85'!$B$2 -> 46093 | C2: ='KI DISCONTINUE D85'!$C$2 -> 46098 | D2: 3259 | E2: 333 | F2: 3 | G2: 1 | I2: COLE | J2: 25882155 | K2: SRB91NV | L2: SS RN STR BAHU POLOS:NAVY BLUE:L | M2: 169900 | N2: 0.9 | O2: =M2-(M2*N2) -> 16990 | P2: PERCENTAGE
A3: 2022 ALL TOP D90 | B3: ='KI DISCONTINUE D85'!$B$2 -> 46093 | C3: ='KI DISCONTINUE D85'!$C$2 -> 46098 | D3: 3259 | E3: 333 | F3: 3 | G3: 1 | I3: COLE | J3: 25882164 | K3: SRB91NV | L3: SS RN STR BAHU POLOS:NAVY BLUE:XL | M3: 169900 | N3: 0.9 | O3: =M3-(M3*N3) -> 16990 | P3: PERCENTAGE
A4: 2022 ALL TOP D90 | B4: ='KI DISCONTINUE D85'!$B$2 -> 46093 | C4: ='KI DISCONTINUE D85'!$C$2 -> 46098 | D4: 3259 | E4: 333 | F4: 3 | G4: 1 | I4: COLE | J4: 26089985 | K4: SRB91WN | L4: SS RN STR BAHU POLOS:WINE:S | M4: 169900 | N4: 0.9 | O4: =M4-(M4*N4) -> 16990 | P4: PERCENTAGE
A5: 2022 ALL TOP D90 | B5: ='KI DISCONTINUE D85'!$B$2 -> 46093 | C5: ='KI DISCONTINUE D85'!$C$2 -> 46098 | D5: 3259 | E5: 333 | F5: 3 | G5: 1 | I5: COLE | J5: 26090008 | K5: SRB91WN | L5: SS RN STR BAHU POLOS:WINE:L | M5: 169900 | N5: 0.9 | O5: =M5-(M5*N5) -> 16990 | P5: PERCENTAGE
A6: 2022 ALL TOP D90 | B6: ='KI DISCONTINUE D85'!$B$2 -> 46093 | C6: ='KI DISCONTINUE D85'!$C$2 -> 46098 | D6: 3259 | E6: 333 | F6: 3 | G6: 1 | I6: COLE | J6: 25882146 | K6: SRB91NV | L6: SS RN STR BAHU POLOS:NAVY BLUE:M | M6: 169900 | N6: 0.9 | O6: =M6-(M6*N6) -> 16990 | P6: PERCENTAGE
A7: 2022 ALL TOP D90 | B7: ='KI DISCONTINUE D85'!$B$2 -> 46093 | C7: ='KI DISCONTINUE D85'!$C$2 -> 46098 | D7: 3259 | E7: 333 | F7: 3 | G7: 1 | I7: COLE | J7: 25882137 | K7: SRB91NV | L7: SS RN STR BAHU POLOS:NAVY BLUE:S | M7: 169900 | N7: 0.9 | O7: =M7-(M7*N7) -> 16990 | P7: PERCENTAGE
A8: 2022 ALL TOP D90 | B8: ='KI DISCONTINUE D85'!$B$2 -> 46093 | C8: ='KI DISCONTINUE D85'!$C$2 -> 46098 | D8: 3259 | E8: 333 | F8: 3 | G8: 1 | I8: COLE | J8: 26089976 | K8: SRB91WN | L8: SS RN STR BAHU POLOS:WINE:XS | M8: 169900 | N8: 0.9 | O8: =M8-(M8*N8) -> 16990 | P8: PERCENTAGE
A9: 2022 ALL TOP D90 | B9: ='KI DISCONTINUE D85'!$B$2 -> 46093 | C9: ='KI DISCONTINUE D85'!$C$2 -> 46098 | D9: 3259 | E9: 333 | F9: 3 | G9: 1 | I9: COLE | J9: 26089994 | K9: SRB91WN | L9: SS RN STR BAHU POLOS:WINE:M | M9: 169900 | N9: 0.9 | O9: =M9-(M9*N9) -> 16990 | P9: PERCENTAGE
A10: 2022 ALL TOP D90 | B10: ='KI DISCONTINUE D85'!$B$2 -> 46093 | C10: ='KI DISCONTINUE D85'!$C$2 -> 46098 | D10: 3259 | E10: 333 | F10: 3 | G10: 1 | I10: COLE | J10: 26090017 | K10: SRB91WN | L10: SS RN STR BAHU POLOS:WINE:XL | M10: 169900 | N10: 0.9 | O10: =M10-(M10*N10) -> 16990 | P10: PERCENTAGE
A11: 2022 ALL TOP D90 | B11: ='KI DISCONTINUE D85'!$B$2 -> 46093 | C11: ='KI DISCONTINUE D85'!$C$2 -> 46098 | D11: 3259 | E11: 333 | F11: 3 | G11: 1 | I11: COLE | J11: 28107326 | K11: TSTREU165 | L11: SS T-SHIRT STRIPE TSTREU165:NAVY BLUE:L:STRIPES:SS T-SHIRT | M11: 169900 | N11: 0.9 | O11: =M11-(M11*N11) -> 16990 | P11: PERCENTAGE
A12: 2022 ALL TOP D90 | B12: ='KI DISCONTINUE D85'!$B$2 -> 46093 | C12: ='KI DISCONTINUE D85'!$C$2 -> 46098 | D12: 3259 | E12: 333 | F12: 3 | G12: 1 | I12: COLE | J12: 28107335 | K12: TSTREU165 | L12: SS T-SHIRT STRIPE TSTREU165:NAVY BLUE:XL:STRIPES:SS T-SHIRT | M12: 169900 | N12: 0.9 | O12: =M12-(M12*N12) -> 16990 | P12: PERCENTAGE
A13: 2022 ALL TOP D90 | B13: ='KI DISCONTINUE D85'!$B$2 -> 46093 | C13: ='KI DISCONTINUE D85'!$C$2 -> 46098 | D13: 3259 | E13: 333 | F13: 3 | G13: 1 | I13: COLE | J13: 28107317 | K13: TSTREU165 | L13: SS T-SHIRT STRIPE TSTREU165:NAVY BLUE:M:STRIPES:SS T-SHIRT | M13: 169900 | N13: 0.9 | O13: =M13-(M13*N13) -> 16990 | P13: PERCENTAGE
... A1785: 2022 ALL TOP D90 | B1785: ='KI DISCONTINUE D85'!$B$2 -> 46093 | C1785: ='KI DISCONTINUE D85'!$C$2 -> 46098 | D1785: 3259 | E1785: 333 | F1785: 3 | G1785: 1 | I1785: COLE | J1785: 66039794 | K1785: LEBSTS16 | L1785: SS KOKO ULOS PINTU LEBSTS16:FROST GREY:XL:STRIPES:SS KOKO | M1785: 329900 | N1785: 0.9 | O1785: =M1785-(M1785*N1785) -> 32990 | P1785: PERCENTAGE

Sheet 2023 KI DISCONTINUE D90
A1: ACARA | B1: FROM DATE | C1: TO DATE | D1: DEPT | E1: WORLD | F1: DIVISION | G1: CLASS | H1: SUPPLIER | I1: BRAND | J1: SKU | K1: ARTICLE | L1: DESCRIPTION | M1: HARGA NORMAL | N1: DISKON | O1: HARGA PROMO | P1: DISCOUNT TYPE
A2: 2023 KI DISCONTINUE D90 | B2: ='KI DISCONTINUE D85'!$B$2 -> 46093 | C2: ='KI DISCONTINUE D85'!$C$2 -> 46098 | D2: 3259 | E2: 333 | F2: 3 | G2: 9 | I2: COLE | J2: 56047893 | K2: KISHEN | L2: SS T-SHIRT HENLEY BASIC KISHEN:BLACK:S:SOLID:SS T-SHIRT | M2: 129900 | N2: 0.9 | O2: =M2-(M2*N2) -> 12990 | P2: PERCENTAGE
A3: 2023 KI DISCONTINUE D90 | B3: ='KI DISCONTINUE D85'!$B$2 -> 46093 | C3: ='KI DISCONTINUE D85'!$C$2 -> 46098 | D3: 3259 | E3: 333 | F3: 3 | G3: 9 | I3: COLE | J3: 56047900 | K3: KISHEN | L3: SS T-SHIRT HENLEY BASIC KISHEN:BLACK:M:SOLID:SS T-SHIRT | M3: 129900 | N3: 0.9 | O3: =M3-(M3*N3) -> 12990 | P3: PERCENTAGE
A4: 2023 KI DISCONTINUE D90 | B4: ='KI DISCONTINUE D85'!$B$2 -> 46093 | C4: ='KI DISCONTINUE D85'!$C$2 -> 46098 | D4: 3259 | E4: 333 | F4: 3 | G4: 9 | I4: COLE | J4: 56047919 | K4: KISHEN | L4: SS T-SHIRT HENLEY BASIC KISHEN:BLACK:L:SOLID:SS T-SHIRT | M4: 129900 | N4: 0.9 | O4: =M4-(M4*N4) -> 12990 | P4: PERCENTAGE
A5: 2023 KI DISCONTINUE D90 | B5: ='KI DISCONTINUE D85'!$B$2 -> 46093 | C5: ='KI DISCONTINUE D85'!$C$2 -> 46098 | D5: 3259 | E5: 333 | F5: 3 | G5: 9 | I5: COLE | J5: 56047928 | K5: KISHEN | L5: SS T-SHIRT HENLEY BASIC KISHEN:BLACK:XL:SOLID:SS T-SHIRT | M5: 129900 | N5: 0.9 | O5: =M5-(M5*N5) -> 12990 | P5: PERCENTAGE
A6: 2023 KI DISCONTINUE D90 | B6: ='KI DISCONTINUE D85'!$B$2 -> 46093 | C6: ='KI DISCONTINUE D85'!$C$2 -> 46098 | D6: 3259 | E6: 333 | F6: 3 | G6: 9 | I6: COLE | J6: 56047937 | K6: KISHEN | L6: SS T-SHIRT HENLEY BASIC KISHEN:BLACK:XXL:SOLID:SS T-SHIRT | M6: 129900 | N6: 0.9 | O6: =M6-(M6*N6) -> 12990 | P6: PERCENTAGE
A7: 2023 KI DISCONTINUE D90 | B7: ='KI DISCONTINUE D85'!$B$2 -> 46093 | C7: ='KI DISCONTINUE D85'!$C$2 -> 46098 | D7: 3259 | E7: 333 | F7: 3 | G7: 9 | I7: COLE | J7: 56047946 | K7: KISHEN | L7: SS T-SHIRT HENLEY BASIC KISHEN:NAVY BLUE:S:SOLID:SS T-SHIRT | M7: 129900 | N7: 0.9 | O7: =M7-(M7*N7) -> 12990 | P7: PERCENTAGE
A8: 2023 KI DISCONTINUE D90 | B8: ='KI DISCONTINUE D85'!$B$2 -> 46093 | C8: ='KI DISCONTINUE D85'!$C$2 -> 46098 | D8: 3259 | E8: 333 | F8: 3 | G8: 9 | I8: COLE | J8: 56047955 | K8: KISHEN | L8: SS T-SHIRT HENLEY BASIC KISHEN:NAVY BLUE:M:SOLID:SS T-SHIRT | M8: 129900 | N8: 0.9 | O8: =M8-(M8*N8) -> 12990 | P8: PERCENTAGE
A9: 2023 KI DISCONTINUE D90 | B9: ='KI DISCONTINUE D85'!$B$2 -> 46093 | C9: ='KI DISCONTINUE D85'!$C$2 -> 46098 | D9: 3259 | E9: 333 | F9: 3 | G9: 9 | I9: COLE | J9: 56047964 | K9: KISHEN | L9: SS T-SHIRT HENLEY BASIC KISHEN:NAVY BLUE:L:SOLID:SS T-SHIRT | M9: 129900 | N9: 0.9 | O9: =M9-(M9*N9) -> 12990 | P9: PERCENTAGE
A10: 2023 KI DISCONTINUE D90 | B10: ='KI DISCONTINUE D85'!$B$2 -> 46093 | C10: ='KI DISCONTINUE D85'!$C$2 -> 46098 | D10: 3259 | E10: 333 | F10: 3 | G10: 9 | I10: COLE | J10: 56047973 | K10: KISHEN | L10: SS T-SHIRT HENLEY BASIC KISHEN:NAVY BLUE:XL:SOLID:SS T-SHIRT | M10: 129900 | N10: 0.9 | O10: =M10-(M10*N10) -> 12990 | P10: PERCENTAGE
A11: 2023 KI DISCONTINUE D90 | B11: ='KI DISCONTINUE D85'!$B$2 -> 46093 | C11: ='KI DISCONTINUE D85'!$C$2 -> 46098 | D11: 3259 | E11: 333 | F11: 3 | G11: 9 | I11: COLE | J11: 56047982 | K11: KISHEN | L11: SS T-SHIRT HENLEY BASIC KISHEN:NAVY BLUE:XXL:SOLID:SS T-SHIRT | M11: 129900 | N11: 0.9 | O11: =M11-(M11*N11) -> 12990 | P11: PERCENTAGE
A12: 2023 KI DISCONTINUE D90 | B12: ='KI DISCONTINUE D85'!$B$2 -> 46093 | C12: ='KI DISCONTINUE D85'!$C$2 -> 46098 | D12: 3259 | E12: 333 | F12: 3 | G12: 9 | I12: COLE | J12: 56047991 | K12: KISHEN | L12: SS T-SHIRT HENLEY BASIC KISHEN:MAROON:S:SOLID:SS T-SHIRT | M12: 129900 | N12: 0.9 | O12: =M12-(M12*N12) -> 12990 | P12: PERCENTAGE
A13: 2023 KI DISCONTINUE D90 | B13: ='KI DISCONTINUE D85'!$B$2 -> 46093 | C13: ='KI DISCONTINUE D85'!$C$2 -> 46098 | D13: 3259 | E13: 333 | F13: 3 | G13: 9 | I13: COLE | J13: 56048007 | K13: KISHEN | L13: SS T-SHIRT HENLEY BASIC KISHEN:MAROON:M:SOLID:SS T-SHIRT | M13: 129900 | N13: 0.9 | O13: =M13-(M13*N13) -> 12990 | P13: PERCENTAGE
... A66: 2023 KI DISCONTINUE D90 | B66: ='KI DISCONTINUE D85'!$B$2 -> 46093 | C66: ='KI DISCONTINUE D85'!$C$2 -> 46098 | D66: 3259 | E66: 333 | F66: 3 | G66: 9 | I66: COLE | J66: 79675126 | K66: ESSRN | L66: SS T-SHIRT OBL BASIC ROUND NECK ESSRN:WOOD BROWN:XXL:SOLID:SS T-SHIRT | M66: 119900 | N66: 0.9 | O66: =M66-(M66*N66) -> 11990 | P66: PERCENTAGE
A67: 2023 KI DISCONTINUE D90 | B67: ='KI DISCONTINUE D85'!B67 -> 46093 | C67: ='KI DISCONTINUE D85'!C67 -> 46098 | D67: 3259 | E67: 333 | F67: 3 | G67: 9 | I67: COLE | J67: 59361958 | K67: ESSRNM | L67: SS T-SHIRT ESSENTIAL SS ROUND NECK ESSRNS:MISTY LIGHT B:S:SOLID:SS T-SHIRT | M67: 119900 | N67: 0.9 | O67: =M67-(M67*N67) -> 11990 | P67: PERCENTAGE
A68: 2023 KI DISCONTINUE D90 | B68: ='KI DISCONTINUE D85'!B68 -> 46093 | C68: ='KI DISCONTINUE D85'!C68 -> 46098 | D68: 3259 | E68: 333 | F68: 3 | G68: 9 | I68: COLE | J68: 59361967 | K68: ESSRNM | L68: SS T-SHIRT ESSENTIAL SS ROUND NECK ESSRNS:MISTY LIGHT B:M:SOLID:SS T-SHIRT | M68: 119900 | N68: 0.9 | O68: =M68-(M68*N68) -> 11990 | P68: PERCENTAGE
A69: 2023 KI DISCONTINUE D90 | B69: ='KI DISCONTINUE D85'!B69 -> 46093 | C69: ='KI DISCONTINUE D85'!C69 -> 46098 | D69: 3259 | E69: 333 | F69: 3 | G69: 9 | I69: COLE | J69: 59361976 | K69: ESSRNM | L69: SS T-SHIRT ESSENTIAL SS ROUND NECK ESSRNS:MISTY LIGHT B:L:SOLID:SS T-SHIRT | M69: 119900 | N69: 0.9 | O69: =M69-(M69*N69) -> 11990 | P69: PERCENTAGE
A70: 2023 KI DISCONTINUE D90 | B70: ='KI DISCONTINUE D85'!B70 -> 46093 | C70: ='KI DISCONTINUE D85'!C70 -> 46098 | D70: 3259 | E70: 333 | F70: 3 | G70: 9 | I70: COLE | J70: 59361985 | K70: ESSRNM | L70: SS T-SHIRT ESSENTIAL SS ROUND NECK ESSRNS:MISTY LIGHT B:XL:SOLID:SS T-SHIRT | M70: 119900 | N70: 0.9 | O70: =M70-(M70*N70) -> 11990 | P70: PERCENTAGE
A71: 2023 KI DISCONTINUE D90 | B71: ='KI DISCONTINUE D85'!B71 -> 46093 | C71: ='KI DISCONTINUE D85'!C71 -> 46098 | D71: 3259 | E71: 333 | F71: 3 | G71: 9 | I71: COLE | J71: 59361994 | K71: ESSRNM | L71: SS T-SHIRT ESSENTIAL SS ROUND NECK ESSRNS:MISTY LIGHT B:XXL:SOLID:SS T-SHIRT | M71: 119900 | N71: 0.9 | O71: =M71-(M71*N71) -> 11990 | P71: PERCENTAGE
A72: 2023 KI DISCONTINUE D90 | B72: ='KI DISCONTINUE D85'!B72 -> 46093 | C72: ='KI DISCONTINUE D85'!C72 -> 46098 | D72: 3259 | E72: 333 | F72: 3 | G72: 9 | I72: COLE | J72: 73800107 | K72: ESLRNB | L72: LS SHIRT OBL BASIC ROUND NECK ESLRNB:GOLDEN BROWN:S:SOLID:LS T-SHIRT | M72: 129900 | N72: 0.9 | O72: =M72-(M72*N72) -> 12990 | P72: PERCENTAGE
A73: 2023 KI DISCONTINUE D90 | B73: ='KI DISCONTINUE D85'!B73 -> 46093 | C73: ='KI DISCONTINUE D85'!C73 -> 46098 | D73: 3259 | E73: 333 | F73: 3 | G73: 9 | I73: COLE | J73: 73800116 | K73: ESLRNB | L73: LS SHIRT OBL BASIC ROUND NECK ESLRNB:GOLDEN BROWN:M:SOLID:LS T-SHIRT | M73: 129900 | N73: 0.9 | O73: =M73-(M73*N73) -> 12990 | P73: PERCENTAGE
A74: 2023 KI DISCONTINUE D90 | B74: ='KI DISCONTINUE D85'!B74 -> 46093 | C74: ='KI DISCONTINUE D85'!C74 -> 46098 | D74: 3259 | E74: 333 | F74: 3 | G74: 9 | I74: COLE | J74: 73800125 | K74: ESLRNB | L74: LS SHIRT OBL BASIC ROUND NECK ESLRNB:GOLDEN BROWN:L:SOLID:LS T-SHIRT | M74: 129900 | N74: 0.9 | O74: =M74-(M74*N74) -> 12990 | P74: PERCENTAGE
A75: 2023 KI DISCONTINUE D90 | B75: ='KI DISCONTINUE D85'!B75 -> 46093 | C75: ='KI DISCONTINUE D85'!C75 -> 46098 | D75: 3259 | E75: 333 | F75: 3 | G75: 9 | I75: COLE | J75: 73800134 | K75: ESLRNB | L75: LS SHIRT OBL BASIC ROUND NECK ESLRNB:GOLDEN BROWN:XL:SOLID:LS T-SHIRT | M75: 129900 | N75: 0.9 | O75: =M75-(M75*N75) -> 12990 | P75: PERCENTAGE
A76: 2023 KI DISCONTINUE D90 | B76: ='KI DISCONTINUE D85'!B76 -> 46093 | C76: ='KI DISCONTINUE D85'!C76 -> 46098 | D76: 3259 | E76: 333 | F76: 3 | G76: 9 | I76: COLE | J76: 73800143 | K76: ESLRNB | L76: LS SHIRT OBL BASIC ROUND NECK ESLRNB:GOLDEN BROWN:XXL:SOLID:LS T-SHIRT | M76: 129900 | N76: 0.9 | O76: =M76-(M76*N76) -> 12990 | P76: PERCENTAGE
A77: 2023 KI DISCONTINUE D90 | B77: ='KI DISCONTINUE D85'!B77 -> 46093 | C77: ='KI DISCONTINUE D85'!C77 -> 46098 | D77: 3259 | E77: 333 | F77: 3 | G77: 9 | I77: COLE | J77: 76165343 | K77: ESSRN | L77: SS T-SHIRT OBL BASIC ROUND NECK ESSRN:CHRISTMAS GREEN:S:SOLID:SS T-SHIRT | M77: 119900 | N77: 0.9 | O77: =M77-(M77*N77) -> 11990 | P77: PERCENTAGE
A78: 2023 KI DISCONTINUE D90 | B78: ='KI DISCONTINUE D85'!B78 -> 46093 | C78: ='KI DISCONTINUE D85'!C78 -> 46098 | D78: 3259 | E78: 333 | F78: 3 | G78: 9 | I78: COLE | J78: 76165352 | K78: ESSRN | L78: SS T-SHIRT OBL BASIC ROUND NECK ESSRN:CHRISTMAS GREEN:M:SOLID:SS T-SHIRT | M78: 119900 | N78: 0.9 | O78: =M78-(M78*N78) -> 11990 | P78: PERCENTAGE
... A81: 2023 KI DISCONTINUE D90 | B81: ='KI DISCONTINUE D85'!B81 -> 46093 | C81: ='KI DISCONTINUE D85'!C81 -> 46098 | D81: 3259 | E81: 333 | F81: 3 | G81: 9 | I81: COLE | J81: 76165389 | K81: ESSRN | L81: SS T-SHIRT OBL BASIC ROUND NECK ESSRN:CHRISTMAS GREEN:XXL:SOLID:SS T-SHIRT | M81: 119900 | N81: 0.9 | O81: =M81-(M81*N81) -> 11990 | P81: PERCENTAGE
A82: 2023 KI DISCONTINUE D90 | B82: ='KI DISCONTINUE D85'!$B$2 -> 46093 | C82: ='KI DISCONTINUE D85'!$C$2 -> 46098 | D82: 3259 | E82: 333 | F82: 3 | G82: 10 | I82: COLE | J82: 73799263 | K82: BSWS | L82: SS POLO SHIRT WK BASIC LACOSE SOLID BSWS:RUSTIC BROWN:S:SOLID:SS POLO SHIRT | M82: 169900 | N82: 0.9 | O82: =M82-(M82*N82) -> 16990 | P82: PERCENTAGE
A83: 2023 KI DISCONTINUE D90 | B83: ='KI DISCONTINUE D85'!$B$2 -> 46093 | C83: ='KI DISCONTINUE D85'!$C$2 -> 46098 | D83: 3259 | E83: 333 | F83: 3 | G83: 10 | I83: COLE | J83: 73799272 | K83: BSWS | L83: SS POLO SHIRT WK BASIC LACOSE SOLID BSWS:RUSTIC BROWN:M:SOLID:SS POLO SHIRT | M83: 169900 | N83: 0.9 | O83: =M83-(M83*N83) -> 16990 | P83: PERCENTAGE
A84: 2023 KI DISCONTINUE D90 | B84: ='KI DISCONTINUE D85'!$B$2 -> 46093 | C84: ='KI DISCONTINUE D85'!$C$2 -> 46098 | D84: 3259 | E84: 333 | F84: 3 | G84: 10 | I84: COLE | J84: 73799281 | K84: BSWS | L84: SS POLO SHIRT WK BASIC LACOSE SOLID BSWS:RUSTIC BROWN:L:SOLID:SS POLO SHIRT | M84: 169900 | N84: 0.9 | O84: =M84-(M84*N84) -> 16990 | P84: PERCENTAGE
A85: 2023 KI DISCONTINUE D90 | B85: ='KI DISCONTINUE D85'!$B$2 -> 46093 | C85: ='KI DISCONTINUE D85'!$C$2 -> 46098 | D85: 3259 | E85: 333 | F85: 3 | G85: 10 | I85: COLE | J85: 73799290 | K85: BSWS | L85: SS POLO SHIRT WK BASIC LACOSE SOLID BSWS:RUSTIC BROWN:XL:SOLID:SS POLO SHIRT | M85: 169900 | N85: 0.9 | O85: =M85-(M85*N85) -> 16990 | P85: PERCENTAGE
A86: 2023 KI DISCONTINUE D90 | B86: ='KI DISCONTINUE D85'!$B$2 -> 46093 | C86: ='KI DISCONTINUE D85'!$C$2 -> 46098 | D86: 3259 | E86: 333 | F86: 3 | G86: 10 | I86: COLE | J86: 73799307 | K86: BSWS | L86: SS POLO SHIRT WK BASIC LACOSE SOLID BSWS:RUSTIC BROWN:XXL:SOLID:SS POLO SHIRT | M86: 169900 | N86: 0.9 | O86: =M86-(M86*N86) -> 16990 | P86: PERCENTAGE
A87: 2023 KI DISCONTINUE D90 | B87: ='KI DISCONTINUE D85'!$B$2 -> 46093 | C87: ='KI DISCONTINUE D85'!$C$2 -> 46098 | D87: 3259 | E87: 333 | F87: 3 | G87: 10 | I87: COLE | J87: 76165521 | K87: BSWS | L87: SS POLO SHIRT WK BASIC LACOSE SOLID BSWS:RUSTIC ORANGE:S:SOLID:SS POLO SHIRT | M87: 169900 | N87: 0.9 | O87: =M87-(M87*N87) -> 16990 | P87: PERCENTAGE
A88: 2023 KI DISCONTINUE D90 | B88: ='KI DISCONTINUE D85'!$B$2 -> 46093 | C88: ='KI DISCONTINUE D85'!$C$2 -> 46098 | D88: 3259 | E88: 333 | F88: 3 | G88: 10 | I88: COLE | J88: 76165530 | K88: BSWS | L88: SS POLO SHIRT WK BASIC LACOSE SOLID BSWS:RUSTIC ORANGE:M:SOLID:SS POLO SHIRT | M88: 169900 | N88: 0.9 | O88: =M88-(M88*N88) -> 16990 | P88: PERCENTAGE
A89: 2023 KI DISCONTINUE D90 | B89: ='KI DISCONTINUE D85'!$B$2 -> 46093 | C89: ='KI DISCONTINUE D85'!$C$2 -> 46098 | D89: 3259 | E89: 333 | F89: 3 | G89: 10 | I89: COLE | J89: 76165549 | K89: BSWS | L89: SS POLO SHIRT WK BASIC LACOSE SOLID BSWS:RUSTIC ORANGE:L:SOLID:SS POLO SHIRT | M89: 169900 | N89: 0.9 | O89: =M89-(M89*N89) -> 16990 | P89: PERCENTAGE
A90: 2023 KI DISCONTINUE D90 | B90: ='KI DISCONTINUE D85'!$B$2 -> 46093 | C90: ='KI DISCONTINUE D85'!$C$2 -> 46098 | D90: 3259 | E90: 333 | F90: 3 | G90: 10 | I90: COLE | J90: 76165558 | K90: BSWS | L90: SS POLO SHIRT WK BASIC LACOSE SOLID BSWS:RUSTIC ORANGE:XL:SOLID:SS POLO SHIRT | M90: 169900 | N90: 0.9 | O90: =M90-(M90*N90) -> 16990 | P90: PERCENTAGE
A91: 2023 KI DISCONTINUE D90 | B91: ='KI DISCONTINUE D85'!$B$2 -> 46093 | C91: ='KI DISCONTINUE D85'!$C$2 -> 46098 | D91: 3259 | E91: 333 | F91: 3 | G91: 10 | I91: COLE | J91: 76165567 | K91: BSWS | L91: SS POLO SHIRT WK BASIC LACOSE SOLID BSWS:RUSTIC ORANGE:XXL:SOLID:SS POLO SHIRT | M91: 169900 | N91: 0.9 | O91: =M91-(M91*N91) -> 16990 | P91: PERCENTAGE
A92: 2023 KI DISCONTINUE D90 | B92: ='KI DISCONTINUE D85'!$B$2 -> 46093 | C92: ='KI DISCONTINUE D85'!$C$2 -> 46098 | D92: 3259 | E92: 333 | F92: 3 | G92: 10 | I92: COLE | J92: 76188524 | K92: BSWS | L92: SS POLO SHIRT WK BASIC LACOSE SOLID BSWS:MANDARIN ORANGE:S:SOLID:SS POLO SHIRT | M92: 169900 | N92: 0.9 | O92: =M92-(M92*N92) -> 16990 | P92: PERCENTAGE
A93: 2023 KI DISCONTINUE D90 | B93: ='KI DISCONTINUE D85'!$B$2 -> 46093 | C93: ='KI DISCONTINUE D85'!$C$2 -> 46098 | D93: 3259 | E93: 333 | F93: 3 | G93: 10 | I93: COLE | J93: 76188533 | K93: BSWS | L93: SS POLO SHIRT WK BASIC LACOSE SOLID BSWS:MANDARIN ORANGE:M:SOLID:SS POLO SHIRT | M93: 169900 | N93: 0.9 | O93: =M93-(M93*N93) -> 16990 | P93: PERCENTAGE
... A111: 2023 KI DISCONTINUE D90 | B111: ='KI DISCONTINUE D85'!$B$2 -> 46093 | C111: ='KI DISCONTINUE D85'!$C$2 -> 46098 | D111: 3259 | E111: 333 | F111: 3 | G111: 10 | I111: COLE | J111: 79669955 | K111: BSWS | L111: SS POLO SHIRT WK BASIC LACOSE SOLID BSWS:WOOD BROWN:XXL:SOLID:SS POLO SHIRT | M111: 169900 | N111: 0.9 | O111: =M111-(M111*N111) -> 16990 | P111: PERCENTAGE

Sheet 2023 ALL TOP D90
A1: ACARA | B1: FROM DATE | C1: TO DATE | D1: DEPT | E1: WORLD | F1: DIVISION | G1: CLASS | H1: SUPPLIER | I1: BRAND | J1: SKU | K1: ARTICLE | L1: DESCRIPTION | M1: HARGA NORMAL | N1: DISKON | O1: HARGA PROMO | P1: DISCOUNT TYPE
A2: 2023 ALL TOP D90 | B2: ='KI DISCONTINUE D85'!$B$2 -> 46093 | C2: ='KI DISCONTINUE D85'!$C$2 -> 46098 | D2: 3259 | E2: 333 | F2: 3 | G2: 1 | I2: COLE | J2: 79382906 | K2: TSLBS001 | L2: SS T-SHIRT IN PIQUE SOLID WITH WELT POCKET TSLBS001:NAVY BLUE:S:SOLID:SS T-SHIRT | M2: 199900 | N2: 0.9 | O2: =M2-(M2*N2) -> 19990 | P2: PERCENTAGE
A3: 2023 ALL TOP D90 | B3: ='KI DISCONTINUE D85'!$B$2 -> 46093 | C3: ='KI DISCONTINUE D85'!$C$2 -> 46098 | D3: 3259 | E3: 333 | F3: 3 | G3: 1 | I3: COLE | J3: 79382915 | K3: TSLBS001 | L3: SS T-SHIRT IN PIQUE SOLID WITH WELT POCKET TSLBS001:NAVY BLUE:M:SOLID:SS T-SHIRT | M3: 199900 | N3: 0.9 | O3: =M3-(M3*N3) -> 19990 | P3: PERCENTAGE
A4: 2023 ALL TOP D90 | B4: ='KI DISCONTINUE D85'!$B$2 -> 46093 | C4: ='KI DISCONTINUE D85'!$C$2 -> 46098 | D4: 3259 | E4: 333 | F4: 3 | G4: 1 | I4: COLE | J4: 79382924 | K4: TSLBS001 | L4: SS T-SHIRT IN PIQUE SOLID WITH WELT POCKET TSLBS001:NAVY BLUE:L:SOLID:SS T-SHIRT | M4: 199900 | N4: 0.9 | O4: =M4-(M4*N4) -> 19990 | P4: PERCENTAGE
A5: 2023 ALL TOP D90 | B5: ='KI DISCONTINUE D85'!$B$2 -> 46093 | C5: ='KI DISCONTINUE D85'!$C$2 -> 46098 | D5: 3259 | E5: 333 | F5: 3 | G5: 1 | I5: COLE | J5: 79382933 | K5: TSLBS001 | L5: SS T-SHIRT IN PIQUE SOLID WITH WELT POCKET TSLBS001:NAVY BLUE:XL:SOLID:SS T-SHIRT | M5: 199900 | N5: 0.9 | O5: =M5-(M5*N5) -> 19990 | P5: PERCENTAGE
A6: 2023 ALL TOP D90 | B6: ='KI DISCONTINUE D85'!$B$2 -> 46093 | C6: ='KI DISCONTINUE D85'!$C$2 -> 46098 | D6: 3259 | E6: 333 | F6: 3 | G6: 1 | I6: COLE | J6: 79382942 | K6: TSLBS001 | L6: SS T-SHIRT IN PIQUE SOLID WITH WELT POCKET TSLBS001:OLIVE:S:SOLID:SS T-SHIRT | M6: 199900 | N6: 0.9 | O6: =M6-(M6*N6) -> 19990 | P6: PERCENTAGE
A7: 2023 ALL TOP D90 | B7: ='KI DISCONTINUE D85'!$B$2 -> 46093 | C7: ='KI DISCONTINUE D85'!$C$2 -> 46098 | D7: 3259 | E7: 333 | F7: 3 | G7: 1 | I7: COLE | J7: 79382951 | K7: TSLBS001 | L7: SS T-SHIRT IN PIQUE SOLID WITH WELT POCKET TSLBS001:OLIVE:M:SOLID:SS T-SHIRT | M7: 199900 | N7: 0.9 | O7: =M7-(M7*N7) -> 19990 | P7: PERCENTAGE
A8: 2023 ALL TOP D90 | B8: ='KI DISCONTINUE D85'!$B$2 -> 46093 | C8: ='KI DISCONTINUE D85'!$C$2 -> 46098 | D8: 3259 | E8: 333 | F8: 3 | G8: 1 | I8: COLE | J8: 79382960 | K8: TSLBS001 | L8: SS T-SHIRT IN PIQUE SOLID WITH WELT POCKET TSLBS001:OLIVE:L:SOLID:SS T-SHIRT | M8: 199900 | N8: 0.9 | O8: =M8-(M8*N8) -> 19990 | P8: PERCENTAGE
A9: 2023 ALL TOP D90 | B9: ='KI DISCONTINUE D85'!$B$2 -> 46093 | C9: ='KI DISCONTINUE D85'!$C$2 -> 46098 | D9: 3259 | E9: 333 | F9: 3 | G9: 1 | I9: COLE | J9: 79382979 | K9: TSLBS001 | L9: SS T-SHIRT IN PIQUE SOLID WITH WELT POCKET TSLBS001:OLIVE:XL:SOLID:SS T-SHIRT | M9: 199900 | N9: 0.9 | O9: =M9-(M9*N9) -> 19990 | P9: PERCENTAGE
A10: 2023 ALL TOP D90 | B10: ='KI DISCONTINUE D85'!$B$2 -> 46093 | C10: ='KI DISCONTINUE D85'!$C$2 -> 46098 | D10: 3259 | E10: 333 | F10: 3 | G10: 1 | I10: COLE | J10: 79382988 | K10: TSLBS002 | L10: SS T-SHIRT HENLEY WITH POP CORN LOOK SOLID TSLBS002:MISTY DARK GREY:S:SOLID:SS T-SHIRT | M10: 199900 | N10: 0.9 | O10: =M10-(M10*N10) -> 19990 | P10: PERCENTAGE
A11: 2023 ALL TOP D90 | B11: ='KI DISCONTINUE D85'!$B$2 -> 46093 | C11: ='KI DISCONTINUE D85'!$C$2 -> 46098 | D11: 3259 | E11: 333 | F11: 3 | G11: 1 | I11: COLE | J11: 79382997 | K11: TSLBS002 | L11: SS T-SHIRT HENLEY WITH POP CORN LOOK SOLID TSLBS002:MISTY DARK GREY:M:SOLID:SS T-SHIRT | M11: 199900 | N11: 0.9 | O11: =M11-(M11*N11) -> 19990 | P11: PERCENTAGE
