Workbook

Sheet 2019 ALL BOTTOM D95
A1: ACARA | B1: FROM DATE | C1: TO DATE | D1: DEPT | E1: WORLD | F1: DIVISION | G1: CLASS | H1: SUPPLIER | I1: BRAND | J1: SKU | K1: ARTICLE | L1: DESCRIPTION | M1: HARGA NORMAL | N1: DISKON | O1: HARGA PROMO | P1: DISCOUNT TYPE
A2: 2019 & Older All Bottom D95 | B2: 46086 | C2: 46092 | D2: 3259 | E2: 333 | F2: 3 | G2: 5 | I2: COLE | J2: 17125952 | K2: 23492LDM | L2: CL SHORT 23492 L DNM | M2: 139900 | N2: 0.95 | O2: =M2-(M2*N2) -> 6995 | P2: PERCENTAGE
A3: 2019 & Older All Bottom D95 | B3: =B2 -> 46086 | C3: =C2 -> 46092 | D3: 3259 | E3: 333 | F3: 3 | G3: 5 | I3: COLE | J3: 17028521 | K3: CDR-02BC | L3: CL SHORT 22939 BLACK | M3: 139900 | N3: 0.95 | O3: =M3-(M3*N3) -> 6995 | P3: PERCENTAGE
A4: 2019 & Older All Bottom D95 | B4: =B3 -> 46086 | C4: =C3 -> 46092 | D4: 3259 | E4: 333 | F4: 3 | G4: 5 | I4: COLE | J4: 15705114 | K4: CL-5PCBC | L4: CL 5 POCKET BLACK | M4: 279900 | N4: 0.95 | O4: =M4-(M4*N4) -> 13995 | P4: PERCENTAGE
A5: 2019 & Older All Bottom D95 | B5: =B4 -> 46086 | C5: =C4 -> 46092 | D5: 3259 | E5: 333 | F5: 3 | G5: 5 | I5: COLE | J5: 15705123 | K5: CL-5PCKH | L5: CL 5 POCKET KHAKI | M5: 279900 | N5: 0.95 | O5: =M5-(M5*N5) -> 13995 | P5: PERCENTAGE
A6: 2019 & Older All Bottom D95 | B6: =B5 -> 46086 | C6: =C5 -> 46092 | D6: 3259 | E6: 333 | F6: 3 | G6: 5 | I6: COLE | J6: 19192493 | K6: DRW57-BR | L6: DRW57-OL DRW S/P R57 W.BROWN:WOOD BROWN:L | M6: 129900 | N6: 0.95 | O6: =M6-(M6*N6) -> 6495 | P6: PERCENTAGE
A7: 2019 & Older All Bottom D95 | B7: =B6 -> 46086 | C7: =C6 -> 46092 | D7: 3259 | E7: 333 | F7: 3 | G7: 5 | I7: COLE | J7: 19190691 | K7: DRW57-OL | L7: DRW57-OL DRW S/P R57 OLIVE:OLIVE:M | M7: 129900 | N7: 0.95 | O7: =M7-(M7*N7) -> 6495 | P7: PERCENTAGE
A8: 2019 & Older All Bottom D95 | B8: =B7 -> 46086 | C8: =C7 -> 46092 | D8: 3259 | E8: 333 | F8: 3 | G8: 5 | I8: COLE | J8: 19190708 | K8: DRW57-OL | L8: DRW57-OL DRW S/P R57 OLIVE:OLIVE:L | M8: 129900 | N8: 0.95 | O8: =M8-(M8*N8) -> 6495 | P8: PERCENTAGE
A9: 2019 & Older All Bottom D95 | B9: =B8 -> 46086 | C9: =C8 -> 46092 | D9: 3259 | E9: 333 | F9: 3 | G9: 5 | I9: COLE | J9: 19190717 | K9: DRW57-OL | L9: DRW57-OL DRW S/P R57 OLIVE:OLIVE:XL | M9: 129900 | N9: 0.95 | O9: =M9-(M9*N9) -> 6495 | P9: PERCENTAGE
A10: 2019 & Older All Bottom D95 | B10: =B9 -> 46086 | C10: =C9 -> 46092 | D10: 3259 | E10: 333 | F10: 3 | G10: 5 | I10: COLE | J10: 19190726 | K10: DRW57-OL | L10: DRW57-OL DRW S/P R57 OLIVE:OLIVE:2XL | M10: 129900 | N10: 0.95 | O10: =M10-(M10*N10) -> 6495 | P10: PERCENTAGE
A11: 2019 & Older All Bottom D95 | B11: =B10 -> 46086 | C11: =C10 -> 46092 | D11: 3259 | E11: 333 | F11: 3 | G11: 5 | I11: COLE | J11: 19093671 | K11: DRWCBMDB | L11: DRW S/P CHAMBRAY MISTY DARK BLUE:MISTY DARK BLUE:2XL | M11: 139900 | N11: 0.95 | O11: =M11-(M11*N11) -> 6995 | P11: PERCENTAGE
A12: 2019 & Older All Bottom D95 | B12: =B11 -> 46086 | C12: =C11 -> 46092 | D12: 3259 | E12: 333 | F12: 3 | G12: 5 | I12: COLE | J12: 15329978 | K12: KI-02BE | L12: KI CHINOS BIEGE | M12: 189900 | N12: 0.95 | O12: =M12-(M12*N12) -> 9495 | P12: PERCENTAGE
A13: 2019 & Older All Bottom D95 | B13: =B12 -> 46086 | C13: =C12 -> 46092 | D13: 3259 | E13: 333 | F13: 3 | G13: 5 | I13: COLE | J13: 16830398 | K13: LPCSLBE | L13: L/P CHINOS LIGHT BIEGE | M13: 279900 | N13: 0.95 | O13: =M13-(M13*N13) -> 13995 | P13: PERCENTAGE
A14: 2019 & Older All Bottom D95 | B14: =B13 -> 46086 | C14: =C13 -> 46092 | D14: 3259 | E14: 333 | F14: 3 | G14: 5 | I14: COLE | J14: 15524079 | K14: SLCSGKH | L14: LP SLIM CHINOS KHAKI | M14: 279900 | N14: 0.95 | O14: =M14-(M14*N14) -> 13995 | P14: PERCENTAGE
... A290: 2019 & Older All Bottom D95 | B290: =B289 -> 46086 | C290: =C289 -> 46092 | D290: 3259 | E290: 333 | F290: 3 | G290: 12 | I290: COLE | J290: 22278224 | K290: ESS-TRNNV | L290: ESSENTIAL TRAINING TERRY:NAVY BLUE:XL | M290: 229900 | N290: 0.95 | O290: =M290-(M290*N290) -> 11495 | P290: PERCENTAGE

Sheet 2020 ALL BOTTOM D90
A1: ACARA | B1: FROM DATE | C1: TO DATE | D1: DEPT | E1: WORLD | F1: DIVISION | G1: CLASS | H1: SUPPLIER | I1: BRAND | J1: SKU | K1: ARTICLE | L1: DESCRIPTION | M1: HARGA NORMAL | N1: DISKON | O1: HARGA PROMO | P1: DISCOUNT TYPE
A2: 2020 All Bottom (Exclude KI) D90 | B2: ='2019 ALL BOTTOM D95'!B2 -> 46086 | C2: ='2019 ALL BOTTOM D95'!C2 -> 46092 | D2: 3259 | E2: 333 | F2: 3 | G2: 5 | H2: 80300 | I2: COLE | J2: 26607003 | K2: 51S008 | L2: DENIM SHORT PANTS PULL ON 51S008:INDIGO BLUE:S:SOLID:DENIM SHORT PANT | M2: 229900 | N2: 0.9 | O2: =M2-(M2*N2) -> 22990 | P2: PERCENTAGE
A3: 2020 All Bottom (Exclude KI) D90 | B3: =B2 -> 46086 | C3: =C2 -> 46092 | D3: 3259 | E3: 333 | F3: 3 | G3: 5 | H3: 80300 | I3: COLE | J3: 26607012 | K3: 51S008 | L3: DENIM SHORT PANTS PULL ON 51S008:INDIGO BLUE:M:SOLID:DENIM SHORT PANT | M3: 229900 | N3: 0.9 | O3: =M3-(M3*N3) -> 22990 | P3: PERCENTAGE
A4: 2020 All Bottom (Exclude KI) D90 | B4: =B3 -> 46086 | C4: =C3 -> 46092 | D4: 3259 | E4: 333 | F4: 3 | G4: 5 | H4: 80300 | I4: COLE | J4: 26607021 | K4: 51S008 | L4: DENIM SHORT PANTS PULL ON 51S008:INDIGO BLUE:L:SOLID:DENIM SHORT PANT | M4: 229900 | N4: 0.9 | O4: =M4-(M4*N4) -> 22990 | P4: PERCENTAGE
A5: 2020 All Bottom (Exclude KI) D90 | B5: =B4 -> 46086 | C5: =C4 -> 46092 | D5: 3259 | E5: 333 | F5: 3 | G5: 5 | H5: 80300 | I5: COLE | J5: 26607030 | K5: 51S008 | L5: DENIM SHORT PANTS PULL ON 51S008:INDIGO BLUE:XL:SOLID:DENIM SHORT PANT | M5: 229900 | N5: 0.9 | O5: =M5-(M5*N5) -> 22990 | P5: PERCENTAGE
A6: 2020 All Bottom (Exclude KI) D90 | B6: =B5 -> 46086 | C6: =C5 -> 46092 | D6: 3259 | E6: 333 | F6: 3 | G6: 5 | H6: 80300 | I6: COLE | J6: 26607049 | K6: 51S008 | L6: DENIM SHORT PANTS PULL ON 51S008:MEDIUM DENIM:S:SOLID:DENIM SHORT PANT | M6: 229900 | N6: 0.9 | O6: =M6-(M6*N6) -> 22990 | P6: PERCENTAGE
A7: 2020 All Bottom (Exclude KI) D90 | B7: =B6 -> 46086 | C7: =C6 -> 46092 | D7: 3259 | E7: 333 | F7: 3 | G7: 5 | H7: 80300 | I7: COLE | J7: 26607058 | K7: 51S008 | L7: DENIM SHORT PANTS PULL ON 51S008:MEDIUM DENIM:M:SOLID:DENIM SHORT PANT | M7: 229900 | N7: 0.9 | O7: =M7-(M7*N7) -> 22990 | P7: PERCENTAGE
A8: 2020 All Bottom (Exclude KI) D90 | B8: =B7 -> 46086 | C8: =C7 -> 46092 | D8: 3259 | E8: 333 | F8: 3 | G8: 5 | H8: 80300 | I8: COLE | J8: 26607067 | K8: 51S008 | L8: DENIM SHORT PANTS PULL ON 51S008:MEDIUM DENIM:L:SOLID:DENIM SHORT PANT | M8: 229900 | N8: 0.9 | O8: =M8-(M8*N8) -> 22990 | P8: PERCENTAGE
A9: 2020 All Bottom (Exclude KI) D90 | B9: =B8 -> 46086 | C9: =C8 -> 46092 | D9: 3259 | E9: 333 | F9: 3 | G9: 5 | H9: 80300 | I9: COLE | J9: 26607076 | K9: 51S008 | L9: DENIM SHORT PANTS PULL ON 51S008:MEDIUM DENIM:XL:SOLID:DENIM SHORT PANT | M9: 229900 | N9: 0.9 | O9: =M9-(M9*N9) -> 22990 | P9: PERCENTAGE
A10: 2020 All Bottom (Exclude KI) D90 | B10: =B9 -> 46086 | C10: =C9 -> 46092 | D10: 3259 | E10: 333 | F10: 3 | G10: 5 | H10: 81517 | I10: COLE | J10: 20097209 | K10: DFSN-BLC | L10: SHORT DENIM FASH:BLACK:29 | M10: 269900 | N10: 0.9 | O10: =M10-(M10*N10) -> 26990 | P10: PERCENTAGE
A11: 2020 All Bottom (Exclude KI) D90 | B11: =B10 -> 46086 | C11: =C10 -> 46092 | D11: 3259 | E11: 333 | F11: 3 | G11: 5 | H11: 81517 | I11: COLE | J11: 20097218 | K11: DFSN-BLC | L11: SHORT DENIM FASH:BLACK:30 | M11: 269900 | N11: 0.9 | O11: =M11-(M11*N11) -> 26990 | P11: PERCENTAGE
A12: 2020 All Bottom (Exclude KI) D90 | B12: =B11 -> 46086 | C12: =C11 -> 46092 | D12: 3259 | E12: 333 | F12: 3 | G12: 5 | H12: 81517 | I12: COLE | J12: 20097227 | K12: DFSN-BLC | L12: SHORT DENIM FASH:BLACK:32 | M12: 269900 | N12: 0.9 | O12: =M12-(M12*N12) -> 26990 | P12: PERCENTAGE
A13: 2020 All Bottom (Exclude KI) D90 | B13: =B12 -> 46086 | C13: =C12 -> 46092 | D13: 3259 | E13: 333 | F13: 3 | G13: 5 | H13: 81517 | I13: COLE | J13: 20097236 | K13: DFSN-BLC | L13: SHORT DENIM FASH:BLACK:34 | M13: 269900 | N13: 0.9 | O13: =M13-(M13*N13) -> 26990 | P13: PERCENTAGE
A14: 2020 All Bottom (Exclude KI) D90 | B14: =B13 -> 46086 | C14: =C13 -> 46092 | D14: 3259 | E14: 333 | F14: 3 | G14: 5 | H14: 81517 | I14: COLE | J14: 20097245 | K14: DFSN-BLC | L14: SHORT DENIM FASH:BLACK:36 | M14: 269900 | N14: 0.9 | O14: =M14-(M14*N14) -> 26990 | P14: PERCENTAGE
... A588: 2020 All Bottom (Exclude KI) D90 | B588: =B587 -> 46086 | C588: =C587 -> 46092 | D588: 3259 | E588: 333 | F588: 3 | G588: 12 | H588: 81679 | I588: COLE | J588: 26594054 | K588: ESS-TRN | L588: LONG PANTS TERRY ESS-TRN:OLIVE:XL:SOLID:LONG PANTS | M588: 199900 | N588: 0.9 | O588: =M588-(M588*N588) -> 19990 | P588: PERCENTAGE

Sheet 2021 ALL BOTTOM D90
A1: ACARA | B1: FROM DATE | C1: TO DATE | D1: DEPT | E1: WORLD | F1: DIVISION | G1: CLASS | H1: SUPPLIER | I1: BRAND | J1: SKU | K1: ARTICLE | L1: DESCRIPTION | M1: HARGA NORMAL | N1: DISKON | O1: HARGA PROMO | P1: DISCOUNT TYPE
A2: 2021 All Bottom (Exclude KI) D90 | B2: ='2019 ALL BOTTOM D95'!B2 -> 46086 | C2: ='2019 ALL BOTTOM D95'!C2 -> 46092 | D2: 3259 | E2: 333 | F2: 3 | G2: 7 | H2: 81515 | I2: COLE | J2: 33471575 | K2: JGPKOMB | L2: JOGGER KNIT KOMBINASI PRINT COLE JGPKOMB:COBALT BLUE:S:TEXT:JOGGER | M2: 229900 | N2: 0.9 | O2: =M2-(M2*N2) -> 22990 | P2: PERCENTAGE
A3: 2021 All Bottom (Exclude KI) D90 | B3: =B2 -> 46086 | C3: =C2 -> 46092 | D3: 3259 | E3: 333 | F3: 3 | G3: 7 | H3: 81515 | I3: COLE | J3: 33471584 | K3: JGPKOMB | L3: JOGGER KNIT KOMBINASI PRINT COLE JGPKOMB:COBALT BLUE:M:TEXT:JOGGER | M3: 229900 | N3: 0.9 | O3: =M3-(M3*N3) -> 22990 | P3: PERCENTAGE
A4: 2021 All Bottom (Exclude KI) D90 | B4: =B3 -> 46086 | C4: =C3 -> 46092 | D4: 3259 | E4: 333 | F4: 3 | G4: 7 | H4: 81515 | I4: COLE | J4: 33471593 | K4: JGPKOMB | L4: JOGGER KNIT KOMBINASI PRINT COLE JGPKOMB:COBALT BLUE:L:TEXT:JOGGER | M4: 229900 | N4: 0.9 | O4: =M4-(M4*N4) -> 22990 | P4: PERCENTAGE
A5: 2021 All Bottom (Exclude KI) D90 | B5: =B4 -> 46086 | C5: =C4 -> 46092 | D5: 3259 | E5: 333 | F5: 3 | G5: 7 | H5: 81515 | I5: COLE | J5: 33471600 | K5: JGPKOMB | L5: JOGGER KNIT KOMBINASI PRINT COLE JGPKOMB:COBALT BLUE:XL:TEXT:JOGGER | M5: 229900 | N5: 0.9 | O5: =M5-(M5*N5) -> 22990 | P5: PERCENTAGE
A6: 2021 All Bottom (Exclude KI) D90 | B6: =B5 -> 46086 | C6: =C5 -> 46092 | D6: 3259 | E6: 333 | F6: 3 | G6: 7 | H6: 81515 | I6: COLE | J6: 33471619 | K6: JGPKOMB | L6: JOGGER KNIT KOMBINASI PRINT COLE JGPKOMB:MISTY MEDIUM G:S:TEXT:JOGGER | M6: 229900 | N6: 0.9 | O6: =M6-(M6*N6) -> 22990 | P6: PERCENTAGE
A7: 2021 All Bottom (Exclude KI) D90 | B7: =B6 -> 46086 | C7: =C6 -> 46092 | D7: 3259 | E7: 333 | F7: 3 | G7: 7 | H7: 81515 | I7: COLE | J7: 33471628 | K7: JGPKOMB | L7: JOGGER KNIT KOMBINASI PRINT COLE JGPKOMB:MISTY MEDIUM G:M:TEXT:JOGGER | M7: 229900 | N7: 0.9 | O7: =M7-(M7*N7) -> 22990 | P7: PERCENTAGE
A8: 2021 All Bottom (Exclude KI) D90 | B8: =B7 -> 46086 | C8: =C7 -> 46092 | D8: 3259 | E8: 333 | F8: 3 | G8: 7 | H8: 81515 | I8: COLE | J8: 33471637 | K8: JGPKOMB | L8: JOGGER KNIT KOMBINASI PRINT COLE JGPKOMB:MISTY MEDIUM G:L:TEXT:JOGGER | M8: 229900 | N8: 0.9 | O8: =M8-(M8*N8) -> 22990 | P8: PERCENTAGE
A9: 2021 All Bottom (Exclude KI) D90 | B9: =B8 -> 46086 | C9: =C8 -> 46092 | D9: 3259 | E9: 333 | F9: 3 | G9: 7 | H9: 81515 | I9: COLE | J9: 33471646 | K9: JGPKOMB | L9: JOGGER KNIT KOMBINASI PRINT COLE JGPKOMB:MISTY MEDIUM G:XL:TEXT:JOGGER | M9: 229900 | N9: 0.9 | O9: =M9-(M9*N9) -> 22990 | P9: PERCENTAGE
A10: 2021 All Bottom (Exclude KI) D90 | B10: =B9 -> 46086 | C10: =C9 -> 46092 | D10: 3259 | E10: 333 | F10: 3 | G10: 7 | H10: 81679 | I10: COLE | J10: 43647616 | K10: SKJBASC | L10: SHORT PANTS KNIT JERSEY BASIC SOLID SKJBASC:BLACK:S:SOLID:SHORT PANTS | M10: 169900 | N10: 0.9 | O10: =M10-(M10*N10) -> 16990 | P10: PERCENTAGE
A11: 2021 All Bottom (Exclude KI) D90 | B11: =B10 -> 46086 | C11: =C10 -> 46092 | D11: 3259 | E11: 333 | F11: 3 | G11: 7 | H11: 81679 | I11: COLE | J11: 43647625 | K11: SKJBASC | L11: SHORT PANTS KNIT JERSEY BASIC SOLID SKJBASC:BLACK:M:SOLID:SHORT PANTS | M11: 169900 | N11: 0.9 | O11: =M11-(M11*N11) -> 16990 | P11: PERCENTAGE
A12: 2021 All Bottom (Exclude KI) D90 | B12: =B11 -> 46086 | C12: =C11 -> 46092 | D12: 3259 | E12: 333 | F12: 3 | G12: 7 | H12: 81679 | I12: COLE | J12: 43647634 | K12: SKJBASC | L12: SHORT PANTS KNIT JERSEY BASIC SOLID SKJBASC:BLACK:L:SOLID:SHORT PANTS | M12: 169900 | N12: 0.9 | O12: =M12-(M12*N12) -> 16990 | P12: PERCENTAGE
A13: 2021 All Bottom (Exclude KI) D90 | B13: =B12 -> 46086 | C13: =C12 -> 46092 | D13: 3259 | E13: 333 | F13: 3 | G13: 7 | H13: 81679 | I13: COLE | J13: 43647643 | K13: SKJBASC | L13: SHORT PANTS KNIT JERSEY BASIC SOLID SKJBASC:BLACK:XL:SOLID:SHORT PANTS | M13: 169900 | N13: 0.9 | O13: =M13-(M13*N13) -> 16990 | P13: PERCENTAGE
A14: 2021 All Bottom (Exclude KI) D90 | B14: =B13 -> 46086 | C14: =C13 -> 46092 | D14: 3259 | E14: 333 | F14: 3 | G14: 7 | H14: 81679 | I14: COLE | J14: 43647652 | K14: SKJBASC | L14: SHORT PANTS KNIT JERSEY BASIC SOLID SKJBASC:INDIGO BLUE:S:SOLID:SHORT PANTS | M14: 169900 | N14: 0.9 | O14: =M14-(M14*N14) -> 16990 | P14: PERCENTAGE
... A624: 2021 All Bottom (Exclude KI) D90 | B624: =B623 -> 46086 | C624: =C623 -> 46092 | D624: 3259 | E624: 333 | F624: 3 | G624: 6 | H624: 81517 | I624: COLE | J624: 32630305 | K624: SPPGEOS | L624: SHORT PANTS WOVEN PULL ON PRINT GEOMETRI SQR SPPGEOS:OLIVE:XL:PRINT:SHORT PANTS | M624: 229900 | N624: 0.9 | O624: =M624-(M624*N624) -> 22990 | P624: PERCENTAGE

Sheet 2022 ALL BOTTOM D90
A1: ACARA | B1: FROM DATE | C1: TO DATE | D1: DEPT | E1: WORLD | F1: DIVISION | G1: CLASS | H1: SUPPLIER | I1: BRAND | J1: SKU | K1: ARTICLE | L1: DESCRIPTION | M1: HARGA NORMAL | N1: DISKON | O1: HARGA PROMO | P1: DISCOUNT TYPE
A2: 2022 All Bottom (Exc KI/RO Continue) D90 | B2: ='2019 ALL BOTTOM D95'!B2 -> 46086 | C2: ='2019 ALL BOTTOM D95'!C2 -> 46092 | D2: 3259 | E2: 333 | F2: 3 | G2: 5 | I2: COLE | J2: 26643572 | K2: 52SOL | L2: DENIM LONG PANTS SOLAR 52SOL:INDIGO BLUE:29:SOLID:DENIM LONG PANTS | M2: 329900 | N2: 0.9 | O2: =M2-(M2*N2) -> 32990 | P2: PERCENTAGE
A3: 2022 All Bottom (Exc KI/RO Continue) D90 | B3: =B2 -> 46086 | C3: =C2 -> 46092 | D3: 3259 | E3: 333 | F3: 3 | G3: 5 | I3: COLE | J3: 26643581 | K3: 52SOL | L3: DENIM LONG PANTS SOLAR 52SOL:INDIGO BLUE:30:SOLID:DENIM LONG PANTS | M3: 329900 | N3: 0.9 | O3: =M3-(M3*N3) -> 32990 | P3: PERCENTAGE
A4: 2022 All Bottom (Exc KI/RO Continue) D90 | B4: =B3 -> 46086 | C4: =C3 -> 46092 | D4: 3259 | E4: 333 | F4: 3 | G4: 5 | I4: COLE | J4: 26643590 | K4: 52SOL | L4: DENIM LONG PANTS SOLAR 52SOL:INDIGO BLUE:32:SOLID:DENIM LONG PANTS | M4: 329900 | N4: 0.9 | O4: =M4-(M4*N4) -> 32990 | P4: PERCENTAGE
A5: 2022 All Bottom (Exc KI/RO Continue) D90 | B5: =B4 -> 46086 | C5: =C4 -> 46092 | D5: 3259 | E5: 333 | F5: 3 | G5: 5 | I5: COLE | J5: 26643607 | K5: 52SOL | L5: DENIM LONG PANTS SOLAR 52SOL:INDIGO BLUE:34:SOLID:DENIM LONG PANTS | M5: 329900 | N5: 0.9 | O5: =M5-(M5*N5) -> 32990 | P5: PERCENTAGE
A6: 2022 All Bottom (Exc KI/RO Continue) D90 | B6: =B5 -> 46086 | C6: =C5 -> 46092 | D6: 3259 | E6: 333 | F6: 3 | G6: 5 | I6: COLE | J6: 26643616 | K6: 52SOL | L6: DENIM LONG PANTS SOLAR 52SOL:INDIGO BLUE:36:SOLID:DENIM LONG PANTS | M6: 329900 | N6: 0.9 | O6: =M6-(M6*N6) -> 32990 | P6: PERCENTAGE
A7: 2022 All Bottom (Exc KI/RO Continue) D90 | B7: =B6 -> 46086 | C7: =C6 -> 46092 | D7: 3259 | E7: 333 | F7: 3 | G7: 5 | I7: COLE | J7: 26643625 | K7: 52SOL | L7: DENIM LONG PANTS SOLAR 52SOL:INDIGO BLUE:38:SOLID:DENIM LONG PANTS | M7: 329900 | N7: 0.9 | O7: =M7-(M7*N7) -> 32990 | P7: PERCENTAGE
A8: 2022 All Bottom (Exc KI/RO Continue) D90 | B8: =B7 -> 46086 | C8: =C7 -> 46092 | D8: 3259 | E8: 333 | F8: 3 | G8: 5 | I8: COLE | J8: 26643634 | K8: 52SOL | L8: DENIM LONG PANTS SOLAR 52SOL:INDIGO BLUE:40:SOLID:DENIM LONG PANTS | M8: 329900 | N8: 0.9 | O8: =M8-(M8*N8) -> 32990 | P8: PERCENTAGE
A9: 2022 All Bottom (Exc KI/RO Continue) D90 | B9: =B8 -> 46086 | C9: =C8 -> 46092 | D9: 3259 | E9: 333 | F9: 3 | G9: 5 | I9: COLE | J9: 26643643 | K9: 52SOL | L9: DENIM LONG PANTS SOLAR 52SOL:MEDIUM DENIM:29:SOLID:DENIM LONG PANTS | M9: 329900 | N9: 0.9 | O9: =M9-(M9*N9) -> 32990 | P9: PERCENTAGE
A10: 2022 All Bottom (Exc KI/RO Continue) D90 | B10: =B9 -> 46086 | C10: =C9 -> 46092 | D10: 3259 | E10: 333 | F10: 3 | G10: 5 | I10: COLE | J10: 26643652 | K10: 52SOL | L10: DENIM LONG PANTS SOLAR 52SOL:MEDIUM DENIM:30:SOLID:DENIM LONG PANTS | M10: 329900 | N10: 0.9 | O10: =M10-(M10*N10) -> 32990 | P10: PERCENTAGE
A11: 2022 All Bottom (Exc KI/RO Continue) D90 | B11: =B10 -> 46086 | C11: =C10 -> 46092 | D11: 3259 | E11: 333 | F11: 3 | G11: 5 | I11: COLE | J11: 26643661 | K11: 52SOL | L11: DENIM LONG PANTS SOLAR 52SOL:MEDIUM DENIM:32:SOLID:DENIM LONG PANTS | M11: 329900 | N11: 0.9 | O11: =M11-(M11*N11) -> 32990 | P11: PERCENTAGE
A12: 2022 All Bottom (Exc KI/RO Continue) D90 | B12: =B11 -> 46086 | C12: =C11 -> 46092 | D12: 3259 | E12: 333 | F12: 3 | G12: 5 | I12: COLE | J12: 26643670 | K12: 52SOL | L12: DENIM LONG PANTS SOLAR 52SOL:MEDIUM DENIM:34:SOLID:DENIM LONG PANTS | M12: 329900 | N12: 0.9 | O12: =M12-(M12*N12) -> 32990 | P12: PERCENTAGE
A13: 2022 All Bottom (Exc KI/RO Continue) D90 | B13: =B12 -> 46086 | C13: =C12 -> 46092 | D13: 3259 | E13: 333 | F13: 3 | G13: 5 | I13: COLE | J13: 26643689 | K13: 52SOL | L13: DENIM LONG PANTS SOLAR 52SOL:MEDIUM DENIM:36:SOLID:DENIM LONG PANTS | M13: 329900 | N13: 0.9 | O13: =M13-(M13*N13) -> 32990 | P13: PERCENTAGE
A14: 2022 All Bottom (Exc KI/RO Continue) D90 | B14: =B13 -> 46086 | C14: =C13 -> 46092 | D14: 3259 | E14: 333 | F14: 3 | G14: 5 | I14: COLE | J14: 26643698 | K14: 52SOL | L14: DENIM LONG PANTS SOLAR 52SOL:MEDIUM DENIM:38:SOLID:DENIM LONG PANTS | M14: 329900 | N14: 0.9 | O14: =M14-(M14*N14) -> 32990 | P14: PERCENTAGE
... A29: 2022 All Bottom (Exc KI/RO Continue) D90 | B29: =B28 -> 46086 | C29: =C28 -> 46092 | D29: 3259 | E29: 333 | F29: 3 | G29: 5 | I29: COLE | J29: 26893516 | K29: G2592 | L29: DENIM LONG PANTS LANCELOT G2592:DARK DENIM:40:SOLID:DENIM LONG PANTS | M29: 329900 | N29: 0.9 | O29: =M29-(M29*N29) -> 32990 | P29: PERCENTAGE
A30: 2022 All Bottom (Exc KI/RO Continue) D90 | B30: =B29 -> 46086 | C30: =C29 -> 46092 | D30: 3259 | E30: 333 | F30: 3 | G30: 5 | H30: 80300 | I30: COLE | J30: 28356290 | K30: G2728 | L30: DENIM LONG PANTS DARK DENIM G2728:DARK DENIM:29:OMBRE:DENIM LONG PANTS | M30: 329900 | N30: 0.9 | O30: =M30-(M30*N30) -> 32990 | P30: PERCENTAGE
A31: 2022 All Bottom (Exc KI/RO Continue) D90 | B31: =B30 -> 46086 | C31: =C30 -> 46092 | D31: 3259 | E31: 333 | F31: 3 | G31: 5 | H31: 80300 | I31: COLE | J31: 28356307 | K31: G2728 | L31: DENIM LONG PANTS DARK DENIM G2728:DARK DENIM:30:OMBRE:DENIM LONG PANTS | M31: 329900 | N31: 0.9 | O31: =M31-(M31*N31) -> 32990 | P31: PERCENTAGE
A32: 2022 All Bottom (Exc KI/RO Continue) D90 | B32: =B31 -> 46086 | C32: =C31 -> 46092 | D32: 3259 | E32: 333 | F32: 3 | G32: 5 | H32: 80300 | I32: COLE | J32: 28356316 | K32: G2728 | L32: DENIM LONG PANTS DARK DENIM G2728:DARK DENIM:32:OMBRE:DENIM LONG PANTS | M32: 329900 | N32: 0.9 | O32: =M32-(M32*N32) -> 32990 | P32: PERCENTAGE
A33: 2022 All Bottom (Exc KI/RO Continue) D90 | B33: =B32 -> 46086 | C33: =C32 -> 46092 | D33: 3259 | E33: 333 | F33: 3 | G33: 5 | H33: 80300 | I33: COLE | J33: 28356325 | K33: G2728 | L33: DENIM LONG PANTS DARK DENIM G2728:DARK DENIM:34:OMBRE:DENIM LONG PANTS | M33: 329900 | N33: 0.9 | O33: =M33-(M33*N33) -> 32990 | P33: PERCENTAGE
A34: 2022 All Bottom (Exc KI/RO Continue) D90 | B34: =B33 -> 46086 | C34: =C33 -> 46092 | D34: 3259 | E34: 333 | F34: 3 | G34: 5 | H34: 80300 | I34: COLE | J34: 28356334 | K34: G2728 | L34: DENIM LONG PANTS DARK DENIM G2728:DARK DENIM:36:OMBRE:DENIM LONG PANTS | M34: 329900 | N34: 0.9 | O34: =M34-(M34*N34) -> 32990 | P34: PERCENTAGE
A35: 2022 All Bottom (Exc KI/RO Continue) D90 | B35: =B34 -> 46086 | C35: =C34 -> 46092 | D35: 3259 | E35: 333 | F35: 3 | G35: 5 | H35: 80300 | I35: COLE | J35: 28356343 | K35: G2728 | L35: DENIM LONG PANTS DARK DENIM G2728:DARK DENIM:38:OMBRE:DENIM LONG PANTS | M35: 329900 | N35: 0.9 | O35: =M35-(M35*N35) -> 32990 | P35: PERCENTAGE
A36: 2022 All Bottom (Exc KI/RO Continue) D90 | B36: =B35 -> 46086 | C36: =C35 -> 46092 | D36: 3259 | E36: 333 | F36: 3 | G36: 5 | H36: 80300 | I36: COLE | J36: 28356352 | K36: G2728 | L36: DENIM LONG PANTS DARK DENIM G2728:DARK DENIM:40:OMBRE:DENIM LONG PANTS | M36: 329900 | N36: 0.9 | O36: =M36-(M36*N36) -> 32990 | P36: PERCENTAGE
A37: 2022 All Bottom (Exc KI/RO Continue) D90 | B37: =B36 -> 46086 | C37: =C36 -> 46092 | D37: 3259 | E37: 333 | F37: 3 | G37: 5 | H37: 80300 | I37: COLE | J37: 28356156 | K37: G2728 | L37: DENIM LONG PANTS INDIGO BLUE G2728:INDIGO BLUE:29:OMBRE:DENIM LONG PANTS | M37: 329900 | N37: 0.9 | O37: =M37-(M37*N37) -> 32990 | P37: PERCENTAGE
A38: 2022 All Bottom (Exc KI/RO Continue) D90 | B38: =B37 -> 46086 | C38: =C37 -> 46092 | D38: 3259 | E38: 333 | F38: 3 | G38: 5 | H38: 80300 | I38: COLE | J38: 28356165 | K38: G2728 | L38: DENIM LONG PANTS INDIGO BLUE G2728:INDIGO BLUE:30:OMBRE:DENIM LONG PANTS | M38: 329900 | N38: 0.9 | O38: =M38-(M38*N38) -> 32990 | P38: PERCENTAGE
A39: 2022 All Bottom (Exc KI/RO Continue) D90 | B39: =B38 -> 46086 | C39: =C38 -> 46092 | D39: 3259 | E39: 333 | F39: 3 | G39: 5 | H39: 80300 | I39: COLE | J39: 28356174 | K39: G2728 | L39: DENIM LONG PANTS INDIGO BLUE G2728:INDIGO BLUE:32:OMBRE:DENIM LONG PANTS | M39: 329900 | N39: 0.9 | O39: =M39-(M39*N39) -> 32990 | P39: PERCENTAGE
A40: 2022 All Bottom (Exc KI/RO Continue) D90 | B40: =B39 -> 46086 | C40: =C39 -> 46092 | D40: 3259 | E40: 333 | F40: 3 | G40: 5 | H40: 80300 | I40: COLE | J40: 28356183 | K40: G2728 | L40: DENIM LONG PANTS INDIGO BLUE G2728:INDIGO BLUE:34:OMBRE:DENIM LONG PANTS | M40: 329900 | N40: 0.9 | O40: =M40-(M40*N40) -> 32990 | P40: PERCENTAGE
A41: 2022 All Bottom (Exc KI/RO Continue) D90 | B41: =B40 -> 46086 | C41: =C40 -> 46092 | D41: 3259 | E41: 333 | F41: 3 | G41: 5 | H41: 80300 | I41: COLE | J41: 28356192 | K41: G2728 | L41: DENIM LONG PANTS INDIGO BLUE G2728:INDIGO BLUE:36:OMBRE:DENIM LONG PANTS | M41: 329900 | N41: 0.9 | O41: =M41-(M41*N41) -> 32990 | P41: PERCENTAGE
... A43: 2022 All Bottom (Exc KI/RO Continue) D90 | B43: =B42 -> 46086 | C43: =C42 -> 46092 | D43: 3259 | E43: 333 | F43: 3 | G43: 5 | H43: 80300 | I43: COLE | J43: 28356218 | K43: G2728 | L43: DENIM LONG PANTS INDIGO BLUEG2728:INDIGO BLUE:40:OMBRE:DENIM LONG PANTS | M43: 329900 | N43: 0.9 | O43: =M43-(M43*N43) -> 32990 | P43: PERCENTAGE
A44: 2022 All Bottom (Exc KI/RO Continue) D90 | B44: =B43 -> 46086 | C44: =C43 -> 46092 | D44: 3259 | E44: 333 | F44: 3 | G44: 5 | I44: COLE | J44: 29555368 | K44: LDRFW | L44: DENIM LONG PANTS REGULAR FASHION WHISKER PATT 1 LDRFW:DARK DENIM:29:SOLID:DENIM LONG | M44: 379900 | N44: 0.9 | O44: =M44-(M44*N44) -> 37990 | P44: PERCENTAGE
A45: 2022 All Bottom (Exc KI/RO Continue) D90 | B45: =B44 -> 46086 | C45: =C44 -> 46092 | D45: 3259 | E45: 333 | F45: 3 | G45: 5 | I45: COLE | J45: 29555377 | K45: LDRFW | L45: DENIM LONG PANTS REGULAR FASHION WHISKER PATT 1 LDRFW:DARK DENIM:30:SOLID:DENIM LONG | M45: 379900 | N45: 0.9 | O45: =M45-(M45*N45) -> 37990 | P45: PERCENTAGE
A46: 2022 All Bottom (Exc KI/RO Continue) D90 | B46: =B45 -> 46086 | C46: =C45 -> 46092 | D46: 3259 | E46: 333 | F46: 3 | G46: 5 | I46: COLE | J46: 29555386 | K46: LDRFW | L46: DENIM LONG PANTS REGULAR FASHION WHISKER PATT 1 LDRFW:DARK DENIM:32:SOLID:DENIM LONG | M46: 379900 | N46: 0.9 | O46: =M46-(M46*N46) -> 37990 | P46: PERCENTAGE
A47: 2022 All Bottom (Exc KI/RO Continue) D90 | B47: =B46 -> 46086 | C47: =C46 -> 46092 | D47: 3259 | E47: 333 | F47: 3 | G47: 5 | I47: COLE | J47: 29555395 | K47: LDRFW | L47: DENIM LONG PANTS REGULAR FASHION WHISKER PATT 1 LDRFW:DARK DENIM:34:SOLID:DENIM LONG | M47: 379900 | N47: 0.9 | O47: =M47-(M47*N47) -> 37990 | P47: PERCENTAGE
A48: 2022 All Bottom (Exc KI/RO Continue) D90 | B48: =B47 -> 46086 | C48: =C47 -> 46092 | D48: 3259 | E48: 333 | F48: 3 | G48: 5 | I48: COLE | J48: 29555402 | K48: LDRFW | L48: DENIM LONG PANTS REGULAR FASHION WHISKER PATT 1 LDRFW:DARK DENIM:36:SOLID:DENIM LONG | M48: 379900 | N48: 0.9 | O48: =M48-(M48*N48) -> 37990 | P48: PERCENTAGE
A49: 2022 All Bottom (Exc KI/RO Continue) D90 | B49: =B48 -> 46086 | C49: =C48 -> 46092 | D49: 3259 | E49: 333 | F49: 3 | G49: 5 | I49: COLE | J49: 29555411 | K49: LDRFW | L49: DENIM LONG PANTS REGULAR FASHION WHISKER PATT 1 LDRFW:DARK DENIM:38:SOLID:DENIM LONG | M49: 379900 | N49: 0.9 | O49: =M49-(M49*N49) -> 37990 | P49: PERCENTAGE
A50: 2022 All Bottom (Exc KI/RO Continue) D90 | B50: =B49 -> 46086 | C50: =C49 -> 46092 | D50: 3259 | E50: 333 | F50: 3 | G50: 5 | I50: COLE | J50: 29555420 | K50: LDRFW | L50: DENIM LONG PANTS REGULAR FASHION WHISKER PATT 1 LDRFW:DARK DENIM:40:SOLID:DENIM LONG | M50: 379900 | N50: 0.9 | O50: =M50-(M50*N50) -> 37990 | P50: PERCENTAGE
A51: 2022 All Bottom (Exc KI/RO Continue) D90 | B51: =B50 -> 46086 | C51: =C50 -> 46092 | D51: 3259 | E51: 333 | F51: 3 | G51: 5 | I51: COLE | J51: 60635534 | K51: LDRFW | L51: DENIM LONG PANTS REGULAR FASHION WHISKER PATT 1 LDRFW:BLACK:29:SOLID:DENIM LONG | M51: 379900 | N51: 0.9 | O51: =M51-(M51*N51) -> 37990 | P51: PERCENTAGE
A52: 2022 All Bottom (Exc KI/RO Continue) D90 | B52: =B51 -> 46086 | C52: =C51 -> 46092 | D52: 3259 | E52: 333 | F52: 3 | G52: 5 | I52: COLE | J52: 60635543 | K52: LDRFW | L52: DENIM LONG PANTS REGULAR FASHION WHISKER PATT 1 LDRFW:BLACK:30:SOLID:DENIM LONG | M52: 379900 | N52: 0.9 | O52: =M52-(M52*N52) -> 37990 | P52: PERCENTAGE
A53: 2022 All Bottom (Exc KI/RO Continue) D90 | B53: =B52 -> 46086 | C53: =C52 -> 46092 | D53: 3259 | E53: 333 | F53: 3 | G53: 5 | I53: COLE | J53: 60635552 | K53: LDRFW | L53: DENIM LONG PANTS REGULAR FASHION WHISKER PATT 1 LDRFW:BLACK:32:SOLID:DENIM LONG | M53: 379900 | N53: 0.9 | O53: =M53-(M53*N53) -> 37990 | P53: PERCENTAGE
A54: 2022 All Bottom (Exc KI/RO Continue) D90 | B54: =B53 -> 46086 | C54: =C53 -> 46092 | D54: 3259 | E54: 333 | F54: 3 | G54: 5 | I54: COLE | J54: 60635561 | K54: LDRFW | L54: DENIM LONG PANTS REGULAR FASHION WHISKER PATT 1 LDRFW:BLACK:34:SOLID:DENIM LONG | M54: 379900 | N54: 0.9 | O54: =M54-(M54*N54) -> 37990 | P54: PERCENTAGE
A55: 2022 All Bottom (Exc KI/RO Continue) D90 | B55: =B54 -> 46086 | C55: =C54 -> 46092 | D55: 3259 | E55: 333 | F55: 3 | G55: 5 | I55: COLE | J55: 60635570 | K55: LDRFW | L55: DENIM LONG PANTS REGULAR FASHION WHISKER PATT 1 LDRFW:BLACK:36:SOLID:DENIM LONG | M55: 379900 | N55: 0.9 | O55: =M55-(M55*N55) -> 37990 | P55: PERCENTAGE
...

Sheet 2023 ALL BOTTOM D90
A1: ACARA | B1: FROM DATE | C1: TO DATE | D1: DEPT | E1: WORLD | F1: DIVISION | G1: CLASS | H1: SUPPLIER | I1: BRAND | J1: SKU | K1: ARTICLE | L1: DESCRIPTION | M1: HARGA NORMAL | N1: DISKON | O1: HARGA PROMO | P1: DISCOUNT TYPE
A2: 2023 ALL (INCLUDE KI & RO) D90 | B2: ='2019 ALL BOTTOM D95'!B2 -> 46086 | C2: ='2019 ALL BOTTOM D95'!C2 -> 46092 | D2: 3259 | E2: 333 | F2: 3 | G2: 5 | H2: 81406 | I2: COLE | J2: 79137252 | K2: PDCOLBK | L2: DENIM LONG PANTS REGULAR 5 POCKET PDCOLBK:BLACK:30:SOLID:DENIM LONG PANTS | M2: 399900 | N2: 0.9 | O2: =M2-(M2*N2) -> 39990 | P2: PERCENTAGE
A3: 2023 ALL (INCLUDE KI & RO) D90 | B3: =B2 -> 46086 | C3: =C2 -> 46092 | D3: 3259 | E3: 333 | F3: 3 | G3: 5 | H3: 81406 | I3: COLE | J3: 79137261 | K3: PDCOLBK | L3: DENIM LONG PANTS REGULAR 5 POCKET PDCOLBK:BLACK:32:SOLID:DENIM LONG PANTS | M3: 399900 | N3: 0.9 | O3: =M3-(M3*N3) -> 39990 | P3: PERCENTAGE
A4: 2023 ALL (INCLUDE KI & RO) D90 | B4: =B3 -> 46086 | C4: =C3 -> 46092 | D4: 3259 | E4: 333 | F4: 3 | G4: 5 | H4: 81406 | I4: COLE | J4: 79137270 | K4: PDCOLBK | L4: DENIM LONG PANTS REGULAR 5 POCKET PDCOLBK:BLACK:34:SOLID:DENIM LONG PANTS | M4: 399900 | N4: 0.9 | O4: =M4-(M4*N4) -> 39990 | P4: PERCENTAGE
A5: 2023 ALL (INCLUDE KI & RO) D90 | B5: =B4 -> 46086 | C5: =C4 -> 46092 | D5: 3259 | E5: 333 | F5: 3 | G5: 5 | H5: 81406 | I5: COLE | J5: 79137289 | K5: PDCOLBK | L5: DENIM LONG PANTS REGULAR 5 POCKET PDCOLBK:BLACK:36:SOLID:DENIM LONG PANTS | M5: 399900 | N5: 0.9 | O5: =M5-(M5*N5) -> 39990 | P5: PERCENTAGE
A6: 2023 ALL (INCLUDE KI & RO) D90 | B6: =B5 -> 46086 | C6: =C5 -> 46092 | D6: 3259 | E6: 333 | F6: 3 | G6: 5 | H6: 81406 | I6: COLE | J6: 79137298 | K6: PDCOLBK | L6: DENIM LONG PANTS REGULAR 5 POCKET PDCOLBK:BLACK:38:SOLID:DENIM LONG PANTS | M6: 399900 | N6: 0.9 | O6: =M6-(M6*N6) -> 39990 | P6: PERCENTAGE
A7: 2023 ALL (INCLUDE KI & RO) D90 | B7: =B6 -> 46086 | C7: =C6 -> 46092 | D7: 3259 | E7: 333 | F7: 3 | G7: 5 | H7: 81406 | I7: COLE | J7: 79137305 | K7: PDCOLBK | L7: DENIM LONG PANTS REGULAR 5 POCKET PDCOLBK:BLACK:40:SOLID:DENIM LONG PANTS | M7: 399900 | N7: 0.9 | O7: =M7-(M7*N7) -> 39990 | P7: PERCENTAGE
A8: 2023 ALL (INCLUDE KI & RO) D90 | B8: =B7 -> 46086 | C8: =C7 -> 46092 | D8: 3259 | E8: 333 | F8: 3 | G8: 5 | H8: 81406 | I8: COLE | J8: 79138322 | K8: PDCOLGR | L8: DENIM LONG PANTS REGULAR 5 POCKET PDCOLGR:FROST GREY:32:SOLID:DENIM LONG PANTS | M8: 399900 | N8: 0.9 | O8: =M8-(M8*N8) -> 39990 | P8: PERCENTAGE
A9: 2023 ALL (INCLUDE KI & RO) D90 | B9: =B8 -> 46086 | C9: =C8 -> 46092 | D9: 3259 | E9: 333 | F9: 3 | G9: 5 | H9: 81406 | I9: COLE | J9: 79138331 | K9: PDCOLGR | L9: DENIM LONG PANTS REGULAR 5 POCKET PDCOLGR:FROST GREY:34:SOLID:DENIM LONG PANTS | M9: 399900 | N9: 0.9 | O9: =M9-(M9*N9) -> 39990 | P9: PERCENTAGE
A10: 2023 ALL (INCLUDE KI & RO) D90 | B10: =B9 -> 46086 | C10: =C9 -> 46092 | D10: 3259 | E10: 333 | F10: 3 | G10: 5 | H10: 81406 | I10: COLE | J10: 79138340 | K10: PDCOLGR | L10: DENIM LONG PANTS REGULAR 5 POCKET PDCOLGR:FROST GREY:36:SOLID:DENIM LONG PANTS | M10: 399900 | N10: 0.9 | O10: =M10-(M10*N10) -> 39990 | P10: PERCENTAGE
A11: 2023 ALL (INCLUDE KI & RO) D90 | B11: =B10 -> 46086 | C11: =C10 -> 46092 | D11: 3259 | E11: 333 | F11: 3 | G11: 5 | H11: 81406 | I11: COLE | J11: 79138359 | K11: PDCOLGR | L11: DENIM LONG PANTS REGULAR 5 POCKET PDCOLGR:FROST GREY:38:SOLID:DENIM LONG PANTS | M11: 399900 | N11: 0.9 | O11: =M11-(M11*N11) -> 39990 | P11: PERCENTAGE
A12: 2023 ALL (INCLUDE KI & RO) D90 | B12: =B11 -> 46086 | C12: =C11 -> 46092 | D12: 3259 | E12: 333 | F12: 3 | G12: 5 | H12: 81406 | I12: COLE | J12: 79138368 | K12: PDCOLGR | L12: DENIM LONG PANTS REGULAR 5 POCKET PDCOLGR:FROST GREY:40:SOLID:DENIM LONG PANTS | M12: 399900 | N12: 0.9 | O12: =M12-(M12*N12) -> 39990 | P12: PERCENTAGE
A13: 2023 ALL (INCLUDE KI & RO) D90 | B13: =B12 -> 46086 | C13: =C12 -> 46092 | D13: 3259 | E13: 333 | F13: 3 | G13: 5 | H13: 81406 | I13: COLE | J13: 83006591 | K13: PDREGFAN | L13: DENIM LONG PANTS WITH FANCY POCKET REGULAR WHISKER SPRAY PDREGFAN:MEDIUM DENIM:32:SOLID:DENIM LONG P | M13: 369900 | N13: 0.9 | O13: =M13-(M13*N13) -> 36990 | P13: PERCENTAGE
A14: 2023 ALL (INCLUDE KI & RO) D90 | B14: =B13 -> 46086 | C14: =C13 -> 46092 | D14: 3259 | E14: 333 | F14: 3 | G14: 5 | H14: 81406 | I14: COLE | J14: 83006608 | K14: PDREGFAN | L14: DENIM LONG PANTS WITH FANCY POCKET REGULAR WHISKER SPRAY PDREGFAN:MEDIUM DENIM:34:SOLID:DENIM LONG P | M14: 369900 | N14: 0.9 | O14: =M14-(M14*N14) -> 36990 | P14: PERCENTAGE
... A673: 2023 ALL (INCLUDE KI & RO) D90 | B673: =B672 -> 46086 | C673: =C672 -> 46092 | D673: 3259 | E673: 333 | F673: 3 | G673: 16 | H673: 81779 | I673: COLE | J673: 81851029 | K673: SKTERPK7 | L673: SHORT PANTS KNIT SOLID RIB STRIPE SPK07 SKTERPK7:MISTY DARK BROWN:XL:SOLID:SHORT PANTS | M673: 229900 | N673: 0.9 | O673: =M673-(M673*N673) -> 22990 | P673: PERCENTAGE

Sheet 2024 ALL BOTTOM D70
A1: ACARA | B1: FROM DATE | C1: TO DATE | D1: DEPT | E1: WORLD | F1: DIVISION | G1: CLASS | H1: SUPPLIER | I1: BRAND | J1: SKU | K1: ARTICLE | L1: DESCRIPTION | M1: HARGA NORMAL | N1: DISKON | O1: HARGA PROMO | P1: DISCOUNT TYPE
A2: 2024 ALL BOTTOM D70 | B2: ='2019 ALL BOTTOM D95'!B4 -> 46086 | C2: ='2019 ALL BOTTOM D95'!C4 -> 46092 | D2: 3259 | E2: 333 | F2: 3 | G2: 6 | I2: COLE | J2: 15256574 | K2: PWGAULSL | L2: LONG PANTS WOVEN GAUL SLIM PWGAULSL:BLACK:30:SOLID:LONG PANTS | M2: 369900 | N2: 0.7 | O2: =M2-(M2*N2) -> 110970 | P2: PERCENTAGE
A3: 2024 ALL BOTTOM D70 | B3: =B2 -> 46086 | C3: =C2 -> 46092 | D3: 3259 | E3: 333 | F3: 3 | G3: 6 | I3: COLE | J3: 15256583 | K3: PWGAULSL | L3: LONG PANTS WOVEN GAUL SLIM PWGAULSL:BLACK:32:SOLID:LONG PANTS | M3: 369900 | N3: 0.7 | O3: =M3-(M3*N3) -> 110970 | P3: PERCENTAGE
A4: 2024 ALL BOTTOM D70 | B4: =B3 -> 46086 | C4: =C3 -> 46092 | D4: 3259 | E4: 333 | F4: 3 | G4: 6 | I4: COLE | J4: 15256592 | K4: PWGAULSL | L4: LONG PANTS WOVEN GAUL SLIM PWGAULSL:BLACK:34:SOLID:LONG PANTS | M4: 369900 | N4: 0.7 | O4: =M4-(M4*N4) -> 110970 | P4: PERCENTAGE
A5: 2024 ALL BOTTOM D70 | B5: =B4 -> 46086 | C5: =C4 -> 46092 | D5: 3259 | E5: 333 | F5: 3 | G5: 6 | I5: COLE | J5: 15256609 | K5: PWGAULSL | L5: LONG PANTS WOVEN GAUL SLIM PWGAULSL:BLACK:36:SOLID:LONG PANTS | M5: 369900 | N5: 0.7 | O5: =M5-(M5*N5) -> 110970 | P5: PERCENTAGE
A6: 2024 ALL BOTTOM D70 | B6: =B5 -> 46086 | C6: =C5 -> 46092 | D6: 3259 | E6: 333 | F6: 3 | G6: 6 | I6: COLE | J6: 15256618 | K6: PWGAULSL | L6: LONG PANTS WOVEN GAUL SLIM PWGAULSL:BLACK:38:SOLID:LONG PANTS | M6: 369900 | N6: 0.7 | O6: =M6-(M6*N6) -> 110970 | P6: PERCENTAGE
A7: 2024 ALL BOTTOM D70 | B7: =B6 -> 46086 | C7: =C6 -> 46092 | D7: 3259 | E7: 333 | F7: 3 | G7: 6 | I7: COLE | J7: 15256627 | K7: PWGAULSL | L7: LONG PANTS WOVEN GAUL SLIM PWGAULSL:BLACK:40:SOLID:LONG PANTS | M7: 369900 | N7: 0.7 | O7: =M7-(M7*N7) -> 110970 | P7: PERCENTAGE
A8: 2024 ALL BOTTOM D70 | B8: =B7 -> 46086 | C8: =C7 -> 46092 | D8: 3259 | E8: 333 | F8: 3 | G8: 6 | I8: COLE | J8: 15256636 | K8: PWGAULSL | L8: LONG PANTS WOVEN GAUL SLIM PWGAULSL:KHAKI:30:SOLID:LONG PANTS | M8: 369900 | N8: 0.7 | O8: =M8-(M8*N8) -> 110970 | P8: PERCENTAGE
A9: 2024 ALL BOTTOM D70 | B9: =B8 -> 46086 | C9: =C8 -> 46092 | D9: 3259 | E9: 333 | F9: 3 | G9: 6 | I9: COLE | J9: 15256645 | K9: PWGAULSL | L9: LONG PANTS WOVEN GAUL SLIM PWGAULSL:KHAKI:32:SOLID:LONG PANTS | M9: 369900 | N9: 0.7 | O9: =M9-(M9*N9) -> 110970 | P9: PERCENTAGE
A10: 2024 ALL BOTTOM D70 | B10: =B9 -> 46086 | C10: =C9 -> 46092 | D10: 3259 | E10: 333 | F10: 3 | G10: 6 | I10: COLE | J10: 15256654 | K10: PWGAULSL | L10: LONG PANTS WOVEN GAUL SLIM PWGAULSL:KHAKI:34:SOLID:LONG PANTS | M10: 369900 | N10: 0.7 | O10: =M10-(M10*N10) -> 110970 | P10: PERCENTAGE
A11: 2024 ALL BOTTOM D70 | B11: =B10 -> 46086 | C11: =C10 -> 46092 | D11: 3259 | E11: 333 | F11: 3 | G11: 6 | I11: COLE | J11: 15256663 | K11: PWGAULSL | L11: LONG PANTS WOVEN GAUL SLIM PWGAULSL:KHAKI:36:SOLID:LONG PANTS | M11: 369900 | N11: 0.7 | O11: =M11-(M11*N11) -> 110970 | P11: PERCENTAGE
A12: 2024 ALL BOTTOM D70 | B12: =B11 -> 46086 | C12: =C11 -> 46092 | D12: 3259 | E12: 333 | F12: 3 | G12: 6 | I12: COLE | J12: 15256672 | K12: PWGAULSL | L12: LONG PANTS WOVEN GAUL SLIM PWGAULSL:KHAKI:38:SOLID:LONG PANTS | M12: 369900 | N12: 0.7 | O12: =M12-(M12*N12) -> 110970 | P12: PERCENTAGE
A13: 2024 ALL BOTTOM D70 | B13: =B12 -> 46086 | C13: =C12 -> 46092 | D13: 3259 | E13: 333 | F13: 3 | G13: 6 | I13: COLE | J13: 15256681 | K13: PWGAULSL | L13: LONG PANTS WOVEN GAUL SLIM PWGAULSL:KHAKI:40:SOLID:LONG PANTS | M13: 369900 | N13: 0.7 | O13: =M13-(M13*N13) -> 110970 | P13: PERCENTAGE
A14: 2024 ALL BOTTOM D70 | B14: =B13 -> 46086 | C14: =C13 -> 46092 | D14: 3259 | E14: 333 | F14: 3 | G14: 6 | I14: COLE | J14: 15258018 | K14: PWGAULRG | L14: LONG PANTS WOVEN GAUL REGULAR PWGAULRG:TAUPE GREY:30:SOLID:LONG PANTS | M14: 369900 | N14: 0.7 | O14: =M14-(M14*N14) -> 110970 | P14: PERCENTAGE
... A204: 2024 ALL BOTTOM D70 | B204: =B203 -> 46086 | C204: =C203 -> 46092 | D204: 3259 | E204: 333 | F204: 3 | G204: 14 | I204: COLE | J204: 18085557 | K204: SDREGBK | L204: DENIM SHORT PANTS SIMPLE REGULAR SDREGBK:MEDIUM DENIM:40:SOLID:DENIM SHORT PANTS | M204: 219900 | N204: 0.7 | O204: =M204-(M204*N204) -> 65970 | P204: PERCENTAGE
A205: 2024 ALL BOTTOM D70 | B205: =B204 -> 46086 | C205: =C204 -> 46092 | D205: 3259 | E205: 333 | F205: 3 | I205: COLE | J205: 15257715 | K205: PDBCREG | L205: DENIM LONG PANTS BASIC NON WHISKER REGULAR PDBCREG:BLACK:30:SOLID:DENIM LONG PANTS | M205: 369900 | N205: 0.7 | O205: =M205-(M205*N205) -> 110970 | P205: PERCENTAGE
A206: 2024 ALL BOTTOM D70 | B206: =B205 -> 46086 | C206: =C205 -> 46092 | D206: 3259 | E206: 333 | F206: 3 | I206: COLE | J206: 15257724 | K206: PDBCREG | L206: DENIM LONG PANTS BASIC NON WHISKER REGULAR PDBCREG:BLACK:32:SOLID:DENIM LONG PANTS | M206: 369900 | N206: 0.7 | O206: =M206-(M206*N206) -> 110970 | P206: PERCENTAGE
A207: 2024 ALL BOTTOM D70 | B207: =B206 -> 46086 | C207: =C206 -> 46092 | D207: 3259 | E207: 333 | F207: 3 | I207: COLE | J207: 15257733 | K207: PDBCREG | L207: DENIM LONG PANTS BASIC NON WHISKER REGULAR PDBCREG:BLACK:34:SOLID:DENIM LONG PANTS | M207: 369900 | N207: 0.7 | O207: =M207-(M207*N207) -> 110970 | P207: PERCENTAGE
A208: 2024 ALL BOTTOM D70 | B208: =B207 -> 46086 | C208: =C207 -> 46092 | D208: 3259 | E208: 333 | F208: 3 | I208: COLE | J208: 15257742 | K208: PDBCREG | L208: DENIM LONG PANTS BASIC NON WHISKER REGULAR PDBCREG:BLACK:36:SOLID:DENIM LONG PANTS | M208: 369900 | N208: 0.7 | O208: =M208-(M208*N208) -> 110970 | P208: PERCENTAGE
A209: 2024 ALL BOTTOM D70 | B209: =B208 -> 46086 | C209: =C208 -> 46092 | D209: 3259 | E209: 333 | F209: 3 | I209: COLE | J209: 15257751 | K209: PDBCREG | L209: DENIM LONG PANTS BASIC NON WHISKER REGULAR PDBCREG:BLACK:38:SOLID:DENIM LONG PANTS | M209: 369900 | N209: 0.7 | O209: =M209-(M209*N209) -> 110970 | P209: PERCENTAGE
A210: 2024 ALL BOTTOM D70 | B210: =B209 -> 46086 | C210: =C209 -> 46092 | D210: 3259 | E210: 333 | F210: 3 | I210: COLE | J210: 15257760 | K210: PDBCREG | L210: DENIM LONG PANTS BASIC NON WHISKER REGULAR PDBCREG:BLACK:40:SOLID:DENIM LONG PANTS | M210: 369900 | N210: 0.7 | O210: =M210-(M210*N210) -> 110970 | P210: PERCENTAGE
A211: 2024 ALL BOTTOM D70 | B211: =B210 -> 46086 | C211: =C210 -> 46092 | D211: 3259 | E211: 333 | F211: 3 | I211: COLE | J211: 15257162 | K211: PDBCSLIM | L211: DENIM LONG PANTS BASIC SPRAY WHISKER SLIM PDBCSLIM:LIGHT DENIM:32:SOLID:DENIM LONG PANTS | M211: 369900 | N211: 0.7 | O211: =M211-(M211*N211) -> 110970 | P211: PERCENTAGE
A212: 2024 ALL BOTTOM D70 | B212: =B211 -> 46086 | C212: =C211 -> 46092 | D212: 3259 | E212: 333 | F212: 3 | I212: COLE | J212: 15257171 | K212: PDBCSLIM | L212: DENIM LONG PANTS BASIC SPRAY WHISKER SLIM PDBCSLIM:LIGHT DENIM:34:SOLID:DENIM LONG PANTS | M212: 369900 | N212: 0.7 | O212: =M212-(M212*N212) -> 110970 | P212: PERCENTAGE
A213: 2024 ALL BOTTOM D70 | B213: =B212 -> 46086 | C213: =C212 -> 46092 | D213: 3259 | E213: 333 | F213: 3 | I213: COLE | J213: 15257180 | K213: PDBCSLIM | L213: DENIM LONG PANTS BASIC SPRAY WHISKER SLIM PDBCSLIM:LIGHT DENIM:36:SOLID:DENIM LONG PANTS | M213: 369900 | N213: 0.7 | O213: =M213-(M213*N213) -> 110970 | P213: PERCENTAGE
A214: 2024 ALL BOTTOM D70 | B214: =B213 -> 46086 | C214: =C213 -> 46092 | D214: 3259 | E214: 333 | F214: 3 | I214: COLE | J214: 15257199 | K214: PDBCSLIM | L214: DENIM LONG PANTS BASIC SPRAY WHISKER SLIM PDBCSLIM:LIGHT DENIM:38:SOLID:DENIM LONG PANTS | M214: 369900 | N214: 0.7 | O214: =M214-(M214*N214) -> 110970 | P214: PERCENTAGE
A215: 2024 ALL BOTTOM D70 | B215: =B214 -> 46086 | C215: =C214 -> 46092 | D215: 3259 | E215: 333 | F215: 3 | I215: COLE | J215: 15257206 | K215: PDBCSLIM | L215: DENIM LONG PANTS BASIC SPRAY WHISKER SLIM PDBCSLIM:LIGHT DENIM:40:SOLID:DENIM LONG PANTS | M215: 369900 | N215: 0.7 | O215: =M215-(M215*N215) -> 110970 | P215: PERCENTAGE
A216: 2024 ALL BOTTOM D70 | B216: =B215 -> 46086 | C216: =C215 -> 46092 | D216: 3259 | E216: 333 | F216: 3 | I216: COLE | J216: 17124211 | K216: PDECSLIM | L216: DENIM LONG PANTS BASIC SLIM ECO PDECSLIM:MEDIUM DENIM:30:SOLID:DENIM LONG PANTS | M216: 369900 | N216: 0.7 | O216: =M216-(M216*N216) -> 110970 | P216: PERCENTAGE
... A221: 2024 ALL BOTTOM D70 | B221: =B220 -> 46086 | C221: =C220 -> 46092 | D221: 3259 | E221: 333 | F221: 3 | I221: COLE | J221: 17124275 | K221: PDECSLIM | L221: DENIM LONG PANTS BASIC SLIM ECO PDECSLIM:MEDIUM DENIM:40:SOLID:DENIM LONG PANTS | M221: 369900 | N221: 0.7 | O221: =M221-(M221*N221) -> 110970 | P221: PERCENTAGE

Sheet 2024 KNITPANTS KNITSHORT D70
A1: ACARA | B1: FROM DATE | C1: TO DATE | D1: DEPT | E1: WORLD | F1: DIVISION | G1: CLASS | H1: SUPPLIER | I1: BRAND | J1: SKU | K1: ARTICLE | L1: DESCRIPTION | M1: HARGA NORMAL | N1: DISKON | O1: HARGA PROMO | P1: DISCOUNT TYPE
A2: 2024 KNITPANTS KNITSHORT D70 | B2: ='2019 ALL BOTTOM D95'!B2 -> 46086 | C2: ='2019 ALL BOTTOM D95'!C2 -> 46092 | D2: 3259 | E2: 333 | F2: 3 | G2: 7 | I2: COLE | J2: 19551765 | K2: PKCSSOL | L2: LONG PANTS KNIT BASIC CUT AND SEWN PKCSSOL:BLACK:S:SOLID:LONG PANTS | M2: 249900 | N2: 0.7 | O2: =M2-(M2*N2) -> 74970 | P2: PERCENTAGE
A3: 2024 KNITPANTS KNITSHORT D70 | B3: =B2 -> 46086 | C3: =C2 -> 46092 | D3: 3259 | E3: 333 | F3: 3 | G3: 7 | I3: COLE | J3: 19551774 | K3: PKCSSOL | L3: LONG PANTS KNIT BASIC CUT AND SEWN PKCSSOL:BLACK:M:SOLID:LONG PANTS | M3: 249900 | N3: 0.7 | O3: =M3-(M3*N3) -> 74970 | P3: PERCENTAGE
A4: 2024 KNITPANTS KNITSHORT D70 | B4: =B3 -> 46086 | C4: =C3 -> 46092 | D4: 3259 | E4: 333 | F4: 3 | G4: 7 | I4: COLE | J4: 19551792 | K4: PKCSSOL | L4: LONG PANTS KNIT BASIC CUT AND SEWN PKCSSOL:BLACK:L:SOLID:LONG PANTS | M4: 249900 | N4: 0.7 | O4: =M4-(M4*N4) -> 74970 | P4: PERCENTAGE
A5: 2024 KNITPANTS KNITSHORT D70 | B5: =B4 -> 46086 | C5: =C4 -> 46092 | D5: 3259 | E5: 333 | F5: 3 | G5: 7 | I5: COLE | J5: 19551809 | K5: PKCSSOL | L5: LONG PANTS KNIT BASIC CUT AND SEWN PKCSSOL:BLACK:XL:SOLID:LONG PANTS | M5: 249900 | N5: 0.7 | O5: =M5-(M5*N5) -> 74970 | P5: PERCENTAGE
A6: 2024 KNITPANTS KNITSHORT D70 | B6: =B5 -> 46086 | C6: =C5 -> 46092 | D6: 3259 | E6: 333 | F6: 3 | G6: 7 | I6: COLE | J6: 19551818 | K6: PKCSSOL | L6: LONG PANTS KNIT BASIC CUT AND SEWN PKCSSOL:RUSTIC BROWN:S:SOLID:LONG PANTS | M6: 249900 | N6: 0.7 | O6: =M6-(M6*N6) -> 74970 | P6: PERCENTAGE
A7: 2024 KNITPANTS KNITSHORT D70 | B7: =B6 -> 46086 | C7: =C6 -> 46092 | D7: 3259 | E7: 333 | F7: 3 | G7: 7 | I7: COLE | J7: 19551827 | K7: PKCSSOL | L7: LONG PANTS KNIT BASIC CUT AND SEWN PKCSSOL:RUSTIC BROWN:M:SOLID:LONG PANTS | M7: 249900 | N7: 0.7 | O7: =M7-(M7*N7) -> 74970 | P7: PERCENTAGE
A8: 2024 KNITPANTS KNITSHORT D70 | B8: =B7 -> 46086 | C8: =C7 -> 46092 | D8: 3259 | E8: 333 | F8: 3 | G8: 7 | I8: COLE | J8: 19551836 | K8: PKCSSOL | L8: LONG PANTS KNIT BASIC CUT AND SEWN PKCSSOL:RUSTIC BROWN:L:SOLID:LONG PANTS | M8: 249900 | N8: 0.7 | O8: =M8-(M8*N8) -> 74970 | P8: PERCENTAGE
A9: 2024 KNITPANTS KNITSHORT D70 | B9: =B8 -> 46086 | C9: =C8 -> 46092 | D9: 3259 | E9: 333 | F9: 3 | G9: 7 | I9: COLE | J9: 19551845 | K9: PKCSSOL | L9: LONG PANTS KNIT BASIC CUT AND SEWN PKCSSOL:RUSTIC BROWN:XL:SOLID:LONG PANTS | M9: 249900 | N9: 0.7 | O9: =M9-(M9*N9) -> 74970 | P9: PERCENTAGE
A10: 2024 KNITPANTS KNITSHORT D70 | B10: =B9 -> 46086 | C10: =C9 -> 46092 | D10: 3259 | E10: 333 | F10: 3 | G10: 7 | I10: COLE | J10: 76164979 | K10: JGTRBC | L10: JOGGER KI LONG JG JGTRBC:BLACK:S:SOLID:JOGGER | M10: 249900 | N10: 0.7 | O10: =M10-(M10*N10) -> 74970 | P10: PERCENTAGE
A11: 2024 KNITPANTS KNITSHORT D70 | B11: =B10 -> 46086 | C11: =C10 -> 46092 | D11: 3259 | E11: 333 | F11: 3 | G11: 7 | I11: COLE | J11: 76164988 | K11: JGTRBC | L11: JOGGER KI LONG JG JGTRBC:BLACK:M:SOLID:JOGGER | M11: 249900 | N11: 0.7 | O11: =M11-(M11*N11) -> 74970 | P11: PERCENTAGE
A12: 2024 KNITPANTS KNITSHORT D70 | B12: =B11 -> 46086 | C12: =C11 -> 46092 | D12: 3259 | E12: 333 | F12: 3 | G12: 7 | I12: COLE | J12: 76164997 | K12: JGTRBC | L12: JOGGER KI LONG JG JGTRBC:BLACK:L:SOLID:JOGGER | M12: 249900 | N12: 0.7 | O12: =M12-(M12*N12) -> 74970 | P12: PERCENTAGE
A13: 2024 KNITPANTS KNITSHORT D70 | B13: =B12 -> 46086 | C13: =C12 -> 46092 | D13: 3259 | E13: 333 | F13: 3 | G13: 7 | I13: COLE | J13: 76165003 | K13: JGTRBC | L13: JOGGER KI LONG JG JGTRBC:BLACK:XL:SOLID:JOGGER | M13: 249900 | N13: 0.7 | O13: =M13-(M13*N13) -> 74970 | P13: PERCENTAGE
A14: 2024 KNITPANTS KNITSHORT D70 | B14: =B13 -> 46086 | C14: =C13 -> 46092 | D14: 3259 | E14: 333 | F14: 3 | G14: 16 | I14: COLE | J14: 76165058 | K14: SKTRBC | L14: SHORT PANTS KI KNIT SKTRBC:BLACK:S:SOLID:SHORT PANTS | M14: 199900 | N14: 0.7 | O14: =M14-(M14*N14) -> 59970 | P14: PERCENTAGE
... A113: 2024 KNITPANTS KNITSHORT D70 | B113: =B112 -> 46086 | C113: =C112 -> 46092 | D113: 3259 | E113: 333 | F113: 3 | G113: 16 | I113: COLE | J113: 15258232 | K113: SKSIMOTT | L113: SHORT PANTS KNIT OTTOMAN BASIC POCKET AND BIG SIZE SKSIMOTT:OLIVE:S:SOLID:SHORT PANTS | M113: 199900 | N113: 0.7 | O113: =M113-(M113*N113) -> 59970 | P113: PERCENTAGE
A114: 2024 KNITPANTS KNITSHORT D70 | B114: =B113 -> 46086 | C114: =C113 -> 46092 | D114: 3259 | E114: 333 | F114: 3 | G114: 7 | J114: 87445841 | K114: PKJOGCSL | L114: LONG PANTS KNIT CASUAL LOOKS PKJOGCSL:MISTY DARK GREY:L:SOLID:LONG PANTS | M114: 179900 | N114: 0.7 | O114: =M114-(M114*N114) -> 53970 | P114: PERCENTAGE
A115: 2024 KNITPANTS KNITSHORT D70 | B115: =B114 -> 46086 | C115: =C114 -> 46092 | D115: 3259 | E115: 333 | F115: 3 | G115: 7 | J115: 87445832 | K115: PKJOGCSL | L115: LONG PANTS KNIT CASUAL LOOKS PKJOGCSL:MISTY DARK GREY:M:SOLID:LONG PANTS | M115: 179900 | N115: 0.7 | O115: =M115-(M115*N115) -> 53970 | P115: PERCENTAGE
A116: 2024 KNITPANTS KNITSHORT D70 | B116: =B115 -> 46086 | C116: =C115 -> 46092 | D116: 3259 | E116: 333 | F116: 3 | G116: 7 | J116: 87445823 | K116: PKJOGCSL | L116: LONG PANTS KNIT CASUAL LOOKS PKJOGCSL:MISTY DARK GREY:S:SOLID:LONG PANTS | M116: 179900 | N116: 0.7 | O116: =M116-(M116*N116) -> 53970 | P116: PERCENTAGE
A117: 2024 KNITPANTS KNITSHORT D70 | B117: =B116 -> 46086 | C117: =C116 -> 46092 | D117: 3259 | E117: 333 | F117: 3 | G117: 7 | J117: 87445850 | K117: PKJOGCSL | L117: LONG PANTS KNIT CASUAL LOOKS PKJOGCSL:MISTY DARK GREY:XL:SOLID:LONG PANTS | M117: 179900 | N117: 0.7 | O117: =M117-(M117*N117) -> 53970 | P117: PERCENTAGE

Sheet 2024 H2 WOVEN SHORT D70
A1: ACARA | B1: FROM DATE | C1: TO DATE | D1: DEPT | E1: WORLD | F1: DIVISION | G1: CLASS | H1: SUPPLIER | I1: BRAND | J1: SKU | K1: ARTICLE | L1: DESCRIPTION | M1: HARGA NORMAL | N1: DISKON | O1: HARGA PROMO | P1: DISCOUNT TYPE
A2: 2024 H2 WOVEN SHORT D70 | B2: ='2019 ALL BOTTOM D95'!B39 -> 46086 | C2: ='2019 ALL BOTTOM D95'!C39 -> 46092 | D2: 3259 | E2: 333 | F2: 3 | G2: 15 | I2: COLE | J2: 26769624 | K2: SWSTRIPE | L2: SHORT PANTS WOVEN PRINT STRIPES BERMUDA W/ ADJUSTER WAIST SWSTRIPE:NAVY BLUE:30:STRIPES:SHORT PANTS | M2: 219900 | N2: 0.7 | O2: =M2-(M2*N2) -> 65970 | P2: PERCENTAGE
A3: 2024 H2 WOVEN SHORT D70 | B3: =B2 -> 46086 | C3: =C2 -> 46092 | D3: 3259 | E3: 333 | F3: 3 | G3: 15 | I3: COLE | J3: 26769633 | K3: SWSTRIPE | L3: SHORT PANTS WOVEN PRINT STRIPES BERMUDA W/ ADJUSTER WAIST SWSTRIPE:NAVY BLUE:32:STRIPES:SHORT PANTS | M3: 219900 | N3: 0.7 | O3: =M3-(M3*N3) -> 65970 | P3: PERCENTAGE
A4: 2024 H2 WOVEN SHORT D70 | B4: =B3 -> 46086 | C4: =C3 -> 46092 | D4: 3259 | E4: 333 | F4: 3 | G4: 15 | I4: COLE | J4: 26769642 | K4: SWSTRIPE | L4: SHORT PANTS WOVEN PRINT STRIPES BERMUDA W/ ADJUSTER WAIST SWSTRIPE:NAVY BLUE:34:STRIPES:SHORT PANTS | M4: 219900 | N4: 0.7 | O4: =M4-(M4*N4) -> 65970 | P4: PERCENTAGE
A5: 2024 H2 WOVEN SHORT D70 | B5: =B4 -> 46086 | C5: =C4 -> 46092 | D5: 3259 | E5: 333 | F5: 3 | G5: 15 | I5: COLE | J5: 26769651 | K5: SWSTRIPE | L5: SHORT PANTS WOVEN PRINT STRIPES BERMUDA W/ ADJUSTER WAIST SWSTRIPE:NAVY BLUE:36:STRIPES:SHORT PANTS | M5: 219900 | N5: 0.7 | O5: =M5-(M5*N5) -> 65970 | P5: PERCENTAGE
A6: 2024 H2 WOVEN SHORT D70 | B6: =B5 -> 46086 | C6: =C5 -> 46092 | D6: 3259 | E6: 333 | F6: 3 | G6: 15 | I6: COLE | J6: 26769660 | K6: SWSTRIPE | L6: SHORT PANTS WOVEN PRINT STRIPES BERMUDA W/ ADJUSTER WAIST SWSTRIPE:NAVY BLUE:38:STRIPES:SHORT PANTS | M6: 219900 | N6: 0.7 | O6: =M6-(M6*N6) -> 65970 | P6: PERCENTAGE
A7: 2024 H2 WOVEN SHORT D70 | B7: =B6 -> 46086 | C7: =C6 -> 46092 | D7: 3259 | E7: 333 | F7: 3 | G7: 15 | I7: COLE | J7: 26769679 | K7: SWSTRIPE | L7: SHORT PANTS WOVEN PRINT STRIPES BERMUDA W/ ADJUSTER WAIST SWSTRIPE:NAVY BLUE:40:STRIPES:SHORT PANTS | M7: 219900 | N7: 0.7 | O7: =M7-(M7*N7) -> 65970 | P7: PERCENTAGE
A8: 2024 H2 WOVEN SHORT D70 | B8: =B7 -> 46086 | C8: =C7 -> 46092 | D8: 3259 | E8: 333 | F8: 3 | G8: 15 | I8: COLE | J8: 26769688 | K8: SWSTRIPE | L8: SHORT PANTS WOVEN PRINT STRIPES BERMUDA W/ ADJUSTER WAIST SWSTRIPE:BLACK:30:STRIPES:SHORT PANTS | M8: 219900 | N8: 0.7 | O8: =M8-(M8*N8) -> 65970 | P8: PERCENTAGE
A9: 2024 H2 WOVEN SHORT D70 | B9: =B8 -> 46086 | C9: =C8 -> 46092 | D9: 3259 | E9: 333 | F9: 3 | G9: 15 | I9: COLE | J9: 26769697 | K9: SWSTRIPE | L9: SHORT PANTS WOVEN PRINT STRIPES BERMUDA W/ ADJUSTER WAIST SWSTRIPE:BLACK:32:STRIPES:SHORT PANTS | M9: 219900 | N9: 0.7 | O9: =M9-(M9*N9) -> 65970 | P9: PERCENTAGE
A10: 2024 H2 WOVEN SHORT D70 | B10: =B9 -> 46086 | C10: =C9 -> 46092 | D10: 3259 | E10: 333 | F10: 3 | G10: 15 | I10: COLE | J10: 26769704 | K10: SWSTRIPE | L10: SHORT PANTS WOVEN PRINT STRIPES BERMUDA W/ ADJUSTER WAIST SWSTRIPE:BLACK:34:STRIPES:SHORT PANTS | M10: 219900 | N10: 0.7 | O10: =M10-(M10*N10) -> 65970 | P10: PERCENTAGE
A11: 2024 H2 WOVEN SHORT D70 | B11: =B10 -> 46086 | C11: =C10 -> 46092 | D11: 3259 | E11: 333 | F11: 3 | G11: 15 | I11: COLE | J11: 26769731 | K11: SWSTRIPE | L11: SHORT PANTS WOVEN PRINT STRIPES BERMUDA W/ ADJUSTER WAIST SWSTRIPE:BLACK:36:STRIPES:SHORT PANTS | M11: 219900 | N11: 0.7 | O11: =M11-(M11*N11) -> 65970 | P11: PERCENTAGE
A12: 2024 H2 WOVEN SHORT D70 | B12: =B11 -> 46086 | C12: =C11 -> 46092 | D12: 3259 | E12: 333 | F12: 3 | G12: 15 | I12: COLE | J12: 26769740 | K12: SWSTRIPE | L12: SHORT PANTS WOVEN PRINT STRIPES BERMUDA W/ ADJUSTER WAIST SWSTRIPE:BLACK:38:STRIPES:SHORT PANTS | M12: 219900 | N12: 0.7 | O12: =M12-(M12*N12) -> 65970 | P12: PERCENTAGE
A13: 2024 H2 WOVEN SHORT D70 | B13: =B12 -> 46086 | C13: =C12 -> 46092 | D13: 3259 | E13: 333 | F13: 3 | G13: 15 | I13: COLE | J13: 26769795 | K13: SWSTRIPE | L13: SHORT PANTS WOVEN PRINT STRIPES BERMUDA W/ ADJUSTER WAIST SWSTRIPE:BLACK:40:STRIPES:SHORT PANTS | M13: 219900 | N13: 0.7 | O13: =M13-(M13*N13) -> 65970 | P13: PERCENTAGE
A14: 2024 H2 WOVEN SHORT D70 | B14: =B13 -> 46086 | C14: =C13 -> 46092 | D14: 3259 | E14: 333 | F14: 3 | G14: 15 | I14: COLE | J14: 26770201 | K14: SWSOLCRG | L14: SHORT PANTS WOVEN CARGO BERMUDA RIBSTOP SWSOLCRG:CHARCOAL:30:SOLID:SHORT PANTS | M14: 219900 | N14: 0.7 | O14: =M14-(M14*N14) -> 65970 | P14: PERCENTAGE
... A55: 2024 H2 WOVEN SHORT D70 | B55: =B54 -> 46086 | C55: =C54 -> 46092 | D55: 3259 | E55: 333 | F55: 3 | G55: 15 | I55: COLE | J55: 26789175 | K55: SWSLRIB | L55: SHORT PANTS WOVEN SOLID PULLON RIB SWSLRIB:WOOD BROWN:XL:SOLID:SHORT PANTS | M55: 199900 | N55: 0.7 | O55: =M55-(M55*N55) -> 59970 | P55: PERCENTAGE

Sheet 2024 H2 WOVEN PANTS D70
A1: ACARA | B1: FROM DATE | C1: TO DATE | D1: DEPT | E1: WORLD | F1: DIVISION | G1: CLASS | H1: SUPPLIER | I1: BRAND | J1: SKU | K1: ARTICLE | L1: DESCRIPTION | M1: HARGA NORMAL | N1: DISKON | O1: HARGA PROMO | P1: DISCOUNT TYPE
A2: 2024 H2 WOVEN PANTS D70 | B2: ='2019 ALL BOTTOM D95'!B115 -> 46086 | C2: ='2019 ALL BOTTOM D95'!C115 -> 46092 | D2: 3259 | E2: 333 | F2: 3 | G2: 6 | I2: COLE | J2: 19199549 | K2: PWSANSL | L2: LONG PANTS WOVEN FANCY STITCH SLIM PWSANSL:KHAKI:30:SOLID:LONG PANTS | M2: 279900 | N2: 0.7 | O2: =M2-(M2*N2) -> 83970 | P2: PERCENTAGE
A3: 2024 H2 WOVEN PANTS D70 | B3: =B2 -> 46086 | C3: =C2 -> 46092 | D3: 3259 | E3: 333 | F3: 3 | G3: 6 | I3: COLE | J3: 19199558 | K3: PWSANSL | L3: LONG PANTS WOVEN FANCY STITCH SLIM PWSANSL:KHAKI:32:SOLID:LONG PANTS | M3: 279900 | N3: 0.7 | O3: =M3-(M3*N3) -> 83970 | P3: PERCENTAGE
A4: 2024 H2 WOVEN PANTS D70 | B4: =B3 -> 46086 | C4: =C3 -> 46092 | D4: 3259 | E4: 333 | F4: 3 | G4: 6 | I4: COLE | J4: 19199567 | K4: PWSANSL | L4: LONG PANTS WOVEN FANCY STITCH SLIM PWSANSL:KHAKI:34:SOLID:LONG PANTS | M4: 279900 | N4: 0.7 | O4: =M4-(M4*N4) -> 83970 | P4: PERCENTAGE
A5: 2024 H2 WOVEN PANTS D70 | B5: =B4 -> 46086 | C5: =C4 -> 46092 | D5: 3259 | E5: 333 | F5: 3 | G5: 6 | I5: COLE | J5: 19199576 | K5: PWSANSL | L5: LONG PANTS WOVEN FANCY STITCH SLIM PWSANSL:KHAKI:36:SOLID:LONG PANTS | M5: 279900 | N5: 0.7 | O5: =M5-(M5*N5) -> 83970 | P5: PERCENTAGE
A6: 2024 H2 WOVEN PANTS D70 | B6: =B5 -> 46086 | C6: =C5 -> 46092 | D6: 3259 | E6: 333 | F6: 3 | G6: 6 | I6: COLE | J6: 19199585 | K6: PWSANSL | L6: LONG PANTS WOVEN FANCY STITCH SLIM PWSANSL:KHAKI:38:SOLID:LONG PANTS | M6: 279900 | N6: 0.7 | O6: =M6-(M6*N6) -> 83970 | P6: PERCENTAGE
A7: 2024 H2 WOVEN PANTS D70 | B7: =B6 -> 46086 | C7: =C6 -> 46092 | D7: 3259 | E7: 333 | F7: 3 | G7: 6 | I7: COLE | J7: 19199594 | K7: PWSANSL | L7: LONG PANTS WOVEN FANCY STITCH SLIM PWSANSL:KHAKI:40:SOLID:LONG PANTS | M7: 279900 | N7: 0.7 | O7: =M7-(M7*N7) -> 83970 | P7: PERCENTAGE
A8: 2024 H2 WOVEN PANTS D70 | B8: =B7 -> 46086 | C8: =C7 -> 46092 | D8: 3259 | E8: 333 | F8: 3 | G8: 6 | I8: COLE | J8: 19199601 | K8: PWSANSL | L8: LONG PANTS WOVEN FANCY STITCH SLIM PWSANSL:OLIVE:30:SOLID:LONG PANTS | M8: 279900 | N8: 0.7 | O8: =M8-(M8*N8) -> 83970 | P8: PERCENTAGE
A9: 2024 H2 WOVEN PANTS D70 | B9: =B8 -> 46086 | C9: =C8 -> 46092 | D9: 3259 | E9: 333 | F9: 3 | G9: 6 | I9: COLE | J9: 19199629 | K9: PWSANSL | L9: LONG PANTS WOVEN FANCY STITCH SLIM PWSANSL:OLIVE:32:SOLID:LONG PANTS | M9: 279900 | N9: 0.7 | O9: =M9-(M9*N9) -> 83970 | P9: PERCENTAGE
A10: 2024 H2 WOVEN PANTS D70 | B10: =B9 -> 46086 | C10: =C9 -> 46092 | D10: 3259 | E10: 333 | F10: 3 | G10: 6 | I10: COLE | J10: 19199665 | K10: PWSANSL | L10: LONG PANTS WOVEN FANCY STITCH SLIM PWSANSL:OLIVE:34:SOLID:LONG PANTS | M10: 279900 | N10: 0.7 | O10: =M10-(M10*N10) -> 83970 | P10: PERCENTAGE
A11: 2024 H2 WOVEN PANTS D70 | B11: =B10 -> 46086 | C11: =C10 -> 46092 | D11: 3259 | E11: 333 | F11: 3 | G11: 6 | I11: COLE | J11: 19199709 | K11: PWSANSL | L11: LONG PANTS WOVEN FANCY STITCH SLIM PWSANSL:OLIVE:36:SOLID:LONG PANTS | M11: 279900 | N11: 0.7 | O11: =M11-(M11*N11) -> 83970 | P11: PERCENTAGE
A12: 2024 H2 WOVEN PANTS D70 | B12: =B11 -> 46086 | C12: =C11 -> 46092 | D12: 3259 | E12: 333 | F12: 3 | G12: 6 | I12: COLE | J12: 19199718 | K12: PWSANSL | L12: LONG PANTS WOVEN FANCY STITCH SLIM PWSANSL:OLIVE:38:SOLID:LONG PANTS | M12: 279900 | N12: 0.7 | O12: =M12-(M12*N12) -> 83970 | P12: PERCENTAGE
A13: 2024 H2 WOVEN PANTS D70 | B13: =B12 -> 46086 | C13: =C12 -> 46092 | D13: 3259 | E13: 333 | F13: 3 | G13: 6 | I13: COLE | J13: 19199727 | K13: PWSANSL | L13: LONG PANTS WOVEN FANCY STITCH SLIM PWSANSL:OLIVE:40:SOLID:LONG PANTS | M13: 279900 | N13: 0.7 | O13: =M13-(M13*N13) -> 83970 | P13: PERCENTAGE
A14: 2024 H2 WOVEN PANTS D70 | B14: =B13 -> 46086 | C14: =C13 -> 46092 | D14: 3259 | E14: 333 | F14: 3 | G14: 6 | I14: COLE | J14: 26769517 | K14: PWCARJG | L14: JOGGER PANTS WOVEN CARGO ELASTIC WAISTBAND PWCARJG:BLACK:S:SOLID:JOGGER | M14: 279900 | N14: 0.7 | O14: =M14-(M14*N14) -> 83970 | P14: PERCENTAGE
... A95: 2024 H2 WOVEN PANTS D70 | B95: =B94 -> 46086 | C95: =C94 -> 46092 | D95: 3259 | E95: 333 | F95: 3 | G95: 6 | I95: COLE | J95: 19199898 | K95: PWJOGSL | L95: JOGGER PANTS WOVEN SLIM PWJOGSL:BLACK:XL:SOLID:JOGGER | M95: 369900 | N95: 0.7 | O95: =M95-(M95*N95) -> 110970 | P95: PERCENTAGE

Sheet 2024 H2 DENIM PANTS D70
A1: ACARA | B1: FROM DATE | C1: TO DATE | D1: DEPT | E1: WORLD | F1: DIVISION | G1: CLASS | H1: SUPPLIER | I1: BRAND | J1: SKU | K1: ARTICLE | L1: DESCRIPTION | M1: HARGA NORMAL | N1: DISKON | O1: HARGA PROMO | P1: DISCOUNT TYPE
A2: 2024 H2 DENIM D70 | B2: ='2019 ALL BOTTOM D95'!B3 -> 46086 | C2: ='2019 ALL BOTTOM D95'!C3 -> 46092 | D2: 3259 | E2: 333 | F2: 3 | G2: 5 | I2: COLE | J2: 15256252 | K2: PDBKSLIM | L2: DENIM LONG PANTS BASIC BLK SLIM PDBKSLIM:BLACK:30:SOLID:DENIM LONG PANTS | M2: 279900 | N2: 0.7 | O2: =M2-(M2*N2) -> 83970 | P2: PERCENTAGE
A3: 2024 H2 DENIM D70 | B3: =B2 -> 46086 | C3: =C2 -> 46092 | D3: 3259 | E3: 333 | F3: 3 | G3: 5 | I3: COLE | J3: 15256270 | K3: PDBKSLIM | L3: DENIM LONG PANTS BASIC BLK SLIM PDBKSLIM:BLACK:34:SOLID:DENIM LONG PANTS | M3: 279900 | N3: 0.7 | O3: =M3-(M3*N3) -> 83970 | P3: PERCENTAGE
A4: 2024 H2 DENIM D70 | B4: =B3 -> 46086 | C4: =C3 -> 46092 | D4: 3259 | E4: 333 | F4: 3 | G4: 5 | I4: COLE | J4: 15256289 | K4: PDBKSLIM | L4: DENIM LONG PANTS BASIC BLK SLIM PDBKSLIM:BLACK:36:SOLID:DENIM LONG PANTS | M4: 279900 | N4: 0.7 | O4: =M4-(M4*N4) -> 83970 | P4: PERCENTAGE
A5: 2024 H2 DENIM D70 | B5: =B4 -> 46086 | C5: =C4 -> 46092 | D5: 3259 | E5: 333 | F5: 3 | G5: 5 | I5: COLE | J5: 15256298 | K5: PDBKSLIM | L5: DENIM LONG PANTS BASIC BLK SLIM PDBKSLIM:BLACK:38:SOLID:DENIM LONG PANTS | M5: 279900 | N5: 0.7 | O5: =M5-(M5*N5) -> 83970 | P5: PERCENTAGE
A6: 2024 H2 DENIM D70 | B6: =B5 -> 46086 | C6: =C5 -> 46092 | D6: 3259 | E6: 333 | F6: 3 | G6: 5 | I6: COLE | J6: 15256305 | K6: PDBKSLIM | L6: DENIM LONG PANTS BASIC BLK SLIM PDBKSLIM:BLACK:40:SOLID:DENIM LONG PANTS | M6: 279900 | N6: 0.7 | O6: =M6-(M6*N6) -> 83970 | P6: PERCENTAGE
A7: 2024 H2 DENIM D70 | B7: =B6 -> 46086 | C7: =C6 -> 46092 | D7: 3259 | E7: 333 | F7: 3 | G7: 5 | I7: COLE | J7: 15257091 | K7: PDBCSLIM | L7: DENIM LONG PANTS BASIC SPRAY WHISKER SLIM PDBCSLIM:INDIGO BLUE:30:SOLID:DENIM LONG PANTS | M7: 279900 | N7: 0.7 | O7: =M7-(M7*N7) -> 83970 | P7: PERCENTAGE
A8: 2024 H2 DENIM D70 | B8: =B7 -> 46086 | C8: =C7 -> 46092 | D8: 3259 | E8: 333 | F8: 3 | G8: 5 | I8: COLE | J8: 15257108 | K8: PDBCSLIM | L8: DENIM LONG PANTS BASIC SPRAY WHISKER SLIM PDBCSLIM:INDIGO BLUE:32:SOLID:DENIM LONG PANTS | M8: 279900 | N8: 0.7 | O8: =M8-(M8*N8) -> 83970 | P8: PERCENTAGE
A9: 2024 H2 DENIM D70 | B9: =B8 -> 46086 | C9: =C8 -> 46092 | D9: 3259 | E9: 333 | F9: 3 | G9: 5 | I9: COLE | J9: 15257117 | K9: PDBCSLIM | L9: DENIM LONG PANTS BASIC SPRAY WHISKER SLIM PDBCSLIM:INDIGO BLUE:34:SOLID:DENIM LONG PANTS | M9: 279900 | N9: 0.7 | O9: =M9-(M9*N9) -> 83970 | P9: PERCENTAGE
A10: 2024 H2 DENIM D70 | B10: =B9 -> 46086 | C10: =C9 -> 46092 | D10: 3259 | E10: 333 | F10: 3 | G10: 5 | I10: COLE | J10: 15257126 | K10: PDBCSLIM | L10: DENIM LONG PANTS BASIC SPRAY WHISKER SLIM PDBCSLIM:INDIGO BLUE:36:SOLID:DENIM LONG PANTS | M10: 279900 | N10: 0.7 | O10: =M10-(M10*N10) -> 83970 | P10: PERCENTAGE
A11: 2024 H2 DENIM D70 | B11: =B10 -> 46086 | C11: =C10 -> 46092 | D11: 3259 | E11: 333 | F11: 3 | G11: 5 | I11: COLE | J11: 15257135 | K11: PDBCSLIM | L11: DENIM LONG PANTS BASIC SPRAY WHISKER SLIM PDBCSLIM:INDIGO BLUE:38:SOLID:DENIM LONG PANTS | M11: 279900 | N11: 0.7 | O11: =M11-(M11*N11) -> 83970 | P11: PERCENTAGE
A12: 2024 H2 DENIM D70 | B12: =B11 -> 46086 | C12: =C11 -> 46092 | D12: 3259 | E12: 333 | F12: 3 | G12: 5 | I12: COLE | J12: 15257144 | K12: PDBCSLIM | L12: DENIM LONG PANTS BASIC SPRAY WHISKER SLIM PDBCSLIM:INDIGO BLUE:40:SOLID:DENIM LONG PANTS | M12: 279900 | N12: 0.7 | O12: =M12-(M12*N12) -> 83970 | P12: PERCENTAGE
A13: 2024 H2 DENIM D70 | B13: =B12 -> 46086 | C13: =C12 -> 46092 | D13: 3259 | E13: 333 | F13: 3 | G13: 5 | I13: COLE | J13: 15257215 | K13: PDBKREG | L13: DENIM LONG PANTS BASIC BLK REGULAR PDBKREG:BLACK:30:SOLID:DENIM LONG PANTS | M13: 279900 | N13: 0.7 | O13: =M13-(M13*N13) -> 83970 | P13: PERCENTAGE
A14: 2024 H2 DENIM D70 | B14: =B13 -> 46086 | C14: =C13 -> 46092 | D14: 3259 | E14: 333 | F14: 3 | G14: 5 | I14: COLE | J14: 15257233 | K14: PDBKREG | L14: DENIM LONG PANTS BASIC BLK REGULAR PDBKREG:BLACK:34:SOLID:DENIM LONG PANTS | M14: 279900 | N14: 0.7 | O14: =M14-(M14*N14) -> 83970 | P14: PERCENTAGE
... A59: 2024 H2 DENIM D70 | B59: =B58 -> 46086 | C59: =C58 -> 46092 | D59: 3259 | E59: 333 | F59: 3 | G59: 5 | I59: COLE | J59: 19551532 | K59: PDBCREC | L59: DENIM LONG PANTS BASIC REGULAR REC CTN WHISKER SPRAY PDBCREC:DARK DENIM:40:SOLID:DENIM LONG PANTS | M59: 279900 | N59: 0.7 | O59: =M59-(M59*N59) -> 83970 | P59: PERCENTAGE

Sheet 25 H1 WVN SHORT WVN PANT D70
A1: ACARA | B1: FROM DATE | C1: TO DATE | D1: DEPT | E1: WORLD | F1: DIVISION | G1: CLASS | H1: SUPPLIER | I1: BRAND | J1: SKU | K1: ARTICLE | L1: DESCRIPTION | M1: HARGA NORMAL | N1: DISKON | O1: HARGA PROMO | P1: DISCOUNT TYPE
A2: 2025 H1 WVN SHORT WVN PANT D70 | B2: ='2019 ALL BOTTOM D95'!B47 -> 46086 | C2: ='2019 ALL BOTTOM D95'!C47 -> 46092 | D2: 3259 | E2: 333 | F2: 3 | H2: 6 | I2: COLE | J2: 16752482 | K2: NYCPWSL01 | L2: LONG PANTS NYC WOVEN SLIM 01 NYCPWSL01:KHAKI:30:SOLID:LONG PANTS | M2: 279900 | N2: 0.7 | O2: =M2-(M2*N2) -> 83970 | P2: PERCENTAGE
A3: 2025 H1 WVN SHORT WVN PANT D70 | B3: =B2 -> 46086 | C3: =C2 -> 46092 | D3: 3259 | E3: 333 | F3: 3 | H3: 6 | I3: COLE | J3: 16752491 | K3: NYCPWSL01 | L3: LONG PANTS NYC WOVEN SLIM 01 NYCPWSL01:KHAKI:32:SOLID:LONG PANTS | M3: 279900 | N3: 0.7 | O3: =M3-(M3*N3) -> 83970 | P3: PERCENTAGE
