Workbook

Sheet NORMAL PRICE
A1: ACARA | B1: FROM DATE | C1: TO DATE | D1: DEPT | E1: WORLD | F1: DIVISION | G1: CLASS | H1: SUPPLIER | I1: BRAND | J1: SKU | K1: ARTICLE | L1: DESCRIPTION | M1: HARGA NORMAL | N1: DISKON | O1: HARGA PROMO | P1: DISCOUNT TYPE
A2: 2024-2025 ALL CLASS NORMAL PRICE | B2: 2026-03-05 | C2: 2026-03-11 | D2: 3327 | E2: 346 | F2: 5 | G2: 9 | I2: SUKO | J2: 80682455 | K2: T1J19351 | L2: T-SHIRT SS ROUND NECK SUPIMA KATUN KERAH BULAT LENGAN PENDEK T1J19351:BLACK:S:SOLID:T-SHIRT | M2: 179900 | N2: 0 | O2: NORMAL PRICE | P2: AMOUNT
A3: 2024-2025 ALL CLASS NORMAL PRICE | B3: =IF($A3<>"",$B$2,"") -> 2026-03-05 | C3: =IF($A3<>"",$C$2,"") -> 2026-03-11 | D3: 3327 | E3: 346 | F3: 5 | G3: 9 | I3: SUKO | J3: 80682464 | K3: T1J19351 | L3: T-SHIRT SS ROUND NECK SUPIMA KATUN KERAH BULAT LENGAN PENDEK T1J19351:BLACK:M:SOLID:T-SHIRT | M3: 179900 | N3: 0 | O3: NORMAL PRICE | P3: AMOUNT
A4: 2024-2025 ALL CLASS NORMAL PRICE | B4: =IF($A4<>"",$B$2,"") -> 2026-03-05 | C4: =IF($A4<>"",$C$2,"") -> 2026-03-11 | D4: 3327 | E4: 346 | F4: 5 | G4: 9 | I4: SUKO | J4: 80682473 | K4: T1J19351 | L4: T-SHIRT SS ROUND NECK SUPIMA KATUN KERAH BULAT LENGAN PENDEK T1J19351:BLACK:L:SOLID:T-SHIRT | M4: 179900 | N4: 0 | O4: NORMAL PRICE | P4: AMOUNT
A5: 2024-2025 ALL CLASS NORMAL PRICE | B5: =IF($A5<>"",$B$2,"") -> 2026-03-05 | C5: =IF($A5<>"",$C$2,"") -> 2026-03-11 | D5: 3327 | E5: 346 | F5: 5 | G5: 9 | I5: SUKO | J5: 80682482 | K5: T1J19351 | L5: T-SHIRT SS ROUND NECK SUPIMA KATUN KERAH BULAT LENGAN PENDEK T1J19351:BLACK:XL:SOLID:T-SHIRT | M5: 179900 | N5: 0 | O5: NORMAL PRICE | P5: AMOUNT
A6: 2024-2025 ALL CLASS NORMAL PRICE | B6: =IF($A6<>"",$B$2,"") -> 2026-03-05 | C6: =IF($A6<>"",$C$2,"") -> 2026-03-11 | D6: 3327 | E6: 346 | F6: 5 | G6: 9 | I6: SUKO | J6: 45312661 | K6: T1J19351 | L6: T-SHIRT SS ROUND NECK SUPIMA KATUN KERAH BULAT LENGAN PENDEK T1J19351:BROWN SUGAR:S:SOLID:T-SHIRT | M6: 179900 | N6: 0 | O6: NORMAL PRICE | P6: AMOUNT
A7: 2024-2025 ALL CLASS NORMAL PRICE | B7: =IF($A7<>"",$B$2,"") -> 2026-03-05 | C7: =IF($A7<>"",$C$2,"") -> 2026-03-11 | D7: 3327 | E7: 346 | F7: 5 | G7: 9 | I7: SUKO | J7: 45312670 | K7: T1J19351 | L7: T-SHIRT SS ROUND NECK SUPIMA KATUN KERAH BULAT LENGAN PENDEK T1J19351:BROWN SUGAR:M:SOLID:T-SHIRT | M7: 179900 | N7: 0 | O7: NORMAL PRICE | P7: AMOUNT
A8: 2024-2025 ALL CLASS NORMAL PRICE | B8: =IF($A8<>"",$B$2,"") -> 2026-03-05 | C8: =IF($A8<>"",$C$2,"") -> 2026-03-11 | D8: 3327 | E8: 346 | F8: 5 | G8: 9 | I8: SUKO | J8: 45312689 | K8: T1J19351 | L8: T-SHIRT SS ROUND NECK SUPIMA KATUN KERAH BULAT LENGAN PENDEK T1J19351:BROWN SUGAR:L:SOLID:T-SHIRT | M8: 179900 | N8: 0 | O8: NORMAL PRICE | P8: AMOUNT
A9: 2024-2025 ALL CLASS NORMAL PRICE | B9: =IF($A9<>"",$B$2,"") -> 2026-03-05 | C9: =IF($A9<>"",$C$2,"") -> 2026-03-11 | D9: 3327 | E9: 346 | F9: 5 | G9: 9 | I9: SUKO | J9: 45312698 | K9: T1J19351 | L9: T-SHIRT SS ROUND NECK SUPIMA KATUN KERAH BULAT LENGAN PENDEK T1J19351:BROWN SUGAR:XL:SOLID:T-SHIRT | M9: 179900 | N9: 0 | O9: NORMAL PRICE | P9: AMOUNT
A10: 2024-2025 ALL CLASS NORMAL PRICE | B10: =IF($A10<>"",$B$2,"") -> 2026-03-05 | C10: =IF($A10<>"",$C$2,"") -> 2026-03-11 | D10: 3327 | E10: 346 | F10: 5 | G10: 9 | I10: SUKO | J10: 45312705 | K10: T1J19351 | L10: T-SHIRT SS ROUND NECK SUPIMA KATUN KERAH BULAT LENGAN PENDEK T1J19351:CHARCOAL:S:SOLID:T-SHIRT | M10: 179900 | N10: 0 | O10: NORMAL PRICE | P10: AMOUNT
A11: 2024-2025 ALL CLASS NORMAL PRICE | B11: =IF($A11<>"",$B$2,"") -> 2026-03-05 | C11: =IF($A11<>"",$C$2,"") -> 2026-03-11 | D11: 3327 | E11: 346 | F11: 5 | G11: 9 | I11: SUKO | J11: 45312714 | K11: T1J19351 | L11: T-SHIRT SS ROUND NECK SUPIMA KATUN KERAH BULAT LENGAN PENDEK T1J19351:CHARCOAL:M:SOLID:T-SHIRT | M11: 179900 | N11: 0 | O11: NORMAL PRICE | P11: AMOUNT
A12: 2024-2025 ALL CLASS NORMAL PRICE | B12: =IF($A12<>"",$B$2,"") -> 2026-03-05 | C12: =IF($A12<>"",$C$2,"") -> 2026-03-11 | D12: 3327 | E12: 346 | F12: 5 | G12: 9 | I12: SUKO | J12: 45312723 | K12: T1J19351 | L12: T-SHIRT SS ROUND NECK SUPIMA KATUN KERAH BULAT LENGAN PENDEK T1J19351:CHARCOAL:L:SOLID:T-SHIRT | M12: 179900 | N12: 0 | O12: NORMAL PRICE | P12: AMOUNT
A13: 2024-2025 ALL CLASS NORMAL PRICE | B13: =IF($A13<>"",$B$2,"") -> 2026-03-05 | C13: =IF($A13<>"",$C$2,"") -> 2026-03-11 | D13: 3327 | E13: 346 | F13: 5 | G13: 9 | I13: SUKO | J13: 45312732 | K13: T1J19351 | L13: T-SHIRT SS ROUND NECK SUPIMA KATUN KERAH BULAT LENGAN PENDEK T1J19351:CHARCOAL:XL:SOLID:T-SHIRT | M13: 179900 | N13: 0 | O13: NORMAL PRICE | P13: AMOUNT
A14: 2024-2025 ALL CLASS NORMAL PRICE | B14: =IF($A14<>"",$B$2,"") -> 2026-03-05 | C14: =IF($A14<>"",$C$2,"") -> 2026-03-11 | D14: 3327 | E14: 346 | F14: 5 | G14: 9 | I14: SUKO | J14: 80682419 | K14: T1J19351 | L14: T-SHIRT SS ROUND NECK SUPIMA KATUN KERAH BULAT LENGAN PENDEK T1J19351:NAVY BLUE:S:SOLID:T-SHIRT | M14: 179900 | N14: 0 | O14: NORMAL PRICE | P14: AMOUNT
... A769: 2024-2025 ALL CLASS NORMAL PRICE | B769: =IF($A769<>"",$B$2,"") -> 2026-03-05 | C769: =IF($A769<>"",$C$2,"") -> 2026-03-11 | D769: 3327 | E769: 346 | F769: 5 | G769: 4 | I769: SUKO | J769: 55253386 | K769: O2M1325H11 | L769: ROMPI PARASUT O2M1325H11:WINE:XL:SOLID:ROMPI PARASUT | M769: 329900 | N769: 0 | O769: NORMAL PRICE | P769: AMOUNT
A770: 2024-2025 ALL CLASS NORMAL PRICE | B770: ='NORMAL PRICE'!$B$2 -> 2026-03-05 | C770: ='NORMAL PRICE'!$C$2 -> 2026-03-11 | D770: 3327 | E770: 346 | F770: 5 | G770: 9 | I770: SUKO | J770: 80682777 | K770: T1J17352 | L770: OVERSIZED T-SHIRT QUICK DRY KERAH BULAT LENGAN PENDEK T1J17352:BLACK:S:SOLID:OVERSIZED T-SHIRT | M770: 179900 | N770: 0 | O770: NORMAL PRICE | P770: AMOUNT
A771: 2024-2025 ALL CLASS NORMAL PRICE | B771: ='NORMAL PRICE'!$B$2 -> 2026-03-05 | C771: ='NORMAL PRICE'!$C$2 -> 2026-03-11 | D771: 3327 | E771: 346 | F771: 5 | G771: 9 | I771: SUKO | J771: 80682786 | K771: T1J17352 | L771: OVERSIZED T-SHIRT QUICK DRY KERAH BULAT LENGAN PENDEK T1J17352:BLACK:M:SOLID:OVERSIZED T-SHIRT | M771: 179900 | N771: 0 | O771: NORMAL PRICE | P771: AMOUNT
A772: 2024-2025 ALL CLASS NORMAL PRICE | B772: ='NORMAL PRICE'!$B$2 -> 2026-03-05 | C772: ='NORMAL PRICE'!$C$2 -> 2026-03-11 | D772: 3327 | E772: 346 | F772: 5 | G772: 9 | I772: SUKO | J772: 80682795 | K772: T1J17352 | L772: OVERSIZED T-SHIRT QUICK DRY KERAH BULAT LENGAN PENDEK T1J17352:BLACK:L:SOLID:OVERSIZED T-SHIRT | M772: 179900 | N772: 0 | O772: NORMAL PRICE | P772: AMOUNT
A773: 2024-2025 ALL CLASS NORMAL PRICE | B773: ='NORMAL PRICE'!$B$2 -> 2026-03-05 | C773: ='NORMAL PRICE'!$C$2 -> 2026-03-11 | D773: 3327 | E773: 346 | F773: 5 | G773: 9 | I773: SUKO | J773: 80682802 | K773: T1J17352 | L773: OVERSIZED T-SHIRT QUICK DRY KERAH BULAT LENGAN PENDEK T1J17352:BLACK:XL:SOLID:OVERSIZED T-SHIRT | M773: 179900 | N773: 0 | O773: NORMAL PRICE | P773: AMOUNT
A774: 2024-2025 ALL CLASS NORMAL PRICE | B774: ='NORMAL PRICE'!$B$2 -> 2026-03-05 | C774: ='NORMAL PRICE'!$C$2 -> 2026-03-11 | D774: 3327 | E774: 346 | F774: 5 | G774: 9 | I774: SUKO | J774: 53340973 | K774: T1J17352 | L774: OVERSIZED T-SHIRT QUICK DRY KERAH BULAT LENGAN PENDEK T1J17352:CERAMIC:S:SOLID:OVERSIZED T-SHIRT | M774: 179900 | N774: 0 | O774: NORMAL PRICE | P774: AMOUNT
A775: 2024-2025 ALL CLASS NORMAL PRICE | B775: ='NORMAL PRICE'!$B$2 -> 2026-03-05 | C775: ='NORMAL PRICE'!$C$2 -> 2026-03-11 | D775: 3327 | E775: 346 | F775: 5 | G775: 9 | I775: SUKO | J775: 53340982 | K775: T1J17352 | L775: OVERSIZED T-SHIRT QUICK DRY KERAH BULAT LENGAN PENDEK T1J17352:CERAMIC:M:SOLID:OVERSIZED T-SHIRT | M775: 179900 | N775: 0 | O775: NORMAL PRICE | P775: AMOUNT
A776: 2024-2025 ALL CLASS NORMAL PRICE | B776: ='NORMAL PRICE'!$B$2 -> 2026-03-05 | C776: ='NORMAL PRICE'!$C$2 -> 2026-03-11 | D776: 3327 | E776: 346 | F776: 5 | G776: 9 | I776: SUKO | J776: 53340991 | K776: T1J17352 | L776: OVERSIZED T-SHIRT QUICK DRY KERAH BULAT LENGAN PENDEK T1J17352:CERAMIC:L:SOLID:OVERSIZED T-SHIRT | M776: 179900 | N776: 0 | O776: NORMAL PRICE | P776: AMOUNT
A777: 2024-2025 ALL CLASS NORMAL PRICE | B777: ='NORMAL PRICE'!$B$2 -> 2026-03-05 | C777: ='NORMAL PRICE'!$C$2 -> 2026-03-11 | D777: 3327 | E777: 346 | F777: 5 | G777: 9 | I777: SUKO | J777: 53341007 | K777: T1J17352 | L777: OVERSIZED T-SHIRT QUICK DRY KERAH BULAT LENGAN PENDEK T1J17352:CERAMIC:XL:SOLID:OVERSIZED T-SHIRT | M777: 179900 | N777: 0 | O777: NORMAL PRICE | P777: AMOUNT
A778: 2024-2025 ALL CLASS NORMAL PRICE | B778: ='NORMAL PRICE'!$B$2 -> 2026-03-05 | C778: ='NORMAL PRICE'!$C$2 -> 2026-03-11 | D778: 3327 | E778: 346 | F778: 5 | G778: 9 | I778: SUKO | J778: 68117857 | K778: T1J17352 | L778: OVERSIZED T-SHIRT QUICK DRY KERAH BULAT LENGAN PENDEK T1J17352:EGGPLANT:S:SOLID:OVERSIZED T-SHIRT | M778: 179900 | N778: 0 | O778: NORMAL PRICE | P778: AMOUNT
A779: 2024-2025 ALL CLASS NORMAL PRICE | B779: ='NORMAL PRICE'!$B$2 -> 2026-03-05 | C779: ='NORMAL PRICE'!$C$2 -> 2026-03-11 | D779: 3327 | E779: 346 | F779: 5 | G779: 9 | I779: SUKO | J779: 68117866 | K779: T1J17352 | L779: OVERSIZED T-SHIRT QUICK DRY KERAH BULAT LENGAN PENDEK T1J17352:EGGPLANT:M:SOLID:OVERSIZED T-SHIRT | M779: 179900 | N779: 0 | O779: NORMAL PRICE | P779: AMOUNT
A780: 2024-2025 ALL CLASS NORMAL PRICE | B780: ='NORMAL PRICE'!$B$2 -> 2026-03-05 | C780: ='NORMAL PRICE'!$C$2 -> 2026-03-11 | D780: 3327 | E780: 346 | F780: 5 | G780: 9 | I780: SUKO | J780: 68117875 | K780: T1J17352 | L780: OVERSIZED T-SHIRT QUICK DRY KERAH BULAT LENGAN PENDEK T1J17352:EGGPLANT:L:SOLID:OVERSIZED T-SHIRT | M780: 179900 | N780: 0 | O780: NORMAL PRICE | P780: AMOUNT
A781: 2024-2025 ALL CLASS NORMAL PRICE | B781: ='NORMAL PRICE'!$B$2 -> 2026-03-05 | C781: ='NORMAL PRICE'!$C$2 -> 2026-03-11 | D781: 3327 | E781: 346 | F781: 5 | G781: 9 | I781: SUKO | J781: 68117884 | K781: T1J17352 | L781: OVERSIZED T-SHIRT QUICK DRY KERAH BULAT LENGAN PENDEK T1J17352:EGGPLANT:XL:SOLID:OVERSIZED T-SHIRT | M781: 179900 | N781: 0 | O781: NORMAL PRICE | P781: AMOUNT
... A878: 2024-2025 ALL CLASS NORMAL PRICE | B878: ='NORMAL PRICE'!$B$2 -> 2026-03-05 | C878: ='NORMAL PRICE'!$C$2 -> 2026-03-11 | D878: 3327 | E878: 346 | F878: 5 | G878: 6 | I878: SUKO | J878: 68181831 | K878: W2M1656A3 | L878: CELANA PANJANG RELAX W2M1656A3:WOOD BROWN:XL:SOLID:CELANA PANJANG RELAX | M878: 349900 | N878: 0 | O878: NORMAL PRICE | P878: AMOUNT

Sheet SP299
A1: ACARA | B1: FROM DATE | C1: TO DATE | D1: DEPT | E1: WORLD | F1: DIVISION | G1: CLASS | H1: SUPPLIER | I1: BRAND | J1: SKU | K1: ARTICLE | L1: DESCRIPTION | M1: HARGA NORMAL | N1: DISKON | O1: HARGA PROMO | P1: DISCOUNT TYPE
A2: 2024-2025 OUTERWEAR, DENIM BOTTOM SP299 | B2: ='NORMAL PRICE'!$B$2 -> 2026-03-05 | C2: ='NORMAL PRICE'!$C$2 -> 2026-03-11 | D2: 3327 | E2: 346 | F2: 5 | G2: 4 | I2: SUKO | J2: 15730006 | K2: O2M134A5 | L2: JAKET RILEKS RELAXED JACKET KNIT TWILL OUTERWEAR JERSEY LENGAN PANJANG O2M134A5:BLACK:S:SOLID:JAKET | M2: 329900 | N2: SP | O2: 299000 | P2: SPECIAL PRICE
A3: 2024-2025 OUTERWEAR, DENIM BOTTOM SP299 | B3: ='NORMAL PRICE'!$B$2 -> 2026-03-05 | C3: ='NORMAL PRICE'!$C$2 -> 2026-03-11 | D3: 3327 | E3: 346 | F3: 5 | G3: 4 | I3: SUKO | J3: 15730015 | K3: O2M134A5 | L3: JAKET RILEKS RELAXED JACKET KNIT TWILL OUTERWEAR JERSEY LENGAN PANJANG O2M134A5:BLACK:M:SOLID:JAKET | M3: 329900 | N3: SP | O3: 299000 | P3: SPECIAL PRICE
A4: 2024-2025 OUTERWEAR, DENIM BOTTOM SP299 | B4: ='NORMAL PRICE'!$B$2 -> 2026-03-05 | C4: ='NORMAL PRICE'!$C$2 -> 2026-03-11 | D4: 3327 | E4: 346 | F4: 5 | G4: 4 | I4: SUKO | J4: 15730024 | K4: O2M134A5 | L4: JAKET RILEKS RELAXED JACKET KNIT TWILL OUTERWEAR JERSEY LENGAN PANJANG O2M134A5:BLACK:L:SOLID:JAKET | M4: 329900 | N4: SP | O4: 299000 | P4: SPECIAL PRICE
A5: 2024-2025 OUTERWEAR, DENIM BOTTOM SP299 | B5: ='NORMAL PRICE'!$B$2 -> 2026-03-05 | C5: ='NORMAL PRICE'!$C$2 -> 2026-03-11 | D5: 3327 | E5: 346 | F5: 5 | G5: 4 | I5: SUKO | J5: 15730033 | K5: O2M134A5 | L5: JAKET RILEKS RELAXED JACKET KNIT TWILL OUTERWEAR JERSEY LENGAN PANJANG O2M134A5:BLACK:XL:SOLID:JAKET | M5: 329900 | N5: SP | O5: 299000 | P5: SPECIAL PRICE
A6: 2024-2025 OUTERWEAR, DENIM BOTTOM SP299 | B6: ='NORMAL PRICE'!$B$2 -> 2026-03-05 | C6: ='NORMAL PRICE'!$C$2 -> 2026-03-11 | D6: 3327 | E6: 346 | F6: 5 | G6: 4 | I6: SUKO | J6: 15729965 | K6: O2M134A5 | L6: JAKET RILEKS RELAXED JACKET KNIT TWILL OUTERWEAR JERSEY LENGAN PANJANG O2M134A5:KHAKI:S:SOLID:JAKET | M6: 329900 | N6: SP | O6: 299000 | P6: SPECIAL PRICE
A7: 2024-2025 OUTERWEAR, DENIM BOTTOM SP299 | B7: ='NORMAL PRICE'!$B$2 -> 2026-03-05 | C7: ='NORMAL PRICE'!$C$2 -> 2026-03-11 | D7: 3327 | E7: 346 | F7: 5 | G7: 4 | I7: SUKO | J7: 15729974 | K7: O2M134A5 | L7: JAKET RILEKS RELAXED JACKET KNIT TWILL OUTERWEAR JERSEY LENGAN PANJANG O2M134A5:KHAKI:M:SOLID:JAKET | M7: 329900 | N7: SP | O7: 299000 | P7: SPECIAL PRICE
A8: 2024-2025 OUTERWEAR, DENIM BOTTOM SP299 | B8: ='NORMAL PRICE'!$B$2 -> 2026-03-05 | C8: ='NORMAL PRICE'!$C$2 -> 2026-03-11 | D8: 3327 | E8: 346 | F8: 5 | G8: 4 | I8: SUKO | J8: 15729983 | K8: O2M134A5 | L8: JAKET RILEKS RELAXED JACKET KNIT TWILL OUTERWEAR JERSEY LENGAN PANJANG O2M134A5:KHAKI:L:SOLID:JAKET | M8: 329900 | N8: SP | O8: 299000 | P8: SPECIAL PRICE
A9: 2024-2025 OUTERWEAR, DENIM BOTTOM SP299 | B9: ='NORMAL PRICE'!$B$2 -> 2026-03-05 | C9: ='NORMAL PRICE'!$C$2 -> 2026-03-11 | D9: 3327 | E9: 346 | F9: 5 | G9: 4 | I9: SUKO | J9: 15729992 | K9: O2M134A5 | L9: JAKET RILEKS RELAXED JACKET KNIT TWILL OUTERWEAR JERSEY LENGAN PANJANG O2M134A5:KHAKI:XL:SOLID:JAKET | M9: 329900 | N9: SP | O9: 299000 | P9: SPECIAL PRICE
A10: 2024-2025 OUTERWEAR, DENIM BOTTOM SP299 | B10: ='NORMAL PRICE'!$B$2 -> 2026-03-05 | C10: ='NORMAL PRICE'!$C$2 -> 2026-03-11 | D10: 3327 | E10: 346 | F10: 5 | G10: 4 | I10: SUKO | J10: 45313428 | K10: O2M134A5 | L10: JAKET RILEKS RELAXED JACKET KNIT TWILL OUTERWEAR JERSEY LENGAN PANJANG O2M134A5:NAVY BLUE:S:SOLID:JA | M10: 329900 | N10: SP | O10: 299000 | P10: SPECIAL PRICE
A11: 2024-2025 OUTERWEAR, DENIM BOTTOM SP299 | B11: ='NORMAL PRICE'!$B$2 -> 2026-03-05 | C11: ='NORMAL PRICE'!$C$2 -> 2026-03-11 | D11: 3327 | E11: 346 | F11: 5 | G11: 4 | I11: SUKO | J11: 45313437 | K11: O2M134A5 | L11: JAKET RILEKS RELAXED JACKET KNIT TWILL OUTERWEAR JERSEY LENGAN PANJANG O2M134A5:NAVY BLUE:M:SOLID:JA | M11: 329900 | N11: SP | O11: 299000 | P11: SPECIAL PRICE
A12: 2024-2025 OUTERWEAR, DENIM BOTTOM SP299 | B12: ='NORMAL PRICE'!$B$2 -> 2026-03-05 | C12: ='NORMAL PRICE'!$C$2 -> 2026-03-11 | D12: 3327 | E12: 346 | F12: 5 | G12: 4 | I12: SUKO | J12: 45313446 | K12: O2M134A5 | L12: JAKET RILEKS RELAXED JACKET KNIT TWILL OUTERWEAR JERSEY LENGAN PANJANG O2M134A5:NAVY BLUE:L:SOLID:JA | M12: 329900 | N12: SP | O12: 299000 | P12: SPECIAL PRICE
A13: 2024-2025 OUTERWEAR, DENIM BOTTOM SP299 | B13: ='NORMAL PRICE'!$B$2 -> 2026-03-05 | C13: ='NORMAL PRICE'!$C$2 -> 2026-03-11 | D13: 3327 | E13: 346 | F13: 5 | G13: 4 | I13: SUKO | J13: 45313455 | K13: O2M134A5 | L13: JAKET RILEKS RELAXED JACKET KNIT TWILL OUTERWEAR JERSEY LENGAN PANJANG O2M134A5:NAVY BLUE:XL:SOLID:J | M13: 329900 | N13: SP | O13: 299000 | P13: SPECIAL PRICE
... A45: 2024-2025 OUTERWEAR, DENIM BOTTOM SP299 | B45: ='NORMAL PRICE'!$B$2 -> 2026-03-05 | C45: ='NORMAL PRICE'!$C$2 -> 2026-03-11 | D45: 3327 | E45: 346 | F45: 5 | G45: 5 | I45: SUKO | J45: 45327315 | K45: D2M6B4H4 | L45: CELANA PANJANG JEANS SLIM FIT D2M6B4H4:MEDIUM DENIM:XL:SOLID:CELANA PANJANG JEANS | M45: 399900 | N45: SP | O45: 299000 | P45: SPECIAL PRICE

Sheet SP279
A1: ACARA | B1: FROM DATE | C1: TO DATE | D1: DEPT | E1: WORLD | F1: DIVISION | G1: CLASS | H1: SUPPLIER | I1: BRAND | J1: SKU | K1: ARTICLE | L1: DESCRIPTION | M1: HARGA NORMAL | N1: DISKON | O1: HARGA PROMO | P1: DISCOUNT TYPE
A2: 2025 KNIT BOTTOM, WOVEN BOTTOM SP279 | B2: ='NORMAL PRICE'!$B$2 -> 2026-03-05 | C2: ='NORMAL PRICE'!$C$2 -> 2026-03-11 | D2: 3327 | E2: 346 | F2: 5 | G2: 7 | I2: SUKO | J2: 53510066 | K2: K2M995D4 | L2: CELANA KARGO JERSEY K2M995D4:CHARCOAL:S:SOLID:CELANA KARGO | M2: 329900 | N2: SP | O2: 279000 | P2: SPECIAL PRICE
A3: 2025 KNIT BOTTOM, WOVEN BOTTOM SP279 | B3: ='NORMAL PRICE'!$B$2 -> 2026-03-05 | C3: ='NORMAL PRICE'!$C$2 -> 2026-03-11 | D3: 3327 | E3: 346 | F3: 5 | G3: 7 | I3: SUKO | J3: 53510075 | K3: K2M995D4 | L3: CELANA KARGO JERSEY K2M995D4:CHARCOAL:M:SOLID:CELANA KARGO | M3: 329900 | N3: SP | O3: 279000 | P3: SPECIAL PRICE
A4: 2025 KNIT BOTTOM, WOVEN BOTTOM SP279 | B4: ='NORMAL PRICE'!$B$2 -> 2026-03-05 | C4: ='NORMAL PRICE'!$C$2 -> 2026-03-11 | D4: 3327 | E4: 346 | F4: 5 | G4: 7 | I4: SUKO | J4: 53510084 | K4: K2M995D4 | L4: CELANA KARGO JERSEY K2M995D4:CHARCOAL:L:SOLID:CELANA KARGO | M4: 329900 | N4: SP | O4: 279000 | P4: SPECIAL PRICE
A5: 2025 KNIT BOTTOM, WOVEN BOTTOM SP279 | B5: ='NORMAL PRICE'!$B$2 -> 2026-03-05 | C5: ='NORMAL PRICE'!$C$2 -> 2026-03-11 | D5: 3327 | E5: 346 | F5: 5 | G5: 7 | I5: SUKO | J5: 53510093 | K5: K2M995D4 | L5: CELANA KARGO JERSEY K2M995D4:CHARCOAL:XL:SOLID:CELANA KARGO | M5: 329900 | N5: SP | O5: 279000 | P5: SPECIAL PRICE
A6: 2025 KNIT BOTTOM, WOVEN BOTTOM SP279 | B6: ='NORMAL PRICE'!$B$2 -> 2026-03-05 | C6: ='NORMAL PRICE'!$C$2 -> 2026-03-11 | D6: 3327 | E6: 346 | F6: 5 | G6: 7 | I6: SUKO | J6: 53510020 | K6: K2M995D4 | L6: CELANA KARGO JERSEY K2M995D4:OFF WHITE:S:SOLID:CELANA KARGO | M6: 329900 | N6: SP | O6: 279000 | P6: SPECIAL PRICE
A7: 2025 KNIT BOTTOM, WOVEN BOTTOM SP279 | B7: ='NORMAL PRICE'!$B$2 -> 2026-03-05 | C7: ='NORMAL PRICE'!$C$2 -> 2026-03-11 | D7: 3327 | E7: 346 | F7: 5 | G7: 7 | I7: SUKO | J7: 53510039 | K7: K2M995D4 | L7: CELANA KARGO JERSEY K2M995D4:OFF WHITE:M:SOLID:CELANA KARGO | M7: 329900 | N7: SP | O7: 279000 | P7: SPECIAL PRICE
A8: 2025 KNIT BOTTOM, WOVEN BOTTOM SP279 | B8: ='NORMAL PRICE'!$B$2 -> 2026-03-05 | C8: ='NORMAL PRICE'!$C$2 -> 2026-03-11 | D8: 3327 | E8: 346 | F8: 5 | G8: 7 | I8: SUKO | J8: 53510048 | K8: K2M995D4 | L8: CELANA KARGO JERSEY K2M995D4:OFF WHITE:L:SOLID:CELANA KARGO | M8: 329900 | N8: SP | O8: 279000 | P8: SPECIAL PRICE
A9: 2025 KNIT BOTTOM, WOVEN BOTTOM SP279 | B9: ='NORMAL PRICE'!$B$2 -> 2026-03-05 | C9: ='NORMAL PRICE'!$C$2 -> 2026-03-11 | D9: 3327 | E9: 346 | F9: 5 | G9: 7 | I9: SUKO | J9: 53510057 | K9: K2M995D4 | L9: CELANA KARGO JERSEY K2M995D4:OFF WHITE:XL:SOLID:CELANA KARGO | M9: 329900 | N9: SP | O9: 279000 | P9: SPECIAL PRICE
A10: 2025 KNIT BOTTOM, WOVEN BOTTOM SP279 | B10: ='NORMAL PRICE'!$B$2 -> 2026-03-05 | C10: ='NORMAL PRICE'!$C$2 -> 2026-03-11 | D10: 3327 | E10: 346 | F10: 5 | G10: 7 | I10: SUKO | J10: 53510100 | K10: K2M995D4 | L10: CELANA KARGO JERSEY K2M995D4:OLIVE:S:SOLID:CELANA KARGO | M10: 329900 | N10: SP | O10: 279000 | P10: SPECIAL PRICE
A11: 2025 KNIT BOTTOM, WOVEN BOTTOM SP279 | B11: ='NORMAL PRICE'!$B$2 -> 2026-03-05 | C11: ='NORMAL PRICE'!$C$2 -> 2026-03-11 | D11: 3327 | E11: 346 | F11: 5 | G11: 7 | I11: SUKO | J11: 53510119 | K11: K2M995D4 | L11: CELANA KARGO JERSEY K2M995D4:OLIVE:M:SOLID:CELANA KARGO | M11: 329900 | N11: SP | O11: 279000 | P11: SPECIAL PRICE
A12: 2025 KNIT BOTTOM, WOVEN BOTTOM SP279 | B12: ='NORMAL PRICE'!$B$2 -> 2026-03-05 | C12: ='NORMAL PRICE'!$C$2 -> 2026-03-11 | D12: 3327 | E12: 346 | F12: 5 | G12: 7 | I12: SUKO | J12: 53510128 | K12: K2M995D4 | L12: CELANA KARGO JERSEY K2M995D4:OLIVE:L:SOLID:CELANA KARGO | M12: 329900 | N12: SP | O12: 279000 | P12: SPECIAL PRICE
A13: 2025 KNIT BOTTOM, WOVEN BOTTOM SP279 | B13: ='NORMAL PRICE'!$B$2 -> 2026-03-05 | C13: ='NORMAL PRICE'!$C$2 -> 2026-03-11 | D13: 3327 | E13: 346 | F13: 5 | G13: 7 | I13: SUKO | J13: 53510137 | K13: K2M995D4 | L13: CELANA KARGO JERSEY K2M995D4:OLIVE:XL:SOLID:CELANA KARGO | M13: 329900 | N13: SP | O13: 279000 | P13: SPECIAL PRICE
... A57: 2025 KNIT BOTTOM, WOVEN BOTTOM SP279 | B57: ='NORMAL PRICE'!$B$2 -> 2026-03-05 | C57: ='NORMAL PRICE'!$C$2 -> 2026-03-11 | D57: 3327 | E57: 346 | F57: 5 | G57: 6 | I57: SUKO | J57: 54822638 | K57: W2M1185G8 | L57: CELANA JOGGER RELAX STRETCH W2M1185G8:SAND:XL:SOLID:CELANA JOGGER RELAX | M57: 349000 | N57: SP | O57: 279000 | P57: SPECIAL PRICE

Sheet SP229
A1: ACARA | B1: FROM DATE | C1: TO DATE | D1: DEPT | E1: WORLD | F1: DIVISION | G1: CLASS | H1: SUPPLIER | I1: BRAND | J1: SKU | K1: ARTICLE | L1: DESCRIPTION | M1: HARGA NORMAL | N1: DISKON | O1: HARGA PROMO | P1: DISCOUNT TYPE
A2: 2025 H1 OUTERWEAR, WOVEN TOP SP229 | B2: ='NORMAL PRICE'!$B$2 -> 2026-03-05 | C2: ='NORMAL PRICE'!$C$2 -> 2026-03-11 | D2: 3327 | E2: 346 | F2: 5 | G2: 4 | I2: SUKO | J2: 53510360 | K2: O2M1035D5 | L2: JAKET RITSLETING 1/2 SWEATER O2M1035D5:BLACK:S:SOLID:JAKET RITSLETING 1/2 | M2: 279900 | N2: SP | O2: 229000 | P2: SPECIAL PRICE
A3: 2025 H1 OUTERWEAR, WOVEN TOP SP229 | B3: ='NORMAL PRICE'!$B$2 -> 2026-03-05 | C3: ='NORMAL PRICE'!$C$2 -> 2026-03-11 | D3: 3327 | E3: 346 | F3: 5 | G3: 4 | I3: SUKO | J3: 53510379 | K3: O2M1035D5 | L3: JAKET RITSLETING 1/2 SWEATER O2M1035D5:BLACK:M:SOLID:JAKET RITSLETING 1/2 | M3: 279900 | N3: SP | O3: 229000 | P3: SPECIAL PRICE
A4: 2025 H1 OUTERWEAR, WOVEN TOP SP229 | B4: ='NORMAL PRICE'!$B$2 -> 2026-03-05 | C4: ='NORMAL PRICE'!$C$2 -> 2026-03-11 | D4: 3327 | E4: 346 | F4: 5 | G4: 4 | I4: SUKO | J4: 53510388 | K4: O2M1035D5 | L4: JAKET RITSLETING 1/2 SWEATER O2M1035D5:BLACK:L:SOLID:JAKET RITSLETING 1/2 | M4: 279900 | N4: SP | O4: 229000 | P4: SPECIAL PRICE
A5: 2025 H1 OUTERWEAR, WOVEN TOP SP229 | B5: ='NORMAL PRICE'!$B$2 -> 2026-03-05 | C5: ='NORMAL PRICE'!$C$2 -> 2026-03-11 | D5: 3327 | E5: 346 | F5: 5 | G5: 4 | I5: SUKO | J5: 53510397 | K5: O2M1035D5 | L5: JAKET RITSLETING 1/2 SWEATER O2M1035D5:BLACK:XL:SOLID:JAKET RITSLETING 1/2 | M5: 279900 | N5: SP | O5: 229000 | P5: SPECIAL PRICE
A6: 2025 H1 OUTERWEAR, WOVEN TOP SP229 | B6: ='NORMAL PRICE'!$B$2 -> 2026-03-05 | C6: ='NORMAL PRICE'!$C$2 -> 2026-03-11 | D6: 3327 | E6: 346 | F6: 5 | G6: 4 | I6: SUKO | J6: 53510280 | K6: O2M1035D5 | L6: JAKET RITSLETING 1/2 SWEATER O2M1035D5:MISTY LIGHT GREY:S:SOLID:JAKET RITSLETING 1/2 | M6: 279900 | N6: SP | O6: 229000 | P6: SPECIAL PRICE
A7: 2025 H1 OUTERWEAR, WOVEN TOP SP229 | B7: ='NORMAL PRICE'!$B$2 -> 2026-03-05 | C7: ='NORMAL PRICE'!$C$2 -> 2026-03-11 | D7: 3327 | E7: 346 | F7: 5 | G7: 4 | I7: SUKO | J7: 53510299 | K7: O2M1035D5 | L7: JAKET RITSLETING 1/2 SWEATER O2M1035D5:MISTY LIGHT GREY:M:SOLID:JAKET RITSLETING 1/2 | M7: 279900 | N7: SP | O7: 229000 | P7: SPECIAL PRICE
A8: 2025 H1 OUTERWEAR, WOVEN TOP SP229 | B8: ='NORMAL PRICE'!$B$2 -> 2026-03-05 | C8: ='NORMAL PRICE'!$C$2 -> 2026-03-11 | D8: 3327 | E8: 346 | F8: 5 | G8: 4 | I8: SUKO | J8: 53510306 | K8: O2M1035D5 | L8: JAKET RITSLETING 1/2 SWEATER O2M1035D5:MISTY LIGHT GREY:L:SOLID:JAKET RITSLETING 1/2 | M8: 279900 | N8: SP | O8: 229000 | P8: SPECIAL PRICE
A9: 2025 H1 OUTERWEAR, WOVEN TOP SP229 | B9: ='NORMAL PRICE'!$B$2 -> 2026-03-05 | C9: ='NORMAL PRICE'!$C$2 -> 2026-03-11 | D9: 3327 | E9: 346 | F9: 5 | G9: 4 | I9: SUKO | J9: 53510315 | K9: O2M1035D5 | L9: JAKET RITSLETING 1/2 SWEATER O2M1035D5:MISTY LIGHT GREY:XL:SOLID:JAKET RITSLETING 1/2 | M9: 279900 | N9: SP | O9: 229000 | P9: SPECIAL PRICE
A10: 2025 H1 OUTERWEAR, WOVEN TOP SP229 | B10: ='NORMAL PRICE'!$B$2 -> 2026-03-05 | C10: ='NORMAL PRICE'!$C$2 -> 2026-03-11 | D10: 3327 | E10: 346 | F10: 5 | G10: 4 | I10: SUKO | J10: 53510324 | K10: O2M1035D5 | L10: JAKET RITSLETING 1/2 SWEATER O2M1035D5:OFF WHITE:S:SOLID:JAKET RITSLETING 1/2 | M10: 279900 | N10: SP | O10: 229000 | P10: SPECIAL PRICE
A11: 2025 H1 OUTERWEAR, WOVEN TOP SP229 | B11: ='NORMAL PRICE'!$B$2 -> 2026-03-05 | C11: ='NORMAL PRICE'!$C$2 -> 2026-03-11 | D11: 3327 | E11: 346 | F11: 5 | G11: 4 | I11: SUKO | J11: 53510333 | K11: O2M1035D5 | L11: JAKET RITSLETING 1/2 SWEATER O2M1035D5:OFF WHITE:M:SOLID:JAKET RITSLETING 1/2 | M11: 279900 | N11: SP | O11: 229000 | P11: SPECIAL PRICE
A12: 2025 H1 OUTERWEAR, WOVEN TOP SP229 | B12: ='NORMAL PRICE'!$B$2 -> 2026-03-05 | C12: ='NORMAL PRICE'!$C$2 -> 2026-03-11 | D12: 3327 | E12: 346 | F12: 5 | G12: 4 | I12: SUKO | J12: 53510342 | K12: O2M1035D5 | L12: JAKET RITSLETING 1/2 SWEATER O2M1035D5:OFF WHITE:L:SOLID:JAKET RITSLETING 1/2 | M12: 279900 | N12: SP | O12: 229000 | P12: SPECIAL PRICE
A13: 2025 H1 OUTERWEAR, WOVEN TOP SP229 | B13: ='NORMAL PRICE'!$B$2 -> 2026-03-05 | C13: ='NORMAL PRICE'!$C$2 -> 2026-03-11 | D13: 3327 | E13: 346 | F13: 5 | G13: 4 | I13: SUKO | J13: 53510351 | K13: O2M1035D5 | L13: JAKET RITSLETING 1/2 SWEATER O2M1035D5:OFF WHITE:XL:SOLID:JAKET RITSLETING 1/2 | M13: 279900 | N13: SP | O13: 229000 | P13: SPECIAL PRICE
... A41: 2025 H1 OUTERWEAR, WOVEN TOP SP229 | B41: ='NORMAL PRICE'!$B$2 -> 2026-03-05 | C41: ='NORMAL PRICE'!$C$2 -> 2026-03-11 | D41: 3327 | E41: 346 | F41: 5 | G41: 4 | I41: SUKO | J41: 53510271 | K41: O2M1015D5 | L41: JAKET GRAPHIC COACH PRINT O2M1015D5:NAVY BLUE:XL:GRAPHIC:JAKET GRAPHIC | M41: 399900 | N41: SP | O41: 229000 | P41: SPECIAL PRICE

Sheet SP169
A1: ACARA | B1: FROM DATE | C1: TO DATE | D1: DEPT | E1: WORLD | F1: DIVISION | G1: CLASS | H1: SUPPLIER | I1: BRAND | J1: SKU | K1: ARTICLE | L1: DESCRIPTION | M1: HARGA NORMAL | N1: DISKON | O1: HARGA PROMO | P1: DISCOUNT TYPE
A2: 2025 H1 DENIM BOTTOM SP169 | B2: ='NORMAL PRICE'!$B$2 -> 2026-03-05 | C2: ='NORMAL PRICE'!$C$2 -> 2026-03-11 | D2: 3327 | E2: 346 | F2: 5 | G2: 5 | I2: SUKO | J2: 53509827 | K2: D1M1025D4 | L2: CELANA PENDEK RELAX CHAMBRAY D1M1025D4:LIGHT BLUE:S:SOLID:CELANA PENDEK RELAX | M2: 299900 | N2: SP | O2: 169000 | P2: SPECIAL PRICE
A3: 2025 H1 DENIM BOTTOM SP169 | B3: ='NORMAL PRICE'!$B$2 -> 2026-03-05 | C3: ='NORMAL PRICE'!$C$2 -> 2026-03-11 | D3: 3327 | E3: 346 | F3: 5 | G3: 5 | I3: SUKO | J3: 53509836 | K3: D1M1025D4 | L3: CELANA PENDEK RELAX CHAMBRAY D1M1025D4:LIGHT BLUE:M:SOLID:CELANA PENDEK RELAX | M3: 299900 | N3: SP | O3: 169000 | P3: SPECIAL PRICE
A4: 2025 H1 DENIM BOTTOM SP169 | B4: ='NORMAL PRICE'!$B$2 -> 2026-03-05 | C4: ='NORMAL PRICE'!$C$2 -> 2026-03-11 | D4: 3327 | E4: 346 | F4: 5 | G4: 5 | I4: SUKO | J4: 53509845 | K4: D1M1025D4 | L4: CELANA PENDEK RELAX CHAMBRAY D1M1025D4:LIGHT BLUE:L:SOLID:CELANA PENDEK RELAX | M4: 299900 | N4: SP | O4: 169000 | P4: SPECIAL PRICE
A5: 2025 H1 DENIM BOTTOM SP169 | B5: ='NORMAL PRICE'!$B$2 -> 2026-03-05 | C5: ='NORMAL PRICE'!$C$2 -> 2026-03-11 | D5: 3327 | E5: 346 | F5: 5 | G5: 5 | I5: SUKO | J5: 53509854 | K5: D1M1025D4 | L5: CELANA PENDEK RELAX CHAMBRAY D1M1025D4:LIGHT BLUE:XL:SOLID:CELANA PENDEK RELAX | M5: 299900 | N5: SP | O5: 169000 | P5: SPECIAL PRICE
A6: 2025 H1 DENIM BOTTOM SP169 | B6: ='NORMAL PRICE'!$B$2 -> 2026-03-05 | C6: ='NORMAL PRICE'!$C$2 -> 2026-03-11 | D6: 3327 | E6: 346 | F6: 5 | G6: 5 | I6: SUKO | J6: 53509783 | K6: D1M1025D4 | L6: CELANA PENDEK RELAX CHAMBRAY D1M1025D4:PASTEL GREY:S:SOLID:CELANA PENDEK RELAX | M6: 299900 | N6: SP | O6: 169000 | P6: SPECIAL PRICE
A7: 2025 H1 DENIM BOTTOM SP169 | B7: ='NORMAL PRICE'!$B$2 -> 2026-03-05 | C7: ='NORMAL PRICE'!$C$2 -> 2026-03-11 | D7: 3327 | E7: 346 | F7: 5 | G7: 5 | I7: SUKO | J7: 53509792 | K7: D1M1025D4 | L7: CELANA PENDEK RELAX CHAMBRAY D1M1025D4:PASTEL GREY:M:SOLID:CELANA PENDEK RELAX | M7: 299900 | N7: SP | O7: 169000 | P7: SPECIAL PRICE
A8: 2025 H1 DENIM BOTTOM SP169 | B8: ='NORMAL PRICE'!$B$2 -> 2026-03-05 | C8: ='NORMAL PRICE'!$C$2 -> 2026-03-11 | D8: 3327 | E8: 346 | F8: 5 | G8: 5 | I8: SUKO | J8: 53509809 | K8: D1M1025D4 | L8: CELANA PENDEK RELAX CHAMBRAY D1M1025D4:PASTEL GREY:L:SOLID:CELANA PENDEK RELAX | M8: 299900 | N8: SP | O8: 169000 | P8: SPECIAL PRICE
A9: 2025 H1 DENIM BOTTOM SP169 | B9: ='NORMAL PRICE'!$B$2 -> 2026-03-05 | C9: ='NORMAL PRICE'!$C$2 -> 2026-03-11 | D9: 3327 | E9: 346 | F9: 5 | G9: 5 | I9: SUKO | J9: 53509818 | K9: D1M1025D4 | L9: CELANA PENDEK RELAX CHAMBRAY D1M1025D4:PASTEL GREY:XL:SOLID:CELANA PENDEK RELAX | M9: 299900 | N9: SP | O9: 169000 | P9: SPECIAL PRICE

Sheet SP149
A1: ACARA | B1: FROM DATE | C1: TO DATE | D1: DEPT | E1: WORLD | F1: DIVISION | G1: CLASS | H1: SUPPLIER | I1: BRAND | J1: SKU | K1: ARTICLE | L1: DESCRIPTION | M1: HARGA NORMAL | N1: DISKON | O1: HARGA PROMO | P1: DISCOUNT TYPE
A2: 2024-2025 ACCESSORIES, WOVEN TOP, OUTERWEAR, DENIM BOTTOM, WOVEN BOTTOM SP149 | B2: ='NORMAL PRICE'!$B$2 -> 2026-03-05 | C2: ='NORMAL PRICE'!$C$2 -> 2026-03-11 | D2: 3327 | E2: 346 | F2: 5 | G2: 5 | I2: SUKO | J2: 16016152 | K2: D2M194A4 | L2: CELANA PANJANG JEANS DENIM PANTS BOTTOM SLIM FIT D2M194A4:BLACK:30:SOLID:CELANA PANJANG JEANS | M2: 299900 | N2: SP | O2: 149000 | P2: SPECIAL PRICE
A3: 2024-2025 ACCESSORIES, WOVEN TOP, OUTERWEAR, DENIM BOTTOM, WOVEN BOTTOM SP149 | B3: ='NORMAL PRICE'!$B$2 -> 2026-03-05 | C3: ='NORMAL PRICE'!$C$2 -> 2026-03-11 | D3: 3327 | E3: 346 | F3: 5 | G3: 5 | I3: SUKO | J3: 16016161 | K3: D2M194A4 | L3: CELANA PANJANG JEANS DENIM PANTS BOTTOM SLIM FIT D2M194A4:BLACK:31:SOLID:CELANA PANJANG JEANS | M3: 299900 | N3: SP | O3: 149000 | P3: SPECIAL PRICE
A4: 2024-2025 ACCESSORIES, WOVEN TOP, OUTERWEAR, DENIM BOTTOM, WOVEN BOTTOM SP149 | B4: ='NORMAL PRICE'!$B$2 -> 2026-03-05 | C4: ='NORMAL PRICE'!$C$2 -> 2026-03-11 | D4: 3327 | E4: 346 | F4: 5 | G4: 5 | I4: SUKO | J4: 16016170 | K4: D2M194A4 | L4: CELANA PANJANG JEANS DENIM PANTS BOTTOM SLIM FIT D2M194A4:BLACK:32:SOLID:CELANA PANJANG JEANS | M4: 299900 | N4: SP | O4: 149000 | P4: SPECIAL PRICE
A5: 2024-2025 ACCESSORIES, WOVEN TOP, OUTERWEAR, DENIM BOTTOM, WOVEN BOTTOM SP149 | B5: ='NORMAL PRICE'!$B$2 -> 2026-03-05 | C5: ='NORMAL PRICE'!$C$2 -> 2026-03-11 | D5: 3327 | E5: 346 | F5: 5 | G5: 5 | I5: SUKO | J5: 16016189 | K5: D2M194A4 | L5: CELANA PANJANG JEANS DENIM PANTS BOTTOM SLIM FIT D2M194A4:BLACK:34:SOLID:CELANA PANJANG JEANS | M5: 299900 | N5: SP | O5: 149000 | P5: SPECIAL PRICE
A6: 2024-2025 ACCESSORIES, WOVEN TOP, OUTERWEAR, DENIM BOTTOM, WOVEN BOTTOM SP149 | B6: ='NORMAL PRICE'!$B$2 -> 2026-03-05 | C6: ='NORMAL PRICE'!$C$2 -> 2026-03-11 | D6: 3327 | E6: 346 | F6: 5 | G6: 5 | I6: SUKO | J6: 16016198 | K6: D2M194A4 | L6: CELANA PANJANG JEANS DENIM PANTS BOTTOM SLIM FIT D2M194A4:BLACK:35:SOLID:CELANA PANJANG JEANS | M6: 299900 | N6: SP | O6: 149000 | P6: SPECIAL PRICE
A7: 2024-2025 ACCESSORIES, WOVEN TOP, OUTERWEAR, DENIM BOTTOM, WOVEN BOTTOM SP149 | B7: ='NORMAL PRICE'!$B$2 -> 2026-03-05 | C7: ='NORMAL PRICE'!$C$2 -> 2026-03-11 | D7: 3327 | E7: 346 | F7: 5 | G7: 5 | I7: SUKO | J7: 16016205 | K7: D2M194A4 | L7: CELANA PANJANG JEANS DENIM PANTS BOTTOM SLIM FIT D2M194A4:BLACK:36:SOLID:CELANA PANJANG JEANS | M7: 299900 | N7: SP | O7: 149000 | P7: SPECIAL PRICE
A8: 2024-2025 ACCESSORIES, WOVEN TOP, OUTERWEAR, DENIM BOTTOM, WOVEN BOTTOM SP149 | B8: ='NORMAL PRICE'!$B$2 -> 2026-03-05 | C8: ='NORMAL PRICE'!$C$2 -> 2026-03-11 | D8: 3327 | E8: 346 | F8: 5 | G8: 5 | I8: SUKO | J8: 16016090 | K8: D2M194A4 | L8: CELANA PANJANG JEANS DENIM PANTS BOTTOM SLIM FIT D2M194A4:MEDIUM DENIM:30:SOLID:CELANA PANJANG JEANS | M8: 299900 | N8: SP | O8: 149000 | P8: SPECIAL PRICE
A9: 2024-2025 ACCESSORIES, WOVEN TOP, OUTERWEAR, DENIM BOTTOM, WOVEN BOTTOM SP149 | B9: ='NORMAL PRICE'!$B$2 -> 2026-03-05 | C9: ='NORMAL PRICE'!$C$2 -> 2026-03-11 | D9: 3327 | E9: 346 | F9: 5 | G9: 5 | I9: SUKO | J9: 16016107 | K9: D2M194A4 | L9: CELANA PANJANG JEANS DENIM PANTS BOTTOM SLIM FIT D2M194A4:MEDIUM DENIM:31:SOLID:CELANA PANJANG JEANS | M9: 299900 | N9: SP | O9: 149000 | P9: SPECIAL PRICE
A10: 2024-2025 ACCESSORIES, WOVEN TOP, OUTERWEAR, DENIM BOTTOM, WOVEN BOTTOM SP149 | B10: ='NORMAL PRICE'!$B$2 -> 2026-03-05 | C10: ='NORMAL PRICE'!$C$2 -> 2026-03-11 | D10: 3327 | E10: 346 | F10: 5 | G10: 5 | I10: SUKO | J10: 16016116 | K10: D2M194A4 | L10: CELANA PANJANG JEANS DENIM PANTS BOTTOM SLIM FIT D2M194A4:MEDIUM DENIM:32:SOLID:CELANA PANJANG JEANS | M10: 299900 | N10: SP | O10: 149000 | P10: SPECIAL PRICE
A11: 2024-2025 ACCESSORIES, WOVEN TOP, OUTERWEAR, DENIM BOTTOM, WOVEN BOTTOM SP149 | B11: ='NORMAL PRICE'!$B$2 -> 2026-03-05 | C11: ='NORMAL PRICE'!$C$2 -> 2026-03-11 | D11: 3327 | E11: 346 | F11: 5 | G11: 5 | I11: SUKO | J11: 16016125 | K11: D2M194A4 | L11: CELANA PANJANG JEANS DENIM PANTS BOTTOM SLIM FIT D2M194A4:MEDIUM DENIM:34:SOLID:CELANA PANJANG JEANS | M11: 299900 | N11: SP | O11: 149000 | P11: SPECIAL PRICE
A12: 2024-2025 ACCESSORIES, WOVEN TOP, OUTERWEAR, DENIM BOTTOM, WOVEN BOTTOM SP149 | B12: ='NORMAL PRICE'!$B$2 -> 2026-03-05 | C12: ='NORMAL PRICE'!$C$2 -> 2026-03-11 | D12: 3327 | E12: 346 | F12: 5 | G12: 5 | I12: SUKO | J12: 16016134 | K12: D2M194A4 | L12: CELANA PANJANG JEANS DENIM PANTS BOTTOM SLIM FIT D2M194A4:MEDIUM DENIM:35:SOLID:CELANA PANJANG JEANS | M12: 299900 | N12: SP | O12: 149000 | P12: SPECIAL PRICE
A13: 2024-2025 ACCESSORIES, WOVEN TOP, OUTERWEAR, DENIM BOTTOM, WOVEN BOTTOM SP149 | B13: ='NORMAL PRICE'!$B$2 -> 2026-03-05 | C13: ='NORMAL PRICE'!$C$2 -> 2026-03-11 | D13: 3327 | E13: 346 | F13: 5 | G13: 5 | I13: SUKO | J13: 16016143 | K13: D2M194A4 | L13: CELANA PANJANG JEANS DENIM PANTS BOTTOM SLIM FIT D2M194A4:MEDIUM DENIM:36:SOLID:CELANA PANJANG JEANS | M13: 299900 | N13: SP | O13: 149000 | P13: SPECIAL PRICE
... A110: 2024-2025 ACCESSORIES, WOVEN TOP, OUTERWEAR, DENIM BOTTOM, WOVEN BOTTOM SP149 | B110: ='NORMAL PRICE'!$B$2 -> 2026-03-05 | C110: ='NORMAL PRICE'!$C$2 -> 2026-03-11 | D110: 3327 | E110: 346 | F110: 5 | G110: 5 | I110: SUKO | J110: 45344252 | K110: D2M1A4JA | L110: CELANA PANJANG JEANS SLIM FIT D2M1A4JA:BLACK:36:SOLID:CELANA PANJANG JEANS | M110: 299900 | N110: SP | O110: 149000 | P110: SPECIAL PRICE

Sheet SP129
A1: ACARA | B1: FROM DATE | C1: TO DATE | D1: DEPT | E1: WORLD | F1: DIVISION | G1: CLASS | H1: SUPPLIER | I1: BRAND | J1: SKU | K1: ARTICLE | L1: DESCRIPTION | M1: HARGA NORMAL | N1: DISKON | O1: HARGA PROMO | P1: DISCOUNT TYPE
A2: 2024-2025 OUTERWEAR, T-SHIRT, KI, KNIT TOP SP129 | B2: ='NORMAL PRICE'!$B$2 -> 2026-03-05 | C2: ='NORMAL PRICE'!$C$2 -> 2026-03-11 | D2: 3327 | E2: 346 | F2: 5 | G2: 4 | I2: SUKO | J2: 22412462 | K2: O1M4C4J1 | L2: SWEATER GRAPHIC SWEATSHIRT PRINT KERAH BULAT LENGAN PANJANG O1M4C4J1:PASTEL GREEN:S:GRAPHIC:SWEATER | M2: 199900 | N2: SP | O2: 129000 | P2: SPECIAL PRICE
A3: 2024-2025 OUTERWEAR, T-SHIRT, KI, KNIT TOP SP129 | B3: ='NORMAL PRICE'!$B$2 -> 2026-03-05 | C3: ='NORMAL PRICE'!$C$2 -> 2026-03-11 | D3: 3327 | E3: 346 | F3: 5 | G3: 4 | I3: SUKO | J3: 22412471 | K3: O1M4C4J1 | L3: SWEATER GRAPHIC SWEATSHIRT PRINT KERAH BULAT LENGAN PANJANG O1M4C4J1:PASTEL GREEN:M:GRAPHIC:SWEATER | M3: 199900 | N3: SP | O3: 129000 | P3: SPECIAL PRICE
A4: 2024-2025 OUTERWEAR, T-SHIRT, KI, KNIT TOP SP129 | B4: ='NORMAL PRICE'!$B$2 -> 2026-03-05 | C4: ='NORMAL PRICE'!$C$2 -> 2026-03-11 | D4: 3327 | E4: 346 | F4: 5 | G4: 4 | I4: SUKO | J4: 22412480 | K4: O1M4C4J1 | L4: SWEATER GRAPHIC SWEATSHIRT PRINT KERAH BULAT LENGAN PANJANG O1M4C4J1:PASTEL GREEN:L:GRAPHIC:SWEATER | M4: 199900 | N4: SP | O4: 129000 | P4: SPECIAL PRICE
A5: 2024-2025 OUTERWEAR, T-SHIRT, KI, KNIT TOP SP129 | B5: ='NORMAL PRICE'!$B$2 -> 2026-03-05 | C5: ='NORMAL PRICE'!$C$2 -> 2026-03-11 | D5: 3327 | E5: 346 | F5: 5 | G5: 4 | I5: SUKO | J5: 22412499 | K5: O1M4C4J1 | L5: SWEATER GRAPHIC SWEATSHIRT PRINT KERAH BULAT LENGAN PANJANG O1M4C4J1:PASTEL GREEN:XL:GRAPHIC:SWEATE | M5: 199900 | N5: SP | O5: 129000 | P5: SPECIAL PRICE
A6: 2024-2025 OUTERWEAR, T-SHIRT, KI, KNIT TOP SP129 | B6: ='NORMAL PRICE'!$B$2 -> 2026-03-05 | C6: ='NORMAL PRICE'!$C$2 -> 2026-03-11 | D6: 3327 | E6: 346 | F6: 5 | G6: 4 | I6: SUKO | J6: 22412453 | K6: O1M4C4J1 | L6: SWEATER GRAPHIC SWEATSHIRT PRINT KERAH BULAT LENGAN PANJANG O1M4C4J1:PASTEL GREEN:XS:GRAPHIC:SWEATE | M6: 199900 | N6: SP | O6: 129000 | P6: SPECIAL PRICE
A7: 2024-2025 OUTERWEAR, T-SHIRT, KI, KNIT TOP SP129 | B7: ='NORMAL PRICE'!$B$2 -> 2026-03-05 | C7: ='NORMAL PRICE'!$C$2 -> 2026-03-11 | D7: 3327 | E7: 346 | F7: 5 | G7: 1 | I7: SUKO | J7: 53510888 | K7: T3M925D1 | L7: T-SHIRT GARIS KERAH BULAT LENGAN PANJANG T3M925D1:NAVY BLUE:S:STRIPES:T-SHIRT GARIS | M7: 179900 | N7: SP | O7: 129000 | P7: SPECIAL PRICE
A8: 2024-2025 OUTERWEAR, T-SHIRT, KI, KNIT TOP SP129 | B8: ='NORMAL PRICE'!$B$2 -> 2026-03-05 | C8: ='NORMAL PRICE'!$C$2 -> 2026-03-11 | D8: 3327 | E8: 346 | F8: 5 | G8: 1 | I8: SUKO | J8: 53510897 | K8: T3M925D1 | L8: T-SHIRT GARIS KERAH BULAT LENGAN PANJANG T3M925D1:NAVY BLUE:M:STRIPES:T-SHIRT GARIS | M8: 179900 | N8: SP | O8: 129000 | P8: SPECIAL PRICE
A9: 2024-2025 OUTERWEAR, T-SHIRT, KI, KNIT TOP SP129 | B9: ='NORMAL PRICE'!$B$2 -> 2026-03-05 | C9: ='NORMAL PRICE'!$C$2 -> 2026-03-11 | D9: 3327 | E9: 346 | F9: 5 | G9: 1 | I9: SUKO | J9: 53510904 | K9: T3M925D1 | L9: T-SHIRT GARIS KERAH BULAT LENGAN PANJANG T3M925D1:NAVY BLUE:L:STRIPES:T-SHIRT GARIS | M9: 179900 | N9: SP | O9: 129000 | P9: SPECIAL PRICE
A10: 2024-2025 OUTERWEAR, T-SHIRT, KI, KNIT TOP SP129 | B10: ='NORMAL PRICE'!$B$2 -> 2026-03-05 | C10: ='NORMAL PRICE'!$C$2 -> 2026-03-11 | D10: 3327 | E10: 346 | F10: 5 | G10: 1 | I10: SUKO | J10: 53510913 | K10: T3M925D1 | L10: T-SHIRT GARIS KERAH BULAT LENGAN PANJANG T3M925D1:NAVY BLUE:XL:STRIPES:T-SHIRT GARIS | M10: 179900 | N10: SP | O10: 129000 | P10: SPECIAL PRICE
A11: 2024-2025 OUTERWEAR, T-SHIRT, KI, KNIT TOP SP129 | B11: ='NORMAL PRICE'!$B$2 -> 2026-03-05 | C11: ='NORMAL PRICE'!$C$2 -> 2026-03-11 | D11: 3327 | E11: 346 | F11: 5 | G11: 1 | I11: SUKO | J11: 53510842 | K11: T3M925D1 | L11: T-SHIRT GARIS KERAH BULAT LENGAN PANJANG T3M925D1:OLIVE:S:STRIPES:T-SHIRT GARIS | M11: 179900 | N11: SP | O11: 129000 | P11: SPECIAL PRICE
A12: 2024-2025 OUTERWEAR, T-SHIRT, KI, KNIT TOP SP129 | B12: ='NORMAL PRICE'!$B$2 -> 2026-03-05 | C12: ='NORMAL PRICE'!$C$2 -> 2026-03-11 | D12: 3327 | E12: 346 | F12: 5 | G12: 1 | I12: SUKO | J12: 53510851 | K12: T3M925D1 | L12: T-SHIRT GARIS KERAH BULAT LENGAN PANJANG T3M925D1:OLIVE:M:STRIPES:T-SHIRT GARIS | M12: 179900 | N12: SP | O12: 129000 | P12: SPECIAL PRICE
A13: 2024-2025 OUTERWEAR, T-SHIRT, KI, KNIT TOP SP129 | B13: ='NORMAL PRICE'!$B$2 -> 2026-03-05 | C13: ='NORMAL PRICE'!$C$2 -> 2026-03-11 | D13: 3327 | E13: 346 | F13: 5 | G13: 1 | I13: SUKO | J13: 53510860 | K13: T3M925D1 | L13: T-SHIRT GARIS KERAH BULAT LENGAN PANJANG T3M925D1:OLIVE:L:STRIPES:T-SHIRT GARIS | M13: 179900 | N13: SP | O13: 129000 | P13: SPECIAL PRICE
... A232: 2024-2025 OUTERWEAR, T-SHIRT, KI, KNIT TOP SP129 | B232: ='NORMAL PRICE'!$B$2 -> 2026-03-05 | C232: ='NORMAL PRICE'!$C$2 -> 2026-03-11 | D232: 3327 | E232: 346 | F232: 5 | G232: 1 | I232: SUKO | J232: 55252789 | K232: T1M16B5G1-4 | L232: T-SHIRT OVERSIZED GRAPHIC T1M16B5G1-4:BROWN SUGAR:XL:EMBRO:T-SHIRT OVERSIZED GRAPHIC | M232: 179900 | N232: SP | O232: 129000 | P232: SPECIAL PRICE
A233: 2024-2025 OUTERWEAR, T-SHIRT, KI, KNIT TOP SP129 | B233: =IF($A233<>"",'NORMAL PRICE'!$B$2,"") -> 2026-03-05 | C233: =IF($A233<>"",'NORMAL PRICE'!$C$2,"") -> 2026-03-11 | D233: 3327 | E233: 346 | F233: 5 | G233: 2 | I233: SUKO | J233: 53781774 | K233: P1M955D6 | L233: KAOS POLO KERAH TEGAK LENGAN PENDEK P1M955D6:BLACK:S:SOLID:KAOS POLO | M233: 179900 | N233: SP | O233: 129000 | P233: SPECIAL PRICE
A234: 2024-2025 OUTERWEAR, T-SHIRT, KI, KNIT TOP SP129 | B234: =IF($A234<>"",'NORMAL PRICE'!$B$2,"") -> 2026-03-05 | C234: =IF($A234<>"",'NORMAL PRICE'!$C$2,"") -> 2026-03-11 | D234: 3327 | E234: 346 | F234: 5 | G234: 2 | I234: SUKO | J234: 53781783 | K234: P1M955D6 | L234: KAOS POLO KERAH TEGAK LENGAN PENDEK P1M955D6:BLACK:M:SOLID:KAOS POLO | M234: 179900 | N234: SP | O234: 129000 | P234: SPECIAL PRICE
A235: 2024-2025 OUTERWEAR, T-SHIRT, KI, KNIT TOP SP129 | B235: =IF($A235<>"",'NORMAL PRICE'!$B$2,"") -> 2026-03-05 | C235: =IF($A235<>"",'NORMAL PRICE'!$C$2,"") -> 2026-03-11 | D235: 3327 | E235: 346 | F235: 5 | G235: 2 | I235: SUKO | J235: 53781792 | K235: P1M955D6 | L235: KAOS POLO KERAH TEGAK LENGAN PENDEK P1M955D6:BLACK:L:SOLID:KAOS POLO | M235: 179900 | N235: SP | O235: 129000 | P235: SPECIAL PRICE
A236: 2024-2025 OUTERWEAR, T-SHIRT, KI, KNIT TOP SP129 | B236: =IF($A236<>"",'NORMAL PRICE'!$B$2,"") -> 2026-03-05 | C236: =IF($A236<>"",'NORMAL PRICE'!$C$2,"") -> 2026-03-11 | D236: 3327 | E236: 346 | F236: 5 | G236: 2 | I236: SUKO | J236: 53781809 | K236: P1M955D6 | L236: KAOS POLO KERAH TEGAK LENGAN PENDEK P1M955D6:BLACK:XL:SOLID:KAOS POLO | M236: 179900 | N236: SP | O236: 129000 | P236: SPECIAL PRICE
A237: 2024-2025 OUTERWEAR, T-SHIRT, KI, KNIT TOP SP129 | B237: =IF($A237<>"",'NORMAL PRICE'!$B$2,"") -> 2026-03-05 | C237: =IF($A237<>"",'NORMAL PRICE'!$C$2,"") -> 2026-03-11 | D237: 3327 | E237: 346 | F237: 5 | G237: 2 | I237: SUKO | J237: 53781738 | K237: P1M955D6 | L237: KAOS POLO KERAH TEGAK LENGAN PENDEK P1M955D6:FROST GREY:S:SOLID:KAOS POLO | M237: 179900 | N237: SP | O237: 129000 | P237: SPECIAL PRICE
A238: 2024-2025 OUTERWEAR, T-SHIRT, KI, KNIT TOP SP129 | B238: =IF($A238<>"",'NORMAL PRICE'!$B$2,"") -> 2026-03-05 | C238: =IF($A238<>"",'NORMAL PRICE'!$C$2,"") -> 2026-03-11 | D238: 3327 | E238: 346 | F238: 5 | G238: 2 | I238: SUKO | J238: 53781747 | K238: P1M955D6 | L238: KAOS POLO KERAH TEGAK LENGAN PENDEK P1M955D6:FROST GREY:M:SOLID:KAOS POLO | M238: 179900 | N238: SP | O238: 129000 | P238: SPECIAL PRICE
A239: 2024-2025 OUTERWEAR, T-SHIRT, KI, KNIT TOP SP129 | B239: =IF($A239<>"",'NORMAL PRICE'!$B$2,"") -> 2026-03-05 | C239: =IF($A239<>"",'NORMAL PRICE'!$C$2,"") -> 2026-03-11 | D239: 3327 | E239: 346 | F239: 5 | G239: 2 | I239: SUKO | J239: 53781756 | K239: P1M955D6 | L239: KAOS POLO KERAH TEGAK LENGAN PENDEK P1M955D6:FROST GREY:L:SOLID:KAOS POLO | M239: 179900 | N239: SP | O239: 129000 | P239: SPECIAL PRICE
A240: 2024-2025 OUTERWEAR, T-SHIRT, KI, KNIT TOP SP129 | B240: =IF($A240<>"",'NORMAL PRICE'!$B$2,"") -> 2026-03-05 | C240: =IF($A240<>"",'NORMAL PRICE'!$C$2,"") -> 2026-03-11 | D240: 3327 | E240: 346 | F240: 5 | G240: 2 | I240: SUKO | J240: 53781765 | K240: P1M955D6 | L240: KAOS POLO KERAH TEGAK LENGAN PENDEK P1M955D6:FROST GREY:XL:SOLID:KAOS POLO | M240: 179900 | N240: SP | O240: 129000 | P240: SPECIAL PRICE
A241: 2024-2025 OUTERWEAR, T-SHIRT, KI, KNIT TOP SP129 | B241: =IF($A241<>"",'NORMAL PRICE'!$B$2,"") -> 2026-03-05 | C241: =IF($A241<>"",'NORMAL PRICE'!$C$2,"") -> 2026-03-11 | D241: 3327 | E241: 346 | F241: 5 | G241: 2 | I241: SUKO | J241: 53781694 | K241: P1M955D6 | L241: KAOS POLO KERAH TEGAK LENGAN PENDEK P1M955D6:NAVY BLUE:S:SOLID:KAOS POLO | M241: 179900 | N241: SP | O241: 129000 | P241: SPECIAL PRICE
A242: 2024-2025 OUTERWEAR, T-SHIRT, KI, KNIT TOP SP129 | B242: =IF($A242<>"",'NORMAL PRICE'!$B$2,"") -> 2026-03-05 | C242: =IF($A242<>"",'NORMAL PRICE'!$C$2,"") -> 2026-03-11 | D242: 3327 | E242: 346 | F242: 5 | G242: 2 | I242: SUKO | J242: 53781701 | K242: P1M955D6 | L242: KAOS POLO KERAH TEGAK LENGAN PENDEK P1M955D6:NAVY BLUE:M:SOLID:KAOS POLO | M242: 179900 | N242: SP | O242: 129000 | P242: SPECIAL PRICE
A243: 2024-2025 OUTERWEAR, T-SHIRT, KI, KNIT TOP SP129 | B243: =IF($A243<>"",'NORMAL PRICE'!$B$2,"") -> 2026-03-05 | C243: =IF($A243<>"",'NORMAL PRICE'!$C$2,"") -> 2026-03-11 | D243: 3327 | E243: 346 | F243: 5 | G243: 2 | I243: SUKO | J243: 53781710 | K243: P1M955D6 | L243: KAOS POLO KERAH TEGAK LENGAN PENDEK P1M955D6:NAVY BLUE:L:SOLID:KAOS POLO | M243: 179900 | N243: SP | O243: 129000 | P243: SPECIAL PRICE
A244: 2024-2025 OUTERWEAR, T-SHIRT, KI, KNIT TOP SP129 | B244: =IF($A244<>"",'NORMAL PRICE'!$B$2,"") -> 2026-03-05 | C244: =IF($A244<>"",'NORMAL PRICE'!$C$2,"") -> 2026-03-11 | D244: 3327 | E244: 346 | F244: 5 | G244: 2 | I244: SUKO | J244: 53781729 | K244: P1M955D6 | L244: KAOS POLO KERAH TEGAK LENGAN PENDEK P1M955D6:NAVY BLUE:XL:SOLID:KAOS POLO | M244: 179900 | N244: SP | O244: 129000 | P244: SPECIAL PRICE
... A252: 2024-2025 OUTERWEAR, T-SHIRT, KI, KNIT TOP SP129 | B252: =IF($A252<>"",'NORMAL PRICE'!$B$2,"") -> 2026-03-05 | C252: =IF($A252<>"",'NORMAL PRICE'!$C$2,"") -> 2026-03-11 | D252: 3327 | E252: 346 | F252: 5 | G252: 2 | I252: SUKO | J252: 53781881 | K252: P1M955D6 | L252: KAOS POLO KERAH TEGAK LENGAN PENDEK P1M955D6:VANILLA:XL:SOLID:KAOS POLO | M252: 179900 | N252: SP | O252: 129000 | P252: SPECIAL PRICE

Sheet B2G1
A1: ACARA | B1: FROM DATE | C1: TO DATE | D1: DEPT | E1: WORLD | F1: DIVISION | G1: CLASS | H1: SUPPLIER | I1: BRAND | J1: SKU | K1: ARTICLE | L1: DESCRIPTION | M1: HARGA NORMAL | N1: DISKON | O1: HARGA PROMO | P1: DISCOUNT TYPE
A2: 2024-2025 KNIT TOP, WOVEN TOP, KI B2G1 | B2: ='NORMAL PRICE'!$B$2 -> 2026-03-05 | C2: ='NORMAL PRICE'!$C$2 -> 2026-03-11 | D2: 3327 | E2: 346 | F2: 5 | G2: 9 | I2: SUKO | J2: 51570611 | K2: P1M084A1 | L2: KAOS POLO SS MANDARIN COLLAR KNIT TOP QUICK DRY KERAH TEGAK LENGAN PENDEK P1M084A1:KHAKI:S:SOLID:KAO | M2: 179900 | N2: BXGY | O2: B2G1 | P2: BXGY
A3: 2024-2025 KNIT TOP, WOVEN TOP, KI B2G1 | B3: ='NORMAL PRICE'!$B$2 -> 2026-03-05 | C3: ='NORMAL PRICE'!$C$2 -> 2026-03-11 | D3: 3327 | E3: 346 | F3: 5 | G3: 9 | I3: SUKO | J3: 51570620 | K3: P1M084A1 | L3: KAOS POLO SS MANDARIN COLLAR KNIT TOP QUICK DRY KERAH TEGAK LENGAN PENDEK P1M084A1:KHAKI:M:SOLID:KAO | M3: 179900 | N3: BXGY | O3: B2G1 | P3: BXGY
A4: 2024-2025 KNIT TOP, WOVEN TOP, KI B2G1 | B4: ='NORMAL PRICE'!$B$2 -> 2026-03-05 | C4: ='NORMAL PRICE'!$C$2 -> 2026-03-11 | D4: 3327 | E4: 346 | F4: 5 | G4: 9 | I4: SUKO | J4: 51570639 | K4: P1M084A1 | L4: KAOS POLO SS MANDARIN COLLAR KNIT TOP QUICK DRY KERAH TEGAK LENGAN PENDEK P1M084A1:KHAKI:L:SOLID:KAO | M4: 179900 | N4: BXGY | O4: B2G1 | P4: BXGY
A5: 2024-2025 KNIT TOP, WOVEN TOP, KI B2G1 | B5: ='NORMAL PRICE'!$B$2 -> 2026-03-05 | C5: ='NORMAL PRICE'!$C$2 -> 2026-03-11 | D5: 3327 | E5: 346 | F5: 5 | G5: 9 | I5: SUKO | J5: 51570648 | K5: P1M084A1 | L5: KAOS POLO SS MANDARIN COLLAR KNIT TOP QUICK DRY KERAH TEGAK LENGAN PENDEK P1M084A1:KHAKI:XL:SOLID:KA | M5: 179900 | N5: BXGY | O5: B2G1 | P5: BXGY
A6: 2024-2025 KNIT TOP, WOVEN TOP, KI B2G1 | B6: ='NORMAL PRICE'!$B$2 -> 2026-03-05 | C6: ='NORMAL PRICE'!$C$2 -> 2026-03-11 | D6: 3327 | E6: 346 | F6: 5 | G6: 9 | I6: SUKO | J6: 51570693 | K6: P1M084A1 | L6: KAOS POLO SS MANDARIN COLLAR KNIT TOP QUICK DRY KERAH TEGAK LENGAN PENDEK P1M084A1:MUSTARD:S:SOLID:K | M6: 179900 | N6: BXGY | O6: B2G1 | P6: BXGY
A7: 2024-2025 KNIT TOP, WOVEN TOP, KI B2G1 | B7: ='NORMAL PRICE'!$B$2 -> 2026-03-05 | C7: ='NORMAL PRICE'!$C$2 -> 2026-03-11 | D7: 3327 | E7: 346 | F7: 5 | G7: 9 | I7: SUKO | J7: 51570700 | K7: P1M084A1 | L7: KAOS POLO SS MANDARIN COLLAR KNIT TOP QUICK DRY KERAH TEGAK LENGAN PENDEK P1M084A1:MUSTARD:M:SOLID:K | M7: 179900 | N7: BXGY | O7: B2G1 | P7: BXGY
A8: 2024-2025 KNIT TOP, WOVEN TOP, KI B2G1 | B8: ='NORMAL PRICE'!$B$2 -> 2026-03-05 | C8: ='NORMAL PRICE'!$C$2 -> 2026-03-11 | D8: 3327 | E8: 346 | F8: 5 | G8: 9 | I8: SUKO | J8: 51570719 | K8: P1M084A1 | L8: KAOS POLO SS MANDARIN COLLAR KNIT TOP QUICK DRY KERAH TEGAK LENGAN PENDEK P1M084A1:MUSTARD:L:SOLID:K | M8: 179900 | N8: BXGY | O8: B2G1 | P8: BXGY
A9: 2024-2025 KNIT TOP, WOVEN TOP, KI B2G1 | B9: ='NORMAL PRICE'!$B$2 -> 2026-03-05 | C9: ='NORMAL PRICE'!$C$2 -> 2026-03-11 | D9: 3327 | E9: 346 | F9: 5 | G9: 9 | I9: SUKO | J9: 51570728 | K9: P1M084A1 | L9: KAOS POLO SS MANDARIN COLLAR KNIT TOP QUICK DRY KERAH TEGAK LENGAN PENDEK P1M084A1:MUSTARD:XL:SOLID: | M9: 179900 | N9: BXGY | O9: B2G1 | P9: BXGY
A10: 2024-2025 KNIT TOP, WOVEN TOP, KI B2G1 | B10: ='NORMAL PRICE'!$B$2 -> 2026-03-05 | C10: ='NORMAL PRICE'!$C$2 -> 2026-03-11 | D10: 3327 | E10: 346 | F10: 5 | G10: 9 | I10: SUKO | J10: 51570657 | K10: P1M084A1 | L10: KAOS POLO SS MANDARIN COLLAR KNIT TOP QUICK DRY KERAH TEGAK LENGAN PENDEK P1M084A1:NAVY BLUE:S:SOLID | M10: 179900 | N10: BXGY | O10: B2G1 | P10: BXGY
A11: 2024-2025 KNIT TOP, WOVEN TOP, KI B2G1 | B11: ='NORMAL PRICE'!$B$2 -> 2026-03-05 | C11: ='NORMAL PRICE'!$C$2 -> 2026-03-11 | D11: 3327 | E11: 346 | F11: 5 | G11: 9 | I11: SUKO | J11: 51570666 | K11: P1M084A1 | L11: KAOS POLO SS MANDARIN COLLAR KNIT TOP QUICK DRY KERAH TEGAK LENGAN PENDEK P1M084A1:NAVY BLUE:M:SOLID | M11: 179900 | N11: BXGY | O11: B2G1 | P11: BXGY
A12: 2024-2025 KNIT TOP, WOVEN TOP, KI B2G1 | B12: ='NORMAL PRICE'!$B$2 -> 2026-03-05 | C12: ='NORMAL PRICE'!$C$2 -> 2026-03-11 | D12: 3327 | E12: 346 | F12: 5 | G12: 9 | I12: SUKO | J12: 51570675 | K12: P1M084A1 | L12: KAOS POLO SS MANDARIN COLLAR KNIT TOP QUICK DRY KERAH TEGAK LENGAN PENDEK P1M084A1:NAVY BLUE:L:SOLID | M12: 179900 | N12: BXGY | O12: B2G1 | P12: BXGY
A13: 2024-2025 KNIT TOP, WOVEN TOP, KI B2G1 | B13: ='NORMAL PRICE'!$B$2 -> 2026-03-05 | C13: ='NORMAL PRICE'!$C$2 -> 2026-03-11 | D13: 3327 | E13: 346 | F13: 5 | G13: 9 | I13: SUKO | J13: 51570684 | K13: P1M084A1 | L13: KAOS POLO SS MANDARIN COLLAR KNIT TOP QUICK DRY KERAH TEGAK LENGAN PENDEK P1M084A1:NAVY BLUE:XL:SOLI | M13: 179900 | N13: BXGY | O13: B2G1 | P13: BXGY
... A117: 2024-2025 KNIT TOP, WOVEN TOP, KI B2G1 | B117: ='NORMAL PRICE'!$B$2 -> 2026-03-05 | C117: ='NORMAL PRICE'!$C$2 -> 2026-03-11 | D117: 3327 | E117: 346 | F117: 5 | G117: 3 | I117: SUKO | J117: 68181359 | K117: S1M1716A1 | L117: KEMEJA SS SOLID KERAH TEGAK S1M1716A1:WHITE:XL:SOLID:KEMEJA | M117: 279900 | N117: BXGY | O117: B2G1 | P117: BXGY

Sheet SP99
A1: ACARA | B1: FROM DATE | C1: TO DATE | D1: DEPT | E1: WORLD | F1: DIVISION | G1: CLASS | H1: SUPPLIER | I1: BRAND | J1: SKU | K1: ARTICLE | L1: DESCRIPTION | M1: HARGA NORMAL | N1: DISKON | O1: HARGA PROMO | P1: DISCOUNT TYPE
A2: 2024-2025 KI (SELECTED COLOR) T-SHIRT, KNIT TOP, WOVEN TOP, WOVEN BOTTOM, KNIT BOTTOM SP99 | B2: ='NORMAL PRICE'!$B$2 -> 2026-03-05 | C2: ='NORMAL PRICE'!$C$2 -> 2026-03-11 | D2: 3327 | E2: 346 | F2: 5 | G2: 9 | I2: SUKO | J2: 15728439 | K2: T2J18352 | L2: T-SHIRT LS ROUND NECK SOFT TOUCH KERAH BULAT LENGAN PANJANG T2J18352:BROWN SUGAR:S:SOLID:T-SHIRT | M2: 179900 | N2: SP | O2: 99000 | P2: SPECIAL PRICE
A3: 2024-2025 KI (SELECTED COLOR) T-SHIRT, KNIT TOP, WOVEN TOP, WOVEN BOTTOM, KNIT BOTTOM SP99 | B3: ='NORMAL PRICE'!$B$2 -> 2026-03-05 | C3: ='NORMAL PRICE'!$C$2 -> 2026-03-11 | D3: 3327 | E3: 346 | F3: 5 | G3: 9 | I3: SUKO | J3: 15728448 | K3: T2J18352 | L3: T-SHIRT LS ROUND NECK SOFT TOUCH KERAH BULAT LENGAN PANJANG T2J18352:BROWN SUGAR:M:SOLID:T-SHIRT | M3: 179900 | N3: SP | O3: 99000 | P3: SPECIAL PRICE
A4: 2024-2025 KI (SELECTED COLOR) T-SHIRT, KNIT TOP, WOVEN TOP, WOVEN BOTTOM, KNIT BOTTOM SP99 | B4: ='NORMAL PRICE'!$B$2 -> 2026-03-05 | C4: ='NORMAL PRICE'!$C$2 -> 2026-03-11 | D4: 3327 | E4: 346 | F4: 5 | G4: 9 | I4: SUKO | J4: 15728457 | K4: T2J18352 | L4: T-SHIRT LS ROUND NECK SOFT TOUCH KERAH BULAT LENGAN PANJANG T2J18352:BROWN SUGAR:L:SOLID:T-SHIRT | M4: 179900 | N4: SP | O4: 99000 | P4: SPECIAL PRICE
A5: 2024-2025 KI (SELECTED COLOR) T-SHIRT, KNIT TOP, WOVEN TOP, WOVEN BOTTOM, KNIT BOTTOM SP99 | B5: ='NORMAL PRICE'!$B$2 -> 2026-03-05 | C5: ='NORMAL PRICE'!$C$2 -> 2026-03-11 | D5: 3327 | E5: 346 | F5: 5 | G5: 9 | I5: SUKO | J5: 15728466 | K5: T2J18352 | L5: T-SHIRT LS ROUND NECK SOFT TOUCH KERAH BULAT LENGAN PANJANG T2J18352:BROWN SUGAR:XL:SOLID:T-SHIRT | M5: 179900 | N5: SP | O5: 99000 | P5: SPECIAL PRICE
A6: 2024-2025 KI (SELECTED COLOR) T-SHIRT, KNIT TOP, WOVEN TOP, WOVEN BOTTOM, KNIT BOTTOM SP99 | B6: ='NORMAL PRICE'!$B$2 -> 2026-03-05 | C6: ='NORMAL PRICE'!$C$2 -> 2026-03-11 | D6: 3327 | E6: 346 | F6: 5 | G6: 9 | I6: SUKO | J6: 51363201 | K6: T2J18352 | L6: T-SHIRT LS ROUND NECK SOFT TOUCH KERAH BULAT LENGAN PANJANG T2J18352:FROST GREY:S:SOLID:T-SHIRT | M6: 179900 | N6: SP | O6: 99000 | P6: SPECIAL PRICE
A7: 2024-2025 KI (SELECTED COLOR) T-SHIRT, KNIT TOP, WOVEN TOP, WOVEN BOTTOM, KNIT BOTTOM SP99 | B7: ='NORMAL PRICE'!$B$2 -> 2026-03-05 | C7: ='NORMAL PRICE'!$C$2 -> 2026-03-11 | D7: 3327 | E7: 346 | F7: 5 | G7: 9 | I7: SUKO | J7: 51363210 | K7: T2J18352 | L7: T-SHIRT LS ROUND NECK SOFT TOUCH KERAH BULAT LENGAN PANJANG T2J18352:FROST GREY:M:SOLID:T-SHIRT | M7: 179900 | N7: SP | O7: 99000 | P7: SPECIAL PRICE
A8: 2024-2025 KI (SELECTED COLOR) T-SHIRT, KNIT TOP, WOVEN TOP, WOVEN BOTTOM, KNIT BOTTOM SP99 | B8: ='NORMAL PRICE'!$B$2 -> 2026-03-05 | C8: ='NORMAL PRICE'!$C$2 -> 2026-03-11 | D8: 3327 | E8: 346 | F8: 5 | G8: 9 | I8: SUKO | J8: 51363229 | K8: T2J18352 | L8: T-SHIRT LS ROUND NECK SOFT TOUCH KERAH BULAT LENGAN PANJANG T2J18352:FROST GREY:L:SOLID:T-SHIRT | M8: 179900 | N8: SP | O8: 99000 | P8: SPECIAL PRICE
A9: 2024-2025 KI (SELECTED COLOR) T-SHIRT, KNIT TOP, WOVEN TOP, WOVEN BOTTOM, KNIT BOTTOM SP99 | B9: ='NORMAL PRICE'!$B$2 -> 2026-03-05 | C9: ='NORMAL PRICE'!$C$2 -> 2026-03-11 | D9: 3327 | E9: 346 | F9: 5 | G9: 9 | I9: SUKO | J9: 51363238 | K9: T2J18352 | L9: T-SHIRT LS ROUND NECK SOFT TOUCH KERAH BULAT LENGAN PANJANG T2J18352:FROST GREY:XL:SOLID:T-SHIRT | M9: 179900 | N9: SP | O9: 99000 | P9: SPECIAL PRICE
A10: 2024-2025 KI (SELECTED COLOR) T-SHIRT, KNIT TOP, WOVEN TOP, WOVEN BOTTOM, KNIT BOTTOM SP99 | B10: ='NORMAL PRICE'!$B$2 -> 2026-03-05 | C10: ='NORMAL PRICE'!$C$2 -> 2026-03-11 | D10: 3327 | E10: 346 | F10: 5 | G10: 9 | I10: SUKO | J10: 53341132 | K10: T2J18352 | L10: T-SHIRT LS ROUND NECK SOFT TOUCH KERAH BULAT LENGAN PANJANG T2J18352:MISTY LIGHT GREY:S:SOLID:T-SHIR | M10: 179900 | N10: SP | O10: 99000 | P10: SPECIAL PRICE
A11: 2024-2025 KI (SELECTED COLOR) T-SHIRT, KNIT TOP, WOVEN TOP, WOVEN BOTTOM, KNIT BOTTOM SP99 | B11: ='NORMAL PRICE'!$B$2 -> 2026-03-05 | C11: ='NORMAL PRICE'!$C$2 -> 2026-03-11 | D11: 3327 | E11: 346 | F11: 5 | G11: 9 | I11: SUKO | J11: 53341141 | K11: T2J18352 | L11: T-SHIRT LS ROUND NECK SOFT TOUCH KERAH BULAT LENGAN PANJANG T2J18352:MISTY LIGHT GREY:M:SOLID:T-SHIR | M11: 179900 | N11: SP | O11: 99000 | P11: SPECIAL PRICE
A12: 2024-2025 KI (SELECTED COLOR) T-SHIRT, KNIT TOP, WOVEN TOP, WOVEN BOTTOM, KNIT BOTTOM SP99 | B12: ='NORMAL PRICE'!$B$2 -> 2026-03-05 | C12: ='NORMAL PRICE'!$C$2 -> 2026-03-11 | D12: 3327 | E12: 346 | F12: 5 | G12: 9 | I12: SUKO | J12: 53341150 | K12: T2J18352 | L12: T-SHIRT LS ROUND NECK SOFT TOUCH KERAH BULAT LENGAN PANJANG T2J18352:MISTY LIGHT GREY:L:SOLID:T-SHIR | M12: 179900 | N12: SP | O12: 99000 | P12: SPECIAL PRICE
A13: 2024-2025 KI (SELECTED COLOR) T-SHIRT, KNIT TOP, WOVEN TOP, WOVEN BOTTOM, KNIT BOTTOM SP99 | B13: ='NORMAL PRICE'!$B$2 -> 2026-03-05 | C13: ='NORMAL PRICE'!$C$2 -> 2026-03-11 | D13: 3327 | E13: 346 | F13: 5 | G13: 9 | I13: SUKO | J13: 53341169 | K13: T2J18352 | L13: T-SHIRT LS ROUND NECK SOFT TOUCH KERAH BULAT LENGAN PANJANG T2J18352:MISTY LIGHT GREY:XL:SOLID:T-SHI | M13: 179900 | N13: SP | O13: 99000 | P13: SPECIAL PRICE
... A389: 2024-2025 KI (SELECTED COLOR) T-SHIRT, KNIT TOP, WOVEN TOP, WOVEN BOTTOM, KNIT BOTTOM SP99 | B389: ='NORMAL PRICE'!$B$2 -> 2026-03-05 | C389: ='NORMAL PRICE'!$C$2 -> 2026-03-11 | D389: 3327 | E389: 346 | F389: 5 | G389: 6 | I389: SUKO | J389: 80683721 | K389: W1J33351 | L389: CELANA PENDEK RELAX PULL ON SHORTS W1J33351:OLIVE:XL:SOLID:CELANA PENDEK RELAX | M389: 199900 | N389: SP | O389: 99000 | P389: SPECIAL PRICE

Sheet SP79
A1: ACARA | B1: FROM DATE | C1: TO DATE | D1: DEPT | E1: WORLD | F1: DIVISION | G1: CLASS | H1: SUPPLIER | I1: BRAND | J1: SKU | K1: ARTICLE | L1: DESCRIPTION | M1: HARGA NORMAL | N1: DISKON | O1: HARGA PROMO | P1: DISCOUNT TYPE
A2: 2023 H1 T-SHIRT, WOVEN TOP, OUTERWEAR, WOVEN BOTTOM, SP79 | B2: ='NORMAL PRICE'!$B$2 -> 2026-03-05 | C2: ='NORMAL PRICE'!$C$2 -> 2026-03-11 | D2: 3327 | E2: 346 | F2: 5 | G2: 1 | I2: SUKO | J2: 13452294 | K2: T1TS23J1 | L2: OVERSIZED T-SHIRT STRIPED TEE SS PRINT JACQUARD GARIS KERAH BULAT LENGAN PENDEK T1TS23J1:EMERALD GRE | M2: 179900 | N2: SP | O2: 79000 | P2: SPECIAL PRICE
A3: 2023 H1 T-SHIRT, WOVEN TOP, OUTERWEAR, WOVEN BOTTOM, SP79 | B3: ='NORMAL PRICE'!$B$2 -> 2026-03-05 | C3: ='NORMAL PRICE'!$C$2 -> 2026-03-11 | D3: 3327 | E3: 346 | F3: 5 | G3: 1 | I3: SUKO | J3: 13452301 | K3: T1TS23J1 | L3: OVERSIZED T-SHIRT STRIPED TEE SS PRINT JACQUARD GARIS KERAH BULAT LENGAN PENDEK T1TS23J1:EMERALD GRE | M3: 179900 | N3: SP | O3: 79000 | P3: SPECIAL PRICE
A4: 2023 H1 T-SHIRT, WOVEN TOP, OUTERWEAR, WOVEN BOTTOM, SP79 | B4: ='NORMAL PRICE'!$B$2 -> 2026-03-05 | C4: ='NORMAL PRICE'!$C$2 -> 2026-03-11 | D4: 3327 | E4: 346 | F4: 5 | G4: 1 | I4: SUKO | J4: 13452310 | K4: T1TS23J1 | L4: OVERSIZED T-SHIRT STRIPED TEE SS PRINT JACQUARD GARIS KERAH BULAT LENGAN PENDEK T1TS23J1:EMERALD GRE | M4: 179900 | N4: SP | O4: 79000 | P4: SPECIAL PRICE
A5: 2023 H1 T-SHIRT, WOVEN TOP, OUTERWEAR, WOVEN BOTTOM, SP79 | B5: ='NORMAL PRICE'!$B$2 -> 2026-03-05 | C5: ='NORMAL PRICE'!$C$2 -> 2026-03-11 | D5: 3327 | E5: 346 | F5: 5 | G5: 1 | I5: SUKO | J5: 13452329 | K5: T1TS23J1 | L5: OVERSIZED T-SHIRT STRIPED TEE SS PRINT JACQUARD GARIS KERAH BULAT LENGAN PENDEK T1TS23J1:EMERALD GRE | M5: 179900 | N5: SP | O5: 79000 | P5: SPECIAL PRICE
A6: 2023 H1 T-SHIRT, WOVEN TOP, OUTERWEAR, WOVEN BOTTOM, SP79 | B6: ='NORMAL PRICE'!$B$2 -> 2026-03-05 | C6: ='NORMAL PRICE'!$C$2 -> 2026-03-11 | D6: 3327 | E6: 346 | F6: 5 | G6: 1 | I6: SUKO | J6: 13452258 | K6: T1TS23J1 | L6: OVERSIZED T-SHIRT STRIPED TEE SS PRINT JACQUARD GARIS KERAH BULAT LENGAN PENDEK T1TS23J1:RUSTIC GOLD | M6: 179900 | N6: SP | O6: 79000 | P6: SPECIAL PRICE
A7: 2023 H1 T-SHIRT, WOVEN TOP, OUTERWEAR, WOVEN BOTTOM, SP79 | B7: ='NORMAL PRICE'!$B$2 -> 2026-03-05 | C7: ='NORMAL PRICE'!$C$2 -> 2026-03-11 | D7: 3327 | E7: 346 | F7: 5 | G7: 1 | I7: SUKO | J7: 13452267 | K7: T1TS23J1 | L7: OVERSIZED T-SHIRT STRIPED TEE SS PRINT JACQUARD GARIS KERAH BULAT LENGAN PENDEK T1TS23J1:RUSTIC GOLD | M7: 179900 | N7: SP | O7: 79000 | P7: SPECIAL PRICE
A8: 2023 H1 T-SHIRT, WOVEN TOP, OUTERWEAR, WOVEN BOTTOM, SP79 | B8: ='NORMAL PRICE'!$B$2 -> 2026-03-05 | C8: ='NORMAL PRICE'!$C$2 -> 2026-03-11 | D8: 3327 | E8: 346 | F8: 5 | G8: 1 | I8: SUKO | J8: 13452276 | K8: T1TS23J1 | L8: OVERSIZED T-SHIRT STRIPED TEE SS PRINT JACQUARD GARIS KERAH BULAT LENGAN PENDEK T1TS23J1:RUSTIC GOLD | M8: 179900 | N8: SP | O8: 79000 | P8: SPECIAL PRICE
A9: 2023 H1 T-SHIRT, WOVEN TOP, OUTERWEAR, WOVEN BOTTOM, SP79 | B9: ='NORMAL PRICE'!$B$2 -> 2026-03-05 | C9: ='NORMAL PRICE'!$C$2 -> 2026-03-11 | D9: 3327 | E9: 346 | F9: 5 | G9: 1 | I9: SUKO | J9: 13452285 | K9: T1TS23J1 | L9: OVERSIZED T-SHIRT STRIPED TEE SS PRINT JACQUARD GARIS KERAH BULAT LENGAN PENDEK T1TS23J1:RUSTIC GOLD | M9: 179900 | N9: SP | O9: 79000 | P9: SPECIAL PRICE
A10: 2023 H1 T-SHIRT, WOVEN TOP, OUTERWEAR, WOVEN BOTTOM, SP79 | B10: ='NORMAL PRICE'!$B$2 -> 2026-03-05 | C10: ='NORMAL PRICE'!$C$2 -> 2026-03-11 | D10: 3327 | E10: 346 | F10: 5 | G10: 4 | I10: SUKO | J10: 13463728 | K10: O2OW43J3 | L10: SHACKET OUTERWEAR JACKET DETTACHABLE HOOD LENGAN PANJANG O2OW43J3:FROST GREY:S:SOLID:SHACKET | M10: 349900 | N10: SP | O10: 79000 | P10: SPECIAL PRICE
A11: 2023 H1 T-SHIRT, WOVEN TOP, OUTERWEAR, WOVEN BOTTOM, SP79 | B11: ='NORMAL PRICE'!$B$2 -> 2026-03-05 | C11: ='NORMAL PRICE'!$C$2 -> 2026-03-11 | D11: 3327 | E11: 346 | F11: 5 | G11: 4 | I11: SUKO | J11: 13463737 | K11: O2OW43J3 | L11: SHACKET OUTERWEAR JACKET DETTACHABLE HOOD LENGAN PANJANG O2OW43J3:FROST GREY:M:SOLID:SHACKET | M11: 349900 | N11: SP | O11: 79000 | P11: SPECIAL PRICE
A12: 2023 H1 T-SHIRT, WOVEN TOP, OUTERWEAR, WOVEN BOTTOM, SP79 | B12: ='NORMAL PRICE'!$B$2 -> 2026-03-05 | C12: ='NORMAL PRICE'!$C$2 -> 2026-03-11 | D12: 3327 | E12: 346 | F12: 5 | G12: 4 | I12: SUKO | J12: 13463746 | K12: O2OW43J3 | L12: SHACKET OUTERWEAR JACKET DETTACHABLE HOOD LENGAN PANJANG O2OW43J3:FROST GREY:L:SOLID:SHACKET | M12: 349900 | N12: SP | O12: 79000 | P12: SPECIAL PRICE
A13: 2023 H1 T-SHIRT, WOVEN TOP, OUTERWEAR, WOVEN BOTTOM, SP79 | B13: ='NORMAL PRICE'!$B$2 -> 2026-03-05 | C13: ='NORMAL PRICE'!$C$2 -> 2026-03-11 | D13: 3327 | E13: 346 | F13: 5 | G13: 4 | I13: SUKO | J13: 13463755 | K13: O2OW43J3 | L13: SHACKET OUTERWEAR JACKET DETTACHABLE HOOD LENGAN PANJANG O2OW43J3:FROST GREY:XL:SOLID:SHACKET | M13: 349900 | N13: SP | O13: 79000 | P13: SPECIAL PRICE
... A195: 2023 H1 T-SHIRT, WOVEN TOP, OUTERWEAR, WOVEN BOTTOM, SP79 | B195: ='NORMAL PRICE'!$B$2 -> 2026-03-05 | C195: ='NORMAL PRICE'!$C$2 -> 2026-03-11 | D195: 3327 | E195: 346 | F195: 5 | G195: 6 | I195: SUKO | J195: 80684006 | K195: W2J46351 | L195: CELANA ANKLE RELAX JOGGER PANTS NON ELASTIC HEMMING W2J46351:NAVY BLUE:XL:SOLID:CELANA ANKLE RELAX | M195: 349900 | N195: SP | O195: 79000 | P195: SPECIAL PRICE

Sheet SP49
A1: ACARA | B1: FROM DATE | C1: TO DATE | D1: DEPT | E1: WORLD | F1: DIVISION | G1: CLASS | H1: SUPPLIER | I1: BRAND | J1: SKU | K1: ARTICLE | L1: DESCRIPTION | M1: HARGA NORMAL | N1: DISKON | O1: HARGA PROMO | P1: DISCOUNT TYPE
A2: 2024 H1 ACCESSORIES SP49 | B2: ='NORMAL PRICE'!$B$2 -> 2026-03-05 | C2: ='NORMAL PRICE'!$C$2 -> 2026-03-11 | D2: 3327 | E2: 346 | F2: 5 | G2: 8 | I2: SUKO | J2: 81848042 | K2: A1CP1351 | L2: TOPI TWILL CAP PROTEKSI SINAR UV A1CP1351:BLACK:F:SOLID:TOPI TWILL | M2: 99900 | N2: SP | O2: 49000 | P2: SPECIAL PRICE
