Workbook

Sheet 2025 NOV-FEB B3 D10 -3321
A1: ACARA | B1: FROM DATE | C1: TO DATE | D1: DEPT | E1: WORLD | F1: DIVISION | G1: CLASS | H1: SUPPLIER | I1: BRAND | J1: SKU | K1: ARTICLE | L1: DESCRIPTION | M1: HARGA NORMAL | N1: DISKON | O1: HARGA PROMO | P1: DISCOUNT TYPE
A2: 2026 NOV-FEB B3 DISC 10% | B2: ='2025 HILITE D80 - 3321'!B4 -> 46086 | C2: ='2025 HILITE D80 - 3321'!C4 -> 46092 | D2: 3321 | E2: 337 | F2: 4 | G2: 1 | H2: 81588 | I2: CHARACTER | J2: 61549064 | K2: TSHPOT3 | L2: SS T-SHIRT POLO HARRY POTTER TSHPOT3:NAVY BLUE:7-8:GRAPHIC:SS T-SHIRT | M2: 129900 | N2: BXGY | O2: B3 DISC 10% | P2: BXGY
A3: =A2 -> 2026 NOV-FEB B3 DISC 10% | B3: =B2 -> 46086 | C3: =C2 -> 46092 | D3: 3321 | E3: 337 | F3: 4 | G3: 1 | H3: 81588 | I3: CHARACTER | J3: 61549073 | K3: TSHPOT3 | L3: SS T-SHIRT POLO HARRY POTTER TSHPOT3:NAVY BLUE:9-10:GRAPHIC:SS T-SHIRT | M3: 129900 | N3: BXGY | O3: B3 DISC 10% | P3: BXGY
A4: =A3 -> 2026 NOV-FEB B3 DISC 10% | B4: =B3 -> 46086 | C4: =C3 -> 46092 | D4: 3321 | E4: 337 | F4: 4 | G4: 1 | H4: 81588 | I4: CHARACTER | J4: 61549082 | K4: TSHPOT3 | L4: SS T-SHIRT POLO HARRY POTTER TSHPOT3:NAVY BLUE:11-12:GRAPHIC:SS T-SHIRT | M4: 129900 | N4: BXGY | O4: =O3 -> B3 DISC 10% | P4: BXGY
A5: =A4 -> 2026 NOV-FEB B3 DISC 10% | B5: =B4 -> 46086 | C5: =C4 -> 46092 | D5: 3321 | E5: 337 | F5: 4 | G5: 1 | H5: 81588 | I5: CHARACTER | J5: 61549091 | K5: TSHPOT3 | L5: SS T-SHIRT POLO HARRY POTTER TSHPOT3:NAVY BLUE:13-14:GRAPHIC:SS T-SHIRT | M5: 99900 | N5: BXGY | O5: B3 DISC 10% | P5: BXGY
A6: =A5 -> 2026 NOV-FEB B3 DISC 10% | B6: =B5 -> 46086 | C6: =C5 -> 46092 | D6: 3321 | E6: 337 | F6: 4 | G6: 1 | H6: 81588 | I6: CHARACTER | J6: 61549028 | K6: TSHPOT2 | L6: SS T-SHIRT HARRY POTTER TSHPOT2:PASTEL GREY:7-8:GRAPHIC:SS T-SHIRT | M6: 99900 | N6: BXGY | O6: =O5 -> B3 DISC 10% | P6: BXGY
A7: =A6 -> 2026 NOV-FEB B3 DISC 10% | B7: =B6 -> 46086 | C7: =C6 -> 46092 | D7: 3321 | E7: 337 | F7: 4 | G7: 1 | H7: 81588 | I7: CHARACTER | J7: 61549037 | K7: TSHPOT2 | L7: SS T-SHIRT HARRY POTTER TSHPOT2:PASTEL GREY:9-10:GRAPHIC:SS T-SHIRT | M7: 99900 | N7: BXGY | O7: B3 DISC 10% | P7: BXGY
A8: =A7 -> 2026 NOV-FEB B3 DISC 10% | B8: =B7 -> 46086 | C8: =C7 -> 46092 | D8: 3321 | E8: 337 | F8: 4 | G8: 1 | H8: 81588 | I8: CHARACTER | J8: 61549046 | K8: TSHPOT2 | L8: SS T-SHIRT HARRY POTTER TSHPOT2:PASTEL GREY:11-12:GRAPHIC:SS T-SHIRT | M8: 99900 | N8: BXGY | O8: =O7 -> B3 DISC 10% | P8: BXGY
A9: =A8 -> 2026 NOV-FEB B3 DISC 10% | B9: =B8 -> 46086 | C9: =C8 -> 46092 | D9: 3321 | E9: 337 | F9: 4 | G9: 1 | H9: 81588 | I9: CHARACTER | J9: 61549055 | K9: TSHPOT2 | L9: SS T-SHIRT HARRY POTTER TSHPOT2:PASTEL GREY:13-14:GRAPHIC:SS T-SHIRT | M9: 99900 | N9: BXGY | O9: B3 DISC 10% | P9: BXGY
A10: =A9 -> 2026 NOV-FEB B3 DISC 10% | B10: =B9 -> 46086 | C10: =C9 -> 46092 | D10: 3321 | E10: 337 | F10: 4 | G10: 1 | H10: 81588 | I10: CHARACTER | J10: 61548985 | K10: TSHPOT1 | L10: SS T-SHIRT HARRY POTTER RIB V TSHPOT1:OFF WHITE:7-8:GRAPHIC:SS T-SHIRT | M10: 99900 | N10: BXGY | O10: =O9 -> B3 DISC 10% | P10: BXGY
A11: =A10 -> 2026 NOV-FEB B3 DISC 10% | B11: =B10 -> 46086 | C11: =C10 -> 46092 | D11: 3321 | E11: 337 | F11: 4 | G11: 1 | H11: 81588 | I11: CHARACTER | J11: 61548994 | K11: TSHPOT1 | L11: SS T-SHIRT HARRY POTTER RIB V TSHPOT1:OFF WHITE:9-10:GRAPHIC:SS T-SHIRT | M11: 99900 | N11: BXGY | O11: B3 DISC 10% | P11: BXGY
A12: =A11 -> 2026 NOV-FEB B3 DISC 10% | B12: =B11 -> 46086 | C12: =C11 -> 46092 | D12: 3321 | E12: 337 | F12: 4 | G12: 1 | H12: 81588 | I12: CHARACTER | J12: 61549000 | K12: TSHPOT1 | L12: SS T-SHIRT HARRY POTTER RIB V TSHPOT1:OFF WHITE:11-12:GRAPHIC:SS T-SHIRT | M12: 99900 | N12: BXGY | O12: =O11 -> B3 DISC 10% | P12: BXGY
A13: =A12 -> 2026 NOV-FEB B3 DISC 10% | B13: =B12 -> 46086 | C13: =C12 -> 46092 | D13: 3321 | E13: 337 | F13: 4 | G13: 1 | H13: 81588 | I13: CHARACTER | J13: 61549019 | K13: TSHPOT1 | L13: SS T-SHIRT HARRY POTTER RIB V TSHPOT1:OFF WHITE:13-14:GRAPHIC:SS T-SHIRT | M13: 99900 | N13: BXGY | O13: B3 DISC 10% | P13: BXGY
A14: =A13 -> 2026 NOV-FEB B3 DISC 10% | B14: =B13 -> 46086 | C14: =C13 -> 46092 | D14: 3321 | E14: 337 | F14: 4 | G14: 1 | H14: 81679 | I14: CHARACTER | J14: 61549288 | K14: TSSPBOB4 | L14: SS T-SHIRT SPONGEBOB TSSPBOB4:OFF WHITE:4:GRAPHIC:SS T-SHIRT | M14: 99900 | N14: BXGY | O14: =O13 -> B3 DISC 10% | P14: BXGY
A15: =A14 -> 2026 NOV-FEB B3 DISC 10% | B15: =B14 -> 46086 | C15: =C14 -> 46092 | D15: 3321 | E15: 337 | F15: 4 | G15: 1 | H15: 81679 | I15: CHARACTER | J15: 61549297 | K15: TSSPBOB4 | L15: SS T-SHIRT SPONGEBOB TSSPBOB4:OFF WHITE:5:GRAPHIC:SS T-SHIRT | M15: 99900 | N15: BXGY | O15: B3 DISC 10% | P15: BXGY
A16: =A15 -> 2026 NOV-FEB B3 DISC 10% | B16: =B15 -> 46086 | C16: =C15 -> 46092 | D16: 3321 | E16: 337 | F16: 4 | G16: 1 | H16: 81679 | I16: CHARACTER | J16: 61549304 | K16: TSSPBOB4 | L16: SS T-SHIRT SPONGEBOB TSSPBOB4:OFF WHITE:6:GRAPHIC:SS T-SHIRT | M16: 99900 | N16: BXGY | O16: =O15 -> B3 DISC 10% | P16: BXGY
A17: =A16 -> 2026 NOV-FEB B3 DISC 10% | B17: =B16 -> 46086 | C17: =C16 -> 46092 | D17: 3321 | E17: 337 | F17: 4 | G17: 1 | H17: 81679 | I17: CHARACTER | J17: 61549313 | K17: TSSPBOB4 | L17: SS T-SHIRT SPONGEBOB TSSPBOB4:OFF WHITE:7-8:GRAPHIC:SS T-SHIRT | M17: 99900 | N17: BXGY | O17: B3 DISC 10% | P17: BXGY
A18: =A17 -> 2026 NOV-FEB B3 DISC 10% | B18: =B17 -> 46086 | C18: =C17 -> 46092 | D18: 3321 | E18: 337 | F18: 4 | G18: 1 | H18: 81679 | I18: CHARACTER | J18: 61549322 | K18: TSSPBOB4 | L18: SS T-SHIRT SPONGEBOB TSSPBOB4:OFF WHITE:9-10:GRAPHIC:SS T-SHIRT | M18: 99900 | N18: BXGY | O18: =O17 -> B3 DISC 10% | P18: BXGY
A19: =A18 -> 2026 NOV-FEB B3 DISC 10% | B19: =B18 -> 46086 | C19: =C18 -> 46092 | D19: 3321 | E19: 337 | F19: 4 | G19: 1 | H19: 81679 | I19: CHARACTER | J19: 61549331 | K19: TSSPBOB4 | L19: SS T-SHIRT SPONGEBOB TSSPBOB4:OFF WHITE:11-12:GRAPHIC:SS T-SHIRT | M19: 99900 | N19: BXGY | O19: B3 DISC 10% | P19: BXGY
A20: =A19 -> 2026 NOV-FEB B3 DISC 10% | B20: =B19 -> 46086 | C20: =C19 -> 46092 | D20: 3321 | E20: 337 | F20: 4 | G20: 1 | H20: 81679 | I20: CHARACTER | J20: 61549224 | K20: TSSPBOB3 | L20: SS T-SHIRT SPONGEBOB TSSPBOB3:PASTEL YELLOW:4:GRAPHIC:SS T-SHIRT | M20: 99900 | N20: BXGY | O20: =O19 -> B3 DISC 10% | P20: BXGY
A21: =A20 -> 2026 NOV-FEB B3 DISC 10% | B21: =B20 -> 46086 | C21: =C20 -> 46092 | D21: 3321 | E21: 337 | F21: 4 | G21: 1 | H21: 81679 | I21: CHARACTER | J21: 61549233 | K21: TSSPBOB3 | L21: SS T-SHIRT SPONGEBOB TSSPBOB3:PASTEL YELLOW:5:GRAPHIC:SS T-SHIRT | M21: 99900 | N21: BXGY | O21: B3 DISC 10% | P21: BXGY
A22: =A21 -> 2026 NOV-FEB B3 DISC 10% | B22: =B21 -> 46086 | C22: =C21 -> 46092 | D22: 3321 | E22: 337 | F22: 4 | G22: 1 | H22: 81679 | I22: CHARACTER | J22: 61549242 | K22: TSSPBOB3 | L22: SS T-SHIRT SPONGEBOB TSSPBOB3:PASTEL YELLOW:6:GRAPHIC:SS T-SHIRT | M22: 99900 | N22: BXGY | O22: =O21 -> B3 DISC 10% | P22: BXGY
A23: =A22 -> 2026 NOV-FEB B3 DISC 10% | B23: =B22 -> 46086 | C23: =C22 -> 46092 | D23: 3321 | E23: 337 | F23: 4 | G23: 1 | H23: 81679 | I23: CHARACTER | J23: 61549251 | K23: TSSPBOB3 | L23: SS T-SHIRT SPONGEBOB TSSPBOB3:PASTEL YELLOW:7-8:GRAPHIC:SS T-SHIRT | M23: 99900 | N23: BXGY | O23: B3 DISC 10% | P23: BXGY
A24: =A23 -> 2026 NOV-FEB B3 DISC 10% | B24: =B23 -> 46086 | C24: =C23 -> 46092 | D24: 3321 | E24: 337 | F24: 4 | G24: 1 | H24: 81679 | I24: CHARACTER | J24: 61549260 | K24: TSSPBOB3 | L24: SS T-SHIRT SPONGEBOB TSSPBOB3:PASTEL YELLOW:9-10:GRAPHIC:SS T-SHIRT | M24: 99900 | N24: BXGY | O24: =O23 -> B3 DISC 10% | P24: BXGY
A25: =A24 -> 2026 NOV-FEB B3 DISC 10% | B25: =B24 -> 46086 | C25: =C24 -> 46092 | D25: 3321 | E25: 337 | F25: 4 | G25: 1 | H25: 81679 | I25: CHARACTER | J25: 61549279 | K25: TSSPBOB3 | L25: SS T-SHIRT SPONGEBOB TSSPBOB3:PASTEL YELLOW:11-12:GRAPHIC:SS T-SHIRT | M25: 99900 | N25: BXGY | O25: B3 DISC 10% | P25: BXGY
A26: =A25 -> 2026 NOV-FEB B3 DISC 10% | B26: =B25 -> 46086 | C26: =C25 -> 46092 | D26: 3321 | E26: 337 | F26: 4 | G26: 1 | H26: 81679 | I26: CHARACTER | J26: 61549108 | K26: TSSPBOB1 | L26: SS T-SHIRT SPONGEBOB TSSPBOB1:CHARCOAL:4:GRAPHIC:SS T-SHIRT | M26: 99900 | N26: BXGY | O26: =O25 -> B3 DISC 10% | P26: BXGY
A27: =A26 -> 2026 NOV-FEB B3 DISC 10% | B27: =B26 -> 46086 | C27: =C26 -> 46092 | D27: 3321 | E27: 337 | F27: 4 | G27: 1 | H27: 81679 | I27: CHARACTER | J27: 61549117 | K27: TSSPBOB1 | L27: SS T-SHIRT SPONGEBOB TSSPBOB1:CHARCOAL:5:GRAPHIC:SS T-SHIRT | M27: 99900 | N27: BXGY | O27: B3 DISC 10% | P27: BXGY
A28: =A27 -> 2026 NOV-FEB B3 DISC 10% | B28: =B27 -> 46086 | C28: =C27 -> 46092 | D28: 3321 | E28: 337 | F28: 4 | G28: 1 | H28: 81679 | I28: CHARACTER | J28: 61549126 | K28: TSSPBOB1 | L28: SS T-SHIRT SPONGEBOB TSSPBOB1:CHARCOAL:6:GRAPHIC:SS T-SHIRT | M28: 99900 | N28: BXGY | O28: =O27 -> B3 DISC 10% | P28: BXGY
A29: =A28 -> 2026 NOV-FEB B3 DISC 10% | B29: =B28 -> 46086 | C29: =C28 -> 46092 | D29: 3321 | E29: 337 | F29: 4 | G29: 1 | H29: 81679 | I29: CHARACTER | J29: 61549135 | K29: TSSPBOB1 | L29: SS T-SHIRT SPONGEBOB TSSPBOB1:CHARCOAL:7-8:GRAPHIC:SS T-SHIRT | M29: 99900 | N29: BXGY | O29: B3 DISC 10% | P29: BXGY
A30: =A29 -> 2026 NOV-FEB B3 DISC 10% | B30: =B29 -> 46086 | C30: =C29 -> 46092 | D30: 3321 | E30: 337 | F30: 4 | G30: 1 | H30: 81679 | I30: CHARACTER | J30: 61549144 | K30: TSSPBOB1 | L30: SS T-SHIRT SPONGEBOB TSSPBOB1:CHARCOAL:9-10:GRAPHIC:SS T-SHIRT | M30: 99900 | N30: BXGY | O30: =O29 -> B3 DISC 10% | P30: BXGY
A31: =A30 -> 2026 NOV-FEB B3 DISC 10% | B31: =B30 -> 46086 | C31: =C30 -> 46092 | D31: 3321 | E31: 337 | F31: 4 | G31: 1 | H31: 81679 | I31: CHARACTER | J31: 61549153 | K31: TSSPBOB1 | L31: SS T-SHIRT SPONGEBOB TSSPBOB1:CHARCOAL:11-12:GRAPHIC:SS T-SHIRT | M31: 99900 | N31: BXGY | O31: B3 DISC 10% | P31: BXGY
A32: =A31 -> 2026 NOV-FEB B3 DISC 10% | B32: =B31 -> 46086 | C32: =C31 -> 46092 | D32: 3321 | E32: 337 | F32: 4 | G32: 1 | H32: 81679 | I32: CHARACTER | J32: 61549162 | K32: TSSPBOB2 | L32: SS T-SHIRT SPONGEBOB TSSPBOB2:PASTEL PINK:4:GRAPHIC:SS T-SHIRT | M32: 99900 | N32: BXGY | O32: =O31 -> B3 DISC 10% | P32: BXGY
A33: =A32 -> 2026 NOV-FEB B3 DISC 10% | B33: =B32 -> 46086 | C33: =C32 -> 46092 | D33: 3321 | E33: 337 | F33: 4 | G33: 1 | H33: 81679 | I33: CHARACTER | J33: 61549171 | K33: TSSPBOB2 | L33: SS T-SHIRT SPONGEBOB TSSPBOB2:PASTEL PINK:5:GRAPHIC:SS T-SHIRT | M33: 99900 | N33: BXGY | O33: B3 DISC 10% | P33: BXGY
A34: =A33 -> 2026 NOV-FEB B3 DISC 10% | B34: =B33 -> 46086 | C34: =C33 -> 46092 | D34: 3321 | E34: 337 | F34: 4 | G34: 1 | H34: 81679 | I34: CHARACTER | J34: 61549180 | K34: TSSPBOB2 | L34: SS T-SHIRT SPONGEBOB TSSPBOB2:PASTEL PINK:6:GRAPHIC:SS T-SHIRT | M34: 99900 | N34: BXGY | O34: =O33 -> B3 DISC 10% | P34: BXGY
A35: =A34 -> 2026 NOV-FEB B3 DISC 10% | B35: =B34 -> 46086 | C35: =C34 -> 46092 | D35: 3321 | E35: 337 | F35: 4 | G35: 1 | H35: 81679 | I35: CHARACTER | J35: 61549199 | K35: TSSPBOB2 | L35: SS T-SHIRT SPONGEBOB TSSPBOB2:PASTEL PINK:7-8:GRAPHIC:SS T-SHIRT | M35: 99900 | N35: BXGY | O35: B3 DISC 10% | P35: BXGY
A36: =A35 -> 2026 NOV-FEB B3 DISC 10% | B36: =B35 -> 46086 | C36: =C35 -> 46092 | D36: 3321 | E36: 337 | F36: 4 | G36: 1 | H36: 81679 | I36: CHARACTER | J36: 61549206 | K36: TSSPBOB2 | L36: SS T-SHIRT SPONGEBOB TSSPBOB2:PASTEL PINK:9-10:GRAPHIC:SS T-SHIRT | M36: 99900 | N36: BXGY | O36: =O35 -> B3 DISC 10% | P36: BXGY
A37: =A36 -> 2026 NOV-FEB B3 DISC 10% | B37: =B36 -> 46086 | C37: =C36 -> 46092 | D37: 3321 | E37: 337 | F37: 4 | G37: 3 | H37: 81679 | I37: CHARACTER | J37: 61549215 | K37: TSSPBOB2 | L37: SS T-SHIRT SPONGEBOB TSSPBOB2:PASTEL PINK:11-12:GRAPHIC:SS T-SHIRT | M37: 229900 | N37: BXGY | O37: B3 DISC 10% | P37: BXGY
A38: =A37 -> 2026 NOV-FEB B3 DISC 10% | B38: =B37 -> 46086 | C38: =C37 -> 46092 | D38: 3321 | E38: 337 | F38: 4 | G38: 3 | H38: 81588 | I38: CHARACTER | J38: 61550025 | K38: JKHPOT | L38: JACKET HOODIE HARRY POTTER JKHPOT:MAROON:7-8:GRAPHIC:JACKET | M38: 229900 | N38: BXGY | O38: =O37 -> B3 DISC 10% | P38: BXGY
A39: =A38 -> 2026 NOV-FEB B3 DISC 10% | B39: =B38 -> 46086 | C39: =C38 -> 46092 | D39: 3321 | E39: 337 | F39: 4 | G39: 3 | H39: 81588 | I39: CHARACTER | J39: 61550034 | K39: JKHPOT | L39: JACKET HOODIE HARRY POTTER JKHPOT:MAROON:9-10:GRAPHIC:JACKET | M39: 229900 | N39: BXGY | O39: B3 DISC 10% | P39: BXGY
A40: =A39 -> 2026 NOV-FEB B3 DISC 10% | B40: =B39 -> 46086 | C40: =C39 -> 46092 | D40: 3321 | E40: 337 | F40: 4 | G40: 3 | H40: 81588 | I40: CHARACTER | J40: 61550043 | K40: JKHPOT | L40: JACKET HOODIE HARRY POTTER JKHPOT:MAROON:11-12:GRAPHIC:JACKET | M40: 229900 | N40: BXGY | O40: =O39 -> B3 DISC 10% | P40: BXGY
...

Sheet 2025 OCT SHARP PRICE - 3321
A1: ACARA | B1: FROM DATE | C1: TO DATE | D1: DEPT | E1: WORLD | F1: DIVISION | G1: CLASS | H1: SUPPLIER | I1: BRAND | J1: SKU | K1: ARTICLE | L1: DESCRIPTION | M1: HARGA NORMAL | N1: DISKON | O1: HARGA PROMO | P1: DISCOUNT TYPE
A2: 2025 OCT SHARP PRICE | B2: ='2025 HILITE D80 - 3321'!B3 -> 46086 | C2: ='2025 HILITE D80 - 3321'!C3 -> 46092 | D2: 3321 | E2: 337 | F2: 4 | G2: 1 | H2: 81588 | I2: CHARACTER | J2: 61094466 | K2: TSTNJ2 | L2: SS T-SHIRT PRINT KANTONG TOM N JERRY TSTNJ2:OFF WHITE:4:GRAPHIC:SS T-SHIRT | M2: 99900 | N2: 0 | O2: SHARP PRICE | P2: AMOUNT
A3: =A2 -> 2025 OCT SHARP PRICE | B3: =B2 -> 46086 | C3: =C2 -> 46092 | D3: 3321 | E3: 337 | F3: 4 | G3: 1 | H3: 81588 | I3: CHARACTER | J3: 61094475 | K3: TSTNJ2 | L3: SS T-SHIRT PRINT KANTONG TOM N JERRY TSTNJ2:OFF WHITE:5:GRAPHIC:SS T-SHIRT | M3: 99900 | N3: 0 | O3: =O2 -> SHARP PRICE | P3: AMOUNT
A4: =A3 -> 2025 OCT SHARP PRICE | B4: =B3 -> 46086 | C4: =C3 -> 46092 | D4: 3321 | E4: 337 | F4: 4 | G4: 1 | H4: 81588 | I4: CHARACTER | J4: 61094484 | K4: TSTNJ2 | L4: SS T-SHIRT PRINT KANTONG TOM N JERRY TSTNJ2:OFF WHITE:6:GRAPHIC:SS T-SHIRT | M4: 99900 | N4: 0 | O4: =O3 -> SHARP PRICE | P4: AMOUNT
A5: =A4 -> 2025 OCT SHARP PRICE | B5: =B4 -> 46086 | C5: =C4 -> 46092 | D5: 3321 | E5: 337 | F5: 4 | G5: 1 | H5: 81588 | I5: CHARACTER | J5: 61094493 | K5: TSTNJ2 | L5: SS T-SHIRT PRINT KANTONG TOM N JERRY TSTNJ2:OFF WHITE:7-8:GRAPHIC:SS T-SHIRT | M5: 99900 | N5: 0 | O5: =O4 -> SHARP PRICE | P5: AMOUNT
A6: =A5 -> 2025 OCT SHARP PRICE | B6: =B5 -> 46086 | C6: =C5 -> 46092 | D6: 3321 | E6: 337 | F6: 4 | G6: 1 | H6: 81588 | I6: CHARACTER | J6: 61094500 | K6: TSTNJ2 | L6: SS T-SHIRT PRINT KANTONG TOM N JERRY TSTNJ2:OFF WHITE:9-10:GRAPHIC:SS T-SHIRT | M6: 99900 | N6: 0 | O6: =O5 -> SHARP PRICE | P6: AMOUNT
A7: =A6 -> 2025 OCT SHARP PRICE | B7: =B6 -> 46086 | C7: =C6 -> 46092 | D7: 3321 | E7: 337 | F7: 4 | G7: 1 | H7: 81588 | I7: CHARACTER | J7: 61094519 | K7: TSTNJ2 | L7: SS T-SHIRT PRINT KANTONG TOM N JERRY TSTNJ2:OFF WHITE:11-12:GRAPHIC:SS T-SHIRT | M7: 99900 | N7: 0 | O7: =O6 -> SHARP PRICE | P7: AMOUNT
A8: =A7 -> 2025 OCT SHARP PRICE | B8: =B7 -> 46086 | C8: =C7 -> 46092 | D8: 3321 | E8: 337 | F8: 4 | G8: 1 | H8: 81588 | I8: CHARACTER | J8: 55507398 | K8: TSTNJ4 | L8: SS T-SHIRT TOM N JERRY HIDE N SEEK TSTNJ4:PASTEL ORANGE:4:GRAPHIC:SS T-SHIRT | M8: 99900 | N8: 0 | O8: =O7 -> SHARP PRICE | P8: AMOUNT
A9: =A8 -> 2025 OCT SHARP PRICE | B9: =B8 -> 46086 | C9: =C8 -> 46092 | D9: 3321 | E9: 337 | F9: 4 | G9: 1 | H9: 81588 | I9: CHARACTER | J9: 55507405 | K9: TSTNJ4 | L9: SS T-SHIRT TOM N JERRY HIDE N SEEK TSTNJ4:PASTEL ORANGE:5:GRAPHIC:SS T-SHIRT | M9: 99900 | N9: 0 | O9: =O8 -> SHARP PRICE | P9: AMOUNT
A10: =A9 -> 2025 OCT SHARP PRICE | B10: =B9 -> 46086 | C10: =C9 -> 46092 | D10: 3321 | E10: 337 | F10: 4 | G10: 1 | H10: 81588 | I10: CHARACTER | J10: 55507414 | K10: TSTNJ4 | L10: SS T-SHIRT TOM N JERRY HIDE N SEEK TSTNJ4:PASTEL ORANGE:6:GRAPHIC:SS T-SHIRT | M10: 99900 | N10: 0 | O10: =O9 -> SHARP PRICE | P10: AMOUNT
A11: =A10 -> 2025 OCT SHARP PRICE | B11: =B10 -> 46086 | C11: =C10 -> 46092 | D11: 3321 | E11: 337 | F11: 4 | G11: 1 | H11: 81588 | I11: CHARACTER | J11: 55507423 | K11: TSTNJ4 | L11: SS T-SHIRT TOM N JERRY HIDE N SEEK TSTNJ4:PASTEL ORANGE:7-8:GRAPHIC:SS T-SHIRT | M11: 99900 | N11: 0 | O11: =O10 -> SHARP PRICE | P11: AMOUNT
A12: =A11 -> 2025 OCT SHARP PRICE | B12: =B11 -> 46086 | C12: =C11 -> 46092 | D12: 3321 | E12: 337 | F12: 4 | G12: 1 | H12: 81588 | I12: CHARACTER | J12: 55507432 | K12: TSTNJ4 | L12: SS T-SHIRT TOM N JERRY HIDE N SEEK TSTNJ4:PASTEL ORANGE:9-10:GRAPHIC:SS T-SHIRT | M12: 99900 | N12: 0 | O12: =O11 -> SHARP PRICE | P12: AMOUNT
A13: =A12 -> 2025 OCT SHARP PRICE | B13: =B12 -> 46086 | C13: =C12 -> 46092 | D13: 3321 | E13: 337 | F13: 4 | G13: 1 | H13: 81588 | I13: CHARACTER | J13: 55507441 | K13: TSTNJ4 | L13: SS T-SHIRT TOM N JERRY HIDE N SEEK TSTNJ4:PASTEL ORANGE:11-12:GRAPHIC:SS T-SHIRT | M13: 99900 | N13: 0 | O13: =O12 -> SHARP PRICE | P13: AMOUNT
A14: =A13 -> 2025 OCT SHARP PRICE | B14: =B13 -> 46086 | C14: =C13 -> 46092 | D14: 3321 | E14: 337 | F14: 4 | G14: 1 | H14: 81588 | I14: CHARACTER | J14: 61094402 | K14: TSTNJ3 | L14: SS T-SHIRT TOM N JERRY TSTNJ3:MAROON:4:GRAPHIC:SS T-SHIRT | M14: 99900 | N14: 0 | O14: =O13 -> SHARP PRICE | P14: AMOUNT
... A19: =A18 -> 2025 OCT SHARP PRICE | B19: =B18 -> 46086 | C19: =C18 -> 46092 | D19: 3321 | E19: 337 | F19: 4 | G19: 1 | H19: 81588 | I19: CHARACTER | J19: 61094457 | K19: TSTNJ3 | L19: SS T-SHIRT TOM N JERRY TSTNJ3:MAROON:11-12:GRAPHIC:SS T-SHIRT | M19: 99900 | N19: 0 | O19: =O18 -> SHARP PRICE | P19: AMOUNT

Sheet 2025 SEPT B1 D30 - 3321
A1: ACARA | B1: FROM DATE | C1: TO DATE | D1: DEPT | E1: WORLD | F1: DIVISION | G1: CLASS | H1: SUPPLIER | I1: BRAND | J1: SKU | K1: ARTICLE | L1: DESCRIPTION | M1: HARGA NORMAL | N1: DISKON | O1: HARGA PROMO | P1: DISCOUNT TYPE
A2: 2025 SEPT B1 30% | B2: ='2025 AUG B1G1-3321'!B87 -> 46086 | C2: ='2025 AUG B1G1-3321'!C87 -> 46092 | D2: 3321 | E2: 337 | F2: 4 | G2: 1 | H2: 81588 | I2: CHARACTER | J2: 55301065 | K2: TS3KU2 | L2: SS T-SHIRT KUROMI TS3KU2:DUSTY PINK:4:GRAPHIC:SS T-SHIRT | M2: 99900 | N2: 0.3 | O2: =M2-((30*M2)/100) -> 69930 | P2: PERCENTAGE
A3: =A2 -> 2025 SEPT B1 30% | B3: =B2 -> 46086 | C3: =C2 -> 46092 | D3: 3321 | E3: 337 | F3: 4 | G3: 1 | H3: 81588 | I3: CHARACTER | J3: 55301074 | K3: TS3KU2 | L3: SS T-SHIRT KUROMI TS3KU2:DUSTY PINK:5:GRAPHIC:SS T-SHIRT | M3: 99900 | N3: =N2 -> 0.3 | O3: =M3-((30*M3)/100) -> 69930 | P3: =P2 -> PERCENTAGE
A4: =A3 -> 2025 SEPT B1 30% | B4: =B3 -> 46086 | C4: =C3 -> 46092 | D4: 3321 | E4: 337 | F4: 4 | G4: 1 | H4: 81588 | I4: CHARACTER | J4: 55301083 | K4: TS3KU2 | L4: SS T-SHIRT KUROMI TS3KU2:DUSTY PINK:6:GRAPHIC:SS T-SHIRT | M4: 99900 | N4: =N3 -> 0.3 | O4: =M4-((30*M4)/100) -> 69930 | P4: =P3 -> PERCENTAGE
A5: =A4 -> 2025 SEPT B1 30% | B5: =B4 -> 46086 | C5: =C4 -> 46092 | D5: 3321 | E5: 337 | F5: 4 | G5: 1 | H5: 81588 | I5: CHARACTER | J5: 55301092 | K5: TS3KU2 | L5: SS T-SHIRT KUROMI TS3KU2:DUSTY PINK:7-8:GRAPHIC:SS T-SHIRT | M5: 99900 | N5: =N4 -> 0.3 | O5: =M5-((30*M5)/100) -> 69930 | P5: =P4 -> PERCENTAGE
A6: =A5 -> 2025 SEPT B1 30% | B6: =B5 -> 46086 | C6: =C5 -> 46092 | D6: 3321 | E6: 337 | F6: 4 | G6: 1 | H6: 81588 | I6: CHARACTER | J6: 55301163 | K6: TS3HK2 | L6: SS T-SHIRT HELLO KITTY CS BAHU TS3HK2:OFF WHITE:4:GRAPHIC:SS T-SHIRT | M6: 99900 | N6: =N5 -> 0.3 | O6: =M6-((30*M6)/100) -> 69930 | P6: =P5 -> PERCENTAGE
A7: =A6 -> 2025 SEPT B1 30% | B7: =B6 -> 46086 | C7: =C6 -> 46092 | D7: 3321 | E7: 337 | F7: 4 | G7: 1 | H7: 81588 | I7: CHARACTER | J7: 55301172 | K7: TS3HK2 | L7: SS T-SHIRT HELLO KITTY CS BAHU TS3HK2:OFF WHITE:5:GRAPHIC:SS T-SHIRT | M7: 99900 | N7: =N6 -> 0.3 | O7: =M7-((30*M7)/100) -> 69930 | P7: =P6 -> PERCENTAGE
A8: =A7 -> 2025 SEPT B1 30% | B8: =B7 -> 46086 | C8: =C7 -> 46092 | D8: 3321 | E8: 337 | F8: 4 | G8: 1 | H8: 81588 | I8: CHARACTER | J8: 55301181 | K8: TS3HK2 | L8: SS T-SHIRT HELLO KITTY CS BAHU TS3HK2:OFF WHITE:6:GRAPHIC:SS T-SHIRT | M8: 99900 | N8: =N7 -> 0.3 | O8: =M8-((30*M8)/100) -> 69930 | P8: =P7 -> PERCENTAGE
A9: =A8 -> 2025 SEPT B1 30% | B9: =B8 -> 46086 | C9: =C8 -> 46092 | D9: 3321 | E9: 337 | F9: 4 | G9: 1 | H9: 81588 | I9: CHARACTER | J9: 55301190 | K9: TS3HK2 | L9: SS T-SHIRT HELLO KITTY CS BAHU TS3HK2:OFF WHITE:7-8:GRAPHIC:SS T-SHIRT | M9: 99900 | N9: =N8 -> 0.3 | O9: =M9-((30*M9)/100) -> 69930 | P9: =P8 -> PERCENTAGE
A10: =A9 -> 2025 SEPT B1 30% | B10: =B9 -> 46086 | C10: =C9 -> 46092 | D10: 3321 | E10: 337 | F10: 4 | G10: 1 | H10: 81588 | I10: CHARACTER | J10: 55301207 | K10: TS3HK2 | L10: SS T-SHIRT HELLO KITTY CS BAHU TS3HK2:OFF WHITE:9-10:GRAPHIC:SS T-SHIRT | M10: 99900 | N10: =N9 -> 0.3 | O10: =M10-((30*M10)/100) -> 69930 | P10: =P9 -> PERCENTAGE
A11: =A10 -> 2025 SEPT B1 30% | B11: =B10 -> 46086 | C11: =C10 -> 46092 | D11: 3321 | E11: 337 | F11: 4 | G11: 1 | H11: 81588 | I11: CHARACTER | J11: 55301216 | K11: TS3HK2 | L11: SS T-SHIRT HELLO KITTY CS BAHU TS3HK2:OFF WHITE:11-12:GRAPHIC:SS T-SHIRT | M11: 99900 | N11: =N10 -> 0.3 | O11: =M11-((30*M11)/100) -> 69930 | P11: =P10 -> PERCENTAGE
A12: =A11 -> 2025 SEPT B1 30% | B12: =B11 -> 46086 | C12: =C11 -> 46092 | D12: 3321 | E12: 337 | F12: 4 | G12: 1 | H12: 81588 | I12: CHARACTER | J12: 55301109 | K12: TS3HK1 | L12: SS T-SHIRT HELLO KITTY PIPING TS3HK1:PASTEL PINK:4:GRAPHIC:SS T-SHIRT | M12: 99900 | N12: =N11 -> 0.3 | O12: =M12-((30*M12)/100) -> 69930 | P12: =P11 -> PERCENTAGE
A13: =A12 -> 2025 SEPT B1 30% | B13: =B12 -> 46086 | C13: =C12 -> 46092 | D13: 3321 | E13: 337 | F13: 4 | G13: 1 | H13: 81588 | I13: CHARACTER | J13: 55301118 | K13: TS3HK1 | L13: SS T-SHIRT HELLO KITTY PIPING TS3HK1:PASTEL PINK:5:GRAPHIC:SS T-SHIRT | M13: 99900 | N13: =N12 -> 0.3 | O13: =M13-((30*M13)/100) -> 69930 | P13: =P12 -> PERCENTAGE
A14: =A13 -> 2025 SEPT B1 30% | B14: =B13 -> 46086 | C14: =C13 -> 46092 | D14: 3321 | E14: 337 | F14: 4 | G14: 1 | H14: 81588 | I14: CHARACTER | J14: 55301127 | K14: TS3HK1 | L14: SS T-SHIRT HELLO KITTY PIPING TS3HK1:PASTEL PINK:6:GRAPHIC:SS T-SHIRT | M14: 99900 | N14: =N13 -> 0.3 | O14: =M14-((30*M14)/100) -> 69930 | P14: =P13 -> PERCENTAGE
... A71: =A70 -> 2025 SEPT B1 30% | B71: =B70 -> 46086 | C71: =C70 -> 46092 | D71: 3321 | E71: 337 | F71: 4 | G71: 4 | H71: 81588 | I71: CHARACTER | J71: 55507745 | K71: JG3KU | L71: JOGGER KUROMI JG3KU:CHARCOAL:11-12:EMBRO:JOGGER | M71: 149900 | N71: =N70 -> 0.3 | O71: =M71-((30*M71)/100) -> 104930 | P71: =P70 -> PERCENTAGE

Sheet 2025 AUG B1G1-3321
A1: ACARA | B1: FROM DATE | C1: TO DATE | D1: DEPT | E1: WORLD | F1: DIVISION | G1: CLASS | H1: SUPPLIER | I1: BRAND | J1: SKU | K1: ARTICLE | L1: DESCRIPTION | M1: HARGA NORMAL | N1: DISKON | O1: HARGA PROMO | P1: DISCOUNT TYPE
A2: 2025 AUG B1G1 | B2: 46086 | C2: 46092 | D2: 3321 | E2: 337 | F2: 4 | G2: 1 | H2: 81588 | I2: CHARACTER | J2: 55301225 | K2: TS3HK3 | L2: SS T-SHIRT HELLO KITTY KTG TS3HK3:MISTY LIGHT GREY:4:GRAPHIC:SS T-SHIRT | M2: 99900 | N2: BXGY | O2: B1G1 | P2: BXGY
A3: =A2 -> 2025 AUG B1G1 | B3: =B2 -> 46086 | C3: =C2 -> 46092 | D3: 3321 | E3: 337 | F3: 4 | G3: 1 | H3: 81588 | I3: CHARACTER | J3: 55301234 | K3: TS3HK3 | L3: SS T-SHIRT HELLO KITTY KTG TS3HK3:MISTY LIGHT GREY:5:GRAPHIC:SS T-SHIRT | M3: 99900 | N3: BXGY | O3: =O2 -> B1G1 | P3: BXGY
A4: =A3 -> 2025 AUG B1G1 | B4: =B3 -> 46086 | C4: =C3 -> 46092 | D4: 3321 | E4: 337 | F4: 4 | G4: 1 | H4: 81588 | I4: CHARACTER | J4: 55301243 | K4: TS3HK3 | L4: SS T-SHIRT HELLO KITTY KTG TS3HK3:MISTY LIGHT GREY:6:GRAPHIC:SS T-SHIRT | M4: 99900 | N4: BXGY | O4: =O3 -> B1G1 | P4: BXGY
A5: =A4 -> 2025 AUG B1G1 | B5: =B4 -> 46086 | C5: =C4 -> 46092 | D5: 3321 | E5: 337 | F5: 4 | G5: 1 | H5: 81588 | I5: CHARACTER | J5: 55301252 | K5: TS3HK3 | L5: SS T-SHIRT HELLO KITTY KTG TS3HK3:MISTY LIGHT GREY:7-8:GRAPHIC:SS T-SHIRT | M5: 99900 | N5: BXGY | O5: =O4 -> B1G1 | P5: BXGY
A6: =A5 -> 2025 AUG B1G1 | B6: =B5 -> 46086 | C6: =C5 -> 46092 | D6: 3321 | E6: 337 | F6: 4 | G6: 1 | H6: 81588 | I6: CHARACTER | J6: 55301261 | K6: TS3HK3 | L6: SS T-SHIRT HELLO KITTY KTG TS3HK3:MISTY LIGHT GREY:9-10:GRAPHIC:SS T-SHIRT | M6: 99900 | N6: BXGY | O6: =O5 -> B1G1 | P6: BXGY
A7: =A6 -> 2025 AUG B1G1 | B7: =B6 -> 46086 | C7: =C6 -> 46092 | D7: 3321 | E7: 337 | F7: 4 | G7: 1 | H7: 81588 | I7: CHARACTER | J7: 55301270 | K7: TS3HK3 | L7: SS T-SHIRT HELLO KITTY KTG TS3HK3:MISTY LIGHT GREY:11-12:GRAPHIC:SS T-SHIRT | M7: 99900 | N7: BXGY | O7: =O6 -> B1G1 | P7: BXGY
A8: =A7 -> 2025 AUG B1G1 | B8: =B7 -> 46086 | C8: =C7 -> 46092 | D8: 3321 | E8: 337 | F8: 4 | G8: 1 | H8: 81588 | I8: CHARACTER | J8: 55507450 | K8: TS3MM1 | L8: SS T-SHIRT MY MELODY TS3MM1:MAROON:4:GRAPHIC:SS T-SHIRT | M8: 99900 | N8: BXGY | O8: =O7 -> B1G1 | P8: BXGY
A9: =A8 -> 2025 AUG B1G1 | B9: =B8 -> 46086 | C9: =C8 -> 46092 | D9: 3321 | E9: 337 | F9: 4 | G9: 1 | H9: 81588 | I9: CHARACTER | J9: 55507469 | K9: TS3MM1 | L9: SS T-SHIRT MY MELODY TS3MM1:MAROON:5:GRAPHIC:SS T-SHIRT | M9: 99900 | N9: BXGY | O9: =O8 -> B1G1 | P9: BXGY
A10: =A9 -> 2025 AUG B1G1 | B10: =B9 -> 46086 | C10: =C9 -> 46092 | D10: 3321 | E10: 337 | F10: 4 | G10: 1 | H10: 81588 | I10: CHARACTER | J10: 55507478 | K10: TS3MM1 | L10: SS T-SHIRT MY MELODY TS3MM1:MAROON:6:GRAPHIC:SS T-SHIRT | M10: 99900 | N10: BXGY | O10: =O9 -> B1G1 | P10: BXGY
A11: =A10 -> 2025 AUG B1G1 | B11: =B10 -> 46086 | C11: =C10 -> 46092 | D11: 3321 | E11: 337 | F11: 4 | G11: 1 | H11: 81588 | I11: CHARACTER | J11: 55507487 | K11: TS3MM1 | L11: SS T-SHIRT MY MELODY TS3MM1:MAROON:7-8:GRAPHIC:SS T-SHIRT | M11: 99900 | N11: BXGY | O11: =O10 -> B1G1 | P11: BXGY
A12: =A11 -> 2025 AUG B1G1 | B12: =B11 -> 46086 | C12: =C11 -> 46092 | D12: 3321 | E12: 337 | F12: 4 | G12: 1 | H12: 81588 | I12: CHARACTER | J12: 55507192 | K12: TS3KU4 | L12: SS T-SHIRT KUROMI TS3KU4:CHARCOAL:4:GRAPHIC:SS T-SHIRT | M12: 99900 | N12: BXGY | O12: =O11 -> B1G1 | P12: BXGY
A13: =A12 -> 2025 AUG B1G1 | B13: =B12 -> 46086 | C13: =C12 -> 46092 | D13: 3321 | E13: 337 | F13: 4 | G13: 1 | H13: 81588 | I13: CHARACTER | J13: 55507209 | K13: TS3KU4 | L13: SS T-SHIRT KUROMI TS3KU4:CHARCOAL:5:GRAPHIC:SS T-SHIRT | M13: 99900 | N13: BXGY | O13: =O12 -> B1G1 | P13: BXGY
A14: =A13 -> 2025 AUG B1G1 | B14: =B13 -> 46086 | C14: =C13 -> 46092 | D14: 3321 | E14: 337 | F14: 4 | G14: 1 | H14: 81588 | I14: CHARACTER | J14: 55507218 | K14: TS3KU4 | L14: SS T-SHIRT KUROMI TS3KU4:CHARCOAL:6:GRAPHIC:SS T-SHIRT | M14: 99900 | N14: BXGY | O14: =O13 -> B1G1 | P14: BXGY
... A87: =A86 -> 2025 AUG B1G1 | B87: =B86 -> 46086 | C87: =C86 -> 46092 | D87: 3321 | E87: 337 | F87: 4 | G87: 1 | H87: 81588 | I87: CHARACTER | J87: 59168159 | K87: TSPAW1 | L87: SS T-SHIRT PAWFECT TEAM PAW PATROL TSPAW1:OFF WHITE:7-8:GRAPHIC:SS T-SHIRT | M87: 99900 | N87: BXGY | O87: =O86 -> B1G1 | P87: BXGY

Sheet 2025 JUL B1G1 - 3321
A1: ACARA | B1: FROM DATE | C1: TO DATE | D1: DEPT | E1: WORLD | F1: DIVISION | G1: CLASS | H1: SUPPLIER | I1: BRAND | J1: SKU | K1: ARTICLE | L1: DESCRIPTION | M1: HARGA NORMAL | N1: DISKON | O1: HARGA PROMO | P1: DISCOUNT TYPE
A2: 2025 JUL B1G1 | B2: ='2025 AUG B1G1-3321'!B87 -> 46086 | C2: ='2025 AUG B1G1-3321'!C87 -> 46092 | D2: 3321 | E2: 337 | F2: 4 | G2: 1 | H2: 81588 | I2: CHARACTER | J2: 54954933 | K2: LP3CN | L2: LONG PANTS CINNAMOROLL LP3CN:NAVY BLUE:11-12:GRAPHIC:LONG PANTS | M2: 149900 | N2: BXGY | O2: B1G1 | P2: BXGY
A3: 2025 JUL B1G1 | B3: =B2 -> 46086 | C3: =C2 -> 46092 | D3: 3321 | E3: 337 | F3: 4 | G3: 1 | H3: 81588 | I3: CHARACTER | J3: 54954915 | K3: LP3CN | L3: LONG PANTS CINNAMOROLL LP3CN:NAVY BLUE:7-8:GRAPHIC:LONG PANTS | M3: 149900 | N3: BXGY | O3: B1G1 | P3: BXGY
A4: 2025 JUL B1G1 | B4: =B3 -> 46086 | C4: =C3 -> 46092 | D4: 3321 | E4: 337 | F4: 4 | G4: 1 | H4: 81588 | I4: CHARACTER | J4: 54954924 | K4: LP3CN | L4: LONG PANTS CINNAMOROLL LP3CN:NAVY BLUE:9-10:GRAPHIC:LONG PANTS | M4: 149900 | N4: BXGY | O4: B1G1 | P4: BXGY
A5: 2025 JUL B1G1 | B5: =B4 -> 46086 | C5: =C4 -> 46092 | D5: 3321 | E5: 337 | F5: 4 | G5: 1 | H5: 81588 | I5: CHARACTER | J5: 54954942 | K5: LP3CN | L5: LONG PANTS CINNAMOROLL LP3CN:NAVY BLUE:13-14:GRAPHIC:LONG PANTS | M5: 149900 | N5: BXGY | O5: B1G1 | P5: BXGY
A6: 2025 JUL B1G1 | B6: =B5 -> 46086 | C6: =C5 -> 46092 | D6: 3321 | E6: 337 | F6: 4 | G6: 1 | H6: 81462 | I6: CHARACTER | J6: 54954559 | K6: TS3CN1 | L6: SS T-SHIRT CINNAMOROLL PITA TS3CN1:PASTEL PINK:4:GRAPHIC:SS T-SHIRT | M6: 99900 | N6: BXGY | O6: B1G1 | P6: BXGY
A7: 2025 JUL B1G1 | B7: =B6 -> 46086 | C7: =C6 -> 46092 | D7: 3321 | E7: 337 | F7: 4 | G7: 1 | H7: 81462 | I7: CHARACTER | J7: 54954568 | K7: TS3CN1 | L7: SS T-SHIRT CINNAMOROLL PITA TS3CN1:PASTEL PINK:5:GRAPHIC:SS T-SHIRT | M7: 99900 | N7: BXGY | O7: B1G1 | P7: BXGY
A8: 2025 JUL B1G1 | B8: =B7 -> 46086 | C8: =C7 -> 46092 | D8: 3321 | E8: 337 | F8: 4 | G8: 1 | H8: 81462 | I8: CHARACTER | J8: 54954577 | K8: TS3CN1 | L8: SS T-SHIRT CINNAMOROLL PITA TS3CN1:PASTEL PINK:6:GRAPHIC:SS T-SHIRT | M8: 99900 | N8: BXGY | O8: B1G1 | P8: BXGY
A9: 2025 JUL B1G1 | B9: =B8 -> 46086 | C9: =C8 -> 46092 | D9: 3321 | E9: 337 | F9: 4 | G9: 1 | H9: 81462 | I9: CHARACTER | J9: 54954586 | K9: TS3CN1 | L9: SS T-SHIRT CINNAMOROLL PITA TS3CN1:PASTEL PINK:7-8:GRAPHIC:SS T-SHIRT | M9: 99900 | N9: BXGY | O9: B1G1 | P9: BXGY
A10: 2025 JUL B1G1 | B10: =B9 -> 46086 | C10: =C9 -> 46092 | D10: 3321 | E10: 337 | F10: 4 | G10: 1 | H10: 81588 | I10: CHARACTER | J10: 54954755 | K10: TS3CN6 | L10: SS T-SHIRT CINNAMOROLL RAGLAN TS3CN6:OFF WHITE:7-8:GRAPHIC:SS T-SHIRT | M10: 99900 | N10: BXGY | O10: B1G1 | P10: BXGY
A11: 2025 JUL B1G1 | B11: =B10 -> 46086 | C11: =C10 -> 46092 | D11: 3321 | E11: 337 | F11: 4 | G11: 1 | H11: 81588 | I11: CHARACTER | J11: 54954764 | K11: TS3CN6 | L11: SS T-SHIRT CINNAMOROLL RAGLAN TS3CN6:OFF WHITE:9-10:GRAPHIC:SS T-SHIRT | M11: 99900 | N11: BXGY | O11: B1G1 | P11: BXGY
A12: 2025 JUL B1G1 | B12: =B11 -> 46086 | C12: =C11 -> 46092 | D12: 3321 | E12: 337 | F12: 4 | G12: 1 | H12: 81588 | I12: CHARACTER | J12: 54954773 | K12: TS3CN6 | L12: SS T-SHIRT CINNAMOROLL RAGLAN TS3CN6:OFF WHITE:11-12:GRAPHIC:SS T-SHIRT | M12: 99900 | N12: BXGY | O12: B1G1 | P12: BXGY
A13: 2025 JUL B1G1 | B13: =B12 -> 46086 | C13: =C12 -> 46092 | D13: 3321 | E13: 337 | F13: 4 | G13: 1 | H13: 81588 | I13: CHARACTER | J13: 54954782 | K13: TS3CN6 | L13: SS T-SHIRT CINNAMOROLL RAGLAN TS3CN6:OFF WHITE:13-14:GRAPHIC:SS T-SHIRT | M13: 99900 | N13: BXGY | O13: B1G1 | P13: BXGY
A14: 2025 JUL B1G1 | B14: =B13 -> 46086 | C14: =C13 -> 46092 | D14: 3321 | E14: 337 | F14: 4 | G14: 1 | H14: 81679 | I14: CHARACTER | J14: 55253457 | K14: TS3UCN1 | L14: SS T-SHIRT CINNAMOROLL AWAN TS3UCN1:OFF WHITE:4:GRAPHIC:SS T-SHIRT | M14: 99900 | N14: BXGY | O14: B1G1 | P14: BXGY
... A63: 2025 JUL B1G1 | B63: =B62 -> 46086 | C63: =C62 -> 46092 | D63: 3321 | E63: 337 | F63: 4 | G63: 5 | H63: 190 | I63: CHARACTER | J63: 54955021 | K63: DSO3CN | L63: SS MIDI DRESS OVL CINNAMOROLL DSO3CN:PASTEL BLUE:7-8:GRAPHIC:SS MIDI DRESS | M63: 149900 | N63: BXGY | O63: B1G1 | P63: BXGY

Sheet 2025 HILITE D80 - 3321
A1: ACARA | B1: FROM DATE | C1: TO DATE | D1: DEPT | E1: WORLD | F1: DIVISION | G1: CLASS | H1: SUPPLIER | I1: BRAND | J1: SKU | K1: ARTICLE | L1: DESCRIPTION | M1: HARGA NORMAL | N1: DISKON | O1: HARGA PROMO | P1: DISCOUNT TYPE
A2: 2025 HILITE DISC 80 | B2: ='2025 AUG B1G1-3321'!B87 -> 46086 | C2: ='2025 AUG B1G1-3321'!C87 -> 46092 | D2: 3321 | E2: 337 | F2: 4 | G2: 3 | H2: 81005 | I2: CHARACTER | J2: 52133270 | K2: LSSWCN | L2: LS SHIRT KOMBI WOVEN CINNAMOROLL LSSWCN:PASTEL PINK:5-6:STRIPES:LS SHIRT | M2: 229900 | N2: 0.8 | O2: =M2-((80*M2)/100) -> 45980 | P2: PERCENTAGE
A3: 2025 HILITE DISC 80 | B3: =B2 -> 46086 | C3: =C2 -> 46092 | D3: 3321 | E3: 337 | F3: 4 | G3: 3 | H3: 81005 | I3: CHARACTER | J3: 52133289 | K3: LSSWCN | L3: LS SHIRT KOMBI WOVEN CINNAMOROLL LSSWCN:PASTEL PINK:7-8:STRIPES:LS SHIRT | M3: 229900 | N3: 0.8 | O3: =M3-((80*M3)/100) -> 45980 | P3: PERCENTAGE
A4: 2025 HILITE DISC 80 | B4: =B3 -> 46086 | C4: =C3 -> 46092 | D4: 3321 | E4: 337 | F4: 4 | G4: 3 | H4: 81005 | I4: CHARACTER | J4: 52133298 | K4: LSSWCN | L4: LS SHIRT KOMBI WOVEN CINNAMOROLL LSSWCN:PASTEL PINK:9-10:STRIPES:LS SHIRT | M4: 229900 | N4: 0.8 | O4: =M4-((80*M4)/100) -> 45980 | P4: PERCENTAGE
A5: 2025 HILITE DISC 80 | B5: =B4 -> 46086 | C5: =C4 -> 46092 | D5: 3321 | E5: 337 | F5: 4 | G5: 3 | H5: 81005 | I5: CHARACTER | J5: 52133305 | K5: LSSWCN | L5: LS SHIRT KOMBI WOVEN CINNAMOROLL LSSWCN:PASTEL PINK:11-12:STRIPES:LS SHIRT | M5: 229900 | N5: 0.8 | O5: =M5-((80*M5)/100) -> 45980 | P5: PERCENTAGE
A6: 2025 HILITE DISC 80 | B6: =B5 -> 46086 | C6: =C5 -> 46092 | D6: 3321 | E6: 337 | F6: 4 | G6: 3 | H6: 81005 | I6: CHARACTER | J6: 52133314 | K6: LSSWKU | L6: LS SHIRT KOMBI WOVEN KUROMI LSSWKU:PASTEL PURPLE:5-6:STRIPES:LS SHIRT | M6: 229900 | N6: 0.8 | O6: =M6-((80*M6)/100) -> 45980 | P6: PERCENTAGE
A7: 2025 HILITE DISC 80 | B7: =B6 -> 46086 | C7: =C6 -> 46092 | D7: 3321 | E7: 337 | F7: 4 | G7: 3 | H7: 81005 | I7: CHARACTER | J7: 52133323 | K7: LSSWKU | L7: LS SHIRT KOMBI WOVEN KUROMI LSSWKU:PASTEL PURPLE:7-8:STRIPES:LS SHIRT | M7: 229900 | N7: 0.8 | O7: =M7-((80*M7)/100) -> 45980 | P7: PERCENTAGE
A8: 2025 HILITE DISC 80 | B8: =B7 -> 46086 | C8: =C7 -> 46092 | D8: 3321 | E8: 337 | F8: 4 | G8: 3 | H8: 81005 | I8: CHARACTER | J8: 52133332 | K8: LSSWKU | L8: LS SHIRT KOMBI WOVEN KUROMI LSSWKU:PASTEL PURPLE:9-10:STRIPES:LS SHIRT | M8: 229900 | N8: 0.8 | O8: =M8-((80*M8)/100) -> 45980 | P8: PERCENTAGE
A9: 2025 HILITE DISC 80 | B9: =B8 -> 46086 | C9: =C8 -> 46092 | D9: 3321 | E9: 337 | F9: 4 | G9: 3 | H9: 81005 | I9: CHARACTER | J9: 52133341 | K9: LSSWKU | L9: LS SHIRT KOMBI WOVEN KUROMI LSSWKU:PASTEL PURPLE:11-12:STRIPES:LS SHIRT | M9: 229900 | N9: 0.8 | O9: =M9-((80*M9)/100) -> 45980 | P9: PERCENTAGE
A10: 2025 HILITE DISC 80 | B10: =B9 -> 46086 | C10: =C9 -> 46092 | D10: 3321 | E10: 337 | F10: 4 | G10: 3 | H10: 81005 | I10: CHARACTER | J10: 52133529 | K10: DL25CN | L10: LS MIDI DRESS MIDI CINNAMOROLL DL25CN:PASTEL BLUE:3-4:STRIPES:LS MIDI DRESS | M10: 299900 | N10: 0.8 | O10: =M10-((80*M10)/100) -> 59980 | P10: PERCENTAGE
A11: 2025 HILITE DISC 80 | B11: =B10 -> 46086 | C11: =C10 -> 46092 | D11: 3321 | E11: 337 | F11: 4 | G11: 3 | H11: 81005 | I11: CHARACTER | J11: 52133538 | K11: DL25CN | L11: LS MIDI DRESS MIDI CINNAMOROLL DL25CN:PASTEL BLUE:4-5:STRIPES:LS MIDI DRESS | M11: 299900 | N11: 0.8 | O11: =M11-((80*M11)/100) -> 59980 | P11: PERCENTAGE
A12: 2025 HILITE DISC 80 | B12: =B11 -> 46086 | C12: =C11 -> 46092 | D12: 3321 | E12: 337 | F12: 4 | G12: 3 | H12: 81005 | I12: CHARACTER | J12: 52133547 | K12: DL25CN | L12: LS MIDI DRESS MIDI CINNAMOROLL DL25CN:PASTEL BLUE:5-6:STRIPES:LS MIDI DRESS | M12: 299900 | N12: 0.8 | O12: =M12-((80*M12)/100) -> 59980 | P12: PERCENTAGE
A13: 2025 HILITE DISC 80 | B13: =B12 -> 46086 | C13: =C12 -> 46092 | D13: 3321 | E13: 337 | F13: 4 | G13: 3 | H13: 81005 | I13: CHARACTER | J13: 52133556 | K13: DL25CN | L13: LS MIDI DRESS MIDI CINNAMOROLL DL25CN:PASTEL BLUE:7-8:STRIPES:LS MIDI DRESS | M13: 299900 | N13: 0.8 | O13: =M13-((80*M13)/100) -> 59980 | P13: PERCENTAGE
A14: 2025 HILITE DISC 80 | B14: =B13 -> 46086 | C14: =C13 -> 46092 | D14: 3321 | E14: 337 | F14: 4 | G14: 3 | H14: 81005 | I14: CHARACTER | J14: 52133565 | K14: DL25CN | L14: LS MIDI DRESS MIDI CINNAMOROLL DL25CN:PASTEL BLUE:9-10:STRIPES:LS MIDI DRESS | M14: 299900 | N14: 0.8 | O14: =M14-((80*M14)/100) -> 59980 | P14: PERCENTAGE
... A29: 2025 HILITE DISC 80 | B29: =B28 -> 46086 | C29: =C28 -> 46092 | D29: 3321 | E29: 337 | F29: 4 | G29: 3 | H29: 81698 | I29: CHARACTER | J29: 52296863 | K29: DL25AKU | L29: LS MIDI DRESS LEB KUROMI DL25AKU:PASTEL PURPLE:11-12:GRAPHIC:LS MIDI DRESS | M29: 339900 | N29: 0.8 | O29: =M29-((80*M29)/100) -> 67980 | P29: PERCENTAGE

Sheet 2024 JULY-SEP B1G2 - 3321
A1: ACARA | B1: FROM DATE | C1: TO DATE | D1: DEPT | E1: WORLD | F1: DIVISION | G1: CLASS | H1: SUPPLIER | I1: BRAND | J1: SKU | K1: ARTICLE | L1: DESCRIPTION | M1: HARGA NORMAL | N1: DISKON | O1: HARGA PROMO | P1: DISCOUNT TYPE
A2: 2024 JULY-DEC B1G2 | B2: ='2025 AUG B1G1-3321'!B87 -> 46086 | C2: ='2025 AUG B1G1-3321'!C87 -> 46092 | D2: 3321 | E2: 337 | F2: 4 | G2: 1 | H2: 81676 | I2: CHARACTER | J2: 20597875 | K2: TSMYM05 | L2: SS T-SHIRT MY MELODY TSMYM05:OFF WHITE:5-6:PRINT:SS T-SHIRT | M2: 129900 | N2: BXGY | O2: B1G2 | P2: BXGY
A3: =A2 -> 2024 JULY-DEC B1G2 | B3: =B2 -> 46086 | C3: =C2 -> 46092 | D3: 3321 | E3: 337 | F3: 4 | G3: 1 | H3: 81676 | I3: CHARACTER | J3: 20597893 | K3: TSMYM05 | L3: SS T-SHIRT MY MELODY TSMYM05:OFF WHITE:7-8:PRINT:SS T-SHIRT | M3: 129900 | N3: BXGY | O3: =O2 -> B1G2 | P3: BXGY
A4: =A3 -> 2024 JULY-DEC B1G2 | B4: =B3 -> 46086 | C4: =C3 -> 46092 | D4: 3321 | E4: 337 | F4: 4 | G4: 1 | H4: 81676 | I4: CHARACTER | J4: 20597900 | K4: TSMYM05 | L4: SS T-SHIRT MY MELODY TSMYM05:OFF WHITE:9-10:PRINT:SS T-SHIRT | M4: 129900 | N4: BXGY | O4: =O3 -> B1G2 | P4: BXGY
A5: =A4 -> 2024 JULY-DEC B1G2 | B5: =B4 -> 46086 | C5: =C4 -> 46092 | D5: 3321 | E5: 337 | F5: 4 | G5: 1 | H5: 81676 | I5: CHARACTER | J5: 20597937 | K5: TSMYM05 | L5: SS T-SHIRT MY MELODY TSMYM05:OFF WHITE:11-12:PRINT:SS T-SHIRT | M5: 129900 | N5: BXGY | O5: =O4 -> B1G2 | P5: BXGY
A6: =A5 -> 2024 JULY-DEC B1G2 | B6: =B5 -> 46086 | C6: =C5 -> 46092 | D6: 3321 | E6: 337 | F6: 4 | G6: 1 | H6: 81676 | I6: CHARACTER | J6: 20597955 | K6: TSMYM06 | L6: SS T-SHIRT MY MELODY TSMYM06:PASTEL BLUE:5-6:GRAPHIC:SS T-SHIRT | M6: 139900 | N6: BXGY | O6: =O5 -> B1G2 | P6: BXGY
A7: =A6 -> 2024 JULY-DEC B1G2 | B7: =B6 -> 46086 | C7: =C6 -> 46092 | D7: 3321 | E7: 337 | F7: 4 | G7: 1 | H7: 81676 | I7: CHARACTER | J7: 20597973 | K7: TSMYM06 | L7: SS T-SHIRT MY MELODY TSMYM06:PASTEL BLUE:7-8:GRAPHIC:SS T-SHIRT | M7: 139900 | N7: BXGY | O7: =O6 -> B1G2 | P7: BXGY
A8: =A7 -> 2024 JULY-DEC B1G2 | B8: =B7 -> 46086 | C8: =C7 -> 46092 | D8: 3321 | E8: 337 | F8: 4 | G8: 1 | H8: 81676 | I8: CHARACTER | J8: 20598007 | K8: TSMYM06 | L8: SS T-SHIRT MY MELODY TSMYM06:PASTEL BLUE:9-10:GRAPHIC:SS T-SHIRT | M8: 139900 | N8: BXGY | O8: =O7 -> B1G2 | P8: BXGY
A9: =A8 -> 2024 JULY-DEC B1G2 | B9: =B8 -> 46086 | C9: =C8 -> 46092 | D9: 3321 | E9: 337 | F9: 4 | G9: 1 | H9: 81676 | I9: CHARACTER | J9: 20598016 | K9: TSMYM06 | L9: SS T-SHIRT MY MELODY TSMYM06:PASTEL BLUE:11-12:GRAPHIC:SS T-SHIRT | M9: 139900 | N9: BXGY | O9: =O8 -> B1G2 | P9: BXGY
A10: =A9 -> 2024 JULY-DEC B1G2 | B10: =B9 -> 46086 | C10: =C9 -> 46092 | D10: 3321 | E10: 337 | F10: 4 | G10: 1 | H10: 81676 | I10: CHARACTER | J10: 21324854 | K10: TSGPPG1 | L10: SS T-SHIRT PPG LOVE TSGPPG1:OFF WHITE:5-6:GRAPHIC:SS T-SHIRT | M10: 129900 | N10: BXGY | O10: =O9 -> B1G2 | P10: BXGY
A11: =A10 -> 2024 JULY-DEC B1G2 | B11: =B10 -> 46086 | C11: =C10 -> 46092 | D11: 3321 | E11: 337 | F11: 4 | G11: 1 | H11: 81676 | I11: CHARACTER | J11: 21324989 | K11: TSGPPG1 | L11: SS T-SHIRT PPG LOVE TSGPPG1:OFF WHITE:7-8:GRAPHIC:SS T-SHIRT | M11: 129900 | N11: BXGY | O11: =O10 -> B1G2 | P11: BXGY
A12: =A11 -> 2024 JULY-DEC B1G2 | B12: =B11 -> 46086 | C12: =C11 -> 46092 | D12: 3321 | E12: 337 | F12: 4 | G12: 1 | H12: 81676 | I12: CHARACTER | J12: 21324998 | K12: TSGPPG1 | L12: SS T-SHIRT PPG LOVE TSGPPG1:OFF WHITE:9-10:GRAPHIC:SS T-SHIRT | M12: 129900 | N12: BXGY | O12: =O11 -> B1G2 | P12: BXGY
A13: =A12 -> 2024 JULY-DEC B1G2 | B13: =B12 -> 46086 | C13: =C12 -> 46092 | D13: 3321 | E13: 337 | F13: 4 | G13: 1 | H13: 81676 | I13: CHARACTER | J13: 21325004 | K13: TSGPPG1 | L13: SS T-SHIRT PPG LOVE TSGPPG1:OFF WHITE:11-12:GRAPHIC:SS T-SHIRT | M13: 129900 | N13: BXGY | O13: =O12 -> B1G2 | P13: BXGY
A14: =A13 -> 2024 JULY-DEC B1G2 | B14: =B13 -> 46086 | C14: =C13 -> 46092 | D14: 3321 | E14: 337 | F14: 4 | G14: 1 | H14: 81421 | I14: CHARACTER | J14: 20597615 | K14: SSKTMYM | L14: SS T-SHIRT TOP KOTAK MY MELODY SSKTMYM:PASTEL PINK:3-4:CHECKS:SS T-SHIRT | M14: 179900 | N14: BXGY | O14: =O13 -> B1G2 | P14: BXGY
... A108: =A107 -> 2024 JULY-DEC B1G2 | B108: =B107 -> 46086 | C108: =C107 -> 46092 | D108: 3321 | E108: 337 | F108: 4 | G108: 5 | H108: 81698 | I108: CHARACTER | J108: 23116754 | K108: DCOSKUR | L108: SS MIDI DRESS COSTUME KUROMI DCOSKUR:PASTEL PURPLE:7-8:GRAPHIC:SS MIDI DRESS | M108: 299900 | N108: BXGY | O108: =O107 -> B1G2 | P108: BXGY
A109: =A108 -> 2024 JULY-DEC B1G2 | B109: =B108 -> 46086 | C109: =C108 -> 46092 | D109: 3321 | E109: 337 | F109: 4 | G109: 1 | H109: 81462 | I109: CHARACTER | J109: 26741886 | K109: TSMMLP2 | L109: SS T-SHIRT LENGAN RUFFLE MY LITTLE PONY TSMMLP2:PASTEL PURPLE:5-6:GRAPHIC:SS T-SHIRT | M109: 139900 | N109: BXGY | O109: B1G2 | P109: BXGY
A110: =A109 -> 2024 JULY-DEC B1G2 | B110: =B109 -> 46086 | C110: =C109 -> 46092 | D110: 3321 | E110: 337 | F110: 4 | G110: 1 | H110: 81462 | I110: CHARACTER | J110: 26741895 | K110: TSMMLP2 | L110: SS T-SHIRT LENGAN RUFFLE MY LITTLE PONY TSMMLP2:PASTEL PURPLE:7-8:GRAPHIC:SS T-SHIRT | M110: 139900 | N110: BXGY | O110: =O109 -> B1G2 | P110: BXGY
A111: =A110 -> 2024 JULY-DEC B1G2 | B111: =B110 -> 46086 | C111: =C110 -> 46092 | D111: 3321 | E111: 337 | F111: 4 | G111: 1 | H111: 81462 | I111: CHARACTER | J111: 26741902 | K111: TSMMLP2 | L111: SS T-SHIRT LENGAN RUFFLE MY LITTLE PONY TSMMLP2:PASTEL PURPLE:9-10:GRAPHIC:SS T-SHIRT | M111: 139900 | N111: BXGY | O111: =O110 -> B1G2 | P111: BXGY
A112: =A111 -> 2024 JULY-DEC B1G2 | B112: =B111 -> 46086 | C112: =C111 -> 46092 | D112: 3321 | E112: 337 | F112: 4 | G112: 1 | H112: 81462 | I112: CHARACTER | J112: 26741911 | K112: TSMMLP2 | L112: SS T-SHIRT LENGAN RUFFLE MY LITTLE PONY TSMMLP2:PASTEL PURPLE:11-12:GRAPHIC:SS T-SHIRT | M112: 139900 | N112: BXGY | O112: =O111 -> B1G2 | P112: BXGY
A113: =A112 -> 2024 JULY-DEC B1G2 | B113: =B112 -> 46086 | C113: =C112 -> 46092 | D113: 3321 | E113: 337 | F113: 4 | G113: 3 | H113: 81005 | I113: CHARACTER | J113: 26741760 | K113: SWMM | L113: SWEATSHIRT PITA MY MELODY SWMM:PASTEL PINK:4-5:GRAPHIC:SWEATSHIRT | M113: 219900 | N113: BXGY | O113: =O112 -> B1G2 | P113: BXGY
A114: =A113 -> 2024 JULY-DEC B1G2 | B114: =B113 -> 46086 | C114: =C113 -> 46092 | D114: 3321 | E114: 337 | F114: 4 | G114: 3 | H114: 81005 | I114: CHARACTER | J114: 26741779 | K114: SWMM | L114: SWEATSHIRT PITA MY MELODY SWMM:PASTEL PINK:5-6:GRAPHIC:SWEATSHIRT | M114: 219900 | N114: BXGY | O114: =O113 -> B1G2 | P114: BXGY
A115: =A114 -> 2024 JULY-DEC B1G2 | B115: =B114 -> 46086 | C115: =C114 -> 46092 | D115: 3321 | E115: 337 | F115: 4 | G115: 3 | H115: 81005 | I115: CHARACTER | J115: 26741788 | K115: SWMM | L115: SWEATSHIRT PITA MY MELODY SWMM:PASTEL PINK:7-8:GRAPHIC:SWEATSHIRT | M115: 219900 | N115: BXGY | O115: =O114 -> B1G2 | P115: BXGY
A116: =A115 -> 2024 JULY-DEC B1G2 | B116: =B115 -> 46086 | C116: =C115 -> 46092 | D116: 3321 | E116: 337 | F116: 4 | G116: 3 | H116: 81005 | I116: CHARACTER | J116: 26741751 | K116: SWMM | L116: SWEATSHIRT PITA MY MELODY SWMM:PASTEL PINK:3-4:GRAPHIC:SWEATSHIRT | M116: 219900 | N116: BXGY | O116: =O115 -> B1G2 | P116: BXGY
A117: =A116 -> 2024 JULY-DEC B1G2 | B117: =B116 -> 46086 | C117: =C116 -> 46092 | D117: 3321 | E117: 337 | F117: 4 | G117: 3 | H117: 81005 | I117: CHARACTER | J117: 26741797 | K117: SWMM | L117: SWEATSHIRT PITA MY MELODY SWMM:PASTEL PINK:9-10:GRAPHIC:SWEATSHIRT | M117: 219900 | N117: BXGY | O117: =O116 -> B1G2 | P117: BXGY
A118: =A117 -> 2024 JULY-DEC B1G2 | B118: =B117 -> 46086 | C118: =C117 -> 46092 | D118: 3321 | E118: 337 | F118: 4 | G118: 5 | H118: 81421 | I118: CHARACTER | J118: 24392650 | K118: DSKUTL | L118: SS MIDI DRESS TULLE KERAH SLING BAG KUROMI DSKUTL:PASTEL PURPLE:3-4:GRAPHIC:SS MIDI DRESS | M118: 299900 | N118: BXGY | O118: =O117 -> B1G2 | P118: BXGY
A119: =A118 -> 2024 JULY-DEC B1G2 | B119: =B118 -> 46086 | C119: =C118 -> 46092 | D119: 3321 | E119: 337 | F119: 4 | G119: 5 | H119: 81421 | I119: CHARACTER | J119: 24392669 | K119: DSKUTL | L119: SS MIDI DRESS TULLE KERAH SLING BAG KUROMI DSKUTL:PASTEL PURPLE:4-5:GRAPHIC:SS MIDI DRESS | M119: 299900 | N119: BXGY | O119: =O118 -> B1G2 | P119: BXGY
A120: =A119 -> 2024 JULY-DEC B1G2 | B120: =B119 -> 46086 | C120: =C119 -> 46092 | D120: 3321 | E120: 337 | F120: 4 | G120: 5 | H120: 81421 | I120: CHARACTER | J120: 24392687 | K120: DSKUTL | L120: SS MIDI DRESS TULLE KERAH SLING BAG KUROMI DSKUTL:PASTEL PURPLE:7-8:GRAPHIC:SS MIDI DRESS | M120: 299900 | N120: BXGY | O120: =O119 -> B1G2 | P120: BXGY
A121: =A120 -> 2024 JULY-DEC B1G2 | B121: =B120 -> 46086 | C121: =C120 -> 46092 | D121: 3321 | E121: 337 | F121: 4 | G121: 5 | H121: 81421 | I121: CHARACTER | J121: 24392678 | K121: DSKUTL | L121: SS MIDI DRESS TULLE KERAH SLING BAG KUROMI DSKUTL:PASTEL PURPLE:5-6:GRAPHIC:SS MIDI DRESS | M121: 299900 | N121: BXGY | O121: =O120 -> B1G2 | P121: BXGY
... A244: =A243 -> 2024 JULY-DEC B1G2 | B244: =B243 -> 46086 | C244: =C243 -> 46092 | D244: 3321 | E244: 337 | F244: 4 | G244: 5 | H244: 81698 | I244: CHARACTER | J244: 26742198 | K244: DSTLMM | L244: SS MIDI DRESS MELODY W 3D FLOWER DSTLMM:PASTEL PINK:4-5:GRAPHIC:SS MIDI DRESS | M244: 319900 | N244: BXGY | O244: =O243 -> B1G2 | P244: BXGY

Sheet 2024 JAN-JUN D70 - 3321
A1: ACARA | B1: FROM DATE | C1: TO DATE | D1: DEPT | E1: WORLD | F1: DIVISION | G1: CLASS | H1: SUPPLIER | I1: BRAND | J1: SKU | K1: ARTICLE | L1: DESCRIPTION | M1: HARGA NORMAL | N1: DISKON | O1: HARGA PROMO | P1: DISCOUNT TYPE
A2: 2024 JAN-JUN DISC 70% | B2: ='2025 AUG B1G1-3321'!B87 -> 46086 | C2: ='2025 AUG B1G1-3321'!C87 -> 46092 | D2: 3321 | E2: 337 | F2: 4 | G2: 1 | H2: 81421 | I2: CHARACTER | J2: 15928526 | K2: TSPPG44 | L2: SS T-SHIRT PPG KERAH TSPPG44:PASTEL PINK:5-6:GRAPHIC:SS T-SHIRT | M2: 159900 | N2: 0.7 | O2: =M2-((70*M2))/100 -> 47970 | P2: PERCENTAGE
A3: =A2 -> 2024 JAN-JUN DISC 70% | B3: =B2 -> 46086 | C3: =C2 -> 46092 | D3: 3321 | E3: 337 | F3: 4 | G3: 1 | H3: 81421 | I3: CHARACTER | J3: 15928535 | K3: TSPPG44 | L3: SS T-SHIRT PPG KERAH TSPPG44:PASTEL PINK:7-8:GRAPHIC:SS T-SHIRT | M3: 159900 | N3: =N2 -> 0.7 | O3: =M3-((70*M3))/100 -> 47970 | P3: PERCENTAGE
A4: =A3 -> 2024 JAN-JUN DISC 70% | B4: =B3 -> 46086 | C4: =C3 -> 46092 | D4: 3321 | E4: 337 | F4: 4 | G4: 1 | H4: 81421 | I4: CHARACTER | J4: 15928553 | K4: TSPPG44 | L4: SS T-SHIRT PPG KERAH TSPPG44:PASTEL PINK:11-12:GRAPHIC:SS T-SHIRT | M4: 159900 | N4: =N3 -> 0.7 | O4: =M4-((70*M4))/100 -> 47970 | P4: PERCENTAGE
A5: =A4 -> 2024 JAN-JUN DISC 70% | B5: =B4 -> 46086 | C5: =C4 -> 46092 | D5: 3321 | E5: 337 | F5: 4 | G5: 1 | H5: 81421 | I5: CHARACTER | J5: 15928562 | K5: TSPPG41 | L5: SS T-SHIRT PPG OMBRE LENGAN RUFFLE TSPPG41:PASTEL PINK:5-6:GRAPHIC:SS T-SHIRT | M5: 149900 | N5: =N4 -> 0.7 | O5: =M5-((70*M5))/100 -> 44970 | P5: PERCENTAGE
A6: =A5 -> 2024 JAN-JUN DISC 70% | B6: =B5 -> 46086 | C6: =C5 -> 46092 | D6: 3321 | E6: 337 | F6: 4 | G6: 1 | H6: 81421 | I6: CHARACTER | J6: 15928571 | K6: TSPPG41 | L6: SS T-SHIRT PPG OMBRE LENGAN RUFFLE TSPPG41:PASTEL PINK:7-8:GRAPHIC:SS T-SHIRT | M6: 149900 | N6: =N5 -> 0.7 | O6: =M6-((70*M6))/100 -> 44970 | P6: PERCENTAGE
A7: =A6 -> 2024 JAN-JUN DISC 70% | B7: =B6 -> 46086 | C7: =C6 -> 46092 | D7: 3321 | E7: 337 | F7: 4 | G7: 1 | H7: 81421 | I7: CHARACTER | J7: 15928580 | K7: TSPPG41 | L7: SS T-SHIRT PPG OMBRE LENGAN RUFFLE TSPPG41:PASTEL PINK:9-10:GRAPHIC:SS T-SHIRT | M7: 149900 | N7: =N6 -> 0.7 | O7: =M7-((70*M7))/100 -> 44970 | P7: PERCENTAGE
A8: =A7 -> 2024 JAN-JUN DISC 70% | B8: =B7 -> 46086 | C8: =C7 -> 46092 | D8: 3321 | E8: 337 | F8: 4 | G8: 1 | H8: 81421 | I8: CHARACTER | J8: 15928599 | K8: TSPPG41 | L8: SS T-SHIRT PPG OMBRE LENGAN RUFFLE TSPPG41:PASTEL PINK:11-12:GRAPHIC:SS T-SHIRT | M8: 149900 | N8: =N7 -> 0.7 | O8: =M8-((70*M8))/100 -> 44970 | P8: PERCENTAGE
A9: =A8 -> 2024 JAN-JUN DISC 70% | B9: =B8 -> 46086 | C9: =C8 -> 46092 | D9: 3321 | E9: 337 | F9: 4 | G9: 1 | H9: 81421 | I9: CHARACTER | J9: 15928606 | K9: TSPPG42 | L9: SS T-SHIRT PPG LENGAN SERUT TSPPG42:PASTEL BLUE:5-6:GRAPHIC:SS T-SHIRT | M9: 149900 | N9: =N8 -> 0.7 | O9: =M9-((70*M9))/100 -> 44970 | P9: PERCENTAGE
A10: =A9 -> 2024 JAN-JUN DISC 70% | B10: =B9 -> 46086 | C10: =C9 -> 46092 | D10: 3321 | E10: 337 | F10: 4 | G10: 1 | H10: 81421 | I10: CHARACTER | J10: 15928615 | K10: TSPPG42 | L10: SS T-SHIRT PPG LENGAN SERUT TSPPG42:PASTEL BLUE:7-8:GRAPHIC:SS T-SHIRT | M10: 149900 | N10: =N9 -> 0.7 | O10: =M10-((70*M10))/100 -> 44970 | P10: PERCENTAGE
A11: =A10 -> 2024 JAN-JUN DISC 70% | B11: =B10 -> 46086 | C11: =C10 -> 46092 | D11: 3321 | E11: 337 | F11: 4 | G11: 1 | H11: 81421 | I11: CHARACTER | J11: 15928624 | K11: TSPPG42 | L11: SS T-SHIRT PPG LENGAN SERUT TSPPG42:PASTEL BLUE:9-10:GRAPHIC:SS T-SHIRT | M11: 149900 | N11: =N10 -> 0.7 | O11: =M11-((70*M11))/100 -> 44970 | P11: PERCENTAGE
A12: =A11 -> 2024 JAN-JUN DISC 70% | B12: =B11 -> 46086 | C12: =C11 -> 46092 | D12: 3321 | E12: 337 | F12: 4 | G12: 1 | H12: 81421 | I12: CHARACTER | J12: 15928633 | K12: TSPPG42 | L12: SS T-SHIRT PPG LENGAN SERUT TSPPG42:PASTEL BLUE:11-12:GRAPHIC:SS T-SHIRT | M12: 149900 | N12: =N11 -> 0.7 | O12: =M12-((70*M12))/100 -> 44970 | P12: PERCENTAGE
A13: =A12 -> 2024 JAN-JUN DISC 70% | B13: =B12 -> 46086 | C13: =C12 -> 46092 | D13: 3321 | E13: 337 | F13: 4 | G13: 1 | H13: 81421 | I13: CHARACTER | J13: 16130706 | K13: TSHK1 | L13: SS T-SHIRT FP BBTR HELLO KITTY W BAG TSHK1:CLASSIC RED:3-4:PRINT:SS T-SHIRT | M13: 179900 | N13: =N12 -> 0.7 | O13: =M13-((70*M13))/100 -> 53970 | P13: PERCENTAGE
A14: =A13 -> 2024 JAN-JUN DISC 70% | B14: =B13 -> 46086 | C14: =C13 -> 46092 | D14: 3321 | E14: 337 | F14: 4 | G14: 1 | H14: 81421 | I14: CHARACTER | J14: 16130715 | K14: TSHK1 | L14: SS T-SHIRT FP BBTR HELLO KITTY W BAG TSHK1:CLASSIC RED:4-5:PRINT:SS T-SHIRT | M14: 179900 | N14: =N13 -> 0.7 | O14: =M14-((70*M14))/100 -> 53970 | P14: PERCENTAGE
... A269: =A268 -> 2024 JAN-JUN DISC 70% | B269: =B268 -> 46086 | C269: =C268 -> 46092 | D269: 3321 | E269: 337 | F269: 4 | G269: 1 | H269: 81048 | I269: CHARACTER | J269: 18769069 | K269: TS50HK3 | L269: SS T-SHIRT RIB HELLO KITTY 50 TS50HK3:OFF WHITE:11-12:GRAPHIC:SS T-SHIRT | M269: 149900 | N269: =N268 -> 0.7 | O269: =M269-((70*M269))/100 -> 44970 | P269: PERCENTAGE

Sheet 2025 JUN B1G1 - 3321
A1: ACARA | B1: FROM DATE | C1: TO DATE | D1: DEPT | E1: WORLD | F1: DIVISION | G1: CLASS | H1: SUPPLIER | I1: BRAND | J1: SKU | K1: ARTICLE | L1: DESCRIPTION | M1: HARGA NORMAL | N1: DISKON | O1: HARGA PROMO | P1: DISCOUNT TYPE
A2: 2025 JUN B1G1 | B2: ='2025 AUG B1G1-3321'!B87 -> 46086 | C2: ='2025 AUG B1G1-3321'!C87 -> 46092 | D2: 3321 | E2: 337 | F2: 4 | G2: 1 | H2: 81676 | I2: CHARACTER | J2: 54462474 | K2: TSGGHK2 | L2: SS T-SHIRT TD HELLO KITTY TSGGHK2:OFF WHITE:3-4:GRAPHIC:SS T-SHIRT | M2: 149900 | N2: BXGY | O2: B1G1 | P2: BXGY
A3: 2025 JUN B1G1 | B3: =B2 -> 46086 | C3: =C2 -> 46092 | D3: 3321 | E3: 337 | F3: 4 | G3: 1 | H3: 81676 | I3: CHARACTER | J3: 54462483 | K3: TSGGHK2 | L3: SS T-SHIRT TD HELLO KITTY TSGGHK2:OFF WHITE:4-5:GRAPHIC:SS T-SHIRT | M3: 149900 | N3: BXGY | O3: B1G1 | P3: BXGY
A4: 2025 JUN B1G1 | B4: =B3 -> 46086 | C4: =C3 -> 46092 | D4: 3321 | E4: 337 | F4: 4 | G4: 1 | H4: 81676 | I4: CHARACTER | J4: 54462492 | K4: TSGGHK2 | L4: SS T-SHIRT TD HELLO KITTY TSGGHK2:OFF WHITE:5-6:GRAPHIC:SS T-SHIRT | M4: 149900 | N4: BXGY | O4: B1G1 | P4: BXGY
A5: 2025 JUN B1G1 | B5: =B4 -> 46086 | C5: =C4 -> 46092 | D5: 3321 | E5: 337 | F5: 4 | G5: 1 | H5: 81676 | I5: CHARACTER | J5: 54462509 | K5: TSGGHK2 | L5: SS T-SHIRT TD HELLO KITTY TSGGHK2:OFF WHITE:7-8:GRAPHIC:SS T-SHIRT | M5: 149900 | N5: BXGY | O5: B1G1 | P5: BXGY
A6: 2025 JUN B1G1 | B6: =B5 -> 46086 | C6: =C5 -> 46092 | D6: 3321 | E6: 337 | F6: 4 | G6: 1 | H6: 81676 | I6: CHARACTER | J6: 54462518 | K6: TSGGHK2 | L6: SS T-SHIRT TD HELLO KITTY TSGGHK2:OFF WHITE:9-10:GRAPHIC:SS T-SHIRT | M6: 149900 | N6: BXGY | O6: B1G1 | P6: BXGY
A7: 2025 JUN B1G1 | B7: =B6 -> 46086 | C7: =C6 -> 46092 | D7: 3321 | E7: 337 | F7: 4 | G7: 1 | H7: 81676 | I7: CHARACTER | J7: 54462527 | K7: TSGGHK2 | L7: SS T-SHIRT TD HELLO KITTY TSGGHK2:OFF WHITE:11-12:GRAPHIC:SS T-SHIRT | M7: 149900 | N7: BXGY | O7: B1G1 | P7: BXGY
A8: 2025 JUN B1G1 | B8: =B7 -> 46086 | C8: =C7 -> 46092 | D8: 3321 | E8: 337 | F8: 4 | G8: 1 | H8: 81676 | I8: CHARACTER | J8: 54462410 | K8: TSGGHK1 | L8: SS T-SHIRT KTG HELLO KITTY TSGGHK1:PASTEL PINK:3-4:GRAPHIC:SS T-SHIRT | M8: 149900 | N8: BXGY | O8: B1G1 | P8: BXGY
A9: 2025 JUN B1G1 | B9: =B8 -> 46086 | C9: =C8 -> 46092 | D9: 3321 | E9: 337 | F9: 4 | G9: 1 | H9: 81676 | I9: CHARACTER | J9: 54462429 | K9: TSGGHK1 | L9: SS T-SHIRT KTG HELLO KITTY TSGGHK1:PASTEL PINK:4-5:GRAPHIC:SS T-SHIRT | M9: 149900 | N9: BXGY | O9: B1G1 | P9: BXGY
A10: 2025 JUN B1G1 | B10: =B9 -> 46086 | C10: =C9 -> 46092 | D10: 3321 | E10: 337 | F10: 4 | G10: 1 | H10: 81676 | I10: CHARACTER | J10: 54462438 | K10: TSGGHK1 | L10: SS T-SHIRT KTG HELLO KITTY TSGGHK1:PASTEL PINK:5-6:GRAPHIC:SS T-SHIRT | M10: 149900 | N10: BXGY | O10: B1G1 | P10: BXGY
A11: 2025 JUN B1G1 | B11: =B10 -> 46086 | C11: =C10 -> 46092 | D11: 3321 | E11: 337 | F11: 4 | G11: 1 | H11: 81676 | I11: CHARACTER | J11: 54462447 | K11: TSGGHK1 | L11: SS T-SHIRT KTG HELLO KITTY TSGGHK1:PASTEL PINK:7-8:GRAPHIC:SS T-SHIRT | M11: 149900 | N11: BXGY | O11: B1G1 | P11: BXGY
A12: 2025 JUN B1G1 | B12: =B11 -> 46086 | C12: =C11 -> 46092 | D12: 3321 | E12: 337 | F12: 4 | G12: 1 | H12: 81676 | I12: CHARACTER | J12: 54462456 | K12: TSGGHK1 | L12: SS T-SHIRT KTG HELLO KITTY TSGGHK1:PASTEL PINK:9-10:GRAPHIC:SS T-SHIRT | M12: 149900 | N12: BXGY | O12: B1G1 | P12: BXGY
A13: 2025 JUN B1G1 | B13: =B12 -> 46086 | C13: =C12 -> 46092 | D13: 3321 | E13: 337 | F13: 4 | G13: 1 | H13: 81676 | I13: CHARACTER | J13: 54462465 | K13: TSGGHK1 | L13: SS T-SHIRT KTG HELLO KITTY TSGGHK1:PASTEL PINK:11-12:GRAPHIC:SS T-SHIRT | M13: 149900 | N13: BXGY | O13: B1G1 | P13: BXGY
A14: 2025 JUN B1G1 | B14: =B13 -> 46086 | C14: =C13 -> 46092 | D14: 3321 | E14: 337 | F14: 4 | G14: 3 | H14: 81005 | I14: CHARACTER | J14: 54391176 | K14: SWKRMM | L14: SWEATSHIRT COLLAR RETS MY MELODY SWKRMM:PASTEL PINK:3-4:GRAPHIC:SWEATSHIRT | M14: 229900 | N14: BXGY | O14: B1G1 | P14: BXGY
... A33: 2025 JUN B1G1 | B33: =B32 -> 46086 | C33: =C32 -> 46092 | D33: 3321 | E33: 337 | F33: 4 | G33: 1 | H33: 81462 | I33: CHARACTER | J33: 54462401 | K33: TS254MM | L33: SS T-SHIRT MY MELODY TS254MM:PASTEL PINK:7-8:GRAPHIC:SS T-SHIRT | M33: 119900 | N33: BXGY | O33: B1G1 | P33: BXGY

Sheet 2025 JAN-MEI B1G2 - 3321
A1: ACARA | B1: FROM DATE | C1: TO DATE | D1: DEPT | E1: WORLD | F1: DIVISION | G1: CLASS | H1: SUPPLIER | I1: BRAND | J1: SKU | K1: ARTICLE | L1: DESCRIPTION | M1: HARGA NORMAL | N1: DISKON | O1: HARGA PROMO | P1: DISCOUNT TYPE
A2: 2025 JAN-MEI B1G2 | B2: ='2025 AUG B1G1-3321'!B87 -> 46086 | C2: ='2025 AUG B1G1-3321'!C87 -> 46092 | D2: 3321 | E2: 337 | F2: 4 | G2: 4 | H2: 81588 | I2: CHARACTER | J2: 51607135 | K2: SKKU | L2: SKORT PARASUT KUROMI SKKU:BLACK:3-4:GRAPHIC:SKORT | M2: 199900 | N2: BXGY | O2: B1G2 | P2: BXGY
A3: 2025 JAN-MEI B1G2 | B3: =B2 -> 46086 | C3: =C2 -> 46092 | D3: 3321 | E3: 337 | F3: 4 | G3: 4 | H3: 81588 | I3: CHARACTER | J3: 51607144 | K3: SKKU | L3: SKORT PARASUT KUROMI SKKU:BLACK:4-5:GRAPHIC:SKORT | M3: 199900 | N3: BXGY | O3: B1G2 | P3: BXGY
A4: 2025 JAN-MEI B1G2 | B4: =B3 -> 46086 | C4: =C3 -> 46092 | D4: 3321 | E4: 337 | F4: 4 | G4: 4 | H4: 81588 | I4: CHARACTER | J4: 51607153 | K4: SKKU | L4: SKORT PARASUT KUROMI SKKU:BLACK:5-6:GRAPHIC:SKORT | M4: 199900 | N4: BXGY | O4: B1G2 | P4: BXGY
A5: 2025 JAN-MEI B1G2 | B5: =B4 -> 46086 | C5: =C4 -> 46092 | D5: 3321 | E5: 337 | F5: 4 | G5: 4 | H5: 81588 | I5: CHARACTER | J5: 51607162 | K5: SKKU | L5: SKORT PARASUT KUROMI SKKU:BLACK:7-8:GRAPHIC:SKORT | M5: 199900 | N5: BXGY | O5: B1G2 | P5: BXGY
A6: 2025 JAN-MEI B1G2 | B6: =B5 -> 46086 | C6: =C5 -> 46092 | D6: 3321 | E6: 337 | F6: 4 | G6: 4 | H6: 81588 | I6: CHARACTER | J6: 51837191 | K6: SKKU | L6: SKORT PARASUT KUROMI SKKU:BLACK:9-10:GRAPHIC:SKORT | M6: 199900 | N6: BXGY | O6: B1G2 | P6: BXGY
A7: 2025 JAN-MEI B1G2 | B7: =B6 -> 46086 | C7: =C6 -> 46092 | D7: 3321 | E7: 337 | F7: 4 | G7: 4 | H7: 81588 | I7: CHARACTER | J7: 51837208 | K7: SKKU | L7: SKORT PARASUT KUROMI SKKU:BLACK:11-12:GRAPHIC:SKORT | M7: 199900 | N7: BXGY | O7: B1G2 | P7: BXGY
A8: 2025 JAN-MEI B1G2 | B8: =B7 -> 46086 | C8: =C7 -> 46092 | D8: 3321 | E8: 337 | F8: 4 | G8: 5 | H8: 190 | I8: CHARACTER | J8: 51607019 | K8: DSOARMM | L8: SS MIDI DRESS OVERALL MY MELODY DSOARMM:PASTEL GREEN:3-4:GRAPHIC:SS MIDI DRESS | M8: 259900 | N8: BXGY | O8: B1G2 | P8: BXGY
A9: 2025 JAN-MEI B1G2 | B9: =B8 -> 46086 | C9: =C8 -> 46092 | D9: 3321 | E9: 337 | F9: 4 | G9: 5 | H9: 190 | I9: CHARACTER | J9: 51607028 | K9: DSOARMM | L9: SS MIDI DRESS OVERALL MY MELODY DSOARMM:PASTEL GREEN:4-5:GRAPHIC:SS MIDI DRESS | M9: 259900 | N9: BXGY | O9: B1G2 | P9: BXGY
A10: 2025 JAN-MEI B1G2 | B10: =B9 -> 46086 | C10: =C9 -> 46092 | D10: 3321 | E10: 337 | F10: 4 | G10: 5 | H10: 190 | I10: CHARACTER | J10: 51607037 | K10: DSOARMM | L10: SS MIDI DRESS OVERALL MY MELODY DSOARMM:PASTEL GREEN:5-6:GRAPHIC:SS MIDI DRESS | M10: 259900 | N10: BXGY | O10: B1G2 | P10: BXGY
A11: 2025 JAN-MEI B1G2 | B11: =B10 -> 46086 | C11: =C10 -> 46092 | D11: 3321 | E11: 337 | F11: 4 | G11: 5 | H11: 190 | I11: CHARACTER | J11: 51607046 | K11: DSOARMM | L11: SS MIDI DRESS OVERALL MY MELODY DSOARMM:PASTEL GREEN:7-8:GRAPHIC:SS MIDI DRESS | M11: 259900 | N11: BXGY | O11: B1G2 | P11: BXGY
A12: 2025 JAN-MEI B1G2 | B12: =B11 -> 46086 | C12: =C11 -> 46092 | D12: 3321 | E12: 337 | F12: 4 | G12: 5 | H12: 190 | I12: CHARACTER | J12: 51607055 | K12: DSPTMM | L12: SS MIDI DRESS MY MELODY DSPTMM:PASTEL PINK:3-4:GRAPHIC:SS MIDI DRESS | M12: 259900 | N12: BXGY | O12: B1G2 | P12: BXGY
A13: 2025 JAN-MEI B1G2 | B13: =B12 -> 46086 | C13: =C12 -> 46092 | D13: 3321 | E13: 337 | F13: 4 | G13: 5 | H13: 190 | I13: CHARACTER | J13: 51607064 | K13: DSPTMM | L13: SS MIDI DRESS MY MELODY DSPTMM:PASTEL PINK:4-5:GRAPHIC:SS MIDI DRESS | M13: 259900 | N13: BXGY | O13: B1G2 | P13: BXGY
A14: 2025 JAN-MEI B1G2 | B14: =B13 -> 46086 | C14: =C13 -> 46092 | D14: 3321 | E14: 337 | F14: 4 | G14: 5 | H14: 190 | I14: CHARACTER | J14: 51607073 | K14: DSPTMM | L14: SS MIDI DRESS MY MELODY DSPTMM:PASTEL PINK:5-6:GRAPHIC:SS MIDI DRESS | M14: 259900 | N14: BXGY | O14: B1G2 | P14: BXGY
... A176: 2025 JAN-MEI B1G2 | B176: =B175 -> 46086 | C176: =C175 -> 46092 | D176: 3321 | E176: 337 | F176: 4 | G176: 4 | H176: 81005 | I176: CHARACTER | J176: 54391247 | K176: SKBMM | L176: MINI SKIRT BALON MY MELODY SKBMM:PASTEL PINK:7-8:PRINT:MINI SKIRT | M176: 199900 | N176: BXGY | O176: B1G2 | P176: BXGY

Sheet 2023 JUN-DEC D90 - 3321
A1: ACARA | B1: FROM DATE | C1: TO DATE | D1: DEPT | E1: WORLD | F1: DIVISION | G1: CLASS | H1: SUPPLIER | I1: BRAND | J1: SKU | K1: ARTICLE | L1: DESCRIPTION | M1: HARGA NORMAL | N1: DISKON | O1: HARGA PROMO | P1: DISCOUNT TYPE
A2: 2023 JUN-DEC DISC 90 | B2: ='2025 HILITE D80 - 3321'!B2 -> 46086 | C2: ='2025 HILITE D80 - 3321'!C2 -> 46092 | D2: 3321 | E2: 337 | F2: 4 | G2: 1 | H2: 81421 | I2: CHARACTER GIRL | J2: 14608392 | K2: TSPPG4 | L2: SS T-SHIRT PPG GIRLS LENGAN KERUT TSPPG4:PASTEL PURPLE:5-6:GRAPHIC:SS T-SHIRT | M2: 149900 | N2: 0.9 | O2: =M2-((90*M2)/100) -> 14990 | P2: PERCENTAGE
A3: 2023 JUN-DEC DISC 90 | B3: =B2 -> 46086 | C3: =C2 -> 46092 | D3: 3321 | E3: 337 | F3: 4 | G3: 1 | H3: 81421 | I3: CHARACTER GIRL | J3: 14608418 | K3: TSPPG4 | L3: SS T-SHIRT PPG GIRLS LENGAN KERUT TSPPG4:PASTEL PURPLE:9-10:GRAPHIC:SS T-SHIRT | M3: 149900 | N3: 0.9 | O3: =M3-((90*M3)/100) -> 14990 | P3: PERCENTAGE
A4: 2023 JUN-DEC DISC 90 | B4: =B3 -> 46086 | C4: =C3 -> 46092 | D4: 3321 | E4: 337 | F4: 4 | G4: 1 | H4: 81421 | I4: CHARACTER GIRL | J4: 14608427 | K4: TSPPG4 | L4: SS T-SHIRT PPG GIRLS LENGAN KERUT TSPPG4:PASTEL PURPLE:11-12:GRAPHIC:SS T-SHIRT | M4: 149900 | N4: 0.9 | O4: =M4-((90*M4)/100) -> 14990 | P4: PERCENTAGE
A5: 2023 JUN-DEC DISC 90 | B5: =B4 -> 46086 | C5: =C4 -> 46092 | D5: 3321 | E5: 337 | F5: 4 | G5: 1 | H5: 81421 | I5: CHARACTER GIRL | J5: 14608436 | K5: TSPPG5 | L5: SS T-SHIRT PPG 25 CUT AND SEWN TSPPG5:PASTEL PINK:5-6:GRAPHIC:SS T-SHIRT | M5: 149900 | N5: 0.9 | O5: =M5-((90*M5)/100) -> 14990 | P5: PERCENTAGE
A6: 2023 JUN-DEC DISC 90 | B6: =B5 -> 46086 | C6: =C5 -> 46092 | D6: 3321 | E6: 337 | F6: 4 | G6: 1 | H6: 81421 | I6: CHARACTER GIRL | J6: 14608445 | K6: TSPPG5 | L6: SS T-SHIRT PPG 25 CUT AND SEWN TSPPG5:PASTEL PINK:7-8:GRAPHIC:SS T-SHIRT | M6: 149900 | N6: 0.9 | O6: =M6-((90*M6)/100) -> 14990 | P6: PERCENTAGE
A7: 2023 JUN-DEC DISC 90 | B7: =B6 -> 46086 | C7: =C6 -> 46092 | D7: 3321 | E7: 337 | F7: 4 | G7: 1 | H7: 81421 | I7: CHARACTER GIRL | J7: 14608454 | K7: TSPPG5 | L7: SS T-SHIRT PPG 25 CUT AND SEWN TSPPG5:PASTEL PINK:9-10:GRAPHIC:SS T-SHIRT | M7: 149900 | N7: 0.9 | O7: =M7-((90*M7)/100) -> 14990 | P7: PERCENTAGE
